Workbook
Name Analysis: Analysis!$B$8
Name BS: Statements!$B$57
Name CF: Statements!$B$101
Name days: Dashboard!$G$18
Name Debt: Schedule!$B$78
Name EF: Scenario!$B$51
Name IS: Statements!$B$17
Name PPE: Schedule!$B$13
Name RE: Schedule!$B$107
Name RF: Scenario!$B$13
Name tax_rate: FCFF!$E$14
Name Terminal_rate: FCFF!$E$13
Name WACC: FCFF!$E$12
Name WC: Schedule!$B$42

Sheet Dashboard
B2: Apple, Inc.
B3: Dashboard
B4: (In millions, except number of shares, which are reflected in thousands, and per-share amounts)
B7: Model Assumption | F7: Units:
B9: Company Name | G9: =B2 -> Apple, Inc.
B10: Ticker | G10: AAPL
B11: Last Historical | F11: Date | G11: =Statements!J7 -> 45961
B13: Selected Scenario | G13: Street
B15: Model Start Date | F15: Date | G15: =Statements!J7 -> 45961
B16: Model End Date | F16: Date | G16: =Statements!O7 -> 47787
B17: No. of Years Projected | F17: Years | G17: =YEARFRAC(G15,G16,1) -> 5.0004564
B18: Days in an Year | F18: Days | G18: 365
B21: Table of Contents
B22: Sl.No | C22: Particulars
B23: 1 | C23: Dashboard
B24: 2 | C24: Equity Report
B25: 3 | C25: Financials
B26: 4 | C26: Statements
B27: 5 | C27: Scenario
B28: 6 | C28: Assumptions
B29: 7 | C29: Schedule
B30: 8 | C30: Valuation | G30: Cell Reference
B31: 9 | C31: Beta
B32: 10 | C32: WACC | G32: Hardcode | H32: Caution
B33: 11 | C33: FCFF | G33: Calculation | H33: Assumptions
B34: 12 | C34: Ratio Analysis | G34: Reference | H34: Notes
B35: 13 | C35: Analysis | G35: (Except for dashboard)

Sheet Report
B2: =Dashboard!B2&" - Equity Research Report" -> Apple, Inc. - Equity Research Report
B4: Apple, Inc | C4: USA | Technology | Technology Equipment
B5: Company Overview | Q5: 24 | R5: 25 | S5: 26 | T5: 27
B6: Apple Inc. (Apple) designs, manufactures, and markets smartphones, personal computers, tablets, wearables, and and accessories and sells a | P6: Market Cap | Q6: =Statements!I47*Statements!I51 -> 93681.218 | R6: =Statements!J47*Statements!J51 -> 111935.04 | S6: =Statements!K47*Statements!K51 -> 101530.46 | T6: =Statements!L47*Statements!L51 -> 114881.8
B7: range of related services. The company’s products include iPhone (50% of FY25 revenue), Mac (8%), iPad (7%), wearables, home, and | P7: Cash | Q7: =Statements!I61 -> 29943 | R7: =Statements!J61 -> 35934 | S7: =Statements!K61 -> 50346.589 | T7: =Statements!L61 -> 39765.201
B8: accessories (9%) like AirPods, Apple TV, Apple Watch, HomePod, and an online services business (26%). | P8: Debt | Q8: =Statements!I82+Statements!I86 -> 96662 | R8: =Statements!J82+Statements!J86 -> 90678 | S8: =Statements!K82+Statements!K86 -> 78285 | T8: =Statements!L82+Statements!L86 -> 68207
P9: EV | Q9: =Q6+Q8-Q7 -> 160400.22 | R9: =R6+R8-R7 -> 166679.04 | S9: =S6+S8-S7 -> 129468.87 | T9: =T6+T8-T7 -> 143323.6
B10: Financial Summary | D10: =Statements!I7 -> 45596 | E10: =Statements!J7 -> 45961 | F10: =Statements!K7 -> 46326 | G10: =Statements!L7 -> 46691 | I10: Key Financial Data
B11: (USD 'Millions)
B12: Sales | D12: =Statements!I22 -> 391035 | E12: =Statements!J22 -> 416161 | F12: =Statements!K22 -> 443442.18 | G12: =Statements!L22 -> 473669.4 | I12: Ticker: | L12: AAPL
B13: Sales Growth (YoY %) | D13: =Scenario!I48 -> 0.020219941 | E13: =Scenario!J48 -> 0.064255118 | F13: =Scenario!K48 -> 0.065554398 | G13: =Scenario!L48 -> 0.068164943 | I13: Sector: | L13: Technology
B14: Gross Profit Margins (%) | D14: ='Ratio Analysis'!F19 -> 0.4620635 | E14: ='Ratio Analysis'!G19 -> 0.46905164 | F14: ='Ratio Analysis'!H19 -> 0.47561943 | G14: ='Ratio Analysis'!I19 -> 0.49017946 | L14: Technology Equipment
B15: EBITDA Margins (%) | D15: =Statements!I54 -> 0.34437071 | E15: =Statements!J54 -> 0.34781731 | F15: =Statements!K54 -> 0.37274545 | G15: =Statements!L54 -> 0.35715955 | I15: Rating: | L15: Overvalued
B16: EBIT Margins (%) | D16: ='Ratio Analysis'!F20 -> 0.31510223 | E16: ='Ratio Analysis'!G20 -> 0.319708 | F16: ='Ratio Analysis'!H20 -> 0.32398431 | G16: ='Ratio Analysis'!I20 -> 0.33751847
B17: Net Profit Margins (%) | D17: ='Ratio Analysis'!F22 -> 0.23971256 | E17: ='Ratio Analysis'!G22 -> 0.26915064 | F17: ='Ratio Analysis'!H22 -> 0.26561469 | G17: ='Ratio Analysis'!I22 -> 0.27829699 | I17: Market Cap (USDb): | L17: =L18*L20 -> 4009935
B18: EPS (in $) | D18: ='Ratio Analysis'!F36 -> 6.11 | E18: ='Ratio Analysis'!G36 -> 7.49 | F18: ='Ratio Analysis'!H36 -> 6.7920167 | G18: ='Ratio Analysis'!I36 -> 7.6851724 | I18: Share Price (USD): | L18: =FCFF!I11 -> 271.86
B19: EPS Growth (YoY %) | D19: ='Ratio Analysis'!F36/'Ratio Analysis'!E36-1 -> -0.0081168831 | E19: ='Ratio Analysis'!G36/'Ratio Analysis'!F36-1 -> 0.22585925 | F19: ='Ratio Analysis'!H36/'Ratio Analysis'!G36-1 -> -0.093188691 | G19: ='Ratio Analysis'!I36/'Ratio Analysis'!H36-1 -> 0.13150081 | I19: Implied Price (USD): | L19: =FCFF!I10 -> 173.91744
B20: Dividend Per Share (YoY %) | D20: ='Ratio Analysis'!F37 -> 0.99180235 | E20: ='Ratio Analysis'!G37 -> 1.0310734 | F20: ='Ratio Analysis'!H37 -> 1.087353 | G20: ='Ratio Analysis'!I37 -> 1.1331551 | I20: Volume (m.Share): | L20: =FCFF!E36 -> 14750
B21: DPS Growth (YoY %) | D21: ='Ratio Analysis'!F37/'Ratio Analysis'!E37-1 -> 0.041288695 | E21: ='Ratio Analysis'!G37/'Ratio Analysis'!F37-1 -> 0.039595595 | F21: ='Ratio Analysis'!H37/'Ratio Analysis'!G37-1 -> 0.054583576 | G21: ='Ratio Analysis'!I37/'Ratio Analysis'!H37-1 -> 0.042122526 | I21: Debt / Equity (x): | L21: =(Statements!J82+Statements!J86)/Statements!J95 -> 1.2298157
B23: Key Financial Ratios | D23: =D10 -> 45596 | E23: =E10 -> 45961 | F23: =F10 -> 46326 | G23: =G10 -> 46691 | I23: Share Price - (5M)
B24: EV/EBITDA (x) | D24: =Q9/'Ratio Analysis'!F13 -> 1.1911408 | E24: =R9/'Ratio Analysis'!G13 -> 1.1515119 | F24: =S9/'Ratio Analysis'!H13 -> 0.78327815 | G24: =T9/'Ratio Analysis'!I13 -> 0.84718862
B25: EV/Sales (x) | D25: =Q9/D12 -> 0.41019402 | E25: =R9/E12 -> 0.40051576 | F25: =S9/F12 -> 0.29196337 | G25: =T9/G12 -> 0.30258151
B26: ROE (%) | D26: ='Ratio Analysis'!F23 -> 0.60303627 | E26: ='Ratio Analysis'!G23 -> 0.73952828 | F26: ='Ratio Analysis'!H23 -> 0.78793697 | G26: ='Ratio Analysis'!I23 -> 0.88183275
B27: ROCE (%) | D27: ='Ratio Analysis'!F24 -> 0.65336077 | E27: ='Ratio Analysis'!G24 -> 0.68720624 | F27: ='Ratio Analysis'!H24 -> 0.70502544 | G27: ='Ratio Analysis'!I24 -> 0.77231532
B29: Investment Overview
B31: iPhone specification upgrades to drive premium model mix higher. We expect the launches
B32: of the ultra-thin iPhone 17 Air in 2025 and Apple's first foldable iPhone in 2026 to set new
B33: benchmarks in the smartphone market. Android manufacturers will likely follow suit,
B34: accelerating their own specification upgrades. We expect the users of iPhone to increase
B35: from 1.56B FY25 to 1.62B FY26, that’s an increase of 4% YoY.
I36: DCF - (Forecast upto year FY29)
B37: Sales growth in China fell by 4% Yoy FY25, whereas iPhone sales in Rest of Aisa Pacific increa-
B38: by 10% YoY FY25. The decline in sales growth in China was offset by higher Net sales of Mac. | I38: Terminal Value: | K38: =FCFF!I29 -> 2788331.9
I39: Enterprise Value: | K39: =FCFF!E31 -> 2523540.2
B40: Risks | I40: Add: Cash: | K40: =FCFF!E32 -> 35934
B41: Apple Inc. faces significant risks from proposed and existing tariffs, primarily due to its heavy | I41: Add: Invest. & Sec.: | K41: =FCFF!E33 -> 96486
B42: reliance on Chinese manufacturing (approx. 80–90% of iPhones), threatening annual cost | I42: Less: Debt: | K42: =FCFF!E34 -> -90678
B43: increases of $8–18 billion. Potential impacts include severe pressure on profit margins, | I43: PV of Equity: | K43: =FCFF!E35 -> 2565282.2
B44: significantly higher U.S. consumer prices for devices, and stock volatility. | I44: Shares Outstanding: | K44: =FCFF!E36 -> 14750
I45: Price per Share (USD): | L45: =FCFF!E37 -> 173.91744
...

Sheet Financials->

Sheet Statements
B2: =Dashboard!B2 -> Apple, Inc.
B3: Financial statements
B4: =Dashboard!B4 -> (In millions, except number of shares, which are reflected in thousands, and per-share amounts)
B5: Active Scenario | D5: =Dashboard!G13 -> Street
B6: Historical / Projections | G6: Historicals | K6: Projections | P6: CAGR | R6: Notes
B7: Year | G7: 44865 | H7: =EDATE(G7,12) -> 45230 | I7: =EDATE(H7,12) -> 45596 | J7: =EDATE(I7,12) -> 45961 | K7: =EDATE(J7,12) -> 46326 | L7: =EDATE(K7,12) -> 46691 | M7: =EDATE(L7,12) -> 47057 | N7: =EDATE(M7,12) -> 47422 | O7: =EDATE(N7,12) -> 47787 | P7: FY 22 - FY 25 | Q7: FY 26 - FY 30
B9: <-Back to dashboard
B11: Go to -> | C11: Income statement | E11: Balance statement | G11: Cash flow statement
B13: Templete: | C13: Standard | E13: Currency: | F13: USD
B14: Period type: | C14: Annual | E14: Units: | F14: Millions
B15: Source: | C15: Company Website | E15: Decimals: | F15: Default
A17: # | B17: Income statement | G17: 44865 | H17: 45230 | I17: 45596 | J17: 45961 | K17: 46326 | L17: 46691 | M17: 47057 | N17: 47422 | O17: 47787
B19: Net sales:
B20: Products | G20: 316199 | H20: 298085 | I20: 294866 | J20: 307003 | K20: =Scenario!K21+Scenario!K27+Scenario!K32+Scenario!K37 -> 319547.85 | L20: =Scenario!L21+Scenario!L27+Scenario!L32+Scenario!L37 -> 331655.52 | M20: =Scenario!M21+Scenario!M27+Scenario!M32+Scenario!M37 -> 343035.13 | N20: =Scenario!N21+Scenario!N27+Scenario!N32+Scenario!N37 -> 353409.88 | O20: =Scenario!O21+Scenario!O27+Scenario!O32+Scenario!O37 -> 362529.28
B21: Services | G21: 78129 | H21: 85200 | I21: 96169 | J21: 109158 | K21: =Scenario!K42 -> 123894.33 | L21: =Scenario!L42 -> 142013.88 | M21: =Scenario!M42 -> 164381.06 | N21: =Scenario!N42 -> 192120.37 | O21: =Scenario!O42 -> 226702.03
B22: Total net sales | G22: =SUM(G20:G21) -> 394328 | H22: =SUM(H20:H21) -> 383285 | I22: =SUM(I20:I21) -> 391035 | J22: =SUM(J20:J21) -> 416161 | K22: =SUM(K20:K21) -> 443442.18 | L22: =SUM(L20:L21) -> 473669.4 | M22: =SUM(M20:M21) -> 507416.2 | N22: =SUM(N20:N21) -> 545530.24 | O22: =SUM(O20:O21) -> 589231.31 | P22: =_xlfn.RRI(3,G22,J22) -> 0.018125357 | Q22: =_xlfn.RRI(4,K22,O22) -> 0.073648701
B24: Cost of sales:
B25: Products | G25: 201471 | H25: 189282 | I25: 185233 | J25: 194116 | K25: =Scenario!K55 -> 203433.57 | L25: =Scenario!L55 -> 210146.88 | M25: =Scenario!M55 -> 213929.52 | N25: =Scenario!N55 -> 214571.31 | O25: =Scenario!O55 -> 211996.45
B26: Services | G26: 22075 | H26: 24855 | I26: 25119 | J26: 26844 | K26: =Scenario!K60 -> 29098.896 | L26: =Scenario!L60 -> 31339.511 | M26: =Scenario!M60 -> 34105.223 | N26: =Scenario!N60 -> 37498.693 | O26: =Scenario!O60 -> 39598.619
B27: Total cost of sales | G27: =SUM(G25:G26) -> 223546 | H27: =SUM(H25:H26) -> 214137 | I27: =SUM(I25:I26) -> 210352 | J27: =SUM(J25:J26) -> 220960 | K27: =SUM(K25:K26) -> 232532.46 | L27: =SUM(L25:L26) -> 241486.39 | M27: =SUM(M25:M26) -> 248034.74 | N27: =SUM(N25:N26) -> 252070 | O27: =SUM(O25:O26) -> 251595.07 | P27: =_xlfn.RRI(3,G27,J27) -> -0.0038709949 | Q27: =_xlfn.RRI(4,K27,O27) -> 0.019893054
B29: Gross margin | G29: =G22-G27 -> 170782 | H29: =H22-H27 -> 169148 | I29: =I22-I27 -> 180683 | J29: =J22-J27 -> 195201 | K29: =K22-K27 -> 210909.72 | L29: =L22-L27 -> 232183.01 | M29: =M22-M27 -> 259381.45 | N29: =N22-N27 -> 293460.24 | O29: =O22-O27 -> 337636.24 | P29: =_xlfn.RRI(3,G29,J29) -> 0.045554433 | Q29: =_xlfn.RRI(4,K29,O29) -> 0.12483317
B31: Operating expenses:
B32: Research and development | G32: 26251 | H32: 29915 | I32: 31370 | J32: 34550 | K32: =Scenario!K70 -> 38039.55 | L32: =Scenario!L70 -> 41634.287 | M32: =Scenario!M70 -> 45298.105 | N32: =Scenario!N70 -> 48989.9 | O32: =Scenario!O70 -> 52664.143
B33: Selling, general and administrative | G33: 25094 | H33: 24932 | I33: 26097 | J33: 27601 | K33: =Scenario!K75 -> 29201.858 | L33: =Scenario!L75 -> 30676.552 | M33: =Scenario!M75 -> 31995.644 | N33: =Scenario!N75 -> 33131.489 | O33: =Scenario!O75 -> 34059.171
B34: Total operating expenses | G34: =SUM(G32:G33) -> 51345 | H34: =SUM(H32:H33) -> 54847 | I34: =SUM(I32:I33) -> 57467 | J34: =SUM(J32:J33) -> 62151 | K34: =SUM(K32:K33) -> 67241.408 | L34: =SUM(L32:L33) -> 72310.839 | M34: =SUM(M32:M33) -> 77293.748 | N34: =SUM(N32:N33) -> 82121.389 | O34: =SUM(O32:O33) -> 86723.313 | P34: =_xlfn.RRI(3,G34,J34) -> 0.065736862 | Q34: =_xlfn.RRI(4,K34,O34) -> 0.065674971
B36: Operating income (EBIT) | G36: =G29-G34 -> 119437 | H36: =H29-H34 -> 114301 | I36: =I29-I34 -> 123216 | J36: =J29-J34 -> 133050 | K36: =K29-K34 -> 143668.31 | L36: =L29-L34 -> 159872.17 | M36: =M29-M34 -> 182087.71 | N36: =N29-N34 -> 211338.85 | O36: =O29-O34 -> 250912.93 | P36: =_xlfn.RRI(3,G36,J36) -> 0.036633718 | Q36: =_xlfn.RRI(4,K36,O36) -> 0.14958347
B38: Finance costs | G38: 0 | H38: 0 | I38: 0 | J38: 0 | K38: =-Schedule!K88+Schedule!K105 -> -3162.138 | L38: =-Schedule!L88+Schedule!L105 -> -2656.32 | M38: =-Schedule!M88+Schedule!M105 -> -2220.315 | N38: =-Schedule!N88+Schedule!N105 -> -1893.2775 | O38: =-Schedule!O88+Schedule!O105 -> -1663.62
B39: Other income/(expense), net | G39: -334 | H39: -565 | I39: 269 | J39: -321 | K39: =Assumptions!K16 -> -286.22359 | L39: =Assumptions!L16 -> -286.36345 | M39: =Assumptions!M16 -> -182.67604 | N39: =Assumptions!N16 -> -380.37365 | O39: =Assumptions!O16 -> -413.16042
B40: Income before provision for income taxes | G40: =G36+G39 -> 119103 | H40: =H36+H39 -> 113736 | I40: =I36+I39 -> 123485 | J40: =J36+J39 -> 132729 | K40: =K36+K39+K38 -> 140219.95 | L40: =L36+L39+L38 -> 156929.49 | M40: =M36+M39+M38 -> 179684.71 | N40: =N36+N39+N38 -> 209065.2 | O40: =O36+O39+O38 -> 248836.15 | P40: =_xlfn.RRI(3,G40,J40) -> 0.036766702 | Q40: =_xlfn.RRI(4,K40,O40) -> 0.1541863
B42: Provision for income taxes | G42: 19300 | H42: 16741 | I42: 29749 | J42: 20719 | K42: =Assumptions!K13 -> 22435.192 | L42: =Assumptions!L13 -> 25108.718 | M42: =Assumptions!M13 -> 28749.554 | N42: =Assumptions!N13 -> 33450.432 | O42: =Assumptions!O13 -> 39813.783
B43: Net income | G43: =G40-G42 -> 99803 | H43: =H40-H42 -> 96995 | I43: =I40-I42 -> 93736 | J43: =J40-J42 -> 112010 | K43: =K40-K42 -> 117784.76 | L43: =L40-L42 -> 131820.77 | M43: =M40-M42 -> 150935.16 | N43: =N40-N42 -> 175614.77 | O43: =O40-O42 -> 209022.36 | P43: =_xlfn.RRI(3,G43,J43) -> 0.039212592 | Q43: =_xlfn.RRI(4,K43,O43) -> 0.1541863
B45: Earnings per share:
B46: Basic | G46: 6.15 | H46: 6.16 | I46: 6.11 | J46: 7.49 | K46: =(K$43-Assumptions!K$22)/K50 -> 6.7920167 | L46: =(L$43-Assumptions!L$22)/L50 -> 7.6851724 | M46: =(M$43-Assumptions!M$22)/M50 -> 8.8954662 | N46: =(N$43-Assumptions!N$22)/N50 -> 10.461582 | O46: =(O$43-Assumptions!O$22)/O50 -> 12.584549 | P46: =_xlfn.RRI(3,G46,J46) -> 0.067912248 | Q46: =_xlfn.RRI(4,K46,O46) -> 0.16670142
B47: Diluted | G47: 6.11 | H47: 6.13 | I47: 6.08 | J47: 7.46 | K47: =(K$43-Assumptions!K$22)/K51 -> 6.7665786 | L47: =(L$43-Assumptions!L$22)/L51 -> 7.6563891 | M47: =(M$43-Assumptions!M$22)/M51 -> 8.86215 | N47: =(N$43-Assumptions!N$22)/N51 -> 10.4224 | O47: =(O$43-Assumptions!O$22)/O51 -> 12.537416 | P47: =_xlfn.RRI(3,G47,J47) -> 0.068806794 | Q47: =_xlfn.RRI(4,K47,O47) -> 0.16670142
B49: Shares used in computing earnings per share:
B50: Basic | G50: 16215.963 | H50: 15744.231 | I50: 15343.783 | J50: 14948.5 | K50: =J50 -> 14948.5 | L50: =K50 -> 14948.5 | M50: =L50 -> 14948.5 | N50: =M50 -> 14948.5 | O50: =N50 -> 14948.5
B51: Diluted | G51: 16325.819 | H51: 15812.547 | I51: 15408.095 | J51: 15004.697 | K51: =J51 -> 15004.697 | L51: =K51 -> 15004.697 | M51: =L51 -> 15004.697 | N51: =M51 -> 15004.697 | O51: =N51 -> 15004.697
B53: EBITDA | H53: =H36+Schedule!H18 -> 125820 | I53: =I36+Schedule!I18 -> 134661 | J53: =J36+Schedule!J18 -> 144748 | K53: =K22-K29-K34 -> 165291.06 | L53: =L22-L29-L34 -> 169175.55 | M53: =M22-M29-M34 -> 170740.99 | N53: =N22-N29-N34 -> 169948.61 | O53: =O22-O29-O34 -> 164871.76
B54: EBITDA Margin | H54: =H53/H22 -> 0.32826748 | I54: =I53/I22 -> 0.34437071 | J54: =J53/J22 -> 0.34781731 | K54: =K53/K22 -> 0.37274545 | L54: =L53/L22 -> 0.35715955 | M54: =M53/M22 -> 0.33649102 | N54: =N53/N22 -> 0.31152922 | O54: =O53/O22 -> 0.27980821
A57: # | B57: Balance sheet | G57: 44865 | H57: 45230 | I57: 45596 | J57: 45961 | K57: 46326 | L57: 46691 | M57: 47057 | N57: 47422 | O57: 47787
...

Sheet Scenario
B2: =Dashboard!B2 -> Apple, Inc.
B3: Scenario
B4: =Dashboard!B4 -> (In millions, except number of shares, which are reflected in thousands, and per-share amounts)
B5: Active Scenario | D5: =Dashboard!G13 -> Street
B6: Historical / Projections | G6: =Statements!G6 -> Historicals | K6: =Statements!K6 -> Projections | P6: CAGR | R6: Notes
B7: Year | G7: 44865 | H7: =EDATE(G7,12) -> 45230 | I7: =EDATE(H7,12) -> 45596 | J7: =EDATE(I7,12) -> 45961 | K7: =EDATE(J7,12) -> 46326 | L7: =EDATE(K7,12) -> 46691 | M7: =EDATE(L7,12) -> 47057 | N7: =EDATE(M7,12) -> 47422 | O7: =EDATE(N7,12) -> 47787 | P7: 22A - 25A | Q7: 26E - 30E
B9: <-Back to dashboard
B11: Go to -> | C11: Revenue forecast | E11: Expense forecast
A13: # | B13: Revenue Forecast
B15: Number of iPhone users worldwide projected
B16: (In Billions) | G16: 1.33 | H16: 1.38 | I16: 1.46 | J16: 1.56 | K16: =J16*(1+K17) -> 1.6224 | L16: =K16*(1+L17) -> 1.6808064 | M16: =L16*(1+M17) -> 1.7345922 | N16: =M16*(1+N17) -> 1.7831608 | O16: =N16*(1+O17) -> 1.8259566 | P16: =_xlfn.RRI(3,G16,J16) -> 0.054607816 | Q16: =_xlfn.RRI(4,K16,O16) -> 0.029990291
B17: yoy iPhone users growth (%) | H17: =H16/G16-1 -> 0.037593985 | I17: =I16/H16-1 -> 0.057971014 | J17: =J16/I16-1 -> 0.068493151 | K17: =K25 -> 0.04 | L17: =L25 -> 0.036 | M17: =M25 -> 0.032 | N17: =N25 -> 0.028 | O17: =O25 -> 0.024
B19: Revenue Products and Service Wise:
B21: iPhone | G21: 205489 | H21: 200583 | I21: 201183 | J21: 209586 | K21: =(K$22/$J$22)*$J$21 -> 217969.44 | L21: =(L$22/$J$22)*$J$21 -> 225816.34 | M21: =(M$22/$J$22)*$J$21 -> 233042.46 | N21: =(N$22/$J$22)*$J$21 -> 239567.65 | O21: =(O$22/$J$22)*$J$21 -> 245317.28 | S21: =J21/J$47 -> 0.50361759
B22: iPhone revenue per user | G22: =G21/(G16*100) -> 1545.0301 | H22: =H21/(H16*100) -> 1453.5 | I22: =I21/(I16*100) -> 1377.9658 | J22: =J21/(J16*100) -> 1343.5 | K22: =J22*(1+K23) -> 1397.24 | L22: =K22*(1+L23) -> 1447.5406 | M22: =L22*(1+M23) -> 1493.8619 | N22: =M22*(1+N23) -> 1535.6901 | O22: =N22*(1+O23) -> 1572.5466 | P22: =_xlfn.RRI(3,G22,J22) -> -0.045519828 | Q22: =_xlfn.RRI(4,K22,O22) -> 0.029990291
B23: yoy iPhone revenue growth per user (%) | H23: =H22/G22-1 -> -0.059241614 | I23: =I22/H22-1 -> -0.051967146 | J23: =J22/I22-1 -> -0.025012054 | K23: =OFFSET(K23,MATCH($D$5,$B24:$B26,0),0) -> 0.04 | L23: =OFFSET(L23,MATCH($D$5,$B24:$B26,0),0) -> 0.036 | M23: =OFFSET(M23,MATCH($D$5,$B24:$B26,0),0) -> 0.032 | N23: =OFFSET(N23,MATCH($D$5,$B24:$B26,0),0) -> 0.028 | O23: =OFFSET(O23,MATCH($D$5,$B24:$B26,0),0) -> 0.024
B24: Optimistic | K24: =K25+$R$24 -> 0.0595 | L24: =L25+$R$24 -> 0.0555 | M24: =M25+$R$24 -> 0.0515 | N24: =N25+$R$24 -> 0.0475 | O24: =O25+$R$24 -> 0.0435 | R24: 0.0195
B25: Street | K25: 0.04 | L25: =K25+($O$25-$K$25)/4 -> 0.036 | M25: =L25+($O$25-$K$25)/4 -> 0.032 | N25: =M25+($O$25-$K$25)/4 -> 0.028 | O25: 0.024
B26: Pessimestic | K26: =K25+$R$26 -> 0.0075 | L26: =L25+$R$26 -> 0.0035 | M26: =M25+$R$26 -> -0.0005 | N26: =N25+$R$26 -> -0.0045 | O26: =O25+$R$26 -> -0.0085 | R26: -0.0325
B27: Mac | G27: 40177 | H27: 29357 | I27: 29984 | J27: 33708 | K27: =J27*(1+K28) -> 37752.96 | L27: =K27*(1+L28) -> 41603.762 | M27: =L27*(1+M28) -> 45098.478 | N27: =M27*(1+N28) -> 48074.977 | O27: =N27*(1+O28) -> 50382.576 | P27: =_xlfn.RRI(3,G27,J27) -> -0.056840464 | Q27: =_xlfn.RRI(4,K27,O27) -> 0.07481159 | S27: =J27/J$47 -> 0.080997499
B28: yoy Mac revenue growth (%) | H28: =H27/G27-1 -> -0.26930831 | I28: =I27/H27-1 -> 0.021357768 | J28: =J27/I27-1 -> 0.12419957 | K28: =OFFSET(K28,MATCH($D$5,$B29:$B31,0),0) -> 0.12 | L28: =OFFSET(L28,MATCH($D$5,$B29:$B31,0),0) -> 0.102 | M28: =OFFSET(M28,MATCH($D$5,$B29:$B31,0),0) -> 0.084 | N28: =OFFSET(N28,MATCH($D$5,$B29:$B31,0),0) -> 0.066 | O28: =OFFSET(O28,MATCH($D$5,$B29:$B31,0),0) -> 0.048
B29: Optimistic | K29: =K30+$R$24 -> 0.1395 | L29: =L30+$R$24 -> 0.1215 | M29: =M30+$R$24 -> 0.1035 | N29: =N30+$R$24 -> 0.0855 | O29: =O30+$R$24 -> 0.0675
B30: Street | K30: 0.12 | L30: =K30+($O$30-$K$30)/4 -> 0.102 | M30: =L30+($O$30-$K$30)/4 -> 0.084 | N30: =M30+($O$30-$K$30)/4 -> 0.066 | O30: 0.048
B31: Pessimestic | K31: =K30+$R$26 -> 0.0875 | L31: =L30+$R$26 -> 0.0695 | M31: =M30+$R$26 -> 0.0515 | N31: =N30+$R$26 -> 0.0335 | O31: =O30+$R$26 -> 0.0155
B32: iPad | G32: 29292 | H32: 28300 | I32: 26694 | J32: 28023 | K32: =J32*(1+K33) -> 29424.15 | L32: =K32*(1+L33) -> 30762.949 | M32: =L32*(1+M33) -> 32024.23 | N32: =M32*(1+N33) -> 33193.114 | O32: =N32*(1+O33) -> 34255.294 | P32: =_xlfn.RRI(3,G32,J32) -> -0.014654509 | Q32: =_xlfn.RRI(4,K32,O32) -> 0.038737816 | S32: =J32/J$47 -> 0.06733692
B33: yoy iPad revenue growth (%) | H33: =H32/G32-1 -> -0.033865902 | I33: =I32/H32-1 -> -0.056749117 | J33: =J32/I32-1 -> 0.049786469 | K33: =OFFSET(K33,MATCH($D$5,$B34:$B36,0),0) -> 0.05 | L33: =OFFSET(L33,MATCH($D$5,$B34:$B36,0),0) -> 0.0455 | M33: =OFFSET(M33,MATCH($D$5,$B34:$B36,0),0) -> 0.041 | N33: =OFFSET(N33,MATCH($D$5,$B34:$B36,0),0) -> 0.0365 | O33: =OFFSET(O33,MATCH($D$5,$B34:$B36,0),0) -> 0.032
B34: Optimistic | K34: =K35+$R$24 -> 0.0695 | L34: =L35+$R$24 -> 0.065 | M34: =M35+$R$24 -> 0.0605 | N34: =N35+$R$24 -> 0.056 | O34: =O35+$R$24 -> 0.0515
B35: Street | K35: 0.05 | L35: =K35+($O$35-$K$35)/4 -> 0.0455 | M35: =L35+($O$35-$K$35)/4 -> 0.041 | N35: =M35+($O$35-$K$35)/4 -> 0.0365 | O35: 0.032
B36: Pessimestic | K36: =K35+$R$26 -> 0.0175 | L36: =L35+$R$26 -> 0.013 | M36: =M35+$R$26 -> 0.0085 | N36: =N35+$R$26 -> 0.004 | O36: =O35+$R$26 -> -0.0005
B37: Wearables, Home and Accessories | G37: 41241 | H37: 39845 | I37: 37005 | J37: 35686 | K37: =J37*(1+K38) -> 34401.304 | L37: =K37*(1+L38) -> 33472.469 | M37: =L37*(1+M38) -> 32869.964 | N37: =M37*(1+N38) -> 32574.135 | O37: =N37*(1+O38) -> 32574.135 | P37: =_xlfn.RRI(3,G37,J37) -> -0.04708047 | Q37: =_xlfn.RRI(4,K37,O37) -> -0.013551321 | S37: =J37/J$47 -> 0.085750467
B38: yoy WHA revenue growth (%) | H38: =H37/G37-1 -> -0.03384981 | I38: =I37/H37-1 -> -0.071276195 | J38: =J37/I37-1 -> -0.035643832 | K38: =OFFSET(K38,MATCH($D$5,$B39:$B41,0),0) -> -0.036 | L38: =OFFSET(L38,MATCH($D$5,$B39:$B41,0),0) -> -0.027 | M38: =OFFSET(M38,MATCH($D$5,$B39:$B41,0),0) -> -0.018 | N38: =OFFSET(N38,MATCH($D$5,$B39:$B41,0),0) -> -0.009 | O38: =OFFSET(O38,MATCH($D$5,$B39:$B41,0),0) -> 0
B39: Optimistic | K39: =K40+$R$24 -> -0.0165 | L39: =L40+$R$24 -> -0.0075 | M39: =M40+$R$24 -> 0.0015 | N39: =N40+$R$24 -> 0.0105 | O39: =O40+$R$24 -> 0.0195
B40: Street | K40: -0.036 | L40: =K40+($O$40-$K$40)/4 -> -0.027 | M40: =L40+($O$40-$K$40)/4 -> -0.018 | N40: =M40+($O$40-$K$40)/4 -> -0.009 | O40: 0
B41: Pessimestic | K41: =K40+$R$26 -> -0.0685 | L41: =L40+$R$26 -> -0.0595 | M41: =M40+$R$26 -> -0.0505 | N41: =N40+$R$26 -> -0.0415 | O41: =O40+$R$26 -> -0.0325
B42: Services | G42: 78129 | H42: 85200 | I42: 96169 | J42: 109158 | K42: =J42*(1+K43) -> 123894.33 | L42: =K42*(1+L43) -> 142013.88 | M42: =L42*(1+M43) -> 164381.06 | N42: =M42*(1+N43) -> 192120.37 | O42: =N42*(1+O43) -> 226702.03 | P42: =_xlfn.RRI(3,G42,J42) -> 0.11792955 | Q42: =_xlfn.RRI(4,K42,O42) -> 0.16305699 | S42: =J42/J$47 -> 0.26229752
B43: yoy Services revenue growth (%) | H43: =H42/G42-1 -> 0.090504166 | I43: =I42/H42-1 -> 0.12874413 | J43: =J42/I42-1 -> 0.13506431 | K43: =OFFSET(K43,MATCH($D$5,$B44:$B46,0),0) -> 0.135 | L43: =OFFSET(L43,MATCH($D$5,$B44:$B46,0),0) -> 0.14625 | M43: =OFFSET(M43,MATCH($D$5,$B44:$B46,0),0) -> 0.1575 | N43: =OFFSET(N43,MATCH($D$5,$B44:$B46,0),0) -> 0.16875 | O43: =OFFSET(O43,MATCH($D$5,$B44:$B46,0),0) -> 0.18
B44: Optimistic | K44: =K45+$R$24 -> 0.1545 | L44: =L45+$R$24 -> 0.16575 | M44: =M45+$R$24 -> 0.177 | N44: =N45+$R$24 -> 0.18825 | O44: =O45+$R$24 -> 0.1995
B45: Street | K45: 0.135 | L45: =K45+($O$45-$K$45)/4 -> 0.14625 | M45: =L45+($O$45-$K$45)/4 -> 0.1575 | N45: =M45+($O$45-$K$45)/4 -> 0.16875 | O45: 0.18
B46: Pessimestic | K46: =K45+$R$26 -> 0.1025 | L46: =L45+$R$26 -> 0.11375 | M46: =M45+$R$26 -> 0.125 | N46: =N45+$R$26 -> 0.13625 | O46: =O45+$R$26 -> 0.1475
B47: Total Revenue | G47: 394328 | H47: 383285 | I47: 391035 | J47: 416161 | K47: =K21+K27+K32+K37+K42 -> 443442.18 | L47: =L21+L27+L32+L37+L42 -> 473669.4 | M47: =M21+M27+M32+M37+M42 -> 507416.2 | N47: =N21+N27+N32+N37+N42 -> 545530.24 | O47: =O21+O27+O32+O37+O42 -> 589231.31 | P47: =_xlfn.RRI(3,G47,J47) -> 0.018125357 | Q47: =_xlfn.RRI(4,K47,O47) -> 0.073648701
...

Sheet Assumptions
B2: =Dashboard!B2 -> Apple, Inc.
B3: Assumptions
B4: =Dashboard!B4 -> (In millions, except number of shares, which are reflected in thousands, and per-share amounts)
B5: Active Scenario | D5: =Dashboard!G13 -> Street
B6: Historical / Projections | G6: =Statements!G6 -> Historicals | K6: =Statements!K6 -> Projections | P6: CAGR | R6: Notes
B7: Year | G7: 44865 | H7: =EDATE(G7,12) -> 45230 | I7: =EDATE(H7,12) -> 45596 | J7: =EDATE(I7,12) -> 45961 | K7: =EDATE(J7,12) -> 46326 | L7: =EDATE(K7,12) -> 46691 | M7: =EDATE(L7,12) -> 47057 | N7: =EDATE(M7,12) -> 47422 | O7: =EDATE(N7,12) -> 47787 | P7: 22A - 25A | Q7: 26E - 30E
B9: <-Back to dashboard
A11: # | B11: Assumptions
B13: Income taxes | G13: =Statements!G42 -> 19300 | H13: =Statements!H42 -> 16741 | I13: =Statements!I42 -> 29749 | J13: =Statements!J42 -> 20719 | K13: =K14*Statements!K40 -> 22435.192 | L13: =L14*Statements!L40 -> 25108.718 | M13: =M14*Statements!M40 -> 28749.554 | N13: =N14*Statements!N40 -> 33450.432 | O13: =O14*Statements!O40 -> 39813.783 | P13: =_xlfn.RRI(3,G13,J13) -> 0.023930533 | Q13: =_xlfn.RRI(4,K13,O13) -> 0.1541863
B14: Income taxes as a % of PBT | G14: =G13/Statements!G40 -> 0.16204462 | H14: =H13/Statements!H40 -> 0.14719174 | I14: =I13/Statements!I40 -> 0.24091185 | J14: =J13/Statements!J40 -> 0.15610002 | K14: 0.16 | L14: 0.16 | M14: 0.16 | N14: 0.16 | O14: 0.16
B16: Other Income / (Expenses) | G16: =Statements!G39 -> -334 | H16: =Statements!H39 -> -565 | I16: =Statements!I39 -> 269 | J16: =Statements!J39 -> -321 | K16: =Statements!K36*Assumptions!K17 -> -286.22359 | L16: =Statements!L36*Assumptions!L17 -> -286.36345 | M16: =Statements!M36*Assumptions!M17 -> -182.67604 | N16: =Statements!N36*Assumptions!N17 -> -380.37365 | O16: =Statements!O36*Assumptions!O17 -> -413.16042 | P16: =_xlfn.RRI(3,G16,J16) -> -0.013146115 | Q16: =_xlfn.RRI(4,K16,O16) -> 0.096107933
B17: Others as a % of EBIT | G17: =G16/Statements!G36 -> -0.0027964534 | H17: =H16/Statements!H36 -> -0.0049430889 | I17: =I16/Statements!I36 -> 0.002183158 | J17: =J16/Statements!J36 -> -0.0024126268 | K17: =AVERAGE(G17:J17) -> -0.0019922528 | L17: =AVERAGE(H17:K17) -> -0.0017912026 | M17: =AVERAGE(I17:L17) -> -0.001003231 | N17: =AVERAGE(J17:M17) -> -0.0017998283 | O17: =AVERAGE(K17:N17) -> -0.0016466287
B19: Share based compensation | H19: 10833 | I19: 11688 | J19: 12863 | K19: =K20*Statements!K22 -> 13164.643 | L19: =L20*Statements!L22 -> 14286.818 | M19: =M20*Statements!M22 -> 15350.711 | N19: =N20*Statements!N22 -> 16384.474 | O19: =O20*Statements!O22 -> 17765.077 | Q19: =_xlfn.RRI(4,K19,O19) -> 0.077803282
B20: Share based compensation as a % of revenue | H20: =H19/Statements!H22 -> 0.028263564 | I20: =I19/Statements!I22 -> 0.029889908 | J20: =J19/Statements!J22 -> 0.030908711 | K20: =AVERAGE(H20:J20) -> 0.029687394 | L20: =AVERAGE(I20:K20) -> 0.030162004 | M20: =AVERAGE(J20:L20) -> 0.030252703 | N20: =AVERAGE(K20:M20) -> 0.030034034 | O20: =AVERAGE(L20:N20) -> 0.03014958
B22: Dividends Paid | H22: 14996 | I22: 15218 | J22: 15413 | K22: =K23*Statements!K$43 -> 16254.297 | L22: =L23*Statements!L$43 -> 16938.969 | M22: =M23*Statements!M$43 -> 17961.284 | N22: =N23*Statements!N$43 -> 19229.817 | O22: =O23*Statements!O$43 -> 20902.236 | Q22: =_xlfn.RRI(4,K22,O22) -> 0.064893418
B23: Dividends paid as a % of Net income | H23: =H22/Statements!H$43 -> 0.15460591 | I23: =I22/Statements!I$43 -> 0.16234958 | J23: =J22/Statements!J$43 -> 0.13760379 | K23: 0.138 | L23: =K23+($O$23-$K$23)/4 -> 0.1285 | M23: =L23+($O$23-$K$23)/4 -> 0.119 | N23: =M23+($O$23-$K$23)/4 -> 0.1095 | O23: 0.1
B25: Share Buy-back | H25: 77046 | I25: 95846 | J25: 90052 | K25: =K26*Statements!K$43 -> 102896.9 | L25: =L26*Statements!L$43 -> 118641.99 | M25: =M26*Statements!M$43 -> 129682.99 | N25: =N26*Statements!N$43 -> 154120.87 | O25: =O26*Statements!O$43 -> 183718.77 | Q25: =_xlfn.RRI(4,K25,O25) -> 0.15594669
B26: Share Buy-back as a % of Net income | H26: =H25/Statements!H$43 -> 0.7943296 | I26: =I25/Statements!I$43 -> 1.02251 | J26: =J25/Statements!J$43 -> 0.80396393 | K26: =AVERAGE(H26:J26) -> 0.87360119 | L26: =AVERAGE(I26:K26) -> 0.90002505 | M26: =AVERAGE(J26:L26) -> 0.85919672 | N26: =AVERAGE(K26:M26) -> 0.87760765 | O26: =AVERAGE(L26:N26) -> 0.87894314

Sheet Schedule
B2: =Dashboard!B2 -> Apple, Inc.
B3: Schedule
B4: =Dashboard!B4 -> (In millions, except number of shares, which are reflected in thousands, and per-share amounts)
B5: Active Scenario | D5: =Dashboard!G13 -> Street
B6: Historical / Projections | G6: =Statements!G6 -> Historicals | K6: =Statements!G6 -> Historicals
B7: Year | G7: 44865 | H7: =EDATE(G7,12) -> 45230 | I7: =EDATE(H7,12) -> 45596 | J7: =EDATE(I7,12) -> 45961 | K7: =EDATE(J7,12) -> 46326 | L7: =EDATE(K7,12) -> 46691 | M7: =EDATE(L7,12) -> 47057 | N7: =EDATE(M7,12) -> 47422 | O7: =EDATE(N7,12) -> 47787
B9: <-Back to dashboard
B11: Go to -> | C11: PPE and intangibles | E11: Working capital | G11: Debt schedule | H11: Equity schedule
A13: # | B13: Property, plant, and equipment and Intangible schedule
B15: CapEx on PPE and intangibles | H15: 10959 | I15: 9447 | J15: 12715 | K15: =K16*Statements!K22 -> 13303.266 | L15: =L16*Statements!L22 -> 14683.751 | M15: =M16*Statements!M22 -> 16237.318 | N15: =N16*Statements!N22 -> 18002.498 | O15: =O16*Statements!O22 -> 20033.865
B16: CapEx as a % of revenue | H16: =H15/Statements!H22 -> 0.028592301 | I16: =I15/Statements!I22 -> 0.024158963 | J16: =J15/Statements!J22 -> 0.030553079 | K16: 0.03 | L16: =K16+($O$16-$K$16)/4 -> 0.031 | M16: =L16+($O$16-$K$16)/4 -> 0.032 | N16: =M16+($O$16-$K$16)/4 -> 0.033 | O16: 0.034
B18: Depreciation and Amortisation | H18: 11519 | I18: 11445 | J18: 11698 | K18: =K20+K24 -> 13546.4 | L18: =L20+L24 -> 14880.301 | M18: =M20+M24 -> 15799.337 | N18: =N20+N24 -> 17860.862 | O18: =O20+O24 -> 19509.955
B20: Depreciation and Ammortisation related to NCA | H20: =H18-H24 -> 3019 | I20: =I18-I24 -> 3245 | J20: =J18-J24 -> 3698 | K20: =K21*K22 -> 3467.8599 | L20: =L21*L22 -> 3844.1035 | M20: =M21*M22 -> 4225.5414 | N20: =N21*N22 -> 4527.124 | O20: =O21*O22 -> 4784.779
B21: Other non-current assets | H21: =Statements!H72 -> 64758 | I21: =Statements!I72 -> 74834 | J21: =Statements!J72 -> 83727 | K21: =K71 -> 77552.005 | L21: =L71 -> 87203.098 | M21: =M71 -> 95337.252 | N21: =N71 -> 102022.91 | O21: =O71 -> 108107.94
B22: Dep and Ammort related to NCA as a % of NCA | H22: =H20/H21 -> 0.046619723 | I22: =I20/I21 -> 0.043362643 | J22: =J20/J21 -> 0.044167353 | K22: =AVERAGE(H22:J22) -> 0.044716573 | L22: =AVERAGE(I22:K22) -> 0.04408219 | M22: =AVERAGE(J22:L22) -> 0.044322039 | N22: =AVERAGE(K22:M22) -> 0.0443736 | O22: =AVERAGE(L22:N22) -> 0.044259276
B24: Depreciation on PPE | H24: 8500 | I24: 8200 | J24: 8000 | K24: =K25*K15 -> 10078.54 | L24: =L25*L15 -> 11036.197 | M24: =M25*M15 -> 11573.796 | N24: =N25*N15 -> 13333.738 | O24: =O25*O15 -> 14725.176
B25: Depreciation as a % of CapEx | H25: =H24/H15 -> 0.77561821 | I25: =I24/I15 -> 0.86800042 | J25: =J24/J15 -> 0.62917814 | K25: =AVERAGE(H25:J25) -> 0.75759892 | L25: =AVERAGE(I25:K25) -> 0.75159249 | M25: =AVERAGE(J25:L25) -> 0.71278985 | N25: =AVERAGE(K25:M25) -> 0.74066042 | O25: =AVERAGE(L25:N25) -> 0.73501426
B27: Property, plant and equipment
B29: Opening balance of Net PPE | I29: =H32 -> 43715 | J29: =I32 -> 45680 | K29: =J32 -> 49834 | L29: =K32 -> 53058.726 | M29: =L32 -> 56706.28 | N29: =M32 -> 61369.802 | O29: =N32 -> 66038.563
B30: Additions to PPE | K30: =K15 -> 13303.266 | L30: =L15 -> 14683.751 | M30: =M15 -> 16237.318 | N30: =N15 -> 18002.498 | O30: =O15 -> 20033.865
B31: Less: Depreciation on PPE | K31: =-K24 -> -10078.54 | L31: =-L24 -> -11036.197 | M31: =-M24 -> -11573.796 | N31: =-N24 -> -13333.738 | O31: =-O24 -> -14725.176
B32: Closing balance of Net PPE block | H32: =Statements!H71 -> 43715 | I32: =Statements!I71 -> 45680 | J32: =Statements!J71 -> 49834 | K32: =SUM(K29:K31) -> 53058.726 | L32: =SUM(L29:L31) -> 56706.28 | M32: =SUM(M29:M31) -> 61369.802 | N32: =SUM(N29:N31) -> 66038.563 | O32: =SUM(O29:O31) -> 71347.251
B34: Other non-current assets
B36: Opening balance of NCA | K36: =J21 -> 83727 | L36: =K39 -> 77552.005 | M36: =L39 -> 87203.098 | N36: =M39 -> 95337.252 | O36: =N39 -> 102022.91
B37: Additions/ (Disposal) to NCA | K37: =K39-K36-K38 -> -2707.1353 | L37: =L39-L36-L38 -> 13495.197 | M37: =M39-M36-M38 -> 12359.695 | N37: =N39-N36-N38 -> 11212.787 | O37: =O39-O36-O38 -> 10869.8
B38: Less: Depreciation related to NCA | K38: =-K20 -> -3467.8599 | L38: =-L20 -> -3844.1035 | M38: =-M20 -> -4225.5414 | N38: =-N20 -> -4527.124 | O38: =-O20 -> -4784.779
B39: Closing balance of NCA (net) | K39: =K21 -> 77552.005 | L39: =L21 -> 87203.098 | M39: =M21 -> 95337.252 | N39: =N21 -> 102022.91 | O39: =O21 -> 108107.94
A42: # | B42: Working capital schedule
B44: Current assets
B45: Accounts receivable, net | G45: =Statements!G63 -> 28184 | H45: =Statements!H63 -> 29508 | I45: =Statements!I63 -> 33410 | J45: =Statements!J63 -> 39777 | K45: =K61*Statements!K$22/days -> 42384.557 | L45: =L61*Statements!L$22/days -> 45273.698 | M45: =M61*Statements!M$22/days -> 48499.244 | N45: =N61*Statements!N$22/days -> 52142.215 | O45: =O61*Statements!O$22/days -> 56319.198
B46: Vendor non-trade receivables | G46: =Statements!G64 -> 32748 | H46: =Statements!H64 -> 31477 | I46: =Statements!I64 -> 32833 | J46: =Statements!J64 -> 33180 | K46: =K62*Statements!K$22/days -> 35355.095 | L46: =L62*Statements!L$22/days -> 37765.073 | M46: =M62*Statements!M$22/days -> 40455.664 | N46: =N62*Statements!N$22/days -> 43494.449 | O46: =O62*Statements!O$22/days -> 46978.681
B47: Inventories | G47: =Statements!G65 -> 4946 | H47: =Statements!H65 -> 6331 | I47: =Statements!I65 -> 7286 | J47: =Statements!J65 -> 5718 | K47: =K63*Statements!K$22/days -> 6092.8401 | L47: =L63*Statements!L$22/days -> 6508.1581 | M47: =M63*Statements!M$22/days -> 6971.835 | N47: =N63*Statements!N$22/days -> 7495.5172 | O47: =O63*Statements!O$22/days -> 8095.9644
B48: Other current assets | G48: =Statements!G66 -> 21223 | H48: =Statements!H66 -> 14695 | I48: =Statements!I66 -> 14287 | J48: =Statements!J66 -> 14585 | K48: =K64*Statements!K$22/days -> 15541.111 | L48: =L64*Statements!L$22/days -> 16600.47 | M48: =M64*Statements!M$22/days -> 17783.178 | N48: =N64*Statements!N$22/days -> 19118.943 | O48: =O64*Statements!O$22/days -> 20650.514
B50: Current liabilities
B51: Accounts payable | G51: =Statements!G78 -> 64115 | H51: =Statements!H78 -> 62611 | I51: =Statements!I78 -> 68960 | J51: =Statements!J78 -> 69860 | K51: =K66*Statements!K$27/days -> 73518.818 | L51: =L66*Statements!L$27/days -> 76349.742 | M51: =M66*Statements!M$27/days -> 78420.108 | N51: =N66*Statements!N$27/days -> 79695.919 | O51: =O66*Statements!O$27/days -> 79545.763
B52: Other current liabilities | G52: =Statements!G79 -> 60845 | H52: =Statements!H79 -> 58829 | I52: =Statements!I79 -> 78304 | J52: =Statements!J79 -> 66387 | K52: =K67*Statements!K$27/days -> 69863.924 | L52: =L67*Statements!L$27/days -> 72554.113 | M52: =M67*Statements!M$27/days -> 74521.553 | N52: =N67*Statements!N$27/days -> 75733.939 | O52: =O67*Statements!O$27/days -> 75591.247
B53: Deferred revenue | G53: =Statements!G80 -> 7912 | H53: =Statements!H80 -> 8061 | I53: =Statements!I80 -> 8249 | J53: =Statements!J80 -> 9055 | K53: =K69*Statements!K22 -> 9306.6948 | L53: =L69*Statements!L22 -> 10050.37 | M53: =M69*Statements!M22 -> 10790.105 | N53: =N69*Statements!N22 -> 11623.71 | O53: =O69*Statements!O22 -> 12488.387
B55: Current assets | G55: =SUM(G45:G48) -> 87101 | H55: =SUM(H45:H48) -> 82011 | I55: =SUM(I45:I48) -> 87816 | J55: =SUM(J45:J48) -> 93260 | K55: =SUM(K45:K48) -> 99373.603 | L55: =SUM(L45:L48) -> 106147.4 | M55: =SUM(M45:M48) -> 113709.92 | N55: =SUM(N45:N48) -> 122251.13 | O55: =SUM(O45:O48) -> 132044.36
B56: Current liabilities | G56: =SUM(G51:G53) -> 132872 | H56: =SUM(H51:H53) -> 129501 | I56: =SUM(I51:I53) -> 155513 | J56: =SUM(J51:J53) -> 145302 | K56: =SUM(K51:K53) -> 152689.44 | L56: =SUM(L51:L53) -> 158954.22 | M56: =SUM(M51:M53) -> 163731.77 | N56: =SUM(N51:N53) -> 167053.57 | O56: =SUM(O51:O53) -> 167625.4
B57: Total working capital | J57: =J55-J56 -> -52042 | K57: =K55-K56 -> -53315.833 | L57: =L55-L56 -> -52806.825 | M57: =M55-M56 -> -50021.845 | N57: =N55-N56 -> -44802.442 | O57: =O55-O56 -> -35581.039
...

Sheet Valuation->
A1: \

Sheet Beta
B2: =Dashboard!B2 -> Apple, Inc.
B3: Beta
B4: =Dashboard!B4 -> (In millions, except number of shares, which are reflected in thousands, and per-share amounts)
B5: Active Scenario | D5: =Dashboard!G13 -> Street
B8: <-Back to dashboard
B10: (Data is the daily closing price from 3/26 to 3/25)
B11: APPLE Inc. | F11: NYSE | J11: Beta Drifting
B13: Date | C13: Price | D13: Returns | F13: Date | G13: Price | H13: Returns | J13: Calculated beta | L13: =SLOPE(D15:D263,H15:H263) -> 1.3948533
B14: 46085 | C14: 262.52 | F14: 46085 | G14: 23086.3
B15: 46084 | C15: 263.75 | D15: =C15/C14-1 -> 0.0046853573 | F15: 46084 | G15: 22998.2 | H15: =G15/G14-1 -> -0.0038161161 | J15: Levered beta | L15: =L13 -> 1.3948533
B16: 46083 | C16: 264.72 | D16: =C16/C15-1 -> 0.0036777251 | F16: 46083 | G16: 23413.1 | H16: =G16/G15-1 -> 0.018040542 | J16: Raw beta weight | L16: 0.75
B17: 46080 | C17: 264.18 | D17: =C17/C16-1 -> -0.0020398912 | F17: 46080 | G17: 23494.4 | H17: =G17/G16-1 -> 0.003472415
B18: 46079 | C18: 272.95 | D18: =C18/C17-1 -> 0.033197063 | F18: 46079 | G18: 23524.8 | H18: =G18/G17-1 -> 0.0012939254 | J18: Market beta | L18: =SLOPE(H15:H263,H15:H263) -> 1
B19: 46078 | C19: 274.23 | D19: =C19/C18-1 -> 0.0046895036 | F19: 46078 | G19: 23452.7 | H19: =G19/G18-1 -> -0.0030648507 | J19: Raw beta weight | L19: 0.25
B20: 46077 | C20: 272.14 | D20: =C20/C19-1 -> -0.0076213398 | F20: 46077 | G20: 23383.8 | H20: =G20/G19-1 -> -0.0029378281
B21: 46076 | C21: 266.18 | D21: =C21/C20-1 -> -0.021900492 | F21: 46076 | G21: 23214.9 | H21: =G21/G20-1 -> -0.0072229492 | J21: Adjusted beta | L21: =L15*L16+L18*L19 -> 1.29614
B22: 46073 | C22: 264.58 | D22: =C22/C21-1 -> -0.00601097 | F22: 46073 | G22: 23452.6 | H22: =G22/G21-1 -> 0.010239114
B23: 46072 | C23: 260.58 | D23: =C23/C22-1 -> -0.015118301 | F23: 46072 | G23: 23358.3 | H23: =G23/G22-1 -> -0.0040208762 | J23: Total years | L23: =YEARFRAC(F263,F14,1) -> 0.99452055
B24: 46071 | C24: 264.35 | D24: =C24/C23-1 -> 0.014467726 | F24: 46071 | G24: 23387.5 | H24: =G24/G23-1 -> 0.001250091 | J24: Market returns (%) | L24: =AVERAGE(H15:H263) -> -0.00062817509
B25: 46070 | C25: 263.88 | D25: =C25/C24-1 -> -0.0017779459 | F25: 46070 | G25: 23300.8 | H25: =G25/G24-1 -> -0.0037071085
B26: 46066 | C26: 255.78 | D26: =C26/C25-1 -> -0.030695771 | F26: 46066 | G26: 23326.1 | H26: =G26/G25-1 -> 0.0010857996
B27: 46065 | C27: 261.73 | D27: =C27/C26-1 -> 0.023262178 | F27: 46065 | G27: 23188.8 | H27: =G27/G26-1 -> -0.0058861104
B28: 46064 | C28: 275.5 | D28: =C28/C27-1 -> 0.05261147 | F28: 46064 | G28: 23479.7 | H28: =G28/G27-1 -> 0.012544849
B29: 46063 | C29: 273.68 | D29: =C29/C28-1 -> -0.0066061706 | F29: 46063 | G29: 23398.1 | H29: =G29/G28-1 -> -0.0034753425
B30: 46062 | C30: 274.62 | D30: =C30/C29-1 -> 0.0034346682 | F30: 46062 | G30: 23340.7 | H30: =G30/G29-1 -> -0.0024531906
B31: 46059 | C31: 278.12 | D31: =C31/C30-1 -> 0.012744884 | F31: 46059 | G31: 23252.8 | H31: =G31/G30-1 -> -0.0037659539
B32: 46058 | C32: 275.91 | D32: =C32/C31-1 -> -0.0079462103 | F32: 46058 | G32: 22733.3 | H32: =G32/G31-1 -> -0.022341395
B33: 46057 | C33: 276.49 | D33: =C33/C32-1 -> 0.0021021348 | F33: 46057 | G33: 22975.6 | H33: =G33/G32-1 -> 0.010658373
B34: 46056 | C34: 269.48 | D34: =C34/C33-1 -> -0.025353539 | F34: 46056 | G34: 22881.2 | H34: =G34/G33-1 -> -0.0041087066
B35: 46055 | C35: 270.01 | D35: =C35/C34-1 -> 0.0019667508 | F35: 46055 | G35: 22885.7 | H35: =G35/G34-1 -> 0.00019666801
B36: 46052 | C36: 259.48 | D36: =C36/C35-1 -> -0.038998556 | F36: 46052 | G36: 22719.3 | H36: =G36/G35-1 -> -0.0072709159
... B263: 45722 | C263: 235.33 | D263: =C263/C262-1 -> -0.015643954 | F263: 45722 | G263: 19506.3 | H263: =G263/G262-1 -> -0.0034128472

Sheet WACC
B2: =Dashboard!B2 -> Apple, Inc.
B3: WACC
B4: =Dashboard!B4 -> (In millions, except number of shares, which are reflected in thousands, and per-share amounts)
B5: Active Scenario | D5: =Dashboard!G13 -> Street
B8: <-Back to dashboard
B10: Cost of Equity | G10: Capital Structure
B11: Risk free rate | D11: 0.04148 | G11: Market Cap | H11: 4000000
B12: Adj. Default Spread | D12: 0.0023 | G12: Debt | H12: =Statements!J82+Statements!J81+Statements!J86 -> 98657
B13: Equity risk premium | D13: 0.0446 | G13: Total Capital | H13: =H11+H12 -> 4098657
B14: Country risk premium | D14: 0.0023
B15: Levered beta | D15: =Beta!L21 -> 1.29614 | G15: Debt / Total Cap | H15: =H11/H13 -> 0.97592943
B16: Cost of equity | D16: =(D11-D12)+(D13*D15)+D14 -> 0.099287844 | G16: Equity / Total Cap | H16: =H12/H13 -> 0.024070568
B18: Cost of Debt | G18: WACC
B19: (Using yield of Apple bond) | G19: Cost of Equity | H19: =D16*H15 -> 0.096897929
B20: CMP | D20: 96 | G20: Cost of Debt | H20: =D28*H16 -> 0.00097494453
B21: Face value | D21: 100 | G21: WACC | H21: =H19+H20 -> 0.097872873
B22: Maturity year | D22: 55953
B23: Total years | D23: =YEARFRAC(TODAY(),D22,1) -> 26.962355
B24: Coupon rate | D24: 0.0485
B25: YTM | D25: =RATE(D23,(D21*D24),-D20,D21) -> 0.051270374
B27: Tax rate | D27: 0.21
B28: Post-tax cost of debt | D28: =D25*(1-D27) -> 0.040503595

Sheet FCFF
B2: =Dashboard!B2 -> Apple, Inc.
B3: FCFF
B4: =Dashboard!B4 -> (In millions, except number of shares, which are reflected in thousands, and per-share amounts)
B5: Active Scenario | D5: =Dashboard!G13 -> Street
B7: <-Back to dashboard
B9: Valuation parameters
B10: Valuation as on specified date | E10: 45961 | G10: Implied Share Price | I10: =E37 -> 173.91744
B11: Date of year ending | E11: 46022 | G11: Current Share Price | I11: 271.86
B12: WACC | E12: =WACC!H21 -> 0.097872873 | G12: Premium / (Discount) | I12: =I11/I10-1 -> 0.56315553
B13: Terminal growth rate | E13: 0.02
B14: Tax Rate | E14: 0.21
B16: Free Cash Flow to Firm | E16: =Statements!K101 -> 46326 | F16: =Statements!L101 -> 46691 | G16: =Statements!M101 -> 47057 | H16: =Statements!N101 -> 47422 | I16: =Statements!O101 -> 47787
B18: EBIT | E18: =Statements!K36 -> 143668.31 | F18: =Statements!L36 -> 159872.17 | G18: =Statements!M36 -> 182087.71 | H18: =Statements!N36 -> 211338.85 | I18: =Statements!O36 -> 250912.93
B19: Tax Rate | E19: =tax_rate -> 0.21 | F19: =tax_rate -> 0.21 | G19: =tax_rate -> 0.21 | H19: =tax_rate -> 0.21 | I19: =tax_rate -> 0.21
B20: NOPAT | E20: =E18*(1-E19) -> 113497.97 | F20: =F18*(1-F19) -> 126299.01 | G20: =G18*(1-G19) -> 143849.29 | H20: =H18*(1-H19) -> 166957.69 | I20: =I18*(1-I19) -> 198221.21
B22: Add: Depreciaton & Amortization | E22: =Statements!K106 -> 13546.4 | F22: =Statements!L106 -> 14880.301 | G22: =Statements!M106 -> 15799.337 | H22: =Statements!N106 -> 17860.862 | I22: =Statements!O106 -> 19509.955
B23: Add: Share-based Compensation | E23: =Statements!K107 -> 13164.643 | F23: =Statements!L107 -> 14286.818 | G23: =Statements!M107 -> 15350.711 | H23: =Statements!N107 -> 16384.474 | I23: =Statements!O107 -> 17765.077
B24: Less: CapEx | E24: =Statements!K117 -> -13303.266 | F24: =Statements!L117 -> -14683.751 | G24: =Statements!M117 -> -16237.318 | H24: =Statements!N117 -> -18002.498 | I24: =Statements!O117 -> -20033.865
B25: Add|Less: Change in NWC | E25: =SUM(Statements!K111:K113) -> 12036.12 | F25: =SUM(Statements!L111:L113) -> 2268.6346 | G25: =SUM(Statements!M111:M113) -> -604.6616 | H25: =SUM(Statements!N111:N113) -> -1529.4486 | I25: =SUM(Statements!O111:O113) -> -2584.5227
B26: FCFF | E26: =SUM(E20:E25) -> 138941.86 | F26: =SUM(F20:F25) -> 143051.02 | G26: =SUM(G20:G25) -> 158157.36 | H26: =SUM(H20:H25) -> 181671.08 | I26: =SUM(I20:I25) -> 212877.86
B28: Discount Factor | E28: =(E11-E10)/(365/2) -> 0.33424658 | F28: =E28+1 -> 1.3342466 | G28: =F28+1 -> 2.3342466 | H28: =G28+1 -> 3.3342466 | I28: =H28+1 -> 4.3342466
B29: Terminal Value | I29: =I26*(1+Terminal_rate)/(WACC-Terminal_rate) -> 2788331.9
B30: PV of Firm | E30: =E26/(1+WACC)^E28 -> 134672.44 | F30: =F26/(1+WACC)^F28 -> 126294.52 | G30: =G26/(1+WACC)^G28 -> 127183.54 | H30: =H26/(1+WACC)^H28 -> 133068.5 | I30: =(I26+I29)/(1+WACC)^I28 -> 2002321.2
B31: Enterprise Value | E31: =SUM(E30:I30) -> 2523540.2
B32: Add: Cash | E32: =Statements!J61 -> 35934
B33: Add: Investments & Securities | E33: =Statements!J62+Statements!J70 -> 96486
B34: Less: Debt | E34: =-(Statements!J82+Statements!J86) -> -90678
B35: PV of Equity | E35: =SUM(E31:E34) -> 2565282.2
B36: Shares Outstanding | E36: 14750
B37: Price per Share | E37: =E35/E36 -> 173.91744
A40: # | B40: Sensitivity Analysis
D42: Terminal Growth %
C43: =E37 -> 173.91744 | D43: 0 | E43: =D43+1% -> 0.01 | F43: =E43+1% -> 0.02 | G43: =F43+1% -> 0.03 | H43: =G43+1% -> 0.04
B44: WACC | C44: =C45+1% -> 0.12 | D44: 119.33181 | E44: 126.82488 | F44: 135.81656 | G44: 146.80638 | H44: 160.54367
C45: =C47+2% -> 0.11 | D45: 130.11227 | E45: 139.3769 | F45: 150.70033 | G45: 164.85461 | H45: 183.05298
C46: 0.097872863 | D46: 146.17726 | E46: 158.46893 | F46: 173.91746 | G46: 193.91818 | H46: 220.83085
C47: =C48+1% -> 0.09 | D47: 158.94803 | E47: 173.98696 | F47: 193.32272 | G47: 219.10373 | H47: 255.19715
C48: =C49+1% -> 0.08 | D48: 178.8252 | E48: 198.76439 | F48: 225.34997 | G48: 262.56978 | H48: 318.3995
C49: 0.07 | D49: 204.42421 | E49: 231.8473 | F49: 270.23963 | G49: 327.82813 | H49: 423.80895

Sheet Ratio Analysis
B2: =Dashboard!B2 -> Apple, Inc.
B3: Ratio Analysis
B4: =Dashboard!B4 -> (In millions, except number of shares, which are reflected in thousands, and per-share amounts)
B5: Active Scenario | D5: =Dashboard!G13 -> Street
B6: Historical / Projections | E6: =Statements!G6 -> Historicals | H6: =Statements!K6 -> Projections
B7: Year | E7: =Statements!H7 -> 45230 | F7: =Statements!I7 -> 45596 | G7: =Statements!J7 -> 45961 | H7: =Statements!K7 -> 46326 | I7: =Statements!L7 -> 46691 | J7: =Statements!M7 -> 47057 | K7: =Statements!N7 -> 47422 | L7: =Statements!O7 -> 47787
B9: <-Back to dashboard
A11: # | B11: Ratio Analysis
B13: EBITDA | E13: =Statements!H53 -> 125820 | F13: =Statements!I53 -> 134661 | G13: =Statements!J53 -> 144748 | H13: =Statements!K53 -> 165291.06 | I13: =Statements!L53 -> 169175.55 | J13: =Statements!M53 -> 170740.99 | K13: =Statements!N53 -> 169948.61 | L13: =Statements!O53 -> 164871.76
B14: EBIT | E14: =Statements!H36 -> 114301 | F14: =Statements!I36 -> 123216 | G14: =Statements!J36 -> 133050 | H14: =Statements!K36 -> 143668.31 | I14: =Statements!L36 -> 159872.17 | J14: =Statements!M36 -> 182087.71 | K14: =Statements!N36 -> 211338.85 | L14: =Statements!O36 -> 250912.93
B15: NOPAT | E15: =E14*(1-Assumptions!H14) -> 97476.837 | F15: =F14*(1-Assumptions!I14) -> 93531.805 | G15: =G14*(1-Assumptions!J14) -> 112280.89 | H15: =H14*(1-Assumptions!K14) -> 120681.38 | I15: =I14*(1-Assumptions!L14) -> 134292.62 | J15: =J14*(1-Assumptions!M14) -> 152953.67 | K15: =K14*(1-Assumptions!N14) -> 177524.64 | L15: =L14*(1-Assumptions!O14) -> 210766.86
B16: PAT | E16: =Statements!H43 -> 96995 | F16: =Statements!I43 -> 93736 | G16: =Statements!J43 -> 112010 | H16: =Statements!K43 -> 117784.76 | I16: =Statements!L43 -> 131820.77 | J16: =Statements!M43 -> 150935.16 | K16: =Statements!N43 -> 175614.77 | L16: =Statements!O43 -> 209022.36
B18: Profitability ratio
B19: Gross Margin (GM) | E19: =Statements!H29/Statements!H22 -> 0.4413113 | F19: =Statements!I29/Statements!I22 -> 0.4620635 | G19: =Statements!J29/Statements!J22 -> 0.46905164 | H19: =Statements!K29/Statements!K22 -> 0.47561943 | I19: =Statements!L29/Statements!L22 -> 0.49017946 | J19: =Statements!M29/Statements!M22 -> 0.51118087 | K19: =Statements!N29/Statements!N22 -> 0.53793579 | L19: =Statements!O29/Statements!O22 -> 0.57301137
B20: Operating Margin (OPM) | E20: =Statements!H36/Statements!H22 -> 0.29821412 | F20: =Statements!I36/Statements!I22 -> 0.31510223 | G20: =Statements!J36/Statements!J22 -> 0.319708 | H20: =Statements!K36/Statements!K22 -> 0.32398431 | I20: =Statements!L36/Statements!L22 -> 0.33751847 | J20: =Statements!M36/Statements!M22 -> 0.35885277 | K20: =Statements!N36/Statements!N22 -> 0.3874008 | L20: =Statements!O36/Statements!O22 -> 0.42583095
B21: PBT Margin | E21: =Statements!H40/Statements!H22 -> 0.29674002 | F21: =Statements!I40/Statements!I22 -> 0.31579015 | G21: =Statements!J40/Statements!J22 -> 0.31893666 | H21: =Statements!K40/Statements!K22 -> 0.31620796 | I21: =Statements!L40/Statements!L22 -> 0.33130594 | J21: =Statements!M40/Statements!M22 -> 0.35411703 | K21: =Statements!N40/Statements!N22 -> 0.38323302 | L21: =Statements!O40/Statements!O22 -> 0.42230639
B22: PAT Margin | E22: =Statements!H43/Statements!H22 -> 0.25306234 | F22: =Statements!I43/Statements!I22 -> 0.23971256 | G22: =Statements!J43/Statements!J22 -> 0.26915064 | H22: =Statements!K43/Statements!K22 -> 0.26561469 | I22: =Statements!L43/Statements!L22 -> 0.27829699 | J22: =Statements!M43/Statements!M22 -> 0.2974583 | K22: =Statements!N43/Statements!N22 -> 0.32191574 | L22: =Statements!O43/Statements!O22 -> 0.35473736
B23: ROE | E23: =Statements!H43/(AVERAGE(Statements!G50:H50)*10) -> 0.60697379 | F23: =Statements!I43/(AVERAGE(Statements!H50:I50)*10) -> 0.60303627 | G23: =Statements!J43/(AVERAGE(Statements!I50:J50)*10) -> 0.73952828 | H23: =Statements!K43/(AVERAGE(Statements!J50:K50)*10) -> 0.78793697 | I23: =Statements!L43/(AVERAGE(Statements!K50:L50)*10) -> 0.88183275 | J23: =Statements!M43/(AVERAGE(Statements!L50:M50)*10) -> 1.009701 | K23: =Statements!N43/(AVERAGE(Statements!M50:N50)*10) -> 1.1747986 | L23: =Statements!O43/(AVERAGE(Statements!N50:O50)*10) -> 1.3982832
B24: ROCE | E24: =Statements!H36/(Statements!H74-Statements!H83) -> 0.55144615 | F24: =Statements!I36/(Statements!I74-Statements!I83) -> 0.65336077 | G24: =Statements!J36/(Statements!J74-Statements!J83) -> 0.68720624 | H24: =Statements!K36/(Statements!K74-Statements!K83) -> 0.70502544 | I24: =Statements!L36/(Statements!L74-Statements!L83) -> 0.77231532 | J24: =Statements!M36/(Statements!M74-Statements!M83) -> 0.83325547 | K24: =Statements!N36/(Statements!N74-Statements!N83) -> 0.89691292 | L24: =Statements!O36/(Statements!O74-Statements!O83) -> 0.96705639
B25: ROIC | H25: =H15/(Statements!K95+Statements!K86+Statements!K82+Statements!K81) -> 0.70238652 | I25: =I15/(Statements!L95+Statements!L86+Statements!L82+Statements!L81) -> 0.77957077 | J25: =J15/(Statements!M95+Statements!M86+Statements!M82+Statements!M81) -> 0.84222615 | K25: =K15/(Statements!N95+Statements!N86+Statements!N82+Statements!N81) -> 0.9102895 | L25: =L15/(Statements!O95+Statements!O86+Statements!O82+Statements!O81) -> 0.99317883
B26: ROA | H26: =H16/AVERAGE(Statements!J74:K74) -> 0.32004209 | I26: =I16/AVERAGE(Statements!K74:L74) -> 0.34547626 | J26: =J16/AVERAGE(Statements!L74:M74) -> 0.38263966 | K26: =K16/AVERAGE(Statements!M74:N74) -> 0.42540268 | L26: =L16/AVERAGE(Statements!N74:O74) -> 0.48025249
B28: Leverage Ratio
B29: Debt to Equity | H29: =Statements!K89/Statements!K95 -> 3.4056078 | I29: =Statements!L89/Statements!L95 -> 3.0216191 | J29: =Statements!M89/Statements!M95 -> 2.5101088 | K29: =Statements!N89/Statements!N95 -> 2.1723972 | L29: =Statements!O89/Statements!O95 -> 1.8771346
B30: Debt to Asset | H30: =Statements!K74/Statements!K95 -> 4.4056078 | I30: =Statements!L74/Statements!L95 -> 4.0216191 | J30: =Statements!M74/Statements!M95 -> 3.5101088 | K30: =Statements!N74/Statements!N95 -> 3.1723972 | L30: =Statements!O74/Statements!O95 -> 2.8771346
B31: Current Ratio | H31: =Statements!K67/Statements!K83 -> 0.97366933 | I31: =Statements!L67/Statements!L83 -> 0.9184145 | J31: =Statements!M67/Statements!M83 -> 0.91360149 | K31: =Statements!N67/Statements!N83 -> 0.94581054 | L31: =Statements!O67/Statements!O83 -> 1.0121415
B32: Quick Ratio | H32: =(Statements!K61+Statements!K62+Statements!K63+Statements!K64)/Statements!K83 -> 0.84864609 | I32: =(Statements!L61+Statements!L62+Statements!L63+Statements!L64)/Statements!L83 -> 0.78953506 | J32: =(Statements!M61+Statements!M62+Statements!M63+Statements!M64)/Statements!M83 -> 0.77912314 | K32: =(Statements!N61+Statements!N62+Statements!N63+Statements!N64)/Statements!N83 -> 0.80379371 | L32: =(Statements!O61+Statements!O62+Statements!O63+Statements!O64)/Statements!O83 -> 0.85921469
B33: Cash Ratio | H33: =Statements!K61/Statements!K83 -> 0.29095442 | I33: =Statements!L61/Statements!L83 -> 0.22177503 | J33: =Statements!M61/Statements!M83 -> 0.19395976 | K33: =Statements!N61/Statements!N83 -> 0.19334821 | L33: =Statements!O61/Statements!O83 -> 0.20986971
B35: Valuation Ratio
B36: EPS (₹) | E36: =Statements!H46 -> 6.16 | F36: =Statements!I46 -> 6.11 | G36: =Statements!J46 -> 7.49 | H36: =Statements!K46 -> 6.7920167 | I36: =Statements!L46 -> 7.6851724 | J36: =Statements!M46 -> 8.8954662 | K36: =Statements!N46 -> 10.461582 | L36: =Statements!O46 -> 12.584549
B37: DPS (₹) | E37: =Assumptions!H22/Statements!H50 -> 0.95247586 | F37: =Assumptions!I22/Statements!I50 -> 0.99180235 | G37: =Assumptions!J22/Statements!J50 -> 1.0310734 | H37: =Assumptions!K22/Statements!K50 -> 1.087353 | I37: =Assumptions!L22/Statements!L50 -> 1.1331551 | J37: =Assumptions!M22/Statements!M50 -> 1.2015442 | K37: =Assumptions!N22/Statements!N50 -> 1.2864045 | L37: =Assumptions!O22/Statements!O50 -> 1.3982832
B38: Dividend Yield | E38: =Assumptions!H23 -> 0.15460591 | F38: =Assumptions!I23 -> 0.16234958 | G38: =Assumptions!J23 -> 0.13760379 | H38: =Assumptions!K23 -> 0.138 | I38: =Assumptions!L23 -> 0.1285 | J38: =Assumptions!M23 -> 0.119 | K38: =Assumptions!N23 -> 0.1095 | L38: =Assumptions!O23 -> 0.1
B40: Operating Ratio
B41: Fixed Asset Turnover | H41: =Statements!K22/AVERAGE(Statements!J71:K71) -> 8.619505 | I41: =Statements!L22/AVERAGE(Statements!K71:L71) -> 8.6306085 | J41: =Statements!M22/AVERAGE(Statements!L71:M71) -> 8.5947329 | K41: =Statements!N22/AVERAGE(Statements!M71:N71) -> 8.5634918 | L41: =Statements!O22/AVERAGE(Statements!N71:O71) -> 8.5777606
B42: Total Asset Turnover | H42: =Statements!K22/AVERAGE(Statements!J74:K74) -> 1.2049111 | I42: =Statements!L22/AVERAGE(Statements!K74:L74) -> 1.2413942 | J42: =Statements!M22/AVERAGE(Statements!L74:M74) -> 1.286364 | K42: =Statements!N22/AVERAGE(Statements!M74:N74) -> 1.3214721 | L42: =Statements!O22/AVERAGE(Statements!N74:O74) -> 1.3538255
B43: Working Capital Turnover | H43: =Statements!K22/(Schedule!J55-Schedule!J56) -> -8.5208521 | I43: =Statements!L22/(Schedule!K55-Schedule!K56) -> -8.8842163 | J43: =Statements!M22/(Schedule!L55-Schedule!L56) -> -9.6089131 | K43: =Statements!N22/(Schedule!M55-Schedule!M56) -> -10.90584 | L43: =Statements!O22/(Schedule!N55-Schedule!N56) -> -13.151768
B45: Dupoint Analysis
B46: Profit Margin | H46: =H22 -> 0.26561469 | I46: =I22 -> 0.27829699 | J46: =J22 -> 0.2974583 | K46: =K22 -> 0.32191574 | L46: =L22 -> 0.35473736
B47: Asset Turnover | H47: =H42 -> 1.2049111 | I47: =I42 -> 1.2413942 | J47: =J42 -> 1.286364 | K47: =K42 -> 1.3214721 | L47: =L42 -> 1.3538255
B48: Asset Leverage | H48: =(Statements!K81+Statements!K82+Statements!K86)/Statements!K74 -> 0.22898388 | I48: =(Statements!L81+Statements!L82+Statements!L86)/Statements!L74 -> 0.19727007 | J48: =(Statements!M81+Statements!M82+Statements!M86)/Statements!M74 -> 0.16618422 | K48: =(Statements!N81+Statements!N82+Statements!N86)/Statements!N74 -> 0.1457854 | L48: =(Statements!O81+Statements!O82+Statements!O86)/Statements!O74 -> 0.12672207
B49: Dupont ROE | H49: =H46*H47*H48 -> 0.073284479 | I49: =I46*I47*I48 -> 0.068152124 | J49: =J46*J47*J48 -> 0.063588671 | K49: =K46*K47*K48 -> 0.062017501 | L49: =L46*L47*L48 -> 0.060858587

Sheet Analysis
B2: =Dashboard!B2 -> Apple, Inc.
B3: Analysis
B4: =Dashboard!B4 -> (In millions, except number of shares, which are reflected in thousands, and per-share amounts)
B5: Active Scenario | D5: =Dashboard!G13 -> Street
B6: Historical / Projections | E6: =Statements!G6 -> Historicals | I6: =Statements!K6 -> Projections
B7: Year | E7: 45230 | F7: =EDATE(E7,12) -> 45596 | G7: =EDATE(F7,12) -> 45961 | H7: =EDATE(G7,12) -> 46326 | I7: =EDATE(H7,12) -> 46691 | J7: =EDATE(I7,12) -> 47057 | K7: =EDATE(J7,12) -> 47422 | L7: =EDATE(K7,12) -> 47787
A9: # | B9: Income Statement (Trend Analysis)
B11: Net sales:
B12: Products | E12: - | F12: =Statements!H20/Statements!G20-1 -> -0.057286709 | G12: =Statements!I20/Statements!H20-1 -> -0.010798933 | H12: =Statements!J20/Statements!I20-1 -> 0.04116107 | I12: =Statements!K20/Statements!J20-1 -> 0.040862317 | J12: =Statements!L20/Statements!K20-1 -> 0.037889991 | K12: =Statements!M20/Statements!L20-1 -> 0.034311551 | L12: =Statements!N20/Statements!M20-1 -> 0.030243967
B13: Services | E13: - | F13: =Statements!H21/Statements!G21-1 -> 0.090504166 | G13: =Statements!I21/Statements!H21-1 -> 0.12874413 | H13: =Statements!J21/Statements!I21-1 -> 0.13506431 | I13: =Statements!K21/Statements!J21-1 -> 0.135 | J13: =Statements!L21/Statements!K21-1 -> 0.14625 | K13: =Statements!M21/Statements!L21-1 -> 0.1575 | L13: =Statements!N21/Statements!M21-1 -> 0.16875
B14: Total net sales | E14: - | F14: =Statements!H22/Statements!G22-1 -> -0.028004605 | G14: =Statements!I22/Statements!H22-1 -> 0.020219941 | H14: =Statements!J22/Statements!I22-1 -> 0.064255118 | I14: =Statements!K22/Statements!J22-1 -> 0.065554398 | J14: =Statements!L22/Statements!K22-1 -> 0.068164943 | K14: =Statements!M22/Statements!L22-1 -> 0.071245474 | L14: =Statements!N22/Statements!M22-1 -> 0.075113975
B16: Cost of sales:
B17: Products | E17: - | F17: =Statements!H25/Statements!G25-1 -> -0.060500022 | G17: =Statements!I25/Statements!H25-1 -> -0.021391363 | H17: =Statements!J25/Statements!I25-1 -> 0.047955818 | I17: =Statements!K25/Statements!J25-1 -> 0.048 | J17: =Statements!L25/Statements!K25-1 -> 0.033 | K17: =Statements!M25/Statements!L25-1 -> 0.018 | L17: =Statements!N25/Statements!M25-1 -> 0.003
B18: Services | E18: - | F18: =Statements!H26/Statements!G26-1 -> 0.12593431 | G18: =Statements!I26/Statements!H26-1 -> 0.010621605 | H18: =Statements!J26/Statements!I26-1 -> 0.068673116 | I18: =Statements!K26/Statements!J26-1 -> 0.084 | J18: =Statements!L26/Statements!K26-1 -> 0.077 | K18: =Statements!M26/Statements!L26-1 -> 0.08825 | L18: =Statements!N26/Statements!M26-1 -> 0.0995
B19: Total cost of sales | E19: - | F19: =Statements!H27/Statements!G27-1 -> -0.042089771 | G19: =Statements!I27/Statements!H27-1 -> -0.0176756 | H19: =Statements!J27/Statements!I27-1 -> 0.050429756 | I19: =Statements!K27/Statements!J27-1 -> 0.05237357 | J19: =Statements!L27/Statements!K27-1 -> 0.038506119 | K19: =Statements!M27/Statements!L27-1 -> 0.027116873 | L19: =Statements!N27/Statements!M27-1 -> 0.016268923
B21: Gross margin | E21: - | F21: =Statements!H29/Statements!G29-1 -> -0.009567753 | G21: =Statements!I29/Statements!H29-1 -> 0.068194717 | H21: =Statements!J29/Statements!I29-1 -> 0.080350669 | I21: =Statements!K29/Statements!J29-1 -> 0.080474588 | J21: =Statements!L29/Statements!K29-1 -> 0.10086443 | K21: =Statements!M29/Statements!L29-1 -> 0.11714227 | L21: =Statements!N29/Statements!M29-1 -> 0.13138483
B23: Operating expenses:
B24: Research and development | E24: - | F24: =Statements!H32/Statements!G32-1 -> 0.13957564 | G24: =Statements!I32/Statements!H32-1 -> 0.048637807 | H24: =Statements!J32/Statements!I32-1 -> 0.10137074 | I24: =Statements!K32/Statements!J32-1 -> 0.101 | J24: =Statements!L32/Statements!K32-1 -> 0.0945 | K24: =Statements!M32/Statements!L32-1 -> 0.088 | L24: =Statements!N32/Statements!M32-1 -> 0.0815
