Workbook
Name BS: Statements!$B$45
Name CF: Statements!$B$102
Name days: Dashboard!$G$17
Name Debt: Schedule!$B$73
Name EF: Scenario!$B$30
Name Equity: Schedule!$B$86
Name IS: Statements!$B$17
Name PPE: Schedule!$B$13
Name RE: Schedule!$B$86
Name RF: Scenario!$B$13
Name WC: Schedule!$B$45

Sheet Dashboard
B2: Borouge PLC
B3: Dashboard
B4: (In Millions AED, except equity share and per equity share data)
B6: Model Assumption | F6: Units:
B8: Company Name | G8: =B2 -> Borouge PLC
B9: Ticker | G9: BOROUGE
B10: Sector | G10: Manufacturing
B12: Selected Scenario | G12: Street
B14: Model Start Date | F14: Date | G14: =Statements!I7 -> 46022
B15: Model End Date | F15: Date | G15: =Statements!M7 -> 47483
B16: No. of Years Projected | F16: Years | G16: =YEARFRAC(G14,G15,1) -> 4.0005476
B17: Days in an Year | F17: Days | G17: 365
B20: Table of Contents
B21: Sl.No | C21: Particulars
B22: 1 | C22: Dashboard
C23: Financials
B24: 2 | C24: Statements
B25: 3 | C25: Scenario
B26: 4 | C26: Assumptions
B27: 5 | C27: Schedule
C28: Valuation
B29: 6 | C29: Beta
B30: 7 | C30: WACC
B31: 8 | C31: FCFF
B32: 9 | C32: Ratio Analysis
B33: 10 | C33: Analysis
C34: Report
B35: 11 | C35: Equity Report
B37: End

Sheet Financials->

Sheet Statements
B2: =Dashboard!B2 -> Borouge PLC
B3: Financial statements
B4: =Dashboard!B4 -> (In Millions AED, except equity share and per equity share data)
B5: Active Scenario | D5: =Dashboard!G12 -> Street
B6: Actuals / Projections | F6: Actuals | I6: Projections | N6: CAGR | P6: Notes
B7: Year | F7: 44926 | G7: =EDATE(F7,12) -> 45291 | H7: =EDATE(G7,12) -> 45657 | I7: =EDATE(H7,12) -> 46022 | J7: =EDATE(I7,12) -> 46387 | K7: =EDATE(J7,12) -> 46752 | L7: =EDATE(K7,12) -> 47118 | M7: =EDATE(L7,12) -> 47483 | N7: 23A - 25A | O7: 25A - 30E
B9: <-Back to dashboard
B11: Go to -> | C11: Income statement | E11: Balance statement
B13: Templete: | C13: Standard | E13: Currency: | F13: AED
B14: Period type: | C14: Annual | E14: Units: | F14: Millions
B15: Source: | C15: Company Website | E15: Decimals: | F15: Default
A17: # | B17: Income Statement | F17: 44926 | G17: 45291 | H17: 45657 | I17: 46022 | J17: 46387 | K17: 46752 | L17: 47118 | M17: 47483
B19: Revenue | F19: 3997.151 | G19: 5791.345 | H19: 6026.123 | I19: =Scenario!J18 -> 5937.12 | J19: =Scenario!K18 -> 7623 | K19: =Scenario!L18 -> 7878 | L19: =Scenario!M18 -> 8137 | M19: =Scenario!N18 -> 8400
B20: Cost of Sales | F20: =-Scenario!G44 -> -2111.911 | G20: =-Scenario!H44 -> -3100.68 | H20: =-Scenario!I44 -> -2971.44 | I20: =-Scenario!J44 -> -2771.3811 | J20: =-Scenario!K44 -> -3737.0797 | K20: =-Scenario!L44 -> -3725.8097 | L20: =-Scenario!M44 -> -3791.6428 | M20: =-Scenario!N44 -> -3912.19
B21: Gross Profit | F21: =SUM(F19:F20) -> 1885.24 | G21: =SUM(G19:G20) -> 2690.665 | H21: =SUM(H19:H20) -> 3054.683 | I21: =SUM(I19:I20) -> 3165.7389 | J21: =SUM(J19:J20) -> 3885.9203 | K21: =SUM(K19:K20) -> 4152.1903 | L21: =SUM(L19:L20) -> 4345.3572 | M21: =SUM(M19:M20) -> 4487.81 | N21: =_xlfn.RRI(2,F21,H21) -> 0.27291602 | O21: =_xlfn.RRI(4,I21,M21) -> 0.091163528
B23: Other Income | F23: 26.707 | G23: 17.35 | H23: 53.951 | I23: =Assumptions!I13 -> 36.869936 | J23: =Assumptions!J13 -> 46.141447 | K23: =Assumptions!K13 -> 55.712822 | L23: =Assumptions!L13 -> 52.442818 | M23: =Assumptions!M13 -> 54.795599
B24: General and administrative expenses | F24: -112.583 | G24: -182.915 | H24: -193.121 | I24: =-Scenario!J47 -> -181.67056 | J24: =-Scenario!K47 -> -239.43998 | K24: =-Scenario!L47 -> -246.99267 | L24: =-Scenario!M47 -> -253.22754 | M24: =-Scenario!N47 -> -262.87215
B25: Selling and distribution expenses | F25: -414.152 | G25: -399.495 | H25: -471.963 | I25: =-Scenario!J53 -> -496.56626 | J25: =-Scenario!K53 -> -586.81462 | K25: =-Scenario!L53 -> -627.44741 | L25: =-Scenario!M53 -> -651.67218 | M25: =-Scenario!N53 -> -662.79508
B26: Impairment loss on PPE & intangible assets | F26: -13.483 | G26: -1.731 | H26: -3.082 | I26: 0 | J26: 0 | K26: 0 | L26: 0 | M26: 0
B27: Operating Income | F27: =F21+SUM(F23:F26) -> 1371.729 | G27: =G21+SUM(G23:G26) -> 2123.874 | H27: =H21+SUM(H23:H26) -> 2440.468 | I27: =I21+SUM(I23:I26) -> 2524.372 | J27: =J21+SUM(J23:J26) -> 3105.8072 | K27: =K21+SUM(K23:K26) -> 3333.463 | L27: =L21+SUM(L23:L26) -> 3492.9003 | M27: =M21+SUM(M23:M26) -> 3616.9383 | N27: =_xlfn.RRI(2,F27,H27) -> 0.33383589 | O27: =_xlfn.RRI(4,I27,M27) -> 0.094074601
B29: Finance income | F29: 19.744 | G29: 26.815 | H29: 28.554 | I29: =Assumptions!I16 -> 28.316249 | J29: =Assumptions!J16 -> 35.924437 | K29: =Assumptions!K16 -> 37.342679 | L29: =Assumptions!L16 -> 38.575123 | M29: =Assumptions!M16 -> 39.741702
B30: Finance costs | F30: -95.841 | G30: -220.909 | H30: -202.025 | I30: =-Schedule!J82 -> -176 | J30: =-Schedule!K82 -> -148.14225 | K30: =-Schedule!L82 -> -94.949975 | L30: =-Schedule!M82 -> -165.70128 | M30: =-Schedule!N82 -> -112.25873
B31: Foreign exchange loss | F31: -2.622 | G31: -2.074 | H31: -2.139 | I31: 0 | J31: 0 | K31: 0 | L31: 0 | M31: 0
B32: Net finance loss | F32: =SUM(F29:F31) -> -78.719 | G32: =SUM(G29:G31) -> -196.168 | H32: =SUM(H29:H31) -> -175.61 | I32: =SUM(I29:I31) -> -147.68375 | J32: =SUM(J29:J31) -> -112.21781 | K32: =SUM(K29:K31) -> -57.607295 | L32: =SUM(L29:L31) -> -127.12616 | M32: =SUM(M29:M31) -> -72.517031
B34: Profit Before Tax | F34: =F27+F32 -> 1293.01 | G34: =G27+G32 -> 1927.706 | H34: =H27+H32 -> 2264.858 | I34: =I27+I32 -> 2376.6883 | J34: =J27+J32 -> 2993.5894 | K34: =K27+K32 -> 3275.8557 | L34: =L27+L32 -> 3365.7742 | M34: =M27+M32 -> 3544.4213 | N34: =_xlfn.RRI(2,F34,H34) -> 0.3234866 | O34: =_xlfn.RRI(4,I34,M34) -> 0.10507888
B36: Income tax expense | F36: -284.835 | G36: -400.333 | H36: -506.361 | I36: =-Assumptions!I19 -> -516.16483 | J36: =-Assumptions!J19 -> -647.0388 | K36: =-Assumptions!K19 -> -717.29513 | L36: =-Assumptions!L19 -> -731.81338 | M36: =-Assumptions!M19 -> -770.95135
B37: Profit After Tax | F37: =F34+F36 -> 1008.175 | G37: =G34+G36 -> 1527.373 | H37: =H34+H36 -> 1758.497 | I37: =I34+I36 -> 1860.5234 | J37: =J34+J36 -> 2346.5506 | K37: =K34+K36 -> 2558.5606 | L37: =L34+L36 -> 2633.9608 | M37: =M34+M36 -> 2773.4699 | N37: =_xlfn.RRI(2,F37,H37) -> 0.32069597 | O37: =_xlfn.RRI(4,I37,M37) -> 0.10496133
B39: Non controlling Interest | F39: -9.478 | G39: -9.545 | H39: -13.675 | I39: =-Assumptions!I22 -> -14.528806 | J39: =-Assumptions!J22 -> -17.078827 | K39: =-Assumptions!K22 -> -19.49946 | L39: =-Assumptions!L22 -> -19.937783 | M39: =-Assumptions!M22 -> -20.7724
B40: Net Income to Common | F40: =F37+F39 -> 998.697 | G40: =G37+G39 -> 1517.828 | H40: =H37+H39 -> 1744.822 | I40: =I37+I39 -> 1845.9946 | J40: =J37+J39 -> 2329.4717 | K40: =K37+K39 -> 2539.0611 | L40: =L37+L39 -> 2614.023 | M40: =M37+M39 -> 2752.6975 | N40: =_xlfn.RRI(2,F40,H40) -> 0.32177853 | O40: =_xlfn.RRI(4,I40,M40) -> 0.10505022
B42: Diluted EPS | F42: 0.02 | G42: 0.03 | H42: 0.04 | I42: =I40/I43 -> 0.06141505 | J42: =J40/J43 -> 0.077500021 | K42: =K40/K43 -> 0.084472925 | L42: =L40/L43 -> 0.086966858 | M42: =M40/M43 -> 0.09158047
B43: No. of Equity Shares | F43: 30057.692 | G43: 30057.692 | H43: 30057.692 | I43: =H43 -> 30057.692 | J43: =I43 -> 30057.692 | K43: =J43 -> 30057.692 | L43: =K43 -> 30057.692 | M43: =L43 -> 30057.692
A45: # | B45: Balance Sheet | F45: 44926 | G45: 45291 | H45: 45657 | I45: 46022 | J45: 46387 | K45: 46752 | L45: 47118 | M45: 47483
B47: Non Current Assets
B48: Property Plant & Equipment | F48: 7053.196 | G48: 6677.355 | H48: 6292.502 | I48: =Schedule!J28 -> 5954.0387 | J48: =Schedule!K28 -> 5588.6135 | K48: =Schedule!L28 -> 5260.2504 | L48: =Schedule!M28 -> 4981.1108 | M48: =Schedule!N28 -> 4731.0511
B49: Intangible Assets | F49: 55.616 | G49: 60.126 | H49: 60.643 | I49: =Schedule!J43 -> 45.256995 | J49: =Schedule!K43 -> 34.014071 | K49: =Schedule!L43 -> 27.119236 | L49: =Schedule!M43 -> 24.872841 | M49: =Schedule!N43 -> 27.682554
B50: Right-of-use assets | F50: 25.208 | G50: 27.304 | H50: 24.797 | I50: =H50 -> 24.797 | J50: =I50 -> 24.797 | K50: =J50 -> 24.797 | L50: =K50 -> 24.797 | M50: =L50 -> 24.797
B51: Investment in Sublease | F51: 135.052 | G51: 138.408 | H51: 135.789 | I51: =H51 -> 135.789 | J51: =I51 -> 135.789 | K51: =J51 -> 135.789 | L51: =K51 -> 135.789 | M51: =L51 -> 135.789
B52: Amounts due from related parties | F52: 2.606 | G52: 0 | H52: 0 | I52: =H52 -> 0 | J52: =I52 -> 0 | K52: =J52 -> 0 | L52: =K52 -> 0 | M52: =L52 -> 0
B53: Loans to employees | F53: 22.665 | G53: 22.769 | H53: 20.509 | I53: =H53 -> 20.509 | J53: =I53 -> 20.509 | K53: =J53 -> 20.509 | L53: =K53 -> 20.509 | M53: =L53 -> 20.509
B54: Deferred tax assets | F54: 0 | G54: 3.45 | H54: 2.397 | I54: =H54 -> 2.397 | J54: =I54 -> 2.397 | K54: =J54 -> 2.397 | L54: =K54 -> 2.397 | M54: =L54 -> 2.397
...

Sheet Scenario
B2: =Dashboard!B2 -> Borouge PLC
B3: Scenario
B4: =Dashboard!B4 -> (In Millions AED, except equity share and per equity share data)
B5: Active Scenario | D5: =Dashboard!G12 -> Street
B6: Actuals / Projections | G6: =Statements!F6 -> Actuals | J6: =Statements!I6 -> Projections | O6: CAGR | Q6: Notes
B7: Year | G7: =Statements!F7 -> 44926 | H7: =EDATE(G7,12) -> 45291 | I7: =EDATE(H7,12) -> 45657 | J7: =EDATE(I7,12) -> 46022 | K7: =EDATE(J7,12) -> 46387 | L7: =EDATE(K7,12) -> 46752 | M7: =EDATE(L7,12) -> 47118 | N7: =EDATE(M7,12) -> 47483 | O7: =Statements!N7 -> 23A - 25A | P7: 26E - 30E
B9: <-Back to dashboard
B11: Go to -> | C11: Revenue forecast | E11: Expense forecast
A13: # | B13: Revenue Forecast | G13: 44926 | H13: 45291 | I13: 45657 | J13: 46022 | K13: 46387 | L13: 46752 | M13: 47118 | N13: 47483
B15: Polyethylene | G15: 2245.241 | H15: 2409.258 | I15: 2431.35 | J15: =($I15/$I$18)*J$18 -> 2395.4401 | K15: =($I15/$I$18)*K$18 -> 3075.6394 | L15: =($I15/$I$18)*L$18 -> 3178.5238 | M15: =($I15/$I$18)*M$18 -> 3283.0221 | N15: =($I15/$I$18)*N$18 -> 3389.1343
B16: Polypropylene | G16: 1603.369 | H16: 3268.596 | I16: 3547.516 | J16: =($I16/$I$18)*J$18 -> 3495.1209 | K16: =($I16/$I$18)*K$18 -> 4487.5809 | L16: =($I16/$I$18)*L$18 -> 4637.6967 | M16: =($I16/$I$18)*M$18 -> 4790.1674 | N16: =($I16/$I$18)*N$18 -> 4944.9927
B17: Ethylene and others | G17: 148.541 | H17: 113.491 | I17: 47.257 | J17: =($I17/$I$18)*J$18 -> 46.559036 | K17: =($I17/$I$18)*K$18 -> 59.779747 | L17: =($I17/$I$18)*L$18 -> 61.779464 | M17: =($I17/$I$18)*M$18 -> 63.810548 | N17: =($I17/$I$18)*N$18 -> 65.873
B18: Net Revenue | G18: =SUM(G15:G17) -> 3997.151 | H18: =SUM(H15:H17) -> 5791.345 | I18: =SUM(I15:I17) -> 6026.123 | J18: =J21*J24 -> 5937.12 | K18: =K21*K24 -> 7623 | L18: =L21*L24 -> 7878 | M18: =M21*M24 -> 8137 | N18: =N21*N24 -> 8400 | O18: =_xlfn.RRI(2,G18,I18) -> 0.22784549 | P18: =_xlfn.RRI(4,J18,N18) -> 0.090626045
B19: yoy Revenue Growth (%) | H19: =H18/G18-1 -> 0.44886821 | I19: =I18/H18-1 -> 0.04053946 | J19: =J18/I18-1 -> -0.014769529 | K19: =K18/J18-1 -> 0.28395586 | L19: =L18/K18-1 -> 0.033451397 | M19: =M18/L18-1 -> 0.032876365 | N19: =N18/M18-1 -> 0.032321494
B21: Sales Volume (ktpa) | G21: 5083 | H21: 5116 | I21: 5335 | J21: 5208 | K21: 6600 | L21: =K21+($N$21-$K$21)/3 -> 6733.3333 | M21: =L21+($N$21-$K$21)/3 -> 6866.6667 | N21: 7000 | O21: =_xlfn.RRI(2,G21,I21) -> 0.024488663 | P21: =_xlfn.RRI(4,J21,N21) -> 0.076729882
B22: Sales Volume growth% | H22: =H21/G21-1 -> 0.006492229 | I22: =I21/H21-1 -> 0.04280688 | J22: =J21/I21-1 -> -0.023805061 | K22: =K21/J21-1 -> 0.26728111 | L22: =L21/K21-1 -> 0.02020202 | M22: =M21/L21-1 -> 0.01980198 | N22: =N21/M21-1 -> 0.019417476
B24: Price per unit ($/ktpa) | G24: =G18/G21 -> 0.78637635 | H24: =H18/H21 -> 1.1320065 | I24: =I18/I21 -> 1.1295451 | J24: =OFFSET(J24,MATCH($D$5,$B25:$B27,0),0) -> 1.14 | K24: =OFFSET(K24,MATCH($D$5,$B25:$B27,0),0) -> 1.155 | L24: =OFFSET(L24,MATCH($D$5,$B25:$B27,0),0) -> 1.17 | M24: =OFFSET(M24,MATCH($D$5,$B25:$B27,0),0) -> 1.185 | N24: =OFFSET(N24,MATCH($D$5,$B25:$B27,0),0) -> 1.2
B25: Optimistic | J25: =J26+$Q$25 -> 1.18 | K25: =K26+$Q$25 -> 1.195 | L25: =L26+$Q$25 -> 1.21 | M25: =M26+$Q$25 -> 1.225 | N25: =N26+$Q$25 -> 1.24 | Q25: 0.04
B26: Street | J26: 1.14 | K26: =J26+($N$26-$J$26)/4 -> 1.155 | L26: =K26+($N$26-$J$26)/4 -> 1.17 | M26: =L26+($N$26-$J$26)/4 -> 1.185 | N26: 1.2
B27: Pessimistic | J27: =J26+$Q$27 -> 1.11 | K27: =K26+$Q$27 -> 1.125 | L27: =L26+$Q$27 -> 1.14 | M27: =M26+$Q$27 -> 1.155 | N27: =N26+$Q$27 -> 1.17 | Q27: -0.03
A30: # | B30: Expenses forecast | G30: 44926 | H30: 45291 | I30: 45657 | J30: 46022 | K30: 46387 | L30: 46752 | M30: 47118 | N30: 47483
B32: Cost of production and other related costs | G32: 1921.335 | H32: 2782.311 | I32: 2633.07 | J32: =J33*J21 -> 2457.1061 | K32: =K33*K21 -> 3320.2091 | L32: =L33*L21 -> 3295.7488 | M32: =M33*M21 -> 3351.6754 | N32: =N33*N21 -> 3454.8213
B33: Cost of production as a % of Sales volume | G33: =G32/G21 -> 0.37799233 | H33: =H32/H21 -> 0.543845 | I33: =I32/I21 -> 0.49354639 | J33: =OFFSET(J33,MATCH($D$5,$B34:$B36,0),0) -> 0.47179457 | K33: =OFFSET(K33,MATCH($D$5,$B34:$B36,0),0) -> 0.50306199 | L33: =OFFSET(L33,MATCH($D$5,$B34:$B36,0),0) -> 0.48946765 | M33: =OFFSET(M33,MATCH($D$5,$B34:$B36,0),0) -> 0.48810807 | N33: =OFFSET(N33,MATCH($D$5,$B34:$B36,0),0) -> 0.4935459
B34: Optimistic | J34: =J35+$Q$34 -> 0.45179457 | K34: =K35+$Q$34 -> 0.48306199 | L34: =L35+$Q$34 -> 0.46946765 | M34: =M35+$Q$34 -> 0.46810807 | N34: =N35+$Q$34 -> 0.4735459 | Q34: -0.02
B35: Street | J35: =AVERAGE(G33:I33) -> 0.47179457 | K35: =AVERAGE(H33:J33) -> 0.50306199 | L35: =AVERAGE(I33:K33) -> 0.48946765 | M35: =AVERAGE(J35:L35) -> 0.48810807 | N35: =AVERAGE(K35:M35) -> 0.4935459
B36: Pessimistic | J36: =J35+$Q$36 -> 0.49579457 | K36: =K35+$Q$36 -> 0.52706199 | L36: =L35+$Q$36 -> 0.51346765 | M36: =M35+$Q$36 -> 0.51210807 | N36: =N35+$Q$36 -> 0.5175459 | Q36: 0.024
B38: Staff costs | G38: 190.576 | H38: 318.369 | I38: 338.37 | J38: =J39*J18 -> 314.27497 | K38: =K39*K18 -> 416.87056 | L38: =L39*L18 -> 430.06089 | M38: =M39*M18 -> 439.96736 | N38: =N39*N18 -> 457.36873
B39: Staff costs as a % of revenue | G39: =G38/G18 -> 0.047677959 | H39: =H38/H18 -> 0.05497324 | I39: =I38/I18 -> 0.05615053 | J39: =OFFSET(J39,MATCH($D$5,$B40:$B42,0),0) -> 0.05293391 | K39: =OFFSET(K39,MATCH($D$5,$B40:$B42,0),0) -> 0.054685893 | L39: =OFFSET(L39,MATCH($D$5,$B40:$B42,0),0) -> 0.054590111 | M39: =OFFSET(M39,MATCH($D$5,$B40:$B42,0),0) -> 0.054069971 | N39: =OFFSET(N39,MATCH($D$5,$B40:$B42,0),0) -> 0.054448658
B40: Optimistic | J40: =J41+$Q$34 -> 0.03293391 | K40: =K41+$Q$34 -> 0.034685893 | L40: =L41+$Q$34 -> 0.034590111 | M40: =M41+$Q$34 -> 0.034069971 | N40: =N41+$Q$34 -> 0.034448658 | Q40: -0.02
B41: Street | J41: =AVERAGE(G39:I39) -> 0.05293391 | K41: =AVERAGE(H39:J39) -> 0.054685893 | L41: =AVERAGE(I39:K39) -> 0.054590111 | M41: =AVERAGE(J41:L41) -> 0.054069971 | N41: =AVERAGE(K41:M41) -> 0.054448658
B42: Pessimistic | J42: =J41+$Q$36 -> 0.07693391 | K42: =K41+$Q$36 -> 0.078685893 | L42: =L41+$Q$36 -> 0.078590111 | M42: =M41+$Q$36 -> 0.078069971 | N42: =N41+$Q$36 -> 0.078448658 | Q42: 0.024
B44: Total Cost of Sales | G44: =G32+G38 -> 2111.911 | H44: =H32+H38 -> 3100.68 | I44: =I32+I38 -> 2971.44 | J44: =J32+J38 -> 2771.3811 | K44: =K32+K38 -> 3737.0797 | L44: =L32+L38 -> 3725.8097 | M44: =M32+M38 -> 3791.6428 | N44: =N32+N38 -> 3912.19 | O44: =_xlfn.RRI(2,G44,I44) -> 0.18616656 | P44: =_xlfn.RRI(4,J44,N44) -> 0.090011106
B45: yoy Total cost of sales (%) | H45: =H44/G44-1 -> 0.46818687 | I45: =I44/H44-1 -> -0.04168118 | J45: =J44/I44-1 -> -0.067327254 | K45: =K44/J44-1 -> 0.34845391 | L45: =L44/K44-1 -> -0.0030157072 | M45: =M44/L44-1 -> 0.017669455 | N45: =N44/M44-1 -> 0.031792889
B47: General and administrative expenses | G47: =-Statements!F24 -> 112.583 | H47: =-Statements!G24 -> 182.915 | I47: =-Statements!H24 -> 193.121 | J47: =J48*J18 -> 181.67056 | K47: =K48*K18 -> 239.43998 | L47: =L48*L18 -> 246.99267 | M47: =M48*M18 -> 253.22754 | N47: =N48*N18 -> 262.87215 | O47: =_xlfn.RRI(2,G47,I47) -> 0.30971965 | P47: =_xlfn.RRI(4,J47,N47) -> 0.096768597
B48: G&A expenses as a % of revenue | G48: =G47/G18 -> 0.028165811 | H48: =H47/H18 -> 0.0315842 | I48: =I47/I18 -> 0.032047305 | J48: =OFFSET(J48,MATCH($D$5,$B49:$B51,0),0) -> 0.030599105 | K48: =OFFSET(K48,MATCH($D$5,$B49:$B51,0),0) -> 0.031410203 | L48: =OFFSET(L48,MATCH($D$5,$B49:$B51,0),0) -> 0.031352204 | M48: =OFFSET(M48,MATCH($D$5,$B49:$B51,0),0) -> 0.031120504 | N48: =OFFSET(N48,MATCH($D$5,$B49:$B51,0),0) -> 0.031294304
B49: Optimistic | J49: =J50+$Q$49 -> 0.023099105 | K49: =K50+$Q$49 -> 0.023910203 | L49: =L50+$Q$49 -> 0.023852204 | M49: =M50+$Q$49 -> 0.023620504 | N49: =N50+$Q$49 -> 0.023794304 | Q49: -0.0075
B50: Street | J50: =AVERAGE(G48:I48) -> 0.030599105 | K50: =AVERAGE(H48:J48) -> 0.031410203 | L50: =AVERAGE(I48:K48) -> 0.031352204 | M50: =AVERAGE(J48:L48) -> 0.031120504 | N50: =AVERAGE(K48:M48) -> 0.031294304
B51: Pessimistic | J51: =J50+$Q$51 -> 0.043099105 | K51: =K50+$Q$51 -> 0.043910203 | L51: =L50+$Q$51 -> 0.043852204 | M51: =M50+$Q$51 -> 0.043620504 | N51: =N50+$Q$51 -> 0.043794304 | Q51: 0.0125
B53: Selling and distribution expenses | G53: =-Statements!F25 -> 414.152 | H53: =-Statements!G25 -> 399.495 | I53: =-Statements!H25 -> 471.963 | J53: =J54*J18 -> 496.56626 | K53: =K54*K18 -> 586.81462 | L53: =L54*L18 -> 627.44741 | M53: =M54*M18 -> 651.67218 | N53: =N54*N18 -> 662.79508 | O53: =_xlfn.RRI(2,G53,I53) -> 0.067515268 | P53: =_xlfn.RRI(4,J53,N53) -> 0.074856579
B54: S&D expenses as a % of revenue | G54: =G53/G18 -> 0.1036118 | H54: =H53/H18 -> 0.068981385 | I54: =I53/I18 -> 0.07831951 | J54: =OFFSET(J54,MATCH($D$5,$B55:$B57,0),0) -> 0.083637564 | K54: =OFFSET(K54,MATCH($D$5,$B55:$B57,0),0) -> 0.076979486 | L54: =OFFSET(L54,MATCH($D$5,$B55:$B57,0),0) -> 0.07964552 | M54: =OFFSET(M54,MATCH($D$5,$B55:$B57,0),0) -> 0.080087524 | N54: =OFFSET(N54,MATCH($D$5,$B55:$B57,0),0) -> 0.078904177
...

Sheet Assumptions
B2: =Dashboard!B2 -> Borouge PLC
B3: Assumptions
B4: =Dashboard!B4 -> (In Millions AED, except equity share and per equity share data)
B5: Active Scenario | D5: =Dashboard!G12 -> Street
B6: Actuals / Projections | F6: Historicals | I6: Forecast | N6: CAGR | P6: Notes
B7: Year | F7: =Statements!F7 -> 44926 | G7: =EDATE(F7,12) -> 45291 | H7: =EDATE(G7,12) -> 45657 | I7: =EDATE(H7,12) -> 46022 | J7: =EDATE(I7,12) -> 46387 | K7: =EDATE(J7,12) -> 46752 | L7: =EDATE(K7,12) -> 47118 | M7: =EDATE(L7,12) -> 47483 | N7: =Statements!N7 -> 23A - 25A | O7: 26E - 30E
B9: <-Back to dashboard
A11: # | B11: Assumptions | F11: 44926 | G11: 45291 | H11: 45657 | I11: 46022 | J11: 46387 | K11: 46752 | L11: 47118 | M11: 47483
B13: Other Income | F13: =Statements!F23 -> 26.707 | G13: =Statements!G23 -> 17.35 | H13: =Statements!H23 -> 53.951 | I13: =I14*Statements!I19 -> 36.869936 | J13: =J14*Statements!J19 -> 46.141447 | K13: =K14*Statements!K19 -> 55.712822 | L13: =L14*Statements!L19 -> 52.442818 | M13: =M14*Statements!M19 -> 54.795599
B14: Other income as a % of revenue | F14: =F13/Statements!F19 -> 0.0066815089 | G14: =G13/Statements!G19 -> 0.0029958498 | H14: =H13/Statements!H19 -> 0.0089528541 | I14: =AVERAGE(F14:H14) -> 0.0062100709 | J14: =AVERAGE(G14:I14) -> 0.006052925 | K14: =AVERAGE(H14:J14) -> 0.00707195 | L14: =AVERAGE(I14:K14) -> 0.006444982 | M14: =AVERAGE(J14:L14) -> 0.0065232856
B16: Finance Income | F16: =Statements!F29 -> 19.744 | G16: =Statements!G29 -> 26.815 | H16: =Statements!H29 -> 28.554 | I16: =I17*Statements!I19 -> 28.316249 | J16: =J17*Statements!J19 -> 35.924437 | K16: =K17*Statements!K19 -> 37.342679 | L16: =L17*Statements!L19 -> 38.575123 | M16: =M17*Statements!M19 -> 39.741702
B17: Finance income as a % of revenue | F17: =F16/Statements!F19 -> 0.0049395182 | G17: =G16/Statements!G19 -> 0.0046301852 | H17: =H16/Statements!H19 -> 0.0047383699 | I17: =AVERAGE(F17:H17) -> 0.0047693578 | J17: =AVERAGE(G17:I17) -> 0.0047126376 | K17: =AVERAGE(H17:J17) -> 0.0047401218 | L17: =AVERAGE(I17:K17) -> 0.0047407057 | M17: =AVERAGE(J17:L17) -> 0.004731155
B19: Income taxes | F19: =-Statements!F36 -> 284.835 | G19: =-Statements!G36 -> 400.333 | H19: =-Statements!H36 -> 506.361 | I19: =I20*Statements!I34 -> 516.16483 | J19: =J20*Statements!J34 -> 647.0388 | K19: =K20*Statements!K34 -> 717.29513 | L19: =L20*Statements!L34 -> 731.81338 | M19: =M20*Statements!M34 -> 770.95135
B20: Income taxes as a % of PBT | F20: =F19/Statements!F34 -> 0.22028832 | G20: =G19/Statements!G34 -> 0.20767327 | H20: =H19/Statements!H34 -> 0.22357296 | I20: =AVERAGE(F20:H20) -> 0.21717818 | J20: =AVERAGE(G20:I20) -> 0.21614147 | K20: =AVERAGE(H20:J20) -> 0.2189642 | L20: =AVERAGE(I20:K20) -> 0.21742795 | M20: =AVERAGE(J20:L20) -> 0.21751121
B22: Non-controlling interests | F22: =-Statements!F39 -> 9.478 | G22: =-Statements!G39 -> 9.545 | H22: =-Statements!H39 -> 13.675 | I22: =I23*Statements!I37 -> 14.528806 | J22: =J23*Statements!J37 -> 17.078827 | K22: =K23*Statements!K37 -> 19.49946 | L22: =L23*Statements!L37 -> 19.937783 | M22: =M23*Statements!M37 -> 20.7724
B23: NCI as a % of PAT | F23: =F22/Statements!F37 -> 0.0094011456 | G23: =G22/Statements!G37 -> 0.0062492921 | H23: =H22/Statements!H37 -> 0.0077765273 | I23: =AVERAGE(F23:H23) -> 0.0078089884 | J23: =AVERAGE(G23:I23) -> 0.0072782693 | K23: =AVERAGE(H23:J23) -> 0.0076212617 | L23: =AVERAGE(I23:K23) -> 0.0075695064 | M23: =AVERAGE(J23:L23) -> 0.0074896791
B25: Dividends issued | F25: 324.927 | G25: 1299.704 | H25: 1299.704 | I25: =I26*Statements!I40 -> 1185.4577 | J25: =J26*Statements!J40 -> 1741.9497 | K25: =K26*Statements!K40 -> 1806.8448 | L25: =L26*Statements!L40 -> 1831.1972 | M25: =M26*Statements!M40 -> 1981.8827
B26: Dividends issued as a % of Net income | F26: =F25/Statements!F40 -> 0.32535093 | G26: =G25/Statements!G40 -> 0.85629202 | H26: =H25/Statements!H40 -> 0.74489203 | I26: =AVERAGE(F26:H26) -> 0.64217833 | J26: =AVERAGE(G26:I26) -> 0.74778746 | K26: =AVERAGE(H26:J26) -> 0.71161927 | L26: =AVERAGE(I26:K26) -> 0.70052835 | M26: =AVERAGE(J26:L26) -> 0.71997836

Sheet Schedule
B2: =Dashboard!B2 -> Borouge PLC
B3: Schedule
B4: =Dashboard!B4 -> (In Millions AED, except equity share and per equity share data)
B5: Active Scenario | D5: =Dashboard!G12 -> Street
B6: Actuals / Projections | G6: =Statements!F6 -> Actuals | J6: Forecast
B7: Year | G7: =Statements!F7 -> 44926 | H7: =EDATE(G7,12) -> 45291 | I7: =EDATE(H7,12) -> 45657 | J7: =EDATE(I7,12) -> 46022 | K7: =EDATE(J7,12) -> 46387 | L7: =EDATE(K7,12) -> 46752 | M7: =EDATE(L7,12) -> 47118 | N7: =EDATE(M7,12) -> 47483
B9: <-Back to dashboard
B11: Go to -> | C11: PPE and intangibles | E11: Working capital | G11: Debt Schedule | H11: Equity schedule
A13: # | B13: Property, plant, and equipment, Intangible schedule | G13: 44926 | H13: 45291 | I13: 45657 | J13: 46022 | K13: 46387 | L13: 46752 | M13: 47118 | N13: 47483
B15: Property, plant and equipment
B17: CapEx on PPE | G17: 112.976 | H17: 191.504 | I17: 160.124 | J17: =J18*J23 -> 157.59566 | K17: =K18*K23 -> 193.03153 | L17: =L18*L23 -> 229.55306 | M17: =M18*M23 -> 267.40157 | N17: =N18*N23 -> 307.14902
B18: CapEx as a % of Gross PPE | G18: =G17/G23 -> 0.0083311727 | H18: =H17/H23 -> 0.01401396 | I18: =I17/I23 -> 0.01158639 | J18: =AVERAGE(G18:I18) -> 0.011310507 | K18: =J18+($N$18-$J$18)/4 -> 0.013732881 | L18: =K18+($N$18-$J$18)/4 -> 0.016155254 | M18: =L18+($N$18-$J$18)/4 -> 0.018577627 | N18: 0.021
B20: Depreciation on PPE | G20: 297.117 | H20: 539.612 | I20: 524.116 | J20: =J21*J26 -> 461.05895 | K20: =K21*K26 -> 518.45675 | L20: =L21*L26 -> 512.9162 | M20: =M21*M26 -> 511.5411 | N20: =N21*N26 -> 532.20879
B21: Depreciation as a % of Closing gross PPE | G21: =G20/G26 -> 0.021742552 | H21: =H20/H26 -> 0.039045708 | I21: =I20/I26 -> 0.037615364 | J21: =AVERAGE(G21:I21) -> 0.032801208 | K21: =AVERAGE(H21:J21) -> 0.036487427 | L21: =AVERAGE(I21:K21) -> 0.035634666 | M21: =AVERAGE(J21:L21) -> 0.034974434 | N21: =AVERAGE(K21:M21) -> 0.035698842
B23: Opening balalnce of Gross PPE | G23: 13560.636 | H23: =G26 -> 13665.231 | I23: =H26 -> 13820.008 | J23: =I26 -> 13933.562 | K23: =J26 -> 14056.158 | L23: =K26 -> 14209.189 | M23: =L26 -> 14393.742 | N23: =M26 -> 14626.144
B24: Additions to PPE | J24: =J17 -> 157.59566 | K24: =K17 -> 193.03153 | L24: =L17 -> 229.55306 | M24: =M17 -> 267.40157 | N24: =N17 -> 307.14902
B25: Disposal of PPE | J25: -35 | K25: -40 | L25: -45 | M25: -35 | N25: -25
B26: Closing balance of Gross PPE | G26: 13665.231 | H26: 13820.008 | I26: 13933.562 | J26: =SUM(J23:J25) -> 14056.158 | K26: =SUM(K23:K25) -> 14209.189 | L26: =SUM(L23:L25) -> 14393.742 | M26: =SUM(M23:M25) -> 14626.144 | N26: =SUM(N23:N25) -> 14908.293
B27: Accumulated depreciation | I27: -7641.06 | J27: =I27-J20 -> -8102.119 | K27: =J27-K20 -> -8620.5757 | L27: =K27-L20 -> -9133.4919 | M27: =L27-M20 -> -9645.033 | N27: =M27-N20 -> -10177.242
B28: Closing balance of Net PPE block | J28: =SUM(J26:J27) -> 5954.0387 | K28: =SUM(K26:K27) -> 5588.6135 | L28: =SUM(L26:L27) -> 5260.2504 | M28: =SUM(M26:M27) -> 4981.1108 | N28: =SUM(N26:N27) -> 4731.0511
B31: Intangible assets
B33: Capex on intangible assets | G33: 0.882 | H33: 7.276 | I33: 7.259 | J33: =J34*J39 -> 8.829675 | K33: =K34*K39 -> 11.313021 | L33: =L34*L39 -> 13.999864 | M33: =M34*M39 -> 16.945668 | N33: =N34*N39 -> 20.213761
B34: Capex as a % of gross intangibles | G34: =G33/G39 -> 0.0034452587 | H34: =H33/H39 -> 0.023348951 | I34: =I33/I39 -> 0.021030704 | J34: 0.025 | K34: =J34+($N$34-$J$34)/4 -> 0.03125 | L34: =K34+($N$34-$J$34)/4 -> 0.0375 | M34: =L34+($N$34-$J$34)/4 -> 0.04375 | N34: 0.05
B36: Amortisation of intangible assets | G36: 10.608 | H36: 28.181 | I36: 23.748 | J36: =J37*J41 -> 24.21568 | K36: =K37*K41 -> 22.555945 | L36: =L37*L41 -> 20.894699 | M36: =M37*M41 -> 19.192063 | N36: =N37*N41 -> 17.404049
B37: Amortisation as a % of gross closing intangibles | G37: =G36/G39 -> 0.041436853 | H37: =H36/H39 -> 0.090433862 | I37: =I36/I39 -> 0.068802475 | J37: =AVERAGE(G37:I37) -> 0.066891063 | K37: =J37+($N$37-$J$37)/4 -> 0.060418297 | L37: =K37+($N$37-$J$37)/4 -> 0.053945532 | M37: =L37+($N$37-$J$37)/4 -> 0.047472766 | N37: 0.041
B39: Opening balance of intangible assets | G39: 256.004 | H39: =G41 -> 311.62 | I39: =H41 -> 345.162 | J39: =I41 -> 353.187 | K39: =J41 -> 362.01668 | L39: =K41 -> 373.3297 | M39: =L41 -> 387.32956 | N39: =M41 -> 404.27523
B40: Additions to intangible assets | J40: =J33 -> 8.829675 | K40: =K33 -> 11.313021 | L40: =L33 -> 13.999864 | M40: =M33 -> 16.945668 | N40: =N33 -> 20.213761
B41: Closing balance of intangible assets | G41: 311.62 | H41: 345.162 | I41: 353.187 | J41: =SUM(J39:J40) -> 362.01668 | K41: =SUM(K39:K40) -> 373.3297 | L41: =SUM(L39:L40) -> 387.32956 | M41: =SUM(M39:M40) -> 404.27523 | N41: =SUM(N39:N40) -> 424.48899
B42: Accumulated amortisation | I42: -292.544 | J42: =I42-J36 -> -316.75968 | K42: =J42-K36 -> -339.31562 | L42: =K42-L36 -> -360.21032 | M42: =L42-M36 -> -379.40239 | N42: =M42-N36 -> -396.80644
B43: Closing balance of Net intangible assets | J43: =SUM(J41:J42) -> 45.256995 | K43: =SUM(K41:K42) -> 34.014071 | L43: =SUM(L41:L42) -> 27.119236 | M43: =SUM(M41:M42) -> 24.872841 | N43: =SUM(N41:N42) -> 27.682554
A45: # | B45: Working capital schedule | G45: 44926 | H45: 45291 | I45: 45657 | J45: 46022 | K45: 46387 | L45: 46752 | M45: 47118 | N45: 47483
B47: Current assets
B49: Inventories | G49: =Statements!F59 -> 654.639 | H49: =Statements!G59 -> 645.184 | I49: =Statements!H59 -> 640.505 | J49: =J66*Statements!I$19/days -> 631.04504 | K49: =K66*Statements!J$19/days -> 810.23398 | L49: =L66*Statements!K$19/days -> 837.33744 | M49: =M66*Statements!L$19/days -> 864.86605 | N49: =N66*Statements!M$19/days -> 892.81981
B50: Amounts due from related parties | G50: =Statements!F60 -> 193.762 | H50: =Statements!G60 -> 181.549 | I50: =Statements!H60 -> 209.937 | J50: =J67*Statements!I$19/days -> 206.83633 | K50: =K67*Statements!J$19/days -> 265.56872 | L50: =L67*Statements!K$19/days -> 274.45236 | M50: =M67*Statements!L$19/days -> 283.47536 | N50: =N67*Statements!M$19/days -> 292.6377
B51: Trade Receivables | G51: =Statements!F61 -> 890.339 | H51: =Statements!G61 -> 796.682 | I51: =Statements!H61 -> 858.768 | J51: =J68*Statements!I$19/days -> 846.0844 | K51: =K68*Statements!J$19/days -> 1086.335 | L51: =L68*Statements!K$19/days -> 1122.6744 | M51: =M68*Statements!L$19/days -> 1159.5839 | N51: =N68*Statements!M$19/days -> 1197.0634
B52: Prepayments and other receivables | G52: =Statements!F64 -> 47.059 | H52: =Statements!G64 -> 20.345 | I52: =Statements!H64 -> 23.917 | J52: =J69*Statements!I$19/days -> 23.563757 | K52: =K69*Statements!J$19/days -> 30.254824 | L52: =L69*Statements!K$19/days -> 31.26689 | M52: =M69*Statements!L$19/days -> 32.294832 | N52: =N69*Statements!M$19/days -> 33.338649
B54: Current liabilities
B56: Trade and other payables | G56: =Statements!F79 -> 369.761 | H56: =Statements!G79 -> 308.333 | I56: =Statements!H79 -> 356.66 | J56: =J70*-Statements!I$20/days -> 332.64706 | K56: =K70*-Statements!J$20/days -> 448.55923 | L56: =L70*-Statements!K$20/days -> 447.20651 | M56: =M70*-Statements!L$20/days -> 455.1084 | N56: =N70*-Statements!M$20/days -> 469.57761
B57: Amounts due to related parties | G57: =Statements!F80 -> 613.621 | H57: =Statements!G80 -> 532.645 | I57: =Statements!H80 -> 520.26 | J57: =J71*-Statements!I$20/days -> 485.23232 | K57: =K71*-Statements!J$20/days -> 654.31342 | L57: =L71*-Statements!K$20/days -> 652.3402 | M57: =M71*-Statements!L$20/days -> 663.8667 | N57: =N71*-Statements!M$20/days -> 684.97294
B59: Current assets | G59: =SUM(G49:G52) -> 1785.799 | H59: =SUM(H49:H52) -> 1643.76 | I59: =SUM(I49:I52) -> 1733.127 | J59: =SUM(J49:J52) -> 1707.5295 | K59: =SUM(K49:K52) -> 2192.3925 | L59: =SUM(L49:L52) -> 2265.7311 | M59: =SUM(M49:M52) -> 2340.2201 | N59: =SUM(N49:N52) -> 2415.8596
...

Sheet Valuation->
A1: \

Sheet Beta
B2: =Dashboard!B2 -> Borouge PLC
B3: Beta
B4: =Dashboard!B4 -> (In Millions AED, except equity share and per equity share data)
B5: Active Scenario | D5: =Dashboard!G12 -> Street | O5: SUMMARY OUTPUT
O7: Regression Statistics
B8: <-Back to dashboard | O8: Multiple R | P8: 0.28929509
O9: R Square | P9: 0.083691648
B10: (The historical data starts from 12/06/2022 to 01/03/2026) | O10: Adjusted R Square | P10: 0.078843455
B11: Borouge PLC | F11: FTSE ADX | J11: Beta Drifting | O11: Standard Error | P11: 0.020109886
O12: Observations | P12: 191
B13: Date | C13: Price | D13: Returns | F13: Date | G13: Price | H13: Returns | J13: Calculated beta | L13: =P22 -> 0.44894895
B14: 46082 | C14: 2.59 | F14: 46082 | G14: 10044.85 | O14: ANOVA
B15: 46075 | C15: 2.59 | D15: =C15/C14-1 -> 0 | F15: 46075 | G15: 10453.88 | H15: =G15/G14-1 -> 0.040720369 | J15: Levered beta | L15: =L13 -> 0.44894895 | P15: df | Q15: SS | R15: MS | S15: F | T15: Significance F
B16: 46068 | C16: 2.6 | D16: =C16/C15-1 -> 0.0038610039 | F16: 46068 | G16: 10580.85 | H16: =G16/G15-1 -> 0.01214573 | J16: Raw beta weight | L16: 0.75 | O16: Regression | P16: 1 | Q16: 0.006981062 | R16: 0.006981062 | S16: 17.262444 | T16: 4.9277162e-05
B17: 46061 | C17: 2.63 | D17: =C17/C16-1 -> 0.011538462 | F17: 46061 | G17: 10636.48 | H17: =G17/G16-1 -> 0.0052576116 | O17: Residual | P17: 189 | Q17: 0.07643302 | R17: 0.00040440751
B18: 46054 | C18: 2.6 | D18: =C18/C17-1 -> -0.011406844 | F18: 46054 | G18: 10563.11 | H18: =G18/G17-1 -> -0.0068979587 | J18: Market beta | L18: =SLOPE(H15:H206,H15:H206) -> 1 | O18: Total | P18: 190 | Q18: 0.083414082
B19: 46047 | C19: 2.61 | D19: =C19/C18-1 -> 0.0038461538 | F19: 46047 | G19: 10281.76 | H19: =G19/G18-1 -> -0.026635148 | J19: Raw beta weight | L19: 0.25
B20: 46040 | C20: 2.61 | D20: =C20/C19-1 -> 0 | F20: 46040 | G20: 10285.77 | H20: =G20/G19-1 -> 0.00039001105 | P20: Coefficients | Q20: Standard Error | R20: t Stat | S20: P-value | T20: Lower 95% | U20: Upper 95% | V20: Lower 95.0% | W20: Upper 95.0%
B21: 46033 | C21: 2.59 | D21: =C21/C20-1 -> -0.0076628352 | F21: 46033 | G21: 10123.26 | H21: =G21/G20-1 -> -0.015799498 | J21: Adjusted beta | L21: =L15*L16+L18*L19 -> 0.58671171 | O21: Intercept | P21: 0.0012561054 | Q21: 0.0014557658 | R21: 0.86284857 | S21: 0.38931429 | T21: -0.001615531 | U21: 0.0041277419 | V21: -0.001615531 | W21: 0.0041277419
B22: 46026 | C22: 2.58 | D22: =C22/C21-1 -> -0.0038610039 | F22: 46026 | G22: 10009.62 | H22: =G22/G21-1 -> -0.011225633 | O22: 0.040720369 | P22: 0.44894895 | Q22: 0.10805524 | R22: 4.1548097 | S22: 4.9277162e-05 | T22: 0.23579972 | U22: 0.66209818 | V22: 0.23579972 | W22: 0.66209818
B23: 46019 | C23: 2.6 | D23: =C23/C22-1 -> 0.007751938 | F23: 46019 | G23: 9994.57 | H23: =G23/G22-1 -> -0.0015035536 | J23: Total years | L23: =YEARFRAC(F206,F14,1) -> 3.7185104
B24: 46012 | C24: 2.61 | D24: =C24/C23-1 -> 0.0038461538 | F24: 46012 | G24: 10032.86 | H24: =G24/G23-1 -> 0.0038310803 | J24: Market returns (%) | L24: =_xlfn.RRI(L23,G206,G14) -> 0.014974912
B25: 46005 | C25: 2.55 | D25: =C25/C24-1 -> -0.022988506 | F25: 46005 | G25: 9967.21 | H25: =G25/G24-1 -> -0.0065434981
B26: 45998 | C26: 2.54 | D26: =C26/C25-1 -> -0.0039215686 | F26: 45998 | G26: 9988.71 | H26: =G26/G25-1 -> 0.002157073
B27: 45991 | C27: 2.52 | D27: =C27/C26-1 -> -0.0078740157 | F27: 45991 | G27: 9950.9 | H27: =G27/G26-1 -> -0.0037852736
B28: 45984 | C28: 2.5 | D28: =C28/C27-1 -> -0.0079365079 | F28: 45984 | G28: 9747.17 | H28: =G28/G27-1 -> -0.020473525
B29: 45977 | C29: 2.51 | D29: =C29/C28-1 -> 0.004 | F29: 45977 | G29: 9795.37 | H29: =G29/G28-1 -> 0.0049450251
B30: 45970 | C30: 2.5 | D30: =C30/C29-1 -> -0.0039840637 | F30: 45970 | G30: 9917.9 | H30: =G30/G29-1 -> 0.012508971
B31: 45963 | C31: 2.51 | D31: =C31/C30-1 -> 0.004 | F31: 45963 | G31: 10075.12 | H31: =G31/G30-1 -> 0.015852146
B32: 45956 | C32: 2.51 | D32: =C32/C31-1 -> 0 | F32: 45956 | G32: 10099.9 | H32: =G32/G31-1 -> 0.0024595241
B33: 45949 | C33: 2.58 | D33: =C33/C32-1 -> 0.027888446 | F33: 45949 | G33: 10201.57 | H33: =G33/G32-1 -> 0.010066436
B34: 45942 | C34: 2.59 | D34: =C34/C33-1 -> 0.003875969 | F34: 45942 | G34: 10124.42 | H34: =G34/G33-1 -> -0.0075625614
B35: 45935 | C35: 2.63 | D35: =C35/C34-1 -> 0.015444015 | F35: 45935 | G35: 10113.91 | H35: =G35/G34-1 -> -0.0010380842
B36: 45928 | C36: 2.54 | D36: =C36/C35-1 -> -0.034220532 | F36: 45928 | G36: 10072.8 | H36: =G36/G35-1 -> -0.004064699
... B206: 44724 | C206: 3.05 | D206: =C206/C205-1 -> 0.033898305 | F206: 44724 | G206: 9504.72 | H206: =G206/G205-1 -> 0.028150853

Sheet WACC
B2: =Dashboard!B2 -> Borouge PLC
B3: WACC
B4: =Dashboard!B4 -> (In Millions AED, except equity share and per equity share data)
B5: Active Scenario | D5: =Dashboard!G12 -> Street
B7: <-Back to dashboard
B9: Cost of Equity | G9: Capital Structure
B10: Risk free rate | D10: 0.04875 | G10: Equity Value | H10: 77260
B11: Equity risk premium | D11: 0.0487 | G11: Total Debt | H11: 11430
B12: Country risk premium | D12: 0.0064 | G12: Total Capital | H12: =H10+H11 -> 88690
B13: Levered beta | D13: =Beta!L21 -> 0.58671171
B14: Cost of equity | D14: =D10+(D11*D13)+D12 -> 0.08372286 | G14: Equity value / Total cap | H14: =H10/H12 -> 0.87112414
G15: Total debt / Total cap | H15: =1-H14 -> 0.12887586
B16: Cost of Debt
B17: (Using Interest expense/Total debt) | G17: WACC
B18: Pre-tax cost of debt | D18: =-Statements!H30/Statements!H73 -> 0.068620291 | G18: Cost of Equity | H18: =D14*H14 -> 0.072933005
B19: Tax Rate | D19: 0.21 | G19: Cost of Debt | H19: =D20*H15 -> 0.0069863643
B20: Post-tax cost of debt | D20: =D18*(1-D19) -> 0.05421003 | G20: WACC | H20: =H18+H19 -> 0.079919369

Sheet DCF
B2: =Dashboard!B2 -> Borouge PLC
B3: FCFF
B4: =Dashboard!B4 -> (In Millions AED, except equity share and per equity share data)
B5: Active Scenario | D5: =Dashboard!G12 -> Street
B7: <-Back to dashboard
B9: Valuation parameters
B10: Valuation as on specified date | E10: 45657 | G10: Implied Share Price | I10: =E34 -> 1.3570401
B11: Date of year ending | E11: 45657 | G11: Current Share Price | I11: 2.55
B12: WACC | E12: =WACC!H20 -> 0.079919369
B13: Terminal growth rate | E13: 0.02
B15: Free Cash Flow to Firm | E15: =Statements!I7 -> 46022 | F15: =EDATE(E15,12) -> 46387 | G15: =EDATE(F15,12) -> 46752 | H15: =EDATE(G15,12) -> 47118 | I15: =EDATE(H15,12) -> 47483
B17: EBIT | E17: =Statements!F27-Statements!F23 -> 1345.022 | F17: =Statements!G27-Statements!G23 -> 2106.524 | G17: =Statements!H27-Statements!H23 -> 2386.517 | H17: =Statements!I27-Statements!I23 -> 2487.5021 | I17: =Statements!J27-Statements!J23 -> 3059.6657
B18: Tax rate (%) | E18: 0.21 | F18: 0.21 | G18: 0.21 | H18: 0.21 | I18: 0.21
B19: NOPAT | E19: =E17*(1-E18) -> 1062.5674 | F19: =F17*(1-F18) -> 1664.154 | G19: =G17*(1-G18) -> 1885.3484 | H19: =H17*(1-H18) -> 1965.1266 | I19: =I17*(1-I18) -> 2417.1359
B21: Add: Depreciation and Amortisation | E21: =Statements!I107 -> 485.27463 | F21: =Statements!J107 -> 541.01269 | G21: =Statements!K107 -> 533.8109 | H21: =Statements!L107 -> 530.73316 | I21: =Statements!M107 -> 549.61284
B22: Add/Less: Change in NWC | E22: =Schedule!J62 -> 33.443146 | F22: =Schedule!K62 -> 199.86975 | G22: =Schedule!L62 -> 76.664534 | H22: =Schedule!M62 -> 55.060611 | I22: =Schedule!N62 -> 40.063961
B23: Less: Capital Expenditure | E23: =-Schedule!J17+Schedule!J33 -> -148.76598 | F23: =-Schedule!K17+Schedule!K33 -> -181.71851 | G23: =-Schedule!L17+Schedule!L33 -> -215.55319 | H23: =-Schedule!M17+Schedule!M33 -> -250.4559 | I23: =-Schedule!N17+Schedule!N33 -> -286.93526
B24: FCFF | E24: =SUM(E19:E23) -> 1432.5192 | F24: =SUM(F19:F23) -> 2223.3179 | G24: =SUM(G19:G23) -> 2280.2707 | H24: =SUM(H19:H23) -> 2300.4645 | I24: =SUM(I19:I23) -> 2719.8775
B26: Discount Factor | E26: =(E11-E10)/(365/2) -> 0 | F26: =E26+1 -> 1 | G26: =F26+1 -> 2 | H26: =G26+1 -> 3 | I26: =H26+1 -> 4
B27: Terminal Value | I27: =I24*(1+E13)/(E12-E13) -> 46300.137
B28: PV of FCFF | E28: =E24/(1+$E$12)^E26 -> 1432.5192 | F28: =F24/(1+$E$12)^F26 -> 2058.7814 | G28: =G24/(1+$E$12)^G26 -> 1955.2565 | H28: =H24/(1+$E$12)^H26 -> 1826.592 | I28: =(I24+I27)/(1+$E$12)^I26 -> 36041.936
B29: Enterprise Value | E29: {=SUM(E28:I28)} -> 43315.085
B30: Add: Cash | E30: =Statements!H58 -> 418.506
B31: Less: Debt | E31: =Statements!H73 -> 2944.1
B32: PV of Equity | E32: =E29+E30-E31 -> 40789.491
B33: No. of Outstanding Shares | E33: =Statements!H43 -> 30057.692
B34: Price Per Share | E34: =E32/E33 -> 1.3570401
B36: Sensitivity Analysis
C38: Terminal growth rate
C39: =E34 -> 1.3570401 | D39: 0 | E39: =D39+1% -> 0.01 | F39: =E39+1% -> 0.02 | G39: =F39+1% -> 0.03 | H39: =G39+1% -> 0.04
C40: =C41+1% -> 0.11 | D40: 0.74930129 | E40: 0.8094508 | F40: 0.88296687 | G40: 0.97486195 | H40: 1.0930128
B41: WACC | C41: =C42+1% -> 0.1 | D41: 0.83093072 | E41: 0.90647006 | F41: 1.0008942 | G41: 1.1222967 | H41: 1.2841667
C42: =C43+1% -> 0.09 | D42: 0.9308218 | E42: 1.0278687 | F42: 1.1526433 | G42: 1.3190095 | H42: 1.551922
C43: =C44+1% -> 0.08 | D43: 1.0558289 | E43: 1.1841017 | F43: 1.355132 | G43: 1.5945745 | H43: 1.9537382
C44: =C45+1% -> 0.07 | D44: 1.2167238 | E44: 1.3925943 | F44: 1.6388131 | G44: 2.0081412 | H44: 2.6236881
C45: =C46+1% -> 0.06 | D45: 1.4314595 | E45: 1.6847127 | F45: 2.0645924 | G45: 2.6977253 | H45: 3.963991
C46: 0.05 | D46: 1.7323526 | E46: 2.1231897 | F46: 2.7745849 | G46: 4.0773754 | H46: 7.9857467

Sheet Ratio Analysis
B2: =Dashboard!B2 -> Borouge PLC
B3: Ratio Analysis
B4: =Dashboard!B4 -> (In Millions AED, except equity share and per equity share data)
B5: Active Scenario | D5: =Dashboard!G12 -> Street | G5: =Statements!F6 -> Actuals | J5: =Statements!I6 -> Projections
B6: Date/Year | G6: =Statements!F7 -> 44926 | H6: =EDATE(G6,12) -> 45291 | I6: =EDATE(H6,12) -> 45657 | J6: =EDATE(I6,12) -> 46022 | K6: =EDATE(J6,12) -> 46387 | L6: =EDATE(K6,12) -> 46752 | M6: =EDATE(L6,12) -> 47118 | N6: =EDATE(M6,12) -> 47483
B8: <-Back to dashboard
A10: # | B10: Ratio Analysis | G10: 44926 | H10: 45291 | I10: 45657 | J10: 46022 | K10: 46387 | L10: 46752 | M10: 47118 | N10: 47483
C12: EBITDA | G12: =Statements!F27-Statements!F23 -> 1345.022 | H12: =Statements!G27-Statements!G23 -> 2106.524 | I12: =Statements!H27-Statements!H23 -> 2386.517 | J12: =Statements!I27-Statements!I23 -> 2487.5021 | K12: =Statements!J27-Statements!J23 -> 3059.6657 | L12: =Statements!K27-Statements!K23 -> 3277.7502 | M12: =Statements!L27-Statements!L23 -> 3440.4575 | N12: =Statements!M27-Statements!M23 -> 3562.1427
C13: EBIT | G13: =Statements!F27-Statements!F23-Schedule!G20 -> 1047.905 | H13: =Statements!G27-Statements!G23-Schedule!H20 -> 1566.912 | I13: =Statements!H27-Statements!H23-Schedule!I20 -> 1862.401 | J13: =Statements!I27-Statements!I23-Schedule!J20 -> 2026.4431 | K13: =Statements!J27-Statements!J23-Schedule!K20 -> 2541.209 | L13: =Statements!K27-Statements!K23-Schedule!L20 -> 2764.834 | M13: =Statements!L27-Statements!L23-Schedule!M20 -> 2928.9164 | N13: =Statements!M27-Statements!M23-Schedule!N20 -> 3029.9339
C14: NOPAT | G14: =Statements!F27*(1-Assumptions!F20) -> 1069.5531 | H14: =Statements!G27*(1-Assumptions!G20) -> 1682.8022 | I14: =Statements!H27*(1-Assumptions!H20) -> 1894.8454 | J14: =Statements!I27*(1-Assumptions!I20) -> 1976.1335 | K14: =Statements!J27*(1-Assumptions!J20) -> 2434.5134 | L14: =Statements!K27*(1-Assumptions!K20) -> 2603.5539 | M14: =Statements!L27*(1-Assumptions!L20) -> 2733.4462 | N14: =Statements!M27*(1-Assumptions!M20) -> 2830.2137
C15: PAT | G15: =Statements!F37 -> 1008.175 | H15: =Statements!G37 -> 1527.373 | I15: =Statements!H37 -> 1758.497 | J15: =Statements!I37 -> 1860.5234 | K15: =Statements!J37 -> 2346.5506 | L15: =Statements!K37 -> 2558.5606 | M15: =Statements!L37 -> 2633.9608 | N15: =Statements!M37 -> 2773.4699
C17: Profitability ratio
C19: Gross Margin (GM) | G19: =Statements!F21/Statements!F19 -> 0.47164593 | H19: =Statements!G21/Statements!G19 -> 0.46460106 | I19: =Statements!H21/Statements!H19 -> 0.50690685 | J19: =Statements!I21/Statements!I19 -> 0.5332112 | K19: =Statements!J21/Statements!J19 -> 0.5097626 | L19: =Statements!K21/Statements!K19 -> 0.52706147 | M19: =Statements!L21/Statements!L19 -> 0.53402448 | N19: =Statements!M21/Statements!M19 -> 0.53426309
C20: Operating Margin (OPM) | G20: =Statements!F27/Statements!F19 -> 0.34317668 | H20: =Statements!G27/Statements!G19 -> 0.36673243 | I20: =Statements!H27/Statements!H19 -> 0.40498144 | J20: =Statements!I27/Statements!I19 -> 0.4251846 | K20: =Statements!J27/Statements!J19 -> 0.40742584 | L20: =Statements!K27/Statements!K19 -> 0.4231357 | M20: =Statements!L27/Statements!L19 -> 0.42926144 | N20: =Statements!M27/Statements!M19 -> 0.43058789
C21: PBT Margin | G21: =Statements!F34/Statements!F19 -> 0.3234829 | H21: =Statements!G34/Statements!G19 -> 0.33285981 | I21: =Statements!H34/Statements!H19 -> 0.37583999 | J21: =Statements!I34/Statements!I19 -> 0.40030996 | K21: =Statements!J34/Statements!J19 -> 0.39270489 | L21: =Statements!K34/Statements!K19 -> 0.41582327 | M21: =Statements!L34/Statements!L19 -> 0.41363822 | N21: =Statements!M34/Statements!M19 -> 0.42195491
C22: PAT Margin | G22: =Statements!F37/Statements!F19 -> 0.2522234 | H22: =Statements!G37/Statements!G19 -> 0.26373373 | I22: =Statements!H37/Statements!H19 -> 0.29181233 | J22: =Statements!I37/Statements!I19 -> 0.31337137 | K22: =Statements!J37/Statements!J19 -> 0.30782508 | L22: =Statements!K37/Statements!K19 -> 0.32477286 | M22: =Statements!L37/Statements!L19 -> 0.32370171 | N22: =Statements!M37/Statements!M19 -> 0.33017499
C23: ROE | G23: =Statements!F37/Statements!F96 -> 0.20795629 | H23: =Statements!G37/Statements!G96 -> 0.3369838 | I23: =Statements!H37/Statements!H96 -> 0.394041 | J23: =Statements!I37/Statements!I96 -> 0.36315205 | K23: =Statements!J37/Statements!J96 -> 0.41089808 | L23: =Statements!K37/Statements!K96 -> 0.39710696 | M23: =Statements!L37/Statements!L96 -> 0.36452033 | N23: =Statements!M37/Statements!M96 -> 0.34682933
C24: ROCE | G24: =G13/(Statements!F96+Statements!F73) -> 0.11864849 | H24: =H13/(Statements!G96+Statements!G73) -> 0.20420562 | I24: =I13/(Statements!H96+Statements!H73) -> 0.25144387 | J24: =J13/(Statements!I96+Statements!I73) -> 0.26778723 | K24: =K13/(Statements!J96+Statements!J73) -> 0.32147324 | L24: =L13/(Statements!K96+Statements!K73) -> 0.35278784 | M24: =M13/(Statements!L96+Statements!L73) -> 0.30446348 | N24: =N13/(Statements!M96+Statements!M73) -> 0.31428431
C25: ROIC | J25: =J14/(Schedule!J17+Schedule!J33) -> 11.873995 | K25: =K14/(Schedule!K17+Schedule!K33) -> 11.913767 | L25: =L14/(Schedule!L17+Schedule!L33) -> 10.68989 | M25: =M14/(Schedule!M17+Schedule!M33) -> 9.6130568 | N25: =N14/(Schedule!N17+Schedule!N33) -> 8.6454962
C26: ROA | J26: =Statements!I37/AVERAGE(Statements!H66:I66) -> 0.2122558 | K26: =Statements!J37/AVERAGE(Statements!I66:J66) -> 0.2566419 | L26: =Statements!K37/AVERAGE(Statements!J66:K66) -> 0.2711121 | M26: =Statements!L37/AVERAGE(Statements!K66:L66) -> 0.25516522 | N26: =Statements!M37/AVERAGE(Statements!L66:M66) -> 0.2460441
C28: Leverage Ratio
C30: Debt to Equity | J30: =Statements!I85/Statements!I96 -> 0.71563015 | K30: =Statements!J85/Statements!J96 -> 0.64813414 | L30: =Statements!K85/Statements!K96 -> 0.44979484 | M30: =Statements!L85/Statements!L96 -> 0.54214654 | N30: =Statements!M85/Statements!M96 -> 0.40054721
C31: Debt to Asset | J31: =Statements!I85/Statements!I66 -> 0.41552281 | K31: =Statements!J85/Statements!J66 -> 0.39113619 | L31: =Statements!K85/Statements!K66 -> 0.30792506 | M31: =Statements!L85/Statements!L66 -> 0.34872473 | N31: =Statements!M85/Statements!M66 -> 0.28318284
C32: Current Ratio | J32: =Statements!I65/Statements!I84 -> 3.0163413 | K32: =Statements!J65/Statements!J84 -> 3.1513097 | L32: =Statements!K65/Statements!K84 -> 3.4054974 | M32: =Statements!L65/Statements!L84 -> 5.1371665 | N32: =Statements!M65/Statements!M84 -> 5.254031
C33: Quick Ratio | J33: =(Statements!I58+Statements!I61+Statements!I63+Statements!I64)/Statements!I84 -> 2.0439038 | K33: =(Statements!J58+Statements!J61+Statements!J63+Statements!J64)/Statements!J84 -> 2.2126664 | L33: =(Statements!K58+Statements!K61+Statements!K63+Statements!K64)/Statements!K84 -> 2.4330559 | M33: =(Statements!L58+Statements!L61+Statements!L63+Statements!L64)/Statements!L84 -> 4.1497164 | N33: =(Statements!M58+Statements!M61+Statements!M63+Statements!M64)/Statements!M84 -> 4.2649415
C34: Cash Ratio | J34: =Statements!I58/Statements!I84 -> 1.0439908 | K34: =Statements!J58/Statements!J84 -> 1.2455222 | L34: =Statements!K58/Statements!K84 -> 1.4308525 | M34: =Statements!L58/Statements!L84 -> 3.1318179 | N34: =Statements!M58/Statements!M84 -> 3.2451364
C36: Valuation Ratio
C38: EPS ($) | G38: =Statements!F42 -> 0.02 | H38: =Statements!G42 -> 0.03 | I38: =Statements!H42 -> 0.04 | J38: =Statements!I42 -> 0.06141505 | K38: =Statements!J42 -> 0.077500021 | L38: =Statements!K42 -> 0.084472925 | M38: =Statements!L42 -> 0.086966858 | N38: =Statements!M42 -> 0.09158047
C39: DPS ($) | G39: =Assumptions!F25/Statements!F43 -> 0.010810112 | H39: =Assumptions!G25/Statements!G43 -> 0.043240313 | I39: =Assumptions!H25/Statements!H43 -> 0.043240313 | J39: =Assumptions!I25/Statements!I43 -> 0.039439414 | K39: =Assumptions!J25/Statements!J43 -> 0.057953544 | L39: =Assumptions!K25/Statements!K43 -> 0.060112561 | M39: =Assumptions!L25/Statements!L43 -> 0.06092275 | N39: =Assumptions!M25/Statements!M43 -> 0.065935957
C41: Operating Ratio
C43: Fixed Asset Turnover | J43: =Statements!I19/AVERAGE(Statements!H48:I48) -> 0.96959952 | K43: =Statements!J19/AVERAGE(Statements!I48:J48) -> 1.3208403 | L43: =Statements!K19/AVERAGE(Statements!J48:K48) -> 1.452318 | M43: =Statements!L19/AVERAGE(Statements!K48:L48) -> 1.5890466 | N43: =Statements!M19/AVERAGE(Statements!L48:M48) -> 1.7297899
C44: Total Asset Turnover | J44: =Statements!I19/AVERAGE(Statements!H66:I66) -> 0.6773299 | K44: =Statements!J19/AVERAGE(Statements!I66:J66) -> 0.83372642 | L44: =Statements!K19/AVERAGE(Statements!J66:K66) -> 0.83477451 | M44: =Statements!L19/AVERAGE(Statements!K66:L66) -> 0.78827269 | N44: =Statements!M19/AVERAGE(Statements!L66:M66) -> 0.74519302
C45: Working Capital Turnover | J45: =Statements!I19/AVERAGE(Schedule!I62:J62) -> 136.69268 | K45: =Statements!J19/AVERAGE(Schedule!J62:K62) -> 65.345725 | L45: =Statements!K19/AVERAGE(Schedule!K62:L62) -> 56.976661 | M45: =Statements!L19/AVERAGE(Schedule!L62:M62) -> 123.54513 | N45: =Statements!M19/AVERAGE(Schedule!M62:N62) -> 176.61052
C47: Dupoint Analysis
C49: Profit Margin | J49: =J22 -> 0.31337137 | K49: =K22 -> 0.30782508 | L49: =L22 -> 0.32477286 | M49: =M22 -> 0.32370171 | N49: =N22 -> 0.33017499
C50: Asset Turnover | J50: =J44 -> 0.6773299 | K50: =K44 -> 0.83372642 | L50: =L44 -> 0.83477451 | M50: =M44 -> 0.78827269 | N50: =N44 -> 0.74519302
C51: Asset Leverage | J51: =Statements!I66/Statements!I96 -> 1.7222404 | K51: =Statements!J66/Statements!J96 -> 1.6570549 | L51: =Statements!K66/Statements!K96 -> 1.4607283 | M51: =Statements!L66/Statements!L96 -> 1.5546547 | N51: =Statements!M66/Statements!M96 -> 1.4144473
C52: Dupont ROE | J52: =J49*J50*J51 -> 0.3655555 | K52: =K49*K50*K51 -> 0.42526972 | L52: =L49*L50*L51 -> 0.39602112 | M52: =M49*M50*M51 -> 0.39669381 | N52: =N49*N50*N51 -> 0.34801642
C54: Revenue Analysis
C56: Sales Volume to Revenue | G56: =Scenario!G21/Scenario!G18 -> 1.2716557 | H56: =Scenario!H21/Scenario!H18 -> 0.88338719 | I56: =Scenario!I21/Scenario!I18 -> 0.88531217 | J56: =Scenario!J21/Scenario!J18 -> 0.87719298 | K56: =Scenario!K21/Scenario!K18 -> 0.86580087 | L56: =Scenario!L21/Scenario!L18 -> 0.85470085 | M56: =Scenario!M21/Scenario!M18 -> 0.84388186 | N56: =Scenario!N21/Scenario!N18 -> 0.83333333
...

Sheet Analysis
B2: =Dashboard!B2 -> Borouge PLC
B3: Analysis
B4: =Dashboard!B4 -> (In Millions AED, except equity share and per equity share data)
A6: # | B6: Horizontal Analysis | E6: 44926 | F6: 45291 | G6: 45657 | H6: 46022 | I6: 46387 | J6: 46752 | K6: 47118 | L6: 47483
B8: Revenue | E8: =Statements!F19/Statements!F$19 -> 1 | F8: =Statements!G19/Statements!G$19 -> 1 | G8: =Statements!H19/Statements!H$19 -> 1 | H8: =Statements!I19/Statements!I$19 -> 1 | I8: =Statements!J19/Statements!J$19 -> 1 | J8: =Statements!K19/Statements!K$19 -> 1 | K8: =Statements!L19/Statements!L$19 -> 1 | L8: =Statements!M19/Statements!M$19 -> 1
B9: Cost of Sales | E9: =-Statements!F20/Statements!F$19 -> 0.52835407 | F9: =-Statements!G20/Statements!G$19 -> 0.53539894 | G9: =-Statements!H20/Statements!H$19 -> 0.49309315 | H9: =-Statements!I20/Statements!I$19 -> 0.4667888 | I9: =-Statements!J20/Statements!J$19 -> 0.4902374 | J9: =-Statements!K20/Statements!K$19 -> 0.47293853 | K9: =-Statements!L20/Statements!L$19 -> 0.46597552 | L9: =-Statements!M20/Statements!M$19 -> 0.46573691
B10: Gross Profit | E10: =Statements!F21/Statements!F$19 -> 0.47164593 | F10: =Statements!G21/Statements!G$19 -> 0.46460106 | G10: =Statements!H21/Statements!H$19 -> 0.50690685 | H10: =Statements!I21/Statements!I$19 -> 0.5332112 | I10: =Statements!J21/Statements!J$19 -> 0.5097626 | J10: =Statements!K21/Statements!K$19 -> 0.52706147 | K10: =Statements!L21/Statements!L$19 -> 0.53402448 | L10: =Statements!M21/Statements!M$19 -> 0.53426309
B12: Other Income | E12: =Statements!F23/Statements!F$19 -> 0.0066815089 | F12: =Statements!G23/Statements!G$19 -> 0.0029958498 | G12: =Statements!H23/Statements!H$19 -> 0.0089528541 | H12: =Statements!I23/Statements!I$19 -> 0.0062100709 | I12: =Statements!J23/Statements!J$19 -> 0.006052925 | J12: =Statements!K23/Statements!K$19 -> 0.00707195 | K12: =Statements!L23/Statements!L$19 -> 0.006444982 | L12: =Statements!M23/Statements!M$19 -> 0.0065232856
B13: General and administrative expenses | E13: =-Statements!F24/Statements!F$19 -> 0.028165811 | F13: =-Statements!G24/Statements!G$19 -> 0.0315842 | G13: =-Statements!H24/Statements!H$19 -> 0.032047305 | H13: =-Statements!I24/Statements!I$19 -> 0.030599105 | I13: =-Statements!J24/Statements!J$19 -> 0.031410203 | J13: =-Statements!K24/Statements!K$19 -> 0.031352204 | K13: =-Statements!L24/Statements!L$19 -> 0.031120504 | L13: =-Statements!M24/Statements!M$19 -> 0.031294304
B14: Selling and distribution expenses | E14: =-Statements!F25/Statements!F$19 -> 0.1036118 | F14: =-Statements!G25/Statements!G$19 -> 0.068981385 | G14: =-Statements!H25/Statements!H$19 -> 0.07831951 | H14: =-Statements!I25/Statements!I$19 -> 0.083637564 | I14: =-Statements!J25/Statements!J$19 -> 0.076979486 | J14: =-Statements!K25/Statements!K$19 -> 0.07964552 | K14: =-Statements!L25/Statements!L$19 -> 0.080087524 | L14: =-Statements!M25/Statements!M$19 -> 0.078904177
B15: Impairment loss on PPE & intangible assets | E15: =-Statements!F26/Statements!F$19 -> 0.0033731525 | F15: =-Statements!G26/Statements!G$19 -> 0.0002988943 | G15: =-Statements!H26/Statements!H$19 -> 0.00051143994 | H15: =-Statements!I26/Statements!I$19 -> 0 | I15: =-Statements!J26/Statements!J$19 -> 0 | J15: =-Statements!K26/Statements!K$19 -> 0 | K15: =-Statements!L26/Statements!L$19 -> 0 | L15: =-Statements!M26/Statements!M$19 -> 0
B16: Operating Income | E16: =Statements!F27/Statements!F$19 -> 0.34317668 | F16: =Statements!G27/Statements!G$19 -> 0.36673243 | G16: =Statements!H27/Statements!H$19 -> 0.40498144 | H16: =Statements!I27/Statements!I$19 -> 0.4251846 | I16: =Statements!J27/Statements!J$19 -> 0.40742584 | J16: =Statements!K27/Statements!K$19 -> 0.4231357 | K16: =Statements!L27/Statements!L$19 -> 0.42926144 | L16: =Statements!M27/Statements!M$19 -> 0.43058789
B18: Finance income | E18: =Statements!F29/Statements!F$19 -> 0.0049395182 | F18: =Statements!G29/Statements!G$19 -> 0.0046301852 | G18: =Statements!H29/Statements!H$19 -> 0.0047383699 | H18: =Statements!I29/Statements!I$19 -> 0.0047693578 | I18: =Statements!J29/Statements!J$19 -> 0.0047126376 | J18: =Statements!K29/Statements!K$19 -> 0.0047401218 | K18: =Statements!L29/Statements!L$19 -> 0.0047407057 | L18: =Statements!M29/Statements!M$19 -> 0.004731155
B19: Finance costs | E19: =-Statements!F30/Statements!F$19 -> 0.023977328 | F19: =-Statements!G30/Statements!G$19 -> 0.03814468 | G19: =-Statements!H30/Statements!H$19 -> 0.033524872 | H19: =-Statements!I30/Statements!I$19 -> 0.029644002 | I19: =-Statements!J30/Statements!J$19 -> 0.019433589 | J19: =-Statements!K30/Statements!K$19 -> 0.012052548 | K19: =-Statements!L30/Statements!L$19 -> 0.020363928 | L19: =-Statements!M30/Statements!M$19 -> 0.013364135
B20: Foreign exchange loss | E20: =-Statements!F31/Statements!F$19 -> 0.00065596721 | F20: =-Statements!G31/Statements!G$19 -> 0.00035812061 | G20: =-Statements!H31/Statements!H$19 -> 0.00035495459 | H20: =-Statements!I31/Statements!I$19 -> 0 | I20: =-Statements!J31/Statements!J$19 -> 0 | J20: =-Statements!K31/Statements!K$19 -> 0 | K20: =-Statements!L31/Statements!L$19 -> 0 | L20: =-Statements!M31/Statements!M$19 -> 0
B21: Net finance loss | E21: =-Statements!F32/Statements!F$19 -> 0.019693777 | F21: =-Statements!G32/Statements!G$19 -> 0.033872615 | G21: =-Statements!H32/Statements!H$19 -> 0.029141456 | H21: =-Statements!I32/Statements!I$19 -> 0.024874645 | I21: =-Statements!J32/Statements!J$19 -> 0.014720951 | J21: =-Statements!K32/Statements!K$19 -> 0.0073124264 | K21: =-Statements!L32/Statements!L$19 -> 0.015623222 | L21: =-Statements!M32/Statements!M$19 -> 0.0086329799
B23: Profit Before Tax | E23: =Statements!F34/Statements!F$19 -> 0.3234829 | F23: =Statements!G34/Statements!G$19 -> 0.33285981 | G23: =Statements!H34/Statements!H$19 -> 0.37583999 | H23: =Statements!I34/Statements!I$19 -> 0.40030996 | I23: =Statements!J34/Statements!J$19 -> 0.39270489 | J23: =Statements!K34/Statements!K$19 -> 0.41582327 | K23: =Statements!L34/Statements!L$19 -> 0.41363822 | L23: =Statements!M34/Statements!M$19 -> 0.42195491
B25: Income tax expense | E25: =-Statements!F36/Statements!F$19 -> 0.071259505 | F25: =-Statements!G36/Statements!G$19 -> 0.069126084 | G25: =-Statements!H36/Statements!H$19 -> 0.084027658 | H25: =-Statements!I36/Statements!I$19 -> 0.086938589 | I25: =-Statements!J36/Statements!J$19 -> 0.084879811 | J25: =-Statements!K36/Statements!K$19 -> 0.09105041 | K25: =-Statements!L36/Statements!L$19 -> 0.089936509 | L25: =-Statements!M36/Statements!M$19 -> 0.091779923
B26: Profit After Tax | E26: =Statements!F37/Statements!F$19 -> 0.2522234 | F26: =Statements!G37/Statements!G$19 -> 0.26373373 | G26: =Statements!H37/Statements!H$19 -> 0.29181233 | H26: =Statements!I37/Statements!I$19 -> 0.31337137 | I26: =Statements!J37/Statements!J$19 -> 0.30782508 | J26: =Statements!K37/Statements!K$19 -> 0.32477286 | K26: =Statements!L37/Statements!L$19 -> 0.32370171 | L26: =Statements!M37/Statements!M$19 -> 0.33017499
A28: # | B28: Trend Analysis | E28: 44926 | F28: 45291 | G28: 45657 | H28: 46022 | I28: 46387 | J28: 46752 | K28: 47118 | L28: 47483
B30: Revenue | E30: 0 | F30: =Statements!G19/Statements!F19-1 -> 0.44886821 | G30: =Statements!H19/Statements!G19-1 -> 0.04053946 | H30: =Statements!I19/Statements!H19-1 -> -0.014769529 | I30: =Statements!J19/Statements!I19-1 -> 0.28395586 | J30: =Statements!K19/Statements!J19-1 -> 0.033451397 | K30: =Statements!L19/Statements!K19-1 -> 0.032876365 | L30: =Statements!M19/Statements!L19-1 -> 0.032321494
B31: Cost of Sales | E31: 0 | F31: =Statements!G20/Statements!F20-1 -> 0.46818687 | G31: =Statements!H20/Statements!G20-1 -> -0.04168118 | H31: =Statements!I20/Statements!H20-1 -> -0.067327254 | I31: =Statements!J20/Statements!I20-1 -> 0.34845391 | J31: =Statements!K20/Statements!J20-1 -> -0.0030157072 | K31: =Statements!L20/Statements!K20-1 -> 0.017669455 | L31: =Statements!M20/Statements!L20-1 -> 0.031792889
B32: Gross Profit | E32: 0 | F32: =Statements!G21/Statements!F21-1 -> 0.42722677 | G32: =Statements!H21/Statements!G21-1 -> 0.13528923 | H32: =Statements!I21/Statements!H21-1 -> 0.036355948 | I32: =Statements!J21/Statements!I21-1 -> 0.22749236 | J32: =Statements!K21/Statements!J21-1 -> 0.068521718 | K32: =Statements!L21/Statements!K21-1 -> 0.046521705 | L32: =Statements!M21/Statements!L21-1 -> 0.032782741
B34: Other Income | E34: 0 | F34: =Statements!G23/Statements!F23-1 -> -0.35035758 | G34: =Statements!H23/Statements!G23-1 -> 2.1095677 | H34: =Statements!I23/Statements!H23-1 -> -0.31660328 | I34: =Statements!J23/Statements!I23-1 -> 0.25146533 | J34: =Statements!K23/Statements!J23-1 -> 0.20743552 | K34: =Statements!L23/Statements!K23-1 -> -0.058693918 | L34: =Statements!M23/Statements!L23-1 -> 0.044863743
B35: General and administrative expenses | E35: 0 | F35: =Statements!G24/Statements!F24-1 -> 0.62471243 | G35: =Statements!H24/Statements!G24-1 -> 0.055796408 | H35: =Statements!I24/Statements!H24-1 -> -0.059291531 | I35: =Statements!J24/Statements!I24-1 -> 0.31798999 | J35: =Statements!K24/Statements!J24-1 -> 0.031543129 | K35: =Statements!L24/Statements!K24-1 -> 0.025243168 | L35: =Statements!M24/Statements!L24-1 -> 0.038086734
B36: Selling and distribution expenses | E36: 0 | F36: =Statements!G25/Statements!F25-1 -> -0.035390388 | G36: =Statements!H25/Statements!G25-1 -> 0.18139902 | H36: =Statements!I25/Statements!H25-1 -> 0.052129627 | I36: =Statements!J25/Statements!I25-1 -> 0.18174487 | J36: =Statements!K25/Statements!J25-1 -> 0.069242962 | K36: =Statements!L25/Statements!K25-1 -> 0.038608449 | L36: =Statements!M25/Statements!L25-1 -> 0.017068252
B37: Impairment loss on PPE & intangible assets | E37: 0 | F37: =Statements!G26/Statements!F26-1 -> -0.87161611 | G37: =Statements!H26/Statements!G26-1 -> 0.78047371 | H37: 0 | I37: 0 | J37: 0 | K37: 0 | L37: 0
B38: Operating Income | E38: 0 | F38: =Statements!G27/Statements!F27-1 -> 0.54831895 | G38: =Statements!H27/Statements!G27-1 -> 0.1490644 | H38: =Statements!I27/Statements!H27-1 -> 0.034380298 | I38: =Statements!J27/Statements!I27-1 -> 0.23032863 | J38: =Statements!K27/Statements!J27-1 -> 0.073300058 | K38: =Statements!L27/Statements!K27-1 -> 0.047829335 | L38: =Statements!M27/Statements!L27-1 -> 0.035511459
