Workbook

Sheet Overview
D2: Valuation & Analysis of Choice Hotels International Inc. (NYSE: CHH)
D4: Overview
D16: Comparable Company Analysis
D18: Universe of Comparable Companies
D20: Sector: | E20: Consumer Discretionary
D21: Industry: | E21: Hotels, Resorts & Cruise Lines (Hospitality / Lodging – Asset-light franchising model)
D22: Geography: | E22: Primarily United States (core revenue concentration), with operations in 50+ countries and territories through direct and master franchising
D23: Products: | E23: Hotel franchising services under multiple brands (economy to upscale), reservation systems, loyalty programs, and ancillary services via travel and vendor partnerships
D24: Customers: | E24: Franchisees (hotel owners, developers, operators), End consumers (business and leisure travelers across price segments)
D25: Competitors: | E25: Marriott International, Airbnb Inc, Hilton Worldwide Holdings, Wyndham Hotels & Resorts Inc, Hyatt Hotels Corporation
D26: Distribution Channel: | E26: Primarily B2B (franchise agreements with hotel owners) supported by B2C channels including direct bookings via brand websites, mobile apps, central reservation systems,
E27: and third-party travel platforms (OTAs)
D28: End Markets: | E28: Business travel, Leisure travel, Budget to midscale lodging segments, Extended stay and select upscale segments
D30: ($ in millions)
D31: List of Comparable Companies
G32: Equity | H32: Enterprise | I32: LTM | J32: LTM
D33: Company | E33: Ticker | F33: Sector | G33: Value | H33: Value | I33: Sales | J33: EBITDA
D34: Marriot International Inc | E34: MAR | F34: Consumer Discretionary | G34: =MAR!H25 -> 96703.864 | H34: =MAR!H31 -> 112549.86 | I34: =MAR!R11 -> 26186 | J34: =MAR!R41 -> 4695
D35: Airbnb Inc CI A | E35: ABNB | F35: Consumer Discretionary | G35: =ABNB!H25 -> 83701.62 | H35: =ABNB!H31 -> 79140.62 | I35: =ABNB!R11 -> 12241 | J35: =ABNB!R42 -> 4297
D36: Hilton Worldwide Holdings Inc. | E36: HLT | F36: Consumer Discretionary | G36: =HLT!H25 -> 78279.057 | H36: =HLT!H31 -> 89714.057 | I36: =HLT!R11 -> 12039 | J36: =HLT!R41 -> 3538
D37: Hyatt Hotels Corporation | E37: H | F37: Consumer Discretionary | G37: =H!H25 -> 16017.976 | H37: =H!H31 -> 19832.976 | I37: =H!R11 -> 7101 | J37: =H!R41 -> 1159
D38: Wyndham Hotels & Resorts Inc | E38: WH | F38: Consumer Discretionary | G38: =WH!H25 -> 6773.941 | H38: =WH!H31 -> 9269.941 | I38: =WH!R11 -> 1429 | J38: =WH!R42 -> 718

Sheet Comps_Sum
D2: Public Market Comparable Valuation — Choice Hotels International Inc. (NYSE: CHH)
D3: Peer Trading Multiples & Implied Equity Value Assessment
E5: Valuation Date | G5: Prepared By | I5: Fiscal Year End | K5: Currency | M5: Projection Period
E6: 04/17/2026 | G6: Eldric Sequeira | I6: 12/31/2025 | K6: USD (millions) | M6: 5 Years ('FY26 - 'FY30)
D8: 1 · Valuation Snapshot
D10: Implied Share Price | F10: Implied EV Range | H10: EV/EBITDA | J10: EV/Revenue | L10: P/E | N10: Current Price
D11: =L64 -> 190.96784 | F11: $ 8,076.9 - $ 15,863.5 | H11: 18.4x | J11: 6.5x | L11: 28.0x | N11: =116.7 -> 116.7
D13: 2 · Peer Universe & Selection Criteria
D14: Screening criteria applied | J14: Target company profile
D15: Sector / Industry | H15: Consumer Discretionary | J15: LTM Revenue | M15: =CHH!R11 -> 1596.793
D16: Market Cap Range | F16: =CompsVal!M10 -> 6170.8628 | G16: - | H16: =CompsVal!O10 -> 13957.392 | J16: LTM EBITDA | M16: =DCF!H18 -> 508.114
D17: Revenue Range | F17: =WH!R11 -> 1429 | G17: - | H17: =ABNB!R11 -> 12241 | J17: EBITDA Margin (LTM) | M17: =DCF!H19 -> 0.31820906
D18: Geography | H18: North America | J18: Revenue Growth (YoY) | M18: =DCF!H9 -> 0.007542722
J19: Net Debt | M19: =CHH!H27 -> 1906.122
J20: Shares Outstanding | M20: =CHH!H24 -> 46.203843
J21: Current Market Cap | M21: =CHH!H25 -> 5390.1403
D23: 3 · Comparable Companies — Trading Multiples
D24: Company | G24: Mkt Cap | H24: EV | I24: EV / Rev | J24: EV / EBITDA | K24: EV / EBIT | L24: P/E | M24: Rev Growth | N24: EBITDA Mg.
D25: =Comps2!D11 -> Marriott International Inc. | G25: =Comps2!H11 -> 96703.864 | H25: =Comps2!I11 -> 112549.86 | I25: =Comps1!J12 -> 4.298093 | J25: =Comps1!M12 -> 23.972282 | K25: =Comps1!P12 -> 27.120449 | L25: =Comps1!U12 -> 9.5065789 | M25: =MAR!E64 -> 0.043266932 | N25: =MAR!R42 -> 0.17929428
D26: =Comps2!D12 -> Airbnb Inc. Cl A | G26: =Comps2!H12 -> 83701.62 | H26: =Comps2!I12 -> 79140.62 | I26: =Comps1!J13 -> 6.4652087 | J26: =Comps1!M13 -> 18.417645 | K26: =Comps1!P13 -> 31.108734 | L26: =Comps1!U13 -> 22.269394 | M26: =ABNB!E64 -> 0.10259413 | N26: =ABNB!R43 -> 0.35103341
D27: =Comps2!D13 -> Hilton Worldwide Holdings Inc. | G27: =Comps2!H13 -> 78279.057 | H27: =Comps2!I13 -> 89714.057 | I27: =Comps1!J14 -> 7.4519526 | J27: =Comps1!M14 -> 25.35728 | K27: =Comps1!P14 -> 33.313798 | L27: =Comps1!U14 -> 53.579094 | M27: =HLT!E64 -> 0.077411849 | N27: =HLT!R42 -> 0.29387823
D28: =Comps2!D14 -> Hyatt Hotels Corporation | G28: =Comps2!H14 -> 16017.976 | H28: =Comps2!I14 -> 19832.976 | I28: =Comps1!J15 -> 2.7929835 | J28: =Comps1!M15 -> 17.112145 | K28: =Comps1!P15 -> 56.991311 | L28: =Comps1!U15 -> -308.038 | M28: =H!E64 -> 0.068140794 | N28: =H!R42 -> 0.16321645
D29: =Comps2!D15 -> Wyndham Hotels & Resorts Inc. | G29: =Comps2!H15 -> 6773.941 | H29: =Comps2!I15 -> 9269.941 | I29: =Comps1!J16 -> 6.4870126 | J29: =Comps1!M16 -> 12.910781 | K29: =Comps1!P16 -> 14.131008 | L29: =Comps1!U16 -> 28.845322 | M29: =WH!E64 -> 0.014914773 | N29: =WH!R43 -> 0.50244927
D31: Min | I31: =MIN(I$25:I$29) -> 2.7929835 | J31: =MIN(J$25:J$29) -> 12.910781 | K31: =MIN(K$25:K$29) -> 14.131008 | L31: =MIN(L$25:L$29) -> -308.038 | M31: =MIN(M$25:M$29) -> 0.014914773 | N31: =MIN(N$25:N$29) -> 0.16321645
D32: 25th Percentile | I32: =PERCENTILE(I$25:I$29,25%) -> 4.298093 | J32: =PERCENTILE(J$25:J$29,25%) -> 17.112145 | K32: =PERCENTILE(K$25:K$29,25%) -> 27.120449 | L32: =PERCENTILE(L$25:L$29,25%) -> 9.5065789 | M32: =PERCENTILE(M$25:M$29,25%) -> 0.043266932 | N32: =PERCENTILE(N$25:N$29,25%) -> 0.17929428
D33: Median | I33: =MEDIAN(I$25:I$29) -> 6.4652087 | J33: =MEDIAN(J$25:J$29) -> 18.417645 | K33: =MEDIAN(K$25:K$29) -> 31.108734 | L33: =MEDIAN(L$25:L$29) -> 22.269394 | M33: =MEDIAN(M$25:M$29) -> 0.068140794 | N33: =MEDIAN(N$25:N$29) -> 0.29387823
D34: Mean | I34: =AVERAGE(I$25:I$29) -> 5.4990501 | J34: =AVERAGE(J$25:J$29) -> 19.554027 | K34: =AVERAGE(K$25:K$29) -> 32.53306 | L34: =AVERAGE(L$25:L$29) -> -38.767523 | M34: =AVERAGE(M$25:M$29) -> 0.061265695 | N34: =AVERAGE(N$25:N$29) -> 0.29797433
D35: 75th Percentile | I35: =PERCENTILE(I$25:I$29,75%) -> 6.4870126 | J35: =PERCENTILE(J$25:J$29,75%) -> 23.972282 | K35: =PERCENTILE(K$25:K$29,75%) -> 33.313798 | L35: =PERCENTILE(L$25:L$29,75%) -> 28.845322 | M35: =PERCENTILE(M$25:M$29,75%) -> 0.077411849 | N35: =PERCENTILE(N$25:N$29,75%) -> 0.35103341
D36: Max | I36: =MAX(I$25:I$29) -> 7.4519526 | J36: =MAX(J$25:J$29) -> 25.35728 | K36: =MAX(K$25:K$29) -> 56.991311 | L36: =MAX(L$25:L$29) -> 53.579094 | M36: =MAX(M$25:M$29) -> 0.10259413 | N36: =MAX(N$25:N$29) -> 0.50244927
D38: 4 · Forward Multiple Benchmarking
D39: Company | G39: Revenue | H39: EBITDA | I39: EV / Rev | J39: EV / EBITDA | K39: EV / EBIT | L39: P/E | M39: PEG Ratio
D40: =D25 -> Marriott International Inc. | G40: =MAR!F37 -> 27901 | H40: =MAR!F39 -> 5900 | I40: =Comps1!K12 -> 4.0339007 | J40: =Comps1!N12 -> 19.076248 | K40: =Comps1!Q12 -> 22.769546 | L40: =Comps1!V12 -> 11.310405 | M40: =Comps2!O11/Comps2!Q11/100 -> 5.3634977
D41: =D26 -> Airbnb Inc. Cl A | G41: =ABNB!F37 -> 13697 | H41: =ABNB!F39 -> 4812 | I41: =Comps1!K13 -> 5.7779528 | J41: =Comps1!N13 -> 16.446513 | K41: =Comps1!Q13 -> 26.424247 | L41: =Comps1!V13 -> 27.956453 | M41: =Comps2!O12/Comps2!Q12/100 -> 2.3297044
D42: =D27 -> Hilton Worldwide Holdings Inc. | G42: =HLT!F37 -> 13095 | H42: =HLT!F39 -> 4032 | I42: =Comps1!K14 -> 6.8510162 | J42: =Comps1!N14 -> 22.25051 | K42: =Comps1!Q14 -> 25.936414 | L42: =Comps1!V14 -> 37.580682 | M42: =Comps2!O13/Comps2!Q13/100 -> 2.5917712
D43: =D28 -> Hyatt Hotels Corporation | G43: =H!F37 -> 7195 | H43: =H!F39 -> 1179 | I43: =Comps1!K15 -> 2.7564943 | J43: =Comps1!N15 -> 16.821863 | K43: =Comps1!Q15 -> 30.758338 | L43: =Comps1!V15 -> 57.216495 | M43: =Comps2!O14/Comps2!Q14/100 -> 8.173785
D44: =D29 -> Wyndham Hotels & Resorts Inc. | G44: =WH!F37 -> 1481 | H44: =WH!F39 -> 741.1 | I44: =Comps1!K16 -> 6.2592444 | J44: =Comps1!N16 -> 12.508354 | K44: =Comps1!Q16 -> 15.296932 | L44: =Comps1!V16 -> 19.169565 | M44: =Comps2!O15/Comps2!Q15/100 -> 2.3961957
D46: Median | I46: =MEDIAN(I40:I44) -> 5.7779528 | J46: =MEDIAN(J40:J44) -> 16.821863 | K46: =MEDIAN(K40:K44) -> 25.936414 | L46: =MEDIAN(L40:L44) -> 27.956453 | M46: =MEDIAN(M40:M44) -> 2.5917712
D48: 5 · Implied Enterprise & Equity Value (USD Millions)
D49: Metric Used | E49: Subject Metric | G49: Peer Low | H49: Peer Median | I49: Peer High | J49: Implied EV (Low) | L49: Implied EV (Mid) | N49: Implied EV (High)
D50: LTM Sales | E50: =DCF!H8 -> 1596.793 | G50: =Comps1!J22 -> 2.7929835 | H50: =Comps1!J19 -> 6.4652087 | I50: =Comps1!J21 -> 7.4519526 | J50: =G50*E50 -> 4459.8166 | L50: =H50*E50 -> 10323.6 | N50: =I50*E50 -> 11899.226
...

Sheet DCF_Sum
D2: DCF Valuation Summary — Choice Hotels International Inc. (NYSE: CHH)
D3: Intrinsic Value Assessment & Equity Valuation Report
E5: Valuation Date | G5: Prepared By | I5: Fiscal Year End | K5: Currency | M5: Projection Period
E6: 04/17/2026 | G6: Eldric Sequeira | I6: 12/31/2025 | K6: USD (millions) | M6: 5 Years ('FY26 - 'FY30)
D8: 1 · Valuation Snapshot
D10: Intrinsic Value per Share | F10: Enterprise Value (EV) | H10: Equity Value | J10: Shares Outstanding | L10: WACC | N10: Terminal Growth Rate
D11: =DCF!K49 -> 148.27396 | F11: =DCF!F49 -> 8711.9516 | H11: =DCF!K45 -> 6850.8266 | J11: =DCF!K47 -> 46.203843 | L11: =DCF!E32 -> 0.078407245 | N11: =DCF!P43 -> 0.03
D13: 2 · Key Assumptions
D14: Operating Assumptions | I14: WACC Components
D15: Revenue CAGR ('FY26 - 'FY30) | G15: =DCF!O8 -> 0.034747978 | I15: Risk-Free Rate | L15: =WACC!F20 -> 0.04261
D16: EBITDA Margin | G16: =DCF!J19 -> 0.31820906 | I16: Equity Risk Premium | L16: =WACC!F21 -> 0.0423
D17: Dep. & Amort. % of Revenue | G17: =Historical!I16 -> 0.037396832 | I17: Beta (Levered) | L17: =WACC!F22 -> 0.94879003
D18: Capex % of Revenue | G18: =Historical!I33 -> 0.024376359 | I18: Cost of Equity (Ke) | L18: =WACC!F24 -> 0.085043818
D19: Change in NWC % of Revenue | G19: =DCF!J29/DCF!J8 -> 0.002405394 | I19: Pre-Tax Cost of Debt (Kd) | L19: =WACC!F14 -> 0.051
D20: Effective Tax Rate | G20: =Historical!I19 -> 0.2 | I20: Debt / Total Capital | L20: =Historical!I96/(Historical!I96+Historical!I111) -> 0.75116644
D22: 3 · Revenue & EBITDA Projections (USD Millions)
D23: Metric | F23: 2026E | G23: 2027E | H23: 2028E | I23: 2029E | J23: 2030E
D24: Revenue | F24: =DCF!J8 -> 1620.7449 | G24: =DCF!K8 -> 1674.2295 | H24: =DCF!L8 -> 1729.479 | I24: =DCF!M8 -> 1795.1993 | J24: =DCF!N8 -> 1858.0312
D25: YoY Growth (%) | F25: =DCF!J9 -> 0.015 | G25: =DCF!K9 -> 0.033 | H25: =DCF!L9 -> 0.033 | I25: =DCF!M9 -> 0.038 | J25: =DCF!N9 -> 0.035
D26: Gross Profit | F26: =DCF!J12 -> 849.62808 | G26: =DCF!K12 -> 877.66581 | H26: =DCF!L12 -> 906.62878 | I26: =DCF!M12 -> 941.08067 | J26: =DCF!N12 -> 974.0185
D27: Gross Margin (%) | F27: =DCF!J13 -> 0.52422073 | G27: =DCF!K13 -> 0.52422073 | H27: =DCF!L13 -> 0.52422073 | I27: =DCF!M13 -> 0.52422073 | J27: =DCF!N13 -> 0.52422073
D28: EBITDA | F28: =DCF!J18 -> 515.73571 | G28: =DCF!K18 -> 532.75499 | H28: =DCF!L18 -> 550.3359 | I28: =DCF!M18 -> 571.24867 | J28: =DCF!N18 -> 591.24237
D29: EBITDA Margin (%) | F29: =DCF!J19 -> 0.31820906 | G29: =DCF!K19 -> 0.31820906 | H29: =DCF!L19 -> 0.31820906 | I29: =DCF!M19 -> 0.31820906 | J29: =DCF!N19 -> 0.31820906
D30: EBIT (NOPAT adj.) | F30: =DCF!J22 -> 455.12498 | G30: =DCF!K22 -> 470.14411 | H30: =DCF!L22 -> 485.65887 | I30: =DCF!M22 -> 504.1139 | J30: =DCF!N22 -> 521.75789
D32: 4 · Unlevered Free Cash Flow Forecast (USD Millions)
D33: Metric | F33: 2026E | G33: 2027E | H33: 2028E | I33: 2029E | J33: 2030E
D34: EBIT | F34: =DCF!J22 -> 455.12498 | G34: =DCF!K22 -> 470.14411 | H34: =DCF!L22 -> 485.65887 | I34: =DCF!M22 -> 504.1139 | J34: =DCF!N22 -> 521.75789
D35: Less: Taxes on EBIT | F35: =-DCF!J24 -> -108.46587 | G35: =-DCF!K24 -> -109.35816 | H35: =-DCF!L24 -> -111.08533 | I35: =-DCF!M24 -> -112.90755 | J35: =-DCF!N24 -> 0
D36: NOPAT | F36: =DCF!J25 -> 346.65911 | G36: =DCF!K25 -> 360.78595 | H36: =DCF!L25 -> 374.57353 | I36: =DCF!M25 -> 391.20636 | J36: =DCF!N25 -> 521.75789
D37: Add: Dep. & Amort. | F37: =DCF!J27 -> 60.610725 | G37: =DCF!K27 -> 62.610879 | H37: =DCF!L27 -> 64.677038 | I37: =DCF!M27 -> 67.134765 | J37: =DCF!N27 -> 69.484482
D38: Less: Capex | F38: =DCF!J28 -> -39.50786 | G38: =DCF!K28 -> -40.811619 | H38: =DCF!L28 -> -42.158403 | I38: =DCF!M28 -> -43.760422 | J38: =DCF!N28 -> -45.292037
D39: Inc/Dec in NWC | F39: =DCF!J29 -> 3.89853 | G39: =DCF!K29 -> 8.7054175 | H39: =DCF!L29 -> 8.9926963 | I39: =DCF!M29 -> 10.696948 | J39: =DCF!N29 -> 10.226846
D40: Unlevered FCF | F40: =DCF!J31 -> 371.66051 | G40: =DCF!K31 -> 391.29062 | H40: =DCF!L31 -> 406.08486 | I40: =DCF!M31 -> 425.27765 | J40: =DCF!N31 -> 556.17718
D41: Discount Factor | F41: =DCF!J34 -> 0.96296078 | G41: =DCF!K34 -> 0.89294725 | H41: =DCF!L34 -> 0.82802416 | I41: =DCF!M34 -> 0.7678214 | J41: =DCF!N34 -> 0.71199577
D42: Present Value of FCF | F42: =DCF!J35 -> 357.89449 | G42: =DCF!K35 -> 349.40189 | H42: =DCF!L35 -> 336.24808 | I42: =DCF!M35 -> 326.53728 | J42: =DCF!N35 -> 395.9958
D44: 5 · NPV & Terminal Value Build (USD Millions)
D58: Bridge to Equity Value | G58: Amount (USD M)
D59: Enterprise Value | G59: =DCF!K39 -> 8711.9516
D60: Less: Total Debt | G60: =DCF!K40 -> -1906.122
D61: Less: Preferred Stock | G61: =DCF!K40 -> -1906.122
...

Sheet Comps Analysis->

Sheet CHH
D2: Choice Hotels International Inc. (NYSE: CHH)
D3: Input Page
D4: ($ in millions, except per share data)
D7: General Information | J7: Reported Income Statement | T7: Balance Sheet Data
D8: Company Name | H8: Choice Hotels International Inc. | P8: Prior Stub 12/31/2025 | Q8: Current Stub 12/31/2025 | R8: LTM 12/31/2025 | W8: 2025A | X8: -
D9: Ticker | H9: CHH | M9: Fiscal Year Ending December 31, | T9: Cash & Cash Equivalents | W9: 44.997
D10: Stock Exchange | H10: NYSE | M10: 2023A | N10: 2024A | O10: 2025A | T10: Accounts Receivables | W10: =207.491+94.686 -> 302.177
D11: Fisical Year Ending | H11: 12/31/2025 | J11: Sales | M11: 1544.165 | N11: 1584.839 | O11: 1596.793 | R11: =O11 -> 1596.793 | T11: Income Tax receivables | W11: 13.456
D12: Moody's Corporate Rating | H12: Baa2 | J12: COGS (incl. D&A) | M12: =1165.401-312.701 -> 852.7 | N12: =1121.066-312.388 -> 808.678 | O12: =1148.394-328.958 -> 819.436 | R12: =O12 -> 819.436 | T12: Prepaids & Other Current Assets | W12: 45.368
D13: S&P Corporate Rating | H13: BBB- | J13: Gross Profit | M13: =M11-M12 -> 691.465 | N13: =N11-N12 -> 776.161 | O13: =O11-O12 -> 777.357 | R13: =O13 -> 777.357 | T13: Total Current Assets | W13: =SUM(W9:W12) -> 405.998
D14: Predicted Beta | H14: 0.84 | J14: SG&A | M14: 312.701 | N14: 312.388 | O14: 328.958 | R14: =O14 -> 328.958
D15: Marginal Tax | H15: 0.2 | J15: EBIT | M15: =M13-M14 -> 378.764 | N15: =N13-N14 -> 463.773 | O15: =O13-O14 -> 448.399 | R15: =O15 -> 448.399 | T15: Property, Plant & Equivalent, net | W15: 649.291
J16: Interest Expense | M16: =63.78-7.764 -> 56.016 | N16: =87.131-8.646 -> 78.485 | O16: =91.148-6.237 -> 84.911 | R16: =O16 -> 84.911 | T16: Goodwill & Intangible Assets | W16: =77.67+305.758+1082.486 -> 1465.914
D17: Selected Market Data | J17: Other income/(expenses), net | M17: =-4.416-10.649-2.879 -> -17.944 | N17: =0.331+1.641-12.329 -> -10.357 | O17: =-100.025-0.713-6.989+14.324 -> -93.403 | R17: =O17 -> -93.403 | T17: Other Assets | W17: =12.49+50.227+134.975+75.371+123.937 -> 397
D18: Current Price | H18: 116.66 | J18: Pre-tax Income | M18: =M15-M16-M17 -> 340.692 | N18: =N15-N16-N17 -> 395.645 | O18: =O15-O16-O17 -> 456.891 | R18: =O18 -> 456.891 | T18: Total Assets | W18: =SUM(W15:W17)+W13 -> 2918.203
D19: % of 52-week High | H19: =H18/H20 -> 0.85496519 | J19: Income Taxes | M19: -78.449 | N19: -95.98 | O19: -86.945 | R19: =O19 -> -86.945
D20: 52-week High Price | H20: 136.45 | J20: Non-controlling Interest | M20: 0 | N20: 0 | O20: 0 | R20: =O20 -> 0 | T20: Liability for guest loyalty program | W20: 85.035
D21: 52-week Low Price | H21: 84.04 | J21: Preferred Dividends | M21: 0 | N21: 0 | O21: 0 | R21: =O21 -> 0 | T21: Accounts Payable | W21: 156.276
D22: Dividend Per Share | H22: 1.15 | J22: Net Income | M22: =SUM(M18:M21) -> 262.243 | N22: =SUM(N18:N21) -> 299.665 | O22: =SUM(O18:O21) -> 369.946 | R22: =O22 -> 369.946 | T22: Accrued Liabilities | W22: 125.282
J23: Effective Tax Rate | M23: =ABS(M19/M18) -> 0.2302637 | N23: =ABS(N19/N18) -> 0.24259121 | O23: =ABS(O19/O18) -> 0.19029703 | R23: =O23 -> 0.19029703 | T23: Deferred revenue | W23: 100.698
D24: Fully Diluted Shares Outstanding | H24: =X44 -> 46.203843 | T24: Total Current Liabilities | W24: =SUM(W20:W23) -> 467.291
D25: Equity Value | H25: =H24*H18 -> 5390.1403 | J25: Weighted Avg. Diluted Shares | M25: 50.7 | N25: 48.078 | O25: =H24 -> 46.203843 | R25: =O25 -> 46.203843
J26: Diluted EPS | M26: =M22/M25 -> 5.1724458 | N26: =N22/N25 -> 6.2328924 | O26: =O22/O25 -> 8.0068232 | R26: =O26 -> 8.0068232 | T26: Total Debt | W26: 1906.122
D27: Plus: Total Debt | H27: =W26 -> 1906.122 | T27: Other Long-term Liabilities | W27: =130.505+56.532+25.303+107.963+39.771+3.487 -> 363.561
D28: Plus: Preferred Stock | H28: =+W31 -> 0 | J28: Adjusted Income Statement | T28: Total Liabilities | W28: =SUM(W26:W27)+W24 -> 2736.974
D29: Plus: Non-controlling Intererst | H29: =+W30 -> 0 | J29: Reported Gross Profit | M29: =M13 -> 691.465 | N29: =N13 -> 776.161 | O29: =O13 -> 777.357 | R29: =O29 -> 777.357
D30: Less: Cash & Cash Equivalents | H30: =-W9 -> -44.997 | J30: Non-recurring items in COGS | M30: 0 | N30: 0 | O30: 0 | R30: =O30 -> 0 | T30: Non-Controlling Interest | W30: 0
D31: Enterprise Value | H31: =SUM(H25:H30) -> 7251.2653 | J31: Adj. Gross Profit | M31: =SUM(M29:M30) -> 691.465 | N31: =SUM(N29:N30) -> 776.161 | O31: =SUM(O29:O30) -> 777.357 | R31: =O31 -> 777.357 | T31: Preferred Stock | W31: 0
J32: % Margin | M32: =M31/M$11 -> 0.44779217 | N32: =N31/N$11 -> 0.48974123 | O32: =O31/O$11 -> 0.4868239 | R32: =O32 -> 0.4868239 | T32: Shareholder's Equity | W32: 181.229
D33: Trading Multiples | T33: Total Liabilities & Equity | W33: =SUM(W30:W32)+W28 -> 2918.203
E34: LTM 12/31/2025 | F34: NFY 12/31/2026 | G34: NFY+1 12/31/2027 | H34: NFY+2 12/31/2028 | J34: Reported EBIT | M34: =M15 -> 378.764 | N34: =N15 -> 463.773 | O34: =O15 -> 448.399 | R34: =O34 -> 448.399
J35: Non-recurring items in COGS | M35: 0 | N35: 0 | O35: 0 | R35: =O35 -> 0 | T35: Balance Check | W35: =IF(W33=W18,W18-W33,W18-W33) -> 4.5474735e-13
D36: EV/Sales | E36: =$H$31/E37 -> 4.5411429 | F36: =$H$31/F37 -> 4.4955147 | G36: =$H$31/G37 -> 4.3525002 | H36: =$H$31/H37 -> 4.2109554 | J36: Other Non-recurring items | M36: 23 | N36: 23 | O36: 23 | R36: =O36 -> 23
D37: Metric | E37: =R11 -> 1596.793 | F37: 1613 | G37: 1666 | H37: 1722 | J37: Adjusted EBIT | M37: =M41-M40 -> 500.841 | N37: =N41-N40 -> 559.062 | O37: =O41-O40 -> 573.647 | R37: =O37 -> 573.647
D38: EV/EBITDA | E38: =$H$31/E39 -> 11.590897 | F38: =$H$31/F39 -> 11.403153 | G38: =$H$31/G39 -> 11.142079 | H38: =$H$31/H39 -> 10.848691 | J38: % Margin | M38: =M37/M$11 -> 0.32434422 | N38: =N37/N$11 -> 0.35275634 | O38: =O37/O$11 -> 0.35924945 | R38: =O38 -> 0.35924945 | T38: Calculation of Fully Diluted Shares Outstanding
D39: Metric | E39: =R41 -> 625.6 | F39: 635.9 | G39: 650.8 | H39: 668.4 | T39: Basic Shares Outstanding | X39: 46.17
D40: EV/EBIT | E40: =$H$31/E41 -> 16.171457 | F40: =$H$31/F41 -> 16.031982 | G40: =$H$31/G41 -> 13.966227 | H40: =$H$31/H41 -> 13.086564 | J40: Depreciation & Amortization | M40: 39.659 | N40: 45.038 | O40: 51.953 | R40: =O40 -> 51.953 | T40: Plus: Shares from In-the-Money Options | X40: =W54 -> 0.695083
D41: Metric | E41: =R34 -> 448.399 | F41: 452.3 | G41: 519.2 | H41: 554.1 | J41: Adjusted EBITDA | M41: 540.5 | N41: 604.1 | O41: 625.6 | R41: =O41 -> 625.6 | T41: Less: Shares Repurchased | X41: =-X54/H18 -> -0.66124045
D42: P/E | E42: =$H$18/E43 -> 14.570073 | F42: =$H$18/F43 -> 19.67285 | G42: =$H$18/G43 -> 16.093254 | H42: =$H$18/H43 -> 14.520787 | J42: % Margin | M42: =M41/M$11 -> 0.35002736 | N42: =N41/N$11 -> 0.38117437 | O42: =O41/O$11 -> 0.39178528 | R42: =O42 -> 0.39178528 | T42: Net New Shares from Options | X42: =SUM(X40:X41) -> 0.033842546
D43: Metric | E43: =R26 -> 8.0068232 | F43: 5.93 | G43: 7.249 | H43: 8.034 | T43: Plus: Shares from Convertible Securities | X43: 0
...

Sheet MAR
D2: Marriott International (NYSE: MAR)
D3: Input Page
D4: ($ in millions, except per share data)
D7: General Information | J7: Reported Income Statement | T7: Balance Sheet Data
D8: Company Name | H8: Marriott International Inc. | P8: Prior Stub 12/31/2025 | Q8: Current Stub 12/31/2025 | R8: LTM 12/31/2025 | W8: 2025A | X8: -
D9: Ticker | H9: MAR | M9: Fiscal Year Ending December 31, | T9: Cash & Cash Equivalents | W9: 358
D10: Stock Exchange | H10: NYSE | M10: 2023A | N10: 2024A | O10: 2025A | T10: Accounts Receivables | W10: 2909
D11: Fisical Year Ending | H11: 12/31/2025 | J11: Sales | M11: 23713 | N11: 25100 | O11: 26186 | R11: =O11 -> 26186 | T11: Inventories | W11: 0
D12: Moody's Corporate Rating | H12: Baa2 | J12: COGS (incl. D&A) | M12: =19849-867 -> 18982 | N12: =21333-945 -> 20388 | O12: =22045-870 -> 21175 | R12: =O12 -> 21175 | T12: Prepaids & Other Current Assets | W12: 317
D13: S&P Corporate Rating | H13: BBB | J13: Gross Profit | M13: =M11-M12 -> 4731 | N13: =N11-N12 -> 4712 | O13: =O11-O12 -> 5011 | R13: =O13 -> 5011 | T13: Total Current Assets | W13: =SUM(W9:W12) -> 3584
D14: Predicted Beta | H14: 1.1 | J14: SG&A | M14: 867 | N14: 945 | O14: 870 | R14: =O14 -> 870
D15: Marginal Tax | H15: 0.2 | J15: Other Income/(Expense) | M15: 40 | N15: 31 | O15: 9 | R15: =O15 -> 9 | T15: Property, Plant & Equivalent, net | W15: 1954
J16: EBIT | M16: =M13-M14+M15 -> 3904 | N16: =N13-N14+N15 -> 3798 | O16: =O13-O14+O15 -> 4150 | R16: =O16 -> 4150 | T16: Goodwill & Intangible Assets | W16: =6207+4129+8907 -> 19243
D17: Selected Market Data | J17: Interest Expense | M17: =30+9-565 -> -526 | N17: =40+8-695 -> -647 | O17: =42+11-809 -> -756 | R17: =O17 -> -756 | T17: Other Assets | W17: =298+151+570+941+799 -> 2759
D18: Current Price | H18: 363.98 | J18: Pre-tax Income | M18: =SUM(M16:M17) -> 3378 | N18: =SUM(N16:N17) -> 3151 | O18: =SUM(O16:O17) -> 3394 | R18: =O18 -> 3394 | T18: Total Assets | W18: =SUM(W15:W17)+W13 -> 27540
D19: % of 52-week High | H19: =H18/H20 -> 0.98372973 | J19: Income Taxes | M19: -295 | N19: -776 | O19: -793 | R19: =O19 -> -793
D20: 52-week High Price | H20: 370 | J20: Non-controlling Interest | M20: 0 | N20: 0 | O20: 0 | R20: =O20 -> 0 | T20: Current Portion of Long-term Debt | W20: 1209
D21: 52-week Low Price | H21: 212.53 | J21: Preferred Dividends | M21: 0 | N21: 0 | O21: 0 | R21: =O21 -> 0 | T21: Accounts Payable | W21: 814
D22: Dividend Per Share | H22: 2.68 | J22: Net Income | M22: =SUM(M18:M21) -> 3083 | N22: =SUM(N18:N21) -> 2375 | O22: =SUM(O18:O21) -> 2601 | R22: =O22 -> 2601 | T22: Accrued Liabilities | W22: =1438+1440 -> 2878
J23: Effective Tax Rate | M23: =ABS(M19/M18) -> 0.087329781 | N23: =ABS(N19/N18) -> 0.24627103 | O23: =ABS(O19/O18) -> 0.23364761 | R23: =O23 -> 0.23364761 | T23: Other Current Liabilties | W23: 3497
D24: Fully Diluted Shares Outstanding | H24: =X44 -> 265.68455 | T24: Total Current Liabilities | W24: =SUM(W20:W23) -> 8398
D25: Equity Value | H25: =H24*H18 -> 96703.864 | J25: Weighted Avg. Diluted Shares | M25: 302.9 | N25: 285.2 | O25: 273.6 | R25: =O25 -> 273.6
J26: Diluted EPS | M26: =M22/M25 -> 10.178277 | N26: =N22/N25 -> 8.3274895 | O26: =O22/O25 -> 9.5065789 | R26: =O26 -> 9.5065789 | T26: Total Debt | W26: 14995
D27: Plus: Total Debt | H27: =+W26+W20 -> 16204 | T27: Other Long-term Liabilities | W27: =4495+79+1200+879+1265 -> 7918
D28: Plus: Preferred Stock | H28: =+W31 -> 0 | J28: Adjusted Income Statement | T28: Total Liabilities | W28: =SUM(W26:W27)+W24 -> 31311
D29: Plus: Non-controlling Intererst | H29: =+W30 -> 0 | J29: Reported Gross Profit | M29: =M13 -> 4731 | N29: =N13 -> 4712 | O29: =O13 -> 5011 | R29: =O29 -> 5011
D30: Less: Cash & Cash Equivalents | H30: =-W9 -> -358 | J30: Non-recurring items in COGS | M30: 0 | N30: 0 | O30: 0 | R30: =O30 -> 0 | T30: Non-Controlling Interest | W30: 0
D31: Enterprise Value | H31: =SUM(H25:H30) -> 112549.86 | J31: Adj. Gross Profit | M31: =SUM(M29:M30) -> 4731 | N31: =SUM(N29:N30) -> 4712 | O31: =SUM(O29:O30) -> 5011 | R31: =O31 -> 5011 | T31: Preferred Stock | W31: 0
J32: % Margin | M32: =M31/M$11 -> 0.19951082 | N32: =N31/N$11 -> 0.18772908 | O32: =O31/O$11 -> 0.1913618 | R32: =O32 -> 0.1913618 | T32: Shareholder's Equity | W32: -3771
D33: Trading Multiples | T33: Total Liabilities & Equity | W33: =SUM(W30:W32)+W28 -> 27540
E34: LTM 12/31/2025 | F34: NFY 12/31/2026 | G34: NFY+1 12/31/2027 | H34: NFY+2 12/31/2028 | J34: Reported EBIT | M34: =M16 -> 3904 | N34: =N16 -> 3798 | O34: =O16 -> 4150 | R34: =O34 -> 4150
J35: Non-recurring items in COGS | M35: 0 | N35: 0 | O35: 0 | R35: =O35 -> 0 | T35: Balance Check | W35: =IF(W33=W18,W18-W33,W18-W33) -> 0
D36: EV/Sales | E36: =$H$31/E37 -> 4.298093 | F36: =$H$31/F37 -> 4.0339007 | G36: =$H$31/G37 -> 3.8293989 | H36: =$H$31/H37 -> 3.7047355 | J36: Other Non-recurring items | M36: 23 | N36: -55 | O36: -54 | R36: =O36 -> -54
D37: Metric | E37: =R11 -> 26186 | F37: 27901 | G37: 29391 | H37: 30380 | J37: Adjusted EBIT | M37: =SUM(M34:M36) -> 3927 | N37: =SUM(N34:N36) -> 3743 | O37: =SUM(O34:O36) -> 4096 | R37: =O37 -> 4096
D38: EV/EBITDA | E38: =$H$31/E39 -> 23.972282 | F38: =$H$31/F39 -> 19.076248 | G38: =$H$31/G39 -> 17.794445 | H38: =$H$31/H39 -> 16.750984 | J38: % Margin | M38: =M37/M$11 -> 0.16560536 | N38: =N37/N$11 -> 0.14912351 | O38: =O37/O$11 -> 0.15641946 | R38: =O38 -> 0.15641946 | T38: Calculation of Fully Diluted Shares Outstanding
D39: Metric | E39: =R41 -> 4695 | F39: 5900 | G39: 6325 | H39: 6719 | T39: Basic Shares Outstanding | X39: 264.98455
D40: EV/EBIT | E40: =$H$31/E41 -> 27.120449 | F40: =$H$31/F41 -> 22.769546 | G40: =$H$31/G41 -> 20.935615 | H40: =$H$31/H41 -> 19.67999 | J40: Depreciation & Amortization | M40: 436 | N40: 492 | O40: 599 | R40: =O40 -> 599 | T40: Plus: Shares from In-the-Money Options | X40: 0
D41: Metric | E41: =R34 -> 4150 | F41: 4943 | G41: 5376 | H41: 5719 | J41: Adjusted EBITDA | M41: =M37+M40 -> 4363 | N41: =N37+N40 -> 4235 | O41: =O37+O40 -> 4695 | R41: =O41 -> 4695 | T41: Less: Shares Repurchased | X41: 0
D42: P/E | E42: =$H$18/E43 -> 38.28717 | F42: =$H$18/F43 -> 32.180986 | G42: =$H$18/G43 -> 29.663762 | H42: =$H$18/H43 -> 27.164007 | J42: % Margin | M42: =M41/M$11 -> 0.1839919 | N42: =N41/N$11 -> 0.1687251 | O42: =O41/O$11 -> 0.17929428 | R42: =O42 -> 0.17929428 | T42: Net New Shares from Options | X42: 0.7
D43: Metric | E43: =R26 -> 9.5065789 | F43: =3005/H24 -> 11.310405 | G43: =3260/H24 -> 12.27019 | H43: =3560/H24 -> 13.399349 | T43: Plus: Shares from Convertible Securities | X43: 0
...

Sheet ABNB
D2: Airbnb Inc. Cl A (NYSE: ABNB)
D3: Input Page
D4: ($ in millions, except per share data)
D7: General Information | J7: Reported Income Statement | T7: Balance Sheet Data
D8: Company Name | H8: Airbnb Inc. Cl A | P8: Prior Stub 12/31/2025 | Q8: Current Stub 12/31/2025 | R8: LTM 12/31/2025 | W8: 2025A | X8: -
D9: Ticker | H9: ABNB | M9: Fiscal Year Ending December 31, | T9: Cash & Cash Equivalents | W9: 6560
D10: Stock Exchange | H10: NYSE | M10: 2023A | N10: 2024A | O10: 2025A | T10: Accounts Receivables | W10: 6959
D11: Fisical Year Ending | H11: 12/31/2025 | J11: Sales | M11: 9917 | N11: 11102 | O11: 12241 | R11: =O11 -> 12241 | T11: Short-term investments | W11: 4454
D12: Moody's Corporate Rating | H12: Baa1 | J12: COGS (incl. D&A) | M12: =1703+1186 -> 2889 | N12: =1878+1282 -> 3160 | O12: =2086+1327 -> 3413 | R12: =O12 -> 3413 | T12: Prepaids & Other Current Assets | W12: 824
D13: S&P Corporate Rating | H13: A- | J13: Gross Profit | M13: =M11-M12 -> 7028 | N13: =N11-N12 -> 7942 | O13: =O11-O12 -> 8828 | R13: =O13 -> 8828 | T13: Total Current Assets | W13: =SUM(W9:W12) -> 18797
D14: Predicted Beta | H14: 1.56 | J14: Product & Development | M14: 1722 | N14: 2056 | O14: 2354 | R14: =O14 -> 2354
D15: Marginal Tax | H15: 0.2 | J15: SG&A | M15: =1763+2025 -> 3788 | N15: =2148+1185 -> 3333 | O15: =2588+1342 -> 3930 | T15: Deferred income tax assets | W15: 2102
J16: EBIT | M16: =M13-M14-M15 -> 1518 | N16: =N13-N14-N15 -> 2553 | O16: =O13-O14-O15 -> 2544 | R16: =O16 -> 2544 | T16: Goodwill & Intangible Assets | W16: 770
D17: Selected Market Data | J17: Interest Income | M17: 721 | N17: 818 | O17: 705 | T17: Other Assets | W17: 539
D18: Current Price | H18: 134.51 | J18: Other expense, net | M18: -137 | N18: -40 | O18: -112 | R18: =O18 -> -112 | T18: Total Assets | W18: =SUM(W15:W17)+W13 -> 22208
D19: % of 52-week High | H19: =H18/H20 -> 0.93487629 | J19: Pre-tax Income | M19: =SUM(M16:M18) -> 2102 | N19: =SUM(N16:N18) -> 3331 | O19: =SUM(O16:O18) -> 3137 | R19: =O19 -> 3137
D20: 52-week High Price | H20: 143.88 | J20: Income Taxes | M20: 2690 | N20: 683 | O20: 626 | R20: =O20 -> 626 | T20: Accrued exp, Acc payable and current | W20: 2948
D21: 52-week Low Price | H21: 109.79 | J21: Non-controlling Interest | M21: 0 | N21: 0 | O21: 0 | R21: =O21 -> 0 | T21: Funds payable and amount payable | W21: 6959
D22: Dividend Per Share | H22: 0 | J22: Preferred Dividends | M22: 0 | N22: 0 | O22: 0 | R22: =O22 -> 0 | T22: Current portion of long-term debt | W22: 1999
J23: Net Income | M23: =SUM(M19:M22) -> 4792 | N23: =SUM(N19:N22) -> 4014 | O23: =SUM(O19:O22) -> 3763 | R23: =O23 -> 3763 | T23: Other Current Liabilties | W23: 1743
D24: Fully Diluted Shares Outstanding | H24: =X44 -> 622.27061 | J24: Effective Tax Rate | M24: =ABS(M20/M19) -> 1.2797336 | N24: =ABS(N20/N19) -> 0.20504353 | O24: =ABS(O20/O19) -> 0.19955371 | R24: =O24 -> 0.19955371 | T24: Total Current Liabilities | W24: =SUM(W20:W23) -> 13649
D25: Equity Value | H25: =H24*H18 -> 83701.62
J26: Weighted Avg. Diluted Shares | M26: 662 | N26: 645 | O26: 623 | R26: =O26 -> 623 | T26: Total Debt | W26: 0
D27: Plus: Total Debt | H27: =W26+W22 -> 1999 | J27: Diluted EPS | M27: =M23/M26 -> 7.2386707 | N27: =N23/N26 -> 6.2232558 | O27: =O23/O26 -> 6.0401284 | R27: =O27 -> 6.0401284 | T27: Other Long-term Liabilities | W27: 360
D28: Plus: Preferred Stock | H28: =+W31 -> 0 | T28: Total Liabilities | W28: =SUM(W26:W27)+W24 -> 14009
D29: Plus: Non-controlling Intererst | H29: =+W30 -> 0 | J29: Adjusted Income Statement
D30: Less: Cash & Cash Equivalents | H30: =-W9 -> -6560 | J30: Reported Gross Profit | M30: =M13 -> 7028 | N30: =N13 -> 7942 | O30: =O13 -> 8828 | R30: =O30 -> 8828 | T30: Non-Controlling Interest | W30: 0
D31: Enterprise Value | H31: =SUM(H25:H30) -> 79140.62 | J31: Non-recurring items in COGS | M31: 0 | N31: 0 | O31: 0 | R31: =O31 -> 0 | T31: Preferred Stock | W31: 0
J32: Adj. Gross Profit | M32: =SUM(M30:M31) -> 7028 | N32: =SUM(N30:N31) -> 7942 | O32: =SUM(O30:O31) -> 8828 | R32: =O32 -> 8828 | T32: Shareholder's Equity | W32: 8199
D33: Trading Multiples | J33: % Margin | M33: =M32/M$11 -> 0.70868206 | N33: =N32/N$11 -> 0.7153666 | O33: =O32/O$11 -> 0.72118291 | R33: =O33 -> 0.72118291 | T33: Total Liabilities & Equity | W33: =SUM(W30:W32)+W28 -> 22208
E34: LTM 12/31/2025 | F34: NFY 12/31/2026 | G34: NFY+1 12/31/2027 | H34: NFY+2 12/31/2028
J35: Reported EBIT | M35: =M16 -> 1518 | N35: =N16 -> 2553 | O35: =O16 -> 2544 | R35: =O35 -> 2544 | T35: Balance Check | W35: =IF(W33=W18,W18-W33,W18-W33) -> 0
D36: EV/Sales | E36: =$H$31/E37 -> 6.4652087 | F36: =$H$31/F37 -> 5.7779528 | G36: =$H$31/G37 -> 5.2487478 | H36: =$H$31/H37 -> 4.7859591 | J36: Non-recurring items in COGS | M36: =1120+974-3 -> 2091 | N36: =1407+23-7 -> 1423 | O36: =1592+74+1-5 -> 1662 | R36: =O36 -> 1662
D37: Metric | E37: =R11 -> 12241 | F37: 13697 | G37: 15078 | H37: 16536 | J37: Other Non-recurring items | M37: 0 | N37: 0 | O37: 0 | R37: =O37 -> 0
D38: EV/EBITDA | E38: =$H$31/E39 -> 18.417645 | F38: =$H$31/F39 -> 16.446513 | G38: =$H$31/G39 -> 14.652957 | H38: =$H$31/H39 -> 13.0552 | J38: Adjusted EBIT | M38: =SUM(M35:M37) -> 3609 | N38: =SUM(N35:N37) -> 3976 | O38: =SUM(O35:O37) -> 4206 | R38: =O38 -> 4206 | T38: Calculation of Fully Diluted Shares Outstanding
D39: Metric | E39: =R42 -> 4297 | F39: 4812 | G39: 5401 | H39: 6062 | J39: % Margin | M39: =M38/M$11 -> 0.36392054 | N39: =N38/N$11 -> 0.35813367 | O39: =O38/O$11 -> 0.34359938 | R39: =O39 -> 0.34359938 | T39: Basic Shares Outstanding | X39: 613
D40: EV/EBIT | E40: =$H$31/E41 -> 31.108734 | F40: =$H$31/F41 -> 26.424247 | G40: =$H$31/G41 -> 22.57935 | H40: =$H$31/H41 -> 19.608677 | T40: Plus: Shares from In-the-Money Options | X40: =W54 -> 37
D41: Metric | E41: =R35 -> 2544 | F41: 2995 | G41: 3505 | H41: 4036 | J41: Depreciation & Amortization | M41: 44 | N41: 65 | O41: 91 | R41: =O41 -> 91 | T41: Less: Shares Repurchased | X41: =-(X54/H18) -> -27.729388
D42: P/E | E42: =$H$18/E43 -> 22.269394 | F42: =$H$18/F43 -> 27.956453 | G42: =$H$18/G43 -> 24.481316 | H42: =$H$18/H43 -> 21.622738 | J42: Adjusted EBITDA | M42: =M38+M41 -> 3653 | N42: =N38+N41 -> 4041 | O42: =O38+O41 -> 4297 | R42: =O42 -> 4297 | T42: Net New Shares from Options | X42: =SUM(X40:X41) -> 9.2706119
D43: Metric | E43: =R27 -> 6.0401284 | F43: =2994/H24 -> 4.8114115 | G43: =3419/H24 -> 5.4943941 | H43: =3871/H24 -> 6.2207662 | J43: % Margin | M43: =M42/M$11 -> 0.36835737 | N43: =N42/N$11 -> 0.36398847 | O43: =O42/O$11 -> 0.35103341 | R43: =O43 -> 0.35103341 | T43: Plus: Shares from Convertible Securities | X43: 0
...

Sheet HLT
D2: Hilton Worldwide Holding Inc. (NYSE: HLT)
D3: Input Page
D4: ($ in millions, except per share data)
D7: General Information | J7: Reported Income Statement | T7: Balance Sheet Data
D8: Company Name | H8: Hilton Worldwide Holdings Inc. | P8: Prior Stub 12/31/2025 | Q8: Current Stub 12/31/2025 | R8: LTM 12/31/2025 | W8: 2025A | X8: -
D9: Ticker | H9: HLT | M9: Fiscal Year Ending December 31, | T9: Cash & Cash Equivalents | W9: =918+52 -> 970
D10: Stock Exchange | H10: NYSE | M10: 2023A | N10: 2024A | O10: 2025A | T10: Accounts Receivables | W10: 1690
D11: Fisical Year Ending | H11: 12/31/2025 | J11: Sales | M11: 10235 | N11: 11174 | O11: 12039 | R11: =O11 -> 12039 | T11: Prepaid expenses | W11: 219
D12: Moody's Corporate Rating | H12: Ba2 | J12: COGS (incl. D&A) | M12: =8010-393 -> 7617 | N12: =8809-415 -> 8394 | O12: =9346-408 -> 8938 | R12: =O12 -> 8938 | T12: Other Current Assets | W12: 117
D13: S&P Corporate Rating | H13: BB+ | J13: Gross Profit | M13: =M11-M12 -> 2618 | N13: =N11-N12 -> 2780 | O13: =O11-O12 -> 3101 | R13: =O13 -> 3101 | T13: Total Current Assets | W13: =SUM(W9:W12) -> 2996
D14: Predicted Beta | H14: 1.04 | J14: SG&A | M14: 393 | N14: 415 | O14: 408 | R14: =O14 -> 408
D15: Marginal Tax | H15: 0.2 | J15: Other Income/(Expense) | M15: 0 | N15: 5 | O15: 0 | R15: =O15 -> 0 | T15: Property, Plant & Equivalent, net | W15: 684
J16: EBIT | M16: =M13-M14+M15 -> 2225 | N16: =N13-N14+N15 -> 2370 | O16: =O13-O14+O15 -> 2693 | R16: =O16 -> 2693 | T16: Goodwill & Intangible Assets | W16: =5081+5023+1471+206 -> 11781
D17: Selected Market Data | J17: Interest Expense | M17: =39-92-16-464 -> -533 | N17: =-6-12-569 -> -587 | O17: =10-11-620 -> -621 | R17: =O17 -> -621 | T17: Other Assets | W17: =577+252+484 -> 1313
D18: Current Price | H18: 330.71 | J18: Pre-tax Income | M18: =SUM(M16:M17) -> 1692 | N18: =SUM(N16:N17) -> 1783 | O18: =SUM(O16:O17) -> 2072 | R18: =O18 -> 2072 | T18: Total Assets | W18: =SUM(W15:W17)+W13 -> 16774
D19: % of 52-week High | H19: =H18/H20 -> 0.99056491 | J19: Income Taxes | M19: -541 | N19: -244 | O19: -611 | R19: =O19 -> -611
D20: 52-week High Price | H20: 333.86 | J20: Non-controlling Interest | M20: 0 | N20: 0 | O20: 0 | R20: =O20 -> 0 | T20: Current Portion of Long-term Debt | W20: 25
D21: 52-week Low Price | H21: 201.15 | J21: Preferred Dividends | M21: 0 | N21: 0 | O21: 0 | R21: =O21 -> 0 | T21: Accounts Payable | W21: 2336
D22: Dividend Per Share | H22: 0.6 | J22: Net Income | M22: =SUM(M18:M21) -> 1151 | N22: =SUM(N18:N21) -> 1539 | O22: =SUM(O18:O21) -> 1461 | R22: =O22 -> 1461 | T22: Accrued Liabilities | W22: 858
J23: Effective Tax Rate | M23: =ABS(M19/M18) -> 0.31973995 | N23: =ABS(N19/N18) -> 0.13684801 | O23: =ABS(O19/O18) -> 0.29488417 | R23: =O23 -> 0.29488417 | T23: Other Current Liabilties | W23: 1289
D24: Fully Diluted Shares Outstanding | H24: =X44 -> 236.7 | T24: Total Current Liabilities | W24: =SUM(W20:W23) -> 4508
D25: Equity Value | H25: =H24*H18 -> 78279.057 | J25: Weighted Avg. Diluted Shares | M25: 264 | N25: 250 | O25: =H24 -> 236.7 | R25: =O25 -> 236.7
J26: Diluted EPS | M26: =M22/M25 -> 4.3598485 | N26: =N22/N25 -> 6.156 | O26: =O22/O25 -> 6.1723701 | R26: =O26 -> 6.1723701 | T26: Total Debt | W26: 12338
D27: Plus: Total Debt | H27: =+W20+W26 -> 12363 | T27: Other Long-term Liabilities | W27: =730+1648+322+1624+950 -> 5274
D28: Plus: Preferred Stock | H28: =+W31 -> 0 | J28: Adjusted Income Statement | T28: Total Liabilities | W28: =SUM(W26:W27)+W24 -> 22120
D29: Plus: Non-controlling Intererst | H29: =+W30 -> 42 | J29: Reported Gross Profit | M29: =M13 -> 2618 | N29: =N13 -> 2780 | O29: =O13 -> 3101 | R29: =O29 -> 3101
D30: Less: Cash & Cash Equivalents | H30: =-W9 -> -970 | J30: Non-recurring items in COGS | M30: 0 | N30: 0 | O30: 0 | R30: =O30 -> 0 | T30: Non-Controlling Interest | W30: =29+13 -> 42
D31: Enterprise Value | H31: =SUM(H25:H30) -> 89714.057 | J31: Adj. Gross Profit | M31: =SUM(M29:M30) -> 2618 | N31: =SUM(N29:N30) -> 2780 | O31: =SUM(O29:O30) -> 3101 | R31: =O31 -> 3101 | T31: Preferred Stock | W31: 0
J32: % Margin | M32: =M31/M$11 -> 0.25578896 | N32: =N31/N$11 -> 0.24879184 | O32: =O31/O$11 -> 0.25757953 | R32: =O32 -> 0.25757953 | T32: Shareholder's Equity | W32: -5388
D33: Trading Multiples | T33: Total Liabilities & Equity | W33: =SUM(W30:W32)+W28 -> 16774
E34: LTM 12/31/2025 | F34: NFY 12/31/2026 | G34: NFY+1 12/31/2027 | H34: NFY+2 12/31/2028 | J34: Reported EBIT | M34: =M16 -> 2225 | N34: =N16 -> 2370 | O34: =O16 -> 2693 | R34: =O34 -> 2693
J35: Non-recurring items in COGS | M35: 0 | N35: 0 | O35: 0 | R35: =O35 -> 0 | T35: Balance Check | W35: =IF(W33=W18,W18-W33,W18-W33) -> 0
D36: EV/Sales | E36: =$H$31/E37 -> 7.4519526 | F36: =$H$31/F37 -> 6.8510162 | G36: =$H$31/G37 -> 6.3227893 | H36: =$H$31/H37 -> 5.8579208 | J36: Other Non-recurring items | M36: =16+92+63+169+38+43+337+28-147 -> 639 | N36: =-5+12+50+57+176+50-6428+6985+34-146 -> 785 | O36: =73+170+57-7085+7550+80-177 -> 668 | R36: =N36 -> 785
D37: Metric | E37: =R11 -> 12039 | F37: 13095 | G37: 14189 | H37: 15315 | J37: Adjusted EBIT | M37: =SUM(M34:M36) -> 2864 | N37: =SUM(N34:N36) -> 3155 | O37: =SUM(O34:O36) -> 3361 | R37: =O37 -> 3361
D38: EV/EBITDA | E38: =$H$31/E39 -> 25.35728 | F38: =$H$31/F39 -> 22.25051 | G38: =$H$31/G39 -> 20.412755 | H38: =$H$31/H39 -> 18.733359 | J38: % Margin | M38: =M37/M$11 -> 0.27982413 | N38: =N37/N$11 -> 0.28235189 | O38: =O37/O$11 -> 0.27917601 | R38: =O38 -> 0.27917601 | T38: Calculation of Fully Diluted Shares Outstanding
D39: Metric | E39: =R41 -> 3538 | F39: 4032 | G39: 4395 | H39: 4789 | T39: Basic Shares Outstanding | X39: 236
D40: EV/EBIT | E40: =$H$31/E41 -> 33.313798 | F40: =$H$31/F41 -> 25.936414 | G40: =$H$31/G41 -> 23.509973 | H40: =$H$31/H41 -> 21.370666 | J40: Depreciation & Amortization | M40: 147 | N40: 146 | O40: 177 | R40: =O40 -> 177 | T40: Plus: Shares from In-the-Money Options | X40: =W54 -> 4.025
D41: Metric | E41: =R34 -> 2693 | F41: 3459 | G41: 3816 | H41: 4198 | J41: Adjusted EBITDA | M41: =M37+M40 -> 3011 | N41: =N37+N40 -> 3301 | O41: =O37+O40 -> 3538 | R41: =O41 -> 3538 | T41: Less: Shares Repurchased | X41: =-X54/H18 -> -1.8649819
D42: P/E | E42: =$H$18/E43 -> 53.579094 | F42: =$H$18/F43 -> 37.580682 | G42: =$H$18/G43 -> 33.203815 | H42: =$H$18/H43 -> 28.558722 | J42: % Margin | M42: =M41/M$11 -> 0.29418661 | N42: =N41/N$11 -> 0.29541793 | O42: =O41/O$11 -> 0.29387823 | R42: =O42 -> 0.29387823 | T42: Net New Shares from Options | X42: 0.7
D43: Metric | E43: =R26 -> 6.1723701 | F43: 8.8 | G43: 9.96 | H43: 11.58 | T43: Plus: Shares from Convertible Securities | X43: 0
...

Sheet H
D2: Hyatt Hotels Corporation (NYSE: H)
D3: Input Page
D4: ($ in millions, except per share data)
D7: General Information | J7: Reported Income Statement | T7: Balance Sheet Data
D8: Company Name | H8: Hyatt Hotels Corporation | P8: Prior Stub 12/31/2025 | Q8: Current Stub 12/31/2025 | R8: LTM 12/31/2025 | W8: 2025A | X8: -
D9: Ticker | H9: H | M9: Fiscal Year Ending December 31, | T9: Cash & Cash Equivalents | W9: 788
D10: Stock Exchange | H10: NYSE | M10: 2023A | N10: 2024A | O10: 2025A | T10: Accounts Receivables | W10: 1123
D11: Fisical Year Ending | H11: 12/31/2025 | J11: Sales | M11: 6667 | N11: 6648 | O11: 7101 | R11: =O11 -> 7101 | T11: Inventories | W11: 8
D12: Moody's Corporate Rating | H12: Baa3 | J12: COGS (incl. D&A) | M12: =6378-578 -> 5800 | N12: =6274-548 -> 5726 | O12: =6753-555 -> 6198 | R12: =O12 -> 6198 | T12: Prepaids & Other Current Assets | W12: =26+169+63 -> 258
D13: S&P Corporate Rating | H13: BBB- | J13: Gross Profit | M13: =M11-M12 -> 867 | N13: =N11-N12 -> 922 | O13: =O11-O12 -> 903 | R13: =O13 -> 903 | T13: Total Current Assets | W13: =SUM(W9:W12) -> 2177
D14: Predicted Beta | H14: 1.22 | J14: SG&A | M14: 578 | N14: 548 | O14: 555 | R14: =O14 -> 555
D15: Marginal Tax | H15: 0.2 | J15: EBIT | M15: =M13-M14 -> 289 | N15: =N13-N14 -> 374 | O15: =O13-O14 -> 348 | R15: =O15 -> 348 | T15: Property, Plant & Equivalent, net | W15: 1577
J16: Interest Expense | M16: -145 | N16: -180 | O16: -317 | R16: =O16 -> -317 | T16: Goodwill & Intangible Assets | W16: =3454+2229 -> 5683
D17: Selected Market Data | J17: Other Income/(Expense) | M17: =55-1+18-30+124 -> 166 | N17: =49+31+1245-213+257 -> 1369 | O17: =50-46-15-40+101 -> 50 | T17: Other Assets | W17: =186+442+328+518+3125 -> 4599
D18: Current Price | H18: 166.5 | J18: Pre-tax Income | M18: =SUM(M15:M17) -> 310 | N18: =SUM(N15:N17) -> 1563 | O18: =SUM(O15:O17) -> 81 | R18: =O18 -> 81 | T18: Total Assets | W18: =SUM(W15:W17)+W13 -> 14036
D19: % of 52-week High | H19: =H18/H20 -> 0.92228438 | J19: Income Taxes | M19: -90 | N19: -267 | O19: -130 | R19: =O19 -> -130
D20: 52-week High Price | H20: 180.53 | J20: Non-controlling Interest | M20: 0 | N20: 0 | O20: -3 | R20: =O20 -> -3 | T20: Current Portion of Long-term Debt | W20: 6
D21: 52-week Low Price | H21: 102.93 | J21: Preferred Dividends | M21: 0 | N21: 0 | O21: 0 | R21: =O21 -> 0 | T21: Accounts Payable | W21: 451
D22: Dividend Per Share | H22: 0.6 | J22: Net Income | M22: =SUM(M18:M21) -> 220 | N22: =SUM(N18:N21) -> 1296 | O22: =SUM(O18:O21) -> -52 | R22: =O22 -> -52 | T22: Accrued Liabilities | W22: 1584
J23: Effective Tax Rate | M23: =ABS(M19/M18) -> 0.29032258 | N23: =ABS(N19/N18) -> 0.17082534 | O23: =ABS(O19/O18) -> 1.6049383 | R23: =O23 -> 1.6049383 | T23: Other Current Liabilties | W23: =592+226+35 -> 853
D24: Fully Diluted Shares Outstanding | H24: =X44 -> 96.204061 | T24: Total Current Liabilities | W24: =SUM(W20:W23) -> 2894
D25: Equity Value | H25: =H24*H18 -> 16017.976 | J25: Weighted Avg. Diluted Shares | M25: 107.72696 | N25: 102.4241 | O25: =H24 -> 96.204061 | R25: =O25 -> 96.204061
J26: Diluted EPS | M26: =M22/M25 -> 2.0422 | N26: =N22/N25 -> 12.653272 | O26: =O22/O25 -> -0.54051772 | R26: =O26 -> -0.54051772 | T26: Total Debt | W26: 4272
D27: Plus: Total Debt | H27: =+W20+W26 -> 4278 | T27: Other Long-term Liabilities | W27: =1012+243+1956 -> 3211
D28: Plus: Preferred Stock | H28: =+W31 -> 0 | J28: Adjusted Income Statement | T28: Total Liabilities | W28: =SUM(W26:W27)+W24 -> 10377
D29: Plus: Non-controlling Intererst | H29: =+W30 -> 325 | J29: Reported Gross Profit | M29: =M13 -> 867 | N29: =N13 -> 922 | O29: =O13 -> 903 | R29: =O29 -> 903
D30: Less: Cash & Cash Equivalents | H30: =-W9 -> -788 | J30: Non-recurring items in COGS | M30: 0 | N30: 0 | O30: 0 | R30: =O30 -> 0 | T30: Non-Controlling Interest | W30: 325
D31: Enterprise Value | H31: =SUM(H25:H30) -> 19832.976 | J31: Adj. Gross Profit | M31: =SUM(M29:M30) -> 867 | N31: =SUM(N29:N30) -> 922 | O31: =SUM(O29:O30) -> 903 | R31: =O31 -> 903 | T31: Preferred Stock | W31: 0
J32: % Margin | M32: =M31/M$11 -> 0.1300435 | N32: =N31/N$11 -> 0.13868833 | O32: =O31/O$11 -> 0.12716519 | R32: =O32 -> 0.12716519 | T32: Shareholder's Equity | W32: 3334
D33: Trading Multiples | T33: Total Liabilities & Equity | W33: =SUM(W30:W32)+W28 -> 14036
E34: LTM 12/31/2025 | F34: NFY 12/31/2026 | G34: NFY+1 12/31/2027 | H34: NFY+2 12/31/2028 | J34: Reported EBIT | M34: =M15 -> 289 | N34: =N15 -> 374 | O34: =O15 -> 348 | R34: =O34 -> 348
J35: Non-recurring items in COGS | M35: 0 | N35: 0 | O35: 0 | R35: =O35 -> 0 | T35: Balance Check | W35: =IF(W33=W18,W18-W33,W18-W33) -> 0
D36: EV/Sales | E36: =$H$31/E37 -> 2.7929835 | F36: =$H$31/F37 -> 2.7564943 | G36: =$H$31/G37 -> 2.5647195 | H36: =$H$31/H37 -> 2.3999245 | J36: Other Non-recurring items | M36: =M37-M34 -> 343 | N36: =N37-N34 -> 389 | O36: =O37-O34 -> 486 | R36: =O36 -> 486
D37: Metric | E37: =R11 -> 7101 | F37: 7195 | G37: 7733 | H37: 8264 | J37: Adjusted EBIT | M37: =M41-M40 -> 632 | N37: =N41-N40 -> 763 | O37: =O41-O40 -> 834 | R37: =O37 -> 834
D38: EV/EBITDA | E38: =$H$31/E39 -> 17.112145 | F38: =$H$31/F39 -> 16.821863 | G38: =$H$31/G39 -> 15.128128 | H38: =$H$31/H39 -> 13.328613 | J38: % Margin | M38: =M37/M$11 -> 0.09479526 | N38: =N37/N$11 -> 0.11477136 | O38: =O37/O$11 -> 0.11744825 | R38: =O38 -> 0.11744825 | T38: Calculation of Fully Diluted Shares Outstanding
D39: Metric | E39: =R41 -> 1159 | F39: 1179 | G39: 1311 | H39: 1488 | T39: Basic Shares Outstanding | X39: 95.504061
D40: EV/EBIT | E40: =$H$31/E41 -> 56.991311 | F40: =$H$31/F41 -> 30.758338 | G40: =$H$31/G41 -> 24.812932 | H40: =$H$31/H41 -> 21.597491 | J40: Depreciation & Amortization | M40: 397 | N40: 333 | O40: 325 | R40: =O40 -> 325 | T40: Plus: Shares from In-the-Money Options | X40: =W54 -> 4.880074
D41: Metric | E41: =R34 -> 348 | F41: 644.8 | G41: 799.3 | H41: 918.3 | J41: Adjusted EBITDA | M41: 1029 | N41: 1096 | O41: 1159 | R41: =O41 -> 1159 | T41: Less: Shares Repurchased | X41: =-X54/H18 -> -2.7774793
D42: P/E | E42: =$H$18/E43 -> -308.038 | F42: =$H$18/F43 -> 57.216495 | G42: =$H$18/G43 -> 39.642857 | H42: =$H$18/H43 -> 32.267442 | J42: % Margin | M42: =M41/M$11 -> 0.15434228 | N42: =N41/N$11 -> 0.16486161 | O42: =O41/O$11 -> 0.16321645 | R42: =O42 -> 0.16321645 | T42: Net New Shares from Options | X42: 0.7
D43: Metric | E43: =R26 -> -0.54051772 | F43: 2.91 | G43: 4.2 | H43: 5.16 | T43: Plus: Shares from Convertible Securities | X43: 0
...

Sheet WH
D2: Wyndham Hotels & Resorts Inc. (NYSE: WH)
D3: Input Page
D4: ($ in millions, except per share data)
D7: General Information | J7: Reported Income Statement | T7: Balance Sheet Data
D8: Company Name | H8: Wyndham Hotels & Resorts Inc. | P8: Prior Stub 12/31/2025 | Q8: Current Stub 12/31/2025 | R8: LTM 12/31/2025 | W8: 2025A | X8: -
D9: Ticker | H9: WH | M9: Fiscal Year Ending December 31, | T9: Cash & Cash Equivalents | W9: 64
D10: Stock Exchange | H10: NYSE | M10: 2023A | N10: 2024A | O10: 2025A | T10: Accounts Receivables | W10: 291
D11: Fisical Year Ending | H11: 12/31/2025 | J11: Sales | M11: 1397 | N11: 1408 | O11: 1429 | R11: =O11 -> 1429 | T11: Prepaid Expenses | W11: 33
D12: Moody's Corporate Rating | H12: Ba2 | J12: COGS (incl. D&A) | M12: =894-569-94 -> 231 | N12: =913-564-81 -> 268 | O12: =1027-565-168 -> 294 | R12: =O12 -> 294 | T12: Other Current Assets | W12: 47
D13: S&P Corporate Rating | H13: BB+ | J13: Gross Profit | M13: =M11-M12 -> 1166 | N13: =N11-N12 -> 1140 | O13: =O11-O12 -> 1135 | R13: =O13 -> 1135 | T13: Total Current Assets | W13: =SUM(W9:W12) -> 435
D14: Predicted Beta | H14: 1.01 | J14: SG&A | M14: 130 | N14: 130 | O14: 125 | R14: =O14 -> 125
D15: Marginal Tax | H15: 0.2 | J15: Other Income/(Expense) | M15: 569 | N15: 564 | O15: 565 | R15: =O15 -> 565 | T15: Property, Plant & Equivalent, net | W15: 104
J16: EBIT | M16: =M13-M14-M15 -> 467 | N16: =N13-N14-N15 -> 446 | O16: =O13-O14-O15 -> 445 | R16: =O16 -> 445 | T16: Goodwill & Intangible Assets | W16: =1525+1208+282 -> 3015
D17: Selected Market Data | J17: Interest Expense | M17: -102 | N17: -124 | O17: -139 | R17: =O17 -> -139 | T17: Other Assets | W17: 628
D18: Current Price | H18: 88.18 | J18: Early extingushment of debt | M18: -3 | N18: -3 | O18: 0 | R18: =O18 -> 0 | T18: Total Assets | W18: =SUM(W15:W17)+W13 -> 4182
D19: % of 52-week High | H19: =H18/H20 -> 0.95134319 | J19: Pre-tax Income | M19: =SUM(M16:M18) -> 362 | N19: =SUM(N16:N18) -> 319 | O19: =SUM(O16:O18) -> 306 | R19: =O19 -> 306
D20: 52-week High Price | H20: 92.69 | J20: Income Taxes | M20: -109 | N20: -79 | O20: -70 | R20: =O20 -> -70 | T20: Current Portion of Long-term Debt | W20: 45
D21: 52-week Low Price | H21: 69.21 | J21: Non-controlling Interest | M21: 0 | N21: 0 | O21: 0 | R21: =O21 -> 0 | T21: Accounts Payable | W21: 38
D22: Dividend Per Share | H22: 1.72 | J22: Preferred Dividends | M22: 0 | N22: 0 | O22: 0 | R22: =O22 -> 0 | T22: Deferred Revenue | W22: 134
J23: Net Income | M23: =SUM(M19:M22) -> 253 | N23: =SUM(N19:N22) -> 240 | O23: =SUM(O19:O22) -> 236 | R23: =O23 -> 236 | T23: Other Current Liabilties | W23: 290
D24: Fully Diluted Shares Outstanding | H24: =X44 -> 76.819472 | J24: Effective Tax Rate | M24: =ABS(M20/M19) -> 0.30110497 | N24: =ABS(N20/N19) -> 0.2476489 | O24: =ABS(O20/O19) -> 0.22875817 | R24: =O24 -> 0.22875817 | T24: Total Current Liabilities | W24: =SUM(W20:W23) -> 507
D25: Equity Value | H25: =H24*H18 -> 6773.941
J26: Weighted Avg. Diluted Shares | M26: 84.9 | N26: 80.1 | O26: 77.2 | R26: =O26 -> 77.2 | T26: Total Debt | W26: 2515
D27: Plus: Total Debt | H27: =+W20+W26 -> 2560 | J27: Diluted EPS | M27: =M23/M26 -> 2.9799764 | N27: =N23/N26 -> 2.9962547 | O27: =O23/O26 -> 3.0569948 | R27: =O27 -> 3.0569948 | T27: Other Long-term Liabilities | W27: =271+220+201 -> 692
D28: Plus: Preferred Stock | H28: =+W31 -> 0 | T28: Total Liabilities | W28: =SUM(W26:W27)+W24 -> 3714
D29: Plus: Non-controlling Intererst | H29: =+W30 -> 0 | J29: Adjusted Income Statement
D30: Less: Cash & Cash Equivalents | H30: =-W9 -> -64 | J30: Reported Gross Profit | M30: =M13 -> 1166 | N30: =N13 -> 1140 | O30: =O13 -> 1135 | R30: =O30 -> 1135 | T30: Non-Controlling Interest | W30: 0
D31: Enterprise Value | H31: =SUM(H25:H30) -> 9269.941 | J31: Non-recurring items in COGS | M31: 0 | N31: 0 | O31: 0 | R31: =O31 -> 0 | T31: Preferred Stock | W31: 0
J32: Adj. Gross Profit | M32: =SUM(M30:M31) -> 1166 | N32: =SUM(N30:N31) -> 1140 | O32: =SUM(O30:O31) -> 1135 | R32: =O32 -> 1135 | T32: Shareholder's Equity | W32: 468
D33: Trading Multiples | J33: % Margin | M33: =M32/M$11 -> 0.83464567 | N33: =N32/N$11 -> 0.80965909 | O33: =O32/O$11 -> 0.79426172 | R33: =O33 -> 0.79426172 | T33: Total Liabilities & Equity | W33: =SUM(W30:W32)+W28 -> 4182
E34: LTM 12/31/2025 | F34: NFY 12/31/2026 | G34: NFY+1 12/31/2027 | H34: NFY+2 12/31/2028
J35: Reported EBIT | M35: =M16 -> 467 | N35: =N16 -> 446 | O35: =O16 -> 445 | R35: =O35 -> 445 | T35: Balance Check | W35: =IF(W33=W18,W18-W33,W18-W33) -> 0
D36: EV/Sales | E36: =$H$31/E37 -> 6.4870126 | F36: =$H$31/F37 -> 6.2592444 | G36: =$H$31/G37 -> 5.9195026 | H36: =$H$31/H37 -> 5.5508629 | J36: Non-recurring items in COGS | M36: 0 | N36: 0 | O36: 0 | R36: =O36 -> 0
D37: Metric | E37: =R11 -> 1429 | F37: 1481 | G37: 1566 | H37: 1670 | J37: Other Non-recurring items | M37: =M38-M35 -> 116 | N37: =N38-N35 -> 177 | O37: =O38-O35 -> 211 | R37: =O37 -> 211
D38: EV/EBITDA | E38: =$H$31/E39 -> 12.910781 | F38: =$H$31/F39 -> 12.508354 | G38: =$H$31/G39 -> 11.722232 | H38: =$H$31/H39 -> 10.786527 | J38: Adjusted EBIT | M38: =M42-M41 -> 583 | N38: =N42-N41 -> 623 | O38: =O42-O41 -> 656 | R38: =O38 -> 656 | T38: Calculation of Fully Diluted Shares Outstanding
D39: Metric | E39: =R42 -> 718 | F39: 741.1 | G39: 790.8 | H39: 859.4 | J39: % Margin | M39: =M38/M$11 -> 0.41732283 | N39: =N38/N$11 -> 0.44247159 | O39: =O38/O$11 -> 0.45906228 | R39: =O39 -> 0.45906228 | T39: Basic Shares Outstanding | X39: 76.8
D40: EV/EBIT | E40: =$H$31/E41 -> 14.131008 | F40: =$H$31/F41 -> 15.296932 | G40: =$H$31/G41 -> 14.250486 | H40: =$H$31/H41 -> 12.777314 | T40: Plus: Shares from In-the-Money Options | X40: =W54 -> 1.3
D41: Metric | E41: =R38 -> 656 | F41: 606 | G41: 650.5 | H41: 725.5 | J41: Depreciation & Amortization | M41: 76 | N41: 71 | O41: 62 | R41: =O41 -> 62 | T41: Less: Shares Repurchased | X41: =-X54/H18 -> -1.2805285
D42: P/E | E42: =$H$18/E43 -> 28.845322 | F42: =$H$18/F43 -> 19.169565 | G42: =$H$18/G43 -> 17.148969 | H42: =$H$18/H43 -> 14.94323 | J42: Adjusted EBITDA | M42: 659 | N42: 694 | O42: 718 | R42: =O42 -> 718 | T42: Net New Shares from Options | X42: =SUM(X40:X41) -> 0.019471535
D43: Metric | E43: =R27 -> 3.0569948 | F43: 4.6 | G43: 5.142 | H43: 5.901 | J43: % Margin | M43: =M42/M$11 -> 0.47172513 | N43: =N42/N$11 -> 0.49289773 | O43: =O42/O$11 -> 0.50244927 | R43: =O43 -> 0.50244927 | T43: Plus: Shares from Convertible Securities | X43: 0
...

Sheet Comps1
D2: Choice Hotels International Inc. (NYSE: CHH)
D3: Company Comparable Analysis (Trading Multiples Output Page)
D4: ($ in millions, except per share data)
F7: Current Share Price | G7: % of 52-week High | J7: Enterprise Value / | S7: LTM | T7: Total | U7: Price/ | X7: LT
H8: Equity | I8: Enterprise | J8: LTM | K8: 2026E | L8: 2027E | M8: LTM | N8: 2026E | O8: 2027E | P8: LTM | Q8: 2026E | R8: 2027E | S8: EBITDA | T8: Debt/ | U8: LTM | V8: 2026E | W8: 2027E | X8: EPS
D9: Company | E9: Ticker | H9: Value | I9: Value | J9: Sales | K9: Sales | L9: Sales | M9: EBITDA | N9: EBITDA | O9: EBITDA | P9: EBIT | Q9: EBIT | R9: EBIT | S9: Margin | T9: EBITDA | U9: EPS | V9: EPS | W9: EPS | X9: Growth
D11: Consumer Discretionary
D12: =MAR!H8 -> Marriott International Inc. | E12: MAR | F12: =MAR!H18 -> 363.98 | G12: =MAR!H19 -> 0.98372973 | H12: =MAR!H25 -> 96703.864 | I12: =MAR!H31 -> 112549.86 | J12: =MAR!E36 -> 4.298093 | K12: =MAR!F36 -> 4.0339007 | L12: =MAR!G36 -> 3.8293989 | M12: =MAR!E38 -> 23.972282 | N12: =MAR!F38 -> 19.076248 | O12: =MAR!G38 -> 17.794445 | P12: =MAR!E40 -> 27.120449 | Q12: =MAR!F40 -> 22.769546 | R12: =MAR!G40 -> 20.935615 | S12: =HLT!R42 -> 0.29387823 | T12: =MAR!H55 -> 3.1938232 | U12: =MAR!E43 -> 9.5065789 | V12: =MAR!F43 -> 11.310405 | W12: =MAR!G43 -> 12.27019 | X12: =MAR!H69 -> 0.06
D13: =ABNB!H8 -> Airbnb Inc. Cl A | E13: ABNB | F13: =ABNB!H18 -> 134.51 | G13: =ABNB!H19 -> 0.93487629 | H13: =ABNB!H25 -> 83701.62 | I13: =ABNB!H31 -> 79140.62 | J13: =ABNB!E36 -> 6.4652087 | K13: =ABNB!F36 -> 5.7779528 | L13: =ABNB!G36 -> 5.2487478 | M13: =ABNB!E38 -> 18.417645 | N13: =ABNB!F38 -> 16.446513 | O13: =ABNB!G38 -> 14.652957 | P13: =ABNB!E40 -> 31.108734 | Q13: =ABNB!F40 -> 26.424247 | R13: =ABNB!G40 -> 22.57935 | S13: =ABNB!R43 -> 0.35103341 | T13: =ABNB!H55 -> 0 | U13: =ABNB!E42 -> 22.269394 | V13: =ABNB!F42 -> 27.956453 | W13: =ABNB!G42 -> 24.481316 | X13: =ABNB!H69 -> 0.12
D14: =HLT!H8 -> Hilton Worldwide Holdings Inc. | E14: HLT | F14: =HLT!H18 -> 330.71 | G14: =HLT!H19 -> 0.99056491 | H14: =HLT!H25 -> 78279.057 | I14: =HLT!H31 -> 89714.057 | J14: =HLT!E36 -> 7.4519526 | K14: =HLT!F36 -> 6.8510162 | L14: =HLT!G36 -> 6.3227893 | M14: =HLT!E38 -> 25.35728 | N14: =HLT!F38 -> 22.25051 | O14: =HLT!G38 -> 20.412755 | P14: =HLT!E40 -> 33.313798 | Q14: =HLT!F40 -> 25.936414 | R14: =HLT!G40 -> 23.509973 | S14: =HLT!R38 -> 0.27917601 | T14: =HLT!H55 -> 3.4872809 | U14: =HLT!E42 -> 53.579094 | V14: =HLT!F42 -> 37.580682 | W14: =HLT!G42 -> 33.203815 | X14: =HLT!H69 -> 0.145
D15: =H!H8 -> Hyatt Hotels Corporation | E15: H | F15: =H!H18 -> 166.5 | G15: =H!H19 -> 0.92228438 | H15: =H!H25 -> 16017.976 | I15: =H!H31 -> 19832.976 | J15: =H!E36 -> 2.7929835 | K15: =H!F36 -> 2.7564943 | L15: =H!G36 -> 2.5647195 | M15: =H!E38 -> 17.112145 | N15: =H!F38 -> 16.821863 | O15: =H!G38 -> 15.128128 | P15: =H!E40 -> 56.991311 | Q15: =H!F40 -> 30.758338 | R15: =H!G40 -> 24.812932 | S15: =H!R42 -> 0.16321645 | T15: =H!H55 -> 3.6859362 | U15: =H!E42 -> -308.038 | V15: =H!F42 -> 57.216495 | W15: =H!G42 -> 39.642857 | X15: =H!H69 -> 0.07
D16: =WH!H8 -> Wyndham Hotels & Resorts Inc. | E16: WH | F16: =WH!H18 -> 88.18 | G16: =WH!H19 -> 0.95134319 | H16: =WH!H25 -> 6773.941 | I16: =WH!H31 -> 9269.941 | J16: =WH!E36 -> 6.4870126 | K16: =WH!F36 -> 6.2592444 | L16: =WH!G36 -> 5.9195026 | M16: =WH!E38 -> 12.910781 | N16: =WH!F38 -> 12.508354 | O16: =WH!G38 -> 11.722232 | P16: =WH!E40 -> 14.131008 | Q16: =WH!F40 -> 15.296932 | R16: =WH!G40 -> 14.250486 | S16: =WH!R43 -> 0.50244927 | T16: =WH!H55 -> 3.5027855 | U16: =WH!E42 -> 28.845322 | V16: =WH!F42 -> 19.169565 | W16: =WH!G42 -> 17.148969 | X16: =WH!H69 -> 0.08
D18: Mean | J18: =AVERAGE(J12:J16) -> 5.4990501 | K18: =AVERAGE(K12:K16) -> 5.1357217 | L18: =AVERAGE(L12:L16) -> 4.7770316 | M18: =AVERAGE(M12:M16) -> 19.554027 | N18: =AVERAGE(N12:N16) -> 17.420698 | O18: =AVERAGE(O12:O16) -> 15.942103 | P18: =AVERAGE(P12:P16) -> 32.53306 | Q18: =AVERAGE(Q12:Q16) -> 24.237095 | ... X18: =AVERAGE(X12:X16) -> 0.095
D19: Median | J19: =MEDIAN(J12:J16) -> 6.4652087 | K19: =MEDIAN(K12:K16) -> 5.7779528 | L19: =MEDIAN(L12:L16) -> 5.2487478 | M19: =MEDIAN(M12:M16) -> 18.417645 | N19: =MEDIAN(N12:N16) -> 16.821863 | O19: =MEDIAN(O12:O16) -> 15.128128 | P19: =MEDIAN(P12:P16) -> 31.108734 | Q19: =MEDIAN(Q12:Q16) -> 25.936414 | ... X19: =MEDIAN(X12:X16) -> 0.08
D21: Maximum | J21: =MAX(J12:J16) -> 7.4519526 | K21: =MAX(K12:K16) -> 6.8510162 | L21: =MAX(L12:L16) -> 6.3227893 | M21: =MAX(M12:M16) -> 25.35728 | N21: =MAX(N12:N16) -> 22.25051 | O21: =MAX(O12:O16) -> 20.412755 | P21: =MAX(P12:P16) -> 56.991311 | Q21: =MAX(Q12:Q16) -> 30.758338 | ... X21: =MAX(X12:X16) -> 0.145
D22: Minimum | J22: =MIN(J12:J16) -> 2.7929835 | K22: =MIN(K12:K16) -> 2.7564943 | L22: =MIN(L12:L16) -> 2.5647195 | M22: =MIN(M12:M16) -> 12.910781 | N22: =MIN(N12:N16) -> 12.508354 | O22: =MIN(O12:O16) -> 11.722232 | P22: =MIN(P12:P16) -> 14.131008 | Q22: =MIN(Q12:Q16) -> 15.296932 | ... X22: =MIN(X12:X16) -> 0.06

Sheet Comps2
D2: Choice Hotels International Inc. (NYSE: CHH)
D3: Company Comparable Analysis (For Equity Research Analysts and Equity Investors)
D4: ($ in millions, except per share data)
F6: Current Share Price | G6: % of 52-week High | L6: 2026E | M6: LTM | N6: LTM | Q6: LT
H7: Equity | I7: Enterprise | J7: EV/EBITDA | L7: EBITDA | M7: Debt/ | N7: Int Exp/ | O7: P/E | Q7: EPS | R7: Div | S7: FCF Yield
D8: Company | E8: Ticker | H8: Value | I8: Value | J8: 2026E | K8: 2027E | L8: Margin | M8: EBITDA | N8: EBITDA | O8: 2026E | P8: 2027E | Q8: Growth | R8: Yield | S8: 2026E | T8: 2027E
D10: Consumer Discretionary
D11: =Comps1!D12 -> Marriott International Inc. | E11: =Comps1!E12 -> MAR | F11: =Comps1!F12 -> 363.98 | G11: =Comps1!G12 -> 0.98372973 | H11: =Comps1!H12 -> 96703.864 | I11: =Comps1!I12 -> 112549.86 | J11: =MAR!F38 -> 19.076248 | K11: =MAR!G38 -> 17.794445 | L11: =MAR!F64 -> 0.10861865 | M11: =MAR!H55 -> 3.1938232 | N11: =MAR!H57 -> 6.2103175 | O11: =MAR!F42 -> 32.180986 | P11: =MAR!G42 -> 29.663762 | Q11: =MAR!H69 -> 0.06 | R11: =MAR!H51 -> 0.0073630419 | S11: =MAR!F44 -> 0.029140511 | T11: =MAR!G44 -> 0.03388696
