Workbook
Name coe: Valuation!$D$29
Name tgr: Valuation!$D$30

Sheet Summary
C2: Emirates NDB
C3: Valuation
C4: ( in AED Million, except earnings per share and shares outstanding)
C5: (Disclaimer - The valuation analysis is conducted only for educational purposes, not as a recommendation to buy/sell stock and securities.)
A7: # | C7: Overview
C8: The valuation analysis is conducted for Emirates NBD (Ticker: ENBD), which is a public joint stock company (PJSC) in the United Arab Emirates.
C9: The market cap for the stock is currently AED 174 Billion. Emirates NBD is recogonised as the 2nd largest bank of UAE.
C10: The stock price is currently trading between AED 26.20 to AED 27.55.
A12: # | C12: Valutation Thesis
B14: * | C14: Valuation Methadology
C15: The intrinsic value of Emirates NBD is determined through two complementary equity valuation frameworks: the Dividend Discount Model (DDM)
C16: and the Free Cash Flow to Equity (FCFE) Model, each applied over an explicit five-year forecast horizon.
B18: * | C18: Rationale for Methodology Selection
C19: Traditional free cash flow approaches — defined as operating cash flow less capital expenditures — are ill-suited for valuing financial institutions.
C21: Given that capital is effectively the raw material of a bank's operations, the distinction between operating, investing, and financing activities becomes
C22: fundamentally ambiguous. Accordingly, the DDM serves as the primary valuation framework, underpinned by the principle that, for regulated financial institutions,
C23: distributable cash flow is best approximated by dividends paid after satisfying prevailing regulatory capital requirements (Basel III).
C25: Furthermore, the relatively stable, predictable, and long-duration nature of bank dividend policies lends itself well to dividend-based valuation,
C26: reinforcing the suitability of the DDM for this analysis.
C28: The FCFE model is applied as a complementary cross-check, with free cash flow to equity defined as net income adjusted for changes in regulatory capital requirements,
C29: reflecting the binding constraint that capital adequacy ratios impose on a bank's capacity to return capital to shareholders.
B31: * | C31: Forecast Construction
C32: Rather than relying on conventional sustainable growth rate approximations, income statement projections are constructed bottom-up over the five-year explicit forecast period
C33: using real-time macroeconomic inputs. Nominal GDP growth serves as the primary driver for balance sheet asset expansion, anchoring the forecasts in observable economic
C34: conditions and enhancing the robustness of forward estimates.
C36: Terminal value in both models is calculated at the conclusion of the explicit forecast period using the Gordon Growth Model, capitalising normalised cash flows at the spread
C37: between the cost of equity and the terminal growth rate.
B39: * | C39: Scenario Analysis
C40: To capture the range of plausible outcomes and reflect the inherent uncertainty in long-term forecasting, the valuation is conducted across three distinct scenarios:
C41: 1.Base Case: Consensus / street assumptions; moderate growth and stable margins
C42: 2. Conservative Case: Downside scenario reflecting macro headwinds or margin compression
C43: 3. Optimistic Case: Upside scenario incorporating accelerated growth or margin expansion
C45: Scenarios are differentiated primarily through two key value drivers: the Cost of Equity (Ke) and the Terminal Growth Rate (g), with all other inputs held consistent across cases.
B47: * | C47: Valuation Mechanics
C48: Dividend Discount Model: Projected dividends are derived from forecasted net income, the prevailing dividend payout ratio, and return on equity.
C49: Dividends over the explicit forecast period and the terminal value are discounted to present value at the cost of equity.
C50: The resulting intrinsic value per share represents the sum of the present value of forecast-period dividends and the present value of the terminal value.
C52: Free Cash Flow to Equity Model: FCFE is computed as net income less the incremental investment required to maintain regulatory capital ratios
C53: (i.e., the change in risk-weighted assets multiplied by the target Tier 1 capital ratio).
C54: Key inputs include risk-weighted assets, Tier 1 capital, book value, return on equity, and net income. Terminal value is similarly derived via the Gordon Growth Model,
...

Sheet Valuation
C2: Emirates NDB
C3: Valuation
C4: ( in AED Million, except earnings per share and shares outstanding)
A7: # | C7: Dashboard
C9: Company Name: | F9: =C2 -> Emirates NDB | I9: Val. Using Dividend Discount Model | M9: Val. Using Free Cash Flow to Firm
C10: Ticker: | F10: ENBD | I10: Implied Price per share: | K10: =K124 -> 23.235493 | M10: Implied Price per share: | O10: =K143 -> 35.373564
I11: Current Share price: | K11: 26.75 | M11: Current Share price: | O11: 28.95
C12: Scenario Selected | G12: 1 | I12: Δ % Price: | K12: =K10/K11-1 -> -0.13138344 | M12: Δ % Price: | O12: =O10/O11-1 -> 0.22188477
C14: Start Date: | F14: Date | G14: 44561
C15: End Date: | F15: Date | G15: 47848
C16: No. of Years: | F16: Years | G16: =YEARFRAC(G14,G15,1) -> 9.0005476
C17: Days in an Year: | F17: Days | G17: 365
C19: Templete: | D19: Standard | F19: Currency: | G19: AED
C20: Period type: | D20: Annual | F20: Units: | G20: Millions
C21: Source: | D21: Company Website | F21: Decimals: | G21: Default
A23: # | C23: Assumptions
C25: Trigger | F25: Conservative | J25: Base / Street | N25: Optimistic
C27: Scenario: | D27: =$G$12 -> 1 | F27: Cost of Equity: | H27: =L27+1% -> 0.16141728 | J27: Cost of Equity: | L27: =CoC!E26 -> 0.15141728 | N27: Cost of Equity: | P27: =L27-1% -> 0.14141728
F28: TGR: | H28: 0.02 | J28: TGR: | L28: 0.03 | N28: TGR: | P28: 0.04
C29: Cost of Equity: | D29: =CHOOSE($D$27,L27,H27,P27) -> 0.15141728
C30: TGR: | D30: =CHOOSE($D$27,L28,H28,P28) -> 0.03
A32: # | C32: Income Statement (13/12 CYE) | G32: 44561 | H32: =EDATE(G32,12) -> 44926 | I32: =EDATE(H32,12) -> 45291 | J32: =EDATE(I32,12) -> 45657 | K32: =EDATE(J32,12) -> 46022 | L32: =EDATE(K32,12) -> 46387 | M32: =EDATE(L32,12) -> 46752 | N32: =EDATE(M32,12) -> 47118 | O32: =EDATE(N32,12) -> 47483 | P32: =EDATE(O32,12) -> 47848
C34: Interest & similar income | G34: =Data!D11 -> 23663.509 | H34: =Data!E11 -> 30779 | I34: =Data!F11 -> 50031 | J34: =Data!G11 -> 69129 | K34: =Data!H11 -> 70892 | L34: =K34*(1+L60) -> 72309.84 | M34: =L34*(1+M60) -> 74117.586 | N34: =M34*(1+N60) -> 75970.526 | O34: =N34*(1+O60) -> 78249.641 | P34: =O34*(1+P60) -> 80597.131
C35: Interest & similar expenses | G35: =Data!D17 -> -8929.717 | H35: =Data!E17 -> -10878 | I35: =Data!F17 -> -25239 | J35: =Data!G17 -> -42760 | K35: =Data!H17 -> -42485 | L35: =K35*(1+L60) -> -43334.7 | M35: =L35*(1+M60) -> -44418.067 | N35: =M35*(1+N60) -> -45528.519 | O35: =N35*(1+O60) -> -46894.375 | P35: =O35*(1+P60) -> -48301.206
C36: Net interest income | G36: =SUM(G34:G35) -> 14733.792 | H36: =SUM(H34:H35) -> 19901 | I36: =SUM(I34:I35) -> 24792 | J36: =SUM(J34:J35) -> 26369 | K36: =SUM(K34:K35) -> 28407 | L36: =SUM(L34:L35) -> 28975.14 | M36: =SUM(M34:M35) -> 29699.518 | N36: =SUM(N34:N35) -> 30442.006 | ... P36: =SUM(P34:P35) -> 32295.925
C38: Income from Islamic financing & Investment products | G38: =Data!D23 -> 2821.9299 | H38: =Data!E23 -> 4059 | I38: =Data!F23 -> 7288 | J38: =Data!G23 -> 9003 | K38: =Data!H23 -> 11083 | L38: =L84 -> 13535.92 | M38: =M84 -> 16086.804 | N38: =N84 -> 18877.855 | O38: =O84 -> 21840.146 | P38: =P84 -> 24911.373
C39: Distribution on Islamic deposits | G39: =-Data!D28 -> -631.241 | H39: =-Data!E28 -> -738 | I39: =-Data!F28 -> -2000 | J39: =-Data!G28 -> -2976 | K39: =-Data!H28 -> -3988 | L39: =-L38*L86 -> -4872.9312 | M39: =-M38*M86 -> -5791.2494 | N39: =-N38*N86 -> -6796.0277 | O39: =-O38*O86 -> -7862.4524 | P39: =-P38*P86 -> -8968.0944
C40: Net interest from IFIP | G40: =SUM(G38:G39) -> 2190.6889 | H40: =SUM(H38:H39) -> 3321 | I40: =SUM(I38:I39) -> 5288 | J40: =SUM(J38:J39) -> 6027 | K40: =SUM(K38:K39) -> 7095 | L40: =SUM(L38:L39) -> 8662.9888 | M40: =SUM(M38:M39) -> 10295.555 | N40: =SUM(N38:N39) -> 12081.827 | ... P40: =SUM(P38:P39) -> 15943.279
C42: Net interest income & Net interest from IFIP | G42: =G36+G40 -> 16924.481 | H42: =H36+H40 -> 23222 | I42: =I36+I40 -> 30080 | J42: =J36+J40 -> 32396 | K42: =K36+K40 -> 35502 | L42: =L36+L40 -> 37638.129 | M42: =M36+M40 -> 39995.073 | N42: =N36+N40 -> 42523.833 | ... P42: =P36+P40 -> 48239.204
C44: Fee and commission income | G44: =Data!D36 -> 6475.045 | H44: =Data!E36 -> 7004 | I44: =Data!F36 -> 8959 | J44: =Data!G36 -> 13347 | K44: =Data!H36 -> 15738 | L44: =L88 -> 18413.46 | M44: =M88 -> 21451.681 | N44: =N88 -> 24669.433 | O44: =O88 -> 27999.806 | P44: =P88 -> 31359.783
C45: Fee and commission expenses | G45: =Data!D37 -> -2639.234 | H45: =Data!E37 -> -2923 | I45: =Data!F37 -> -4086 | J45: =Data!G37 -> -6554 | K45: =Data!H37 -> -7706 | L45: =-L44*L94 -> -8286.057 | M45: =-M44*M94 -> -9653.2564 | N45: =-N44*N94 -> -11101.245 | O45: =-O44*O94 -> -12599.913 | P45: =-P44*P94 -> -14111.902
C46: Net fee and commission income | G46: =SUM(G44:G45) -> 3835.811 | H46: =SUM(H44:H45) -> 4081 | I46: =SUM(I44:I45) -> 4873 | J46: =SUM(J44:J45) -> 6793 | K46: =SUM(K44:K45) -> 8032 | L46: =SUM(L44:L45) -> 10127.403 | M46: =SUM(M44:M45) -> 11798.424 | N46: =SUM(N44:N45) -> 13568.188 | ... P46: =SUM(P44:P45) -> 17247.881
C47: Net gain on trading securities | G47: 150.818 | H47: 52 | I47: 480 | J47: 838 | K47: 2263 | L47: =L96 -> 2715.6 | M47: =M96 -> 3122.94 | N47: =N96 -> 3435.234 | O47: =O96 -> 3606.9957 | P47: =P96 -> 3606.9957
C48: Other operating income | G48: 2910.461 | H48: 5152 | I48: 7595 | J48: 4107 | K48: 3522 | L48: =L102 -> 4087.8638 | M48: =M102 -> 4121.7532 | N48: =N102 -> 3675.848 | O48: =O102 -> 3600.7987 | P48: =P102 -> 3637.1267
C50: Total operating income | G50: =G42+G46+G47+G48 -> 23821.571 | H50: =H42+H46+H47+H48 -> 32507 | I50: =I42+I46+I47+I48 -> 43028 | J50: =J42+J46+J47+J48 -> 44134 | K50: =K42+K46+K47+K48 -> 49319 | L50: =L42+L46+L47+L48 -> 54568.996 | M50: =M42+M46+M47+M48 -> 59038.191 | N50: =N42+N46+N47+N48 -> 63203.104 | ... P50: =P42+P46+P47+P48 -> 72731.207
C52: Profit Before Taxes | G52: 9900 | H52: 15000 | I52: 23700 | J52: 27100 | K52: 29800 | L52: =L50*L105 -> 32741.397 | M52: =M50*M105 -> 35422.914 | N52: =N50*N105 -> 37921.862 | O52: =O50*O105 -> 40764.389 | P52: =P50*P105 -> 43638.724
C53: Income Taxes | G53: =G52-G55 -> 600 | H53: =H52-H55 -> 2000 | I53: =I52-I55 -> 2200 | J53: =J52-J55 -> 4100 | K53: =K52-K55 -> 5800 | L53: =L52*L107 -> 5893.4515 | M53: =M52*M107 -> 6376.1246 | N53: =N52*N107 -> 6825.9352 | O53: =O52*O107 -> 7337.59 | P53: =P52*P107 -> 7854.9703
C55: Profit After Taxes | G55: 9300 | H55: 13000 | I55: 21500 | J55: 23000 | K55: 24000 | L55: =L52-L53 -> 26847.946 | M55: =M52-M53 -> 29046.79 | N55: =N52-N53 -> 31095.927 | O55: =O52-O53 -> 33426.799 | P55: =P52-P53 -> 35783.754
A57: # | C57: Assumptions (13/12 CYE) | G57: 44561 | H57: =EDATE(G57,12) -> 44926 | I57: =EDATE(H57,12) -> 45291 | J57: =EDATE(I57,12) -> 45657 | K57: =EDATE(J57,12) -> 46022 | L57: =EDATE(K57,12) -> 46387 | M57: =EDATE(L57,12) -> 46752 | N57: =EDATE(M57,12) -> 47118 | O57: =EDATE(N57,12) -> 47483 | P57: =EDATE(O57,12) -> 47848
C59: United Arab Emirates Nominal GDP: | G59: 422.4 | H59: 511.4 | I59: 522.6 | J59: 552.3 | K59: 569 | L59: =K59*(1+L60) -> 580.38 | M59: =L59*(1+M60) -> 594.8895 | N59: =M59*(1+N60) -> 609.76174 | O59: =N59*(1+O60) -> 628.05459 | P59: =O59*(1+P60) -> 646.89623
...

Sheet 52_week
C2: 52-week share price
C4: Date | D4: Close
C5: 46099 | D5: 27.55 | F5: Mean | H5: =AVERAGE($D$5:$D$276) -> 25.496324
C6: 46098 | D6: 27.8 | F6: Median | H6: =MEDIAN($D$5:$D$276) -> 25.5
C7: 46097 | D7: 26.5 | F7: 75th Percentile | H7: =PERCENTILE(($D$5:$D$276),75%) -> 27.8
C8: 46094 | D8: 26.95 | F8: 25th Percentile | H8: =PERCENTILE(($D$5:$D$276),25%) -> 21.9375
C9: 46093 | D9: 28.35
C10: 46092 | D10: 29.8
C11: 46091 | D11: 31.35
C12: 46090 | D12: 28.95
C13: 46087 | D13: 29.4
C14: 46086 | D14: 29.8
C15: 46085 | D15: 31.35
C16: 46080 | D16: 33
C17: 46079 | D17: 34.8
C18: 46078 | D18: 36.3
C19: 46077 | D19: 35.5
C20: 46076 | D20: 37
... C276: 45705 | D276: 21

Sheet CoC
B2: Comparable Companies - Financial Services & Commerical Banks with above $ 5 Billion in Market Cap
B3: (in AED millions, except Price per share and other ratios)
B5: Company Name | D5: Share Price | E5: Revenue | F5: Net Income | G5: P / BV | H5: ROE | J5: Median | L5: =MEDIAN($D$6:$D$12) -> 11.88
B6: First Abu Dhabi Bank | D6: 16.52 | E6: 31600 | F6: 17100 | G6: 1.57 | H6: 0.168 | J6: 75th Percentile | L6: =PERCENTILE(($D$6:$D$12),75%) -> 17.87
B7: Abu Dhabi Commercial Bank | D7: 11.88 | E7: 19100 | F7: 11400 | G7: 1.31 | H7: 0.153 | J7: 25th Percenile | L7: =PERCENTILE(($D$6:$D$12),25%) -> 9.775
B8: Abu Dhabi Islamic Bank | D8: 19.22 | E8: 10600 | F8: 6100 | G8: 4.2 | H8: 0.28
B9: Emirates Islamic Bank | D9: 10.85 | E9: 5400 | F9: 2800 | G9: 1.64 | H9: 0.197
B10: Dubai Islamic Bank | D10: 7.09 | E10: 23300 | F10: 8200 | G10: 1.62 | H10: 0.22
B11: MashreqBank | D11: 209 | E11: 13400 | F11: 9000 | G11: 1.6 | H11: 0.29
B12: Commerical Bank of Dubai | D12: 8.7 | E12: 5500 | F12: 3000 | G12: 2.7 | H12: 0.235
B14: Emirates NDB Bank | D14: 29.45 | E14: 49139 | F14: 24000 | G14: 1.44 | H14: 0.173
F16: Average | G16: =AVERAGE(G6:G12) -> 2.0914286 | H16: =AVERAGE(H6:H12) -> 0.22042857
F17: Median | G17: =MEDIAN(G6:G12) -> 1.62 | H17: =MEDIAN(H6:H12) -> 0.22
A19: * | B19: Cost of Equity
B20: Median P / BV | E20: =G17 -> 1.62
B21: Median ROE | E21: =H17 -> 0.22
B22: Expected growth rate | E22: 0.045
B23: Adj. Default spread | E23: 0.0042
B24: Adj. Expected growth rate (g) | E24: =E22-E23 -> 0.0408
B26: Cost of Equity | E26: =((E21-E24)/E20)+E24 -> 0.15141728 | F26: PBV = (ROE - g) / (Cost of equity - g)

Sheet Data
D2: AED Millions
B3: Interest & similar Income | D3: 21 | E3: 22 | F3: 23 | G3: 24 | H3: 25 | L3: To find cost of equity
B4: Loans and receivables to customers | D4: 20682.642 | E4: 24185 | F4: 35568 | G4: 47380 | H4: 50236
B5: Loans and receivables to banks | D5: 544.387 | E5: 1337 | F5: 6431 | G5: 11661 | H5: 9736 | L5: 1. Comparable comps of all the banks near to market cap
B6: Investment securities at FVOCI | D6: 1140.994 | E6: 2952 | F6: 2990 | G6: 3133 | H6: 3393 | L6: 2. Find median price to book ratio
B7: Trading securities at amortised cost | D7: 975.134 | E7: 1577 | F7: 3487 | G7: 4141 | H7: 3814 | L7: 3. Find median return on equity for big banks
B8: Trading securities & designated at | D8: 148.034 | E8: 136 | F8: 209 | G8: 591 | H8: 933 | L8: 4. Expected growth rate in perpetuity (set it to risk free rate)
B9: FVPTL invesetment securities | L9: PBV = (ROE-g) / (Cost of equity - g)
B10: Others | D10: 172.318 | E10: 592 | F10: 1346 | G10: 2223 | H10: 2780
D11: =SUM(D4:D10) -> 23663.509 | E11: =SUM(E4:E10) -> 30779 | F11: =SUM(F4:F10) -> 50031 | G11: =SUM(G4:G10) -> 69129 | H11: =SUM(H4:H10) -> 70892 | L11: Dividend Discount model
B12: Interest & similar expense
B13: Deposits from customers | D13: -5702.153 | E13: -7085 | F13: -19265 | G13: -34814 | H13: -34474 | L13: Expected growth in EPS = ROE x (1-Dividend Payout Ratio)
B14: Borrowings from banks & financial institutions | D14: -639.311 | E14: -974 | F14: -1622 | G14: -2088 | H14: -4159
B15: Debt issued & borrowed funds | D15: -2408.283 | E15: -2656 | F15: -4140 | G15: -5443 | H15: -3441 | L15: After year 5 expected perpetuity growth rate is reduced to stable rate
B16: Others | D16: -179.97 | E16: -163 | F16: -212 | G16: -415 | H16: -411 | L16: Payout ratio = 1 - Stable rate / ROE
D17: =SUM(D13:D16) -> -8929.717 | E17: =SUM(E13:E16) -> -10878 | F17: =SUM(F13:F16) -> -25239 | G17: =SUM(G13:G16) -> -42760 | H17: =SUM(H13:H16) -> -42485
L18: Terminal value = (Net income at year 6 x Stable payout) / (Cost of equity - Expected growth rate)
B19: Income from Islamic financing & Investment products
B20: Murabaha | D20: 1273.602 | E20: 1946 | F20: 3559 | G20: 4153 | H20: 4826 | L20: FCFE
B21: Ijara | D21: 595.96 | E21: 853 | F21: 1459 | G21: 1544 | H21: 1732
B22: Others | D22: =40.1199+912.248 -> 952.3679 | E22: 1260 | F22: 2270 | G22: 3306 | H22: 4525 | L22: Risk adjusted assets
D23: =SUM(D20:D22) -> 2821.9299 | E23: =SUM(E20:E22) -> 4059 | F23: =SUM(F20:F22) -> 7288 | G23: =SUM(G20:G22) -> 9003 | H23: =SUM(H20:H22) -> 11083 | L23: Tier 1 Capital
L24: Change in regulatory Capital (Tier 1)
B25: Distribution on Islamic deposits | L25: Book equity
B26: Distribution to depositors | D26: 537.834 | E26: 664 | F26: 1885 | G26: 2761 | H26: 3588
B27: Profit paid to sukuk holders | D27: 93.407 | E27: 74 | F27: 115 | G27: 215 | H27: 400 | L27: FCFE = Net income - Investment in regulatory capital
B28: Total | D28: =SUM(D26:D27) -> 631.241 | E28: =SUM(E26:E27) -> 738 | F28: =SUM(F26:F27) -> 2000 | G28: =SUM(G26:G27) -> 2976 | H28: =SUM(H26:H27) -> 3988
B31: Net fee and commission income
B32: Fee income | D32: 5304.812 | E32: 5878 | F32: 7581 | G32: 11716 | H32: 13696
B33: Commission income on trade finance products / services | D33: 831.195 | E33: 878 | F33: 1074 | G33: 1170 | H33: 1455
B34: Portfolio and other management fees | D34: 276.564 | E34: 54 | F34: 69 | G34: 385 | H34: 519
B35: Brokerage fees | D35: 62.474 | E35: 194 | F35: 235 | G35: 76 | H35: 68
B36: Total fee and commission income | D36: =SUM(D32:D35) -> 6475.045 | E36: =SUM(E32:E35) -> 7004 | F36: =SUM(F32:F35) -> 8959 | G36: =SUM(G32:G35) -> 13347 | H36: =SUM(H32:H35) -> 15738
B37: Fee and commission expense | D37: -2639.234 | E37: -2923 | F37: -4086 | G37: -6554 | H37: -7706
B38: Net | D38: =SUM(D36:D37) -> 3835.811 | E38: =SUM(E36:E37) -> 4081 | F38: =SUM(F36:F37) -> 4873 | G38: =SUM(G36:G37) -> 6793 | H38: =SUM(H36:H37) -> 8032
B41: Overview
B42: The valuation is done for Emirates NBD (Ticker: ENBD), which is a public joint stock company (PJSC) in the United Arab Emirates.
B43: The market cap for the stock is currently AED 174 Billion. Emirates NBD is recogonised as the 2nd largest bank of UAE.
B44: The stock price is currently trading between AED 26.20 to AED 27.55.
B46: Valutation Thesis
...
