Workbook
Name BS: Financials!$B$47
Name CF: Financials!$B$101
Name days: Dashboard!$G$18
Name EF: Scenario!$B$45
Name IS: Financials!$B$13
Name PPE: Schedule!$B$10
Name RE: Schedule!$B$99
Name RF: Scenario!$B$17
Name tgr: DCF!$E$19
Name wacc: DCF!$E$18
Name WC: Schedule!$B$58

Sheet Dashboard
C2: Infosys Ltd.
C3: Dashboard
C4: (In ₹ Crore, except equity share and per equity share data)
B6: # | C6: Model Assumption
C8: Company Name: | G8: =C2 -> Infosys Ltd. | I8: Val.Using Free Cash Flow to Firm
C9: Ticker: | G9: INFY
C10: Sector: | G10: IT - Software & Consulting | I10: Current Share Price: | L10: 1280
I11: Implied Share Price: | L11: =DCF!G41 -> 1078.4773
C12: Selected Scenario | G12: Street | I12: Δ Price %: | L12: =L10/L11-1 -> 0.18685853
C13: Selected Scenario for Adoption of AI | G13: Low AI Impact
C15: Model Start Date | G15: =Financials!I6 -> 45747 | I15: Key Financial Metrices | L15: 45747 | M15: 46112 | N15: 46477
C16: Model End Date | G16: =Financials!N6 -> 47573 | I16: Gross Margin % | L16: ='Ratio Analysis'!H9 -> 0.25713428 | M16: ='Ratio Analysis'!I9 -> 0.2426101 | N16: ='Ratio Analysis'!J9 -> 0.23696325
C17: No. of Years Projected | G17: =YEARFRAC(G15,G16,1) -> 5.0004564 | I17: EBITDA Margin % | L17: ='Ratio Analysis'!H10 -> 0.22575185 | M17: ='Ratio Analysis'!I10 -> 0.23365543 | N17: ='Ratio Analysis'!J10 -> 0.2261837
C18: Days in an Year | G18: 365 | I18: Net Profit Margin % | L18: ='Ratio Analysis'!H12 -> 0.16057386 | M18: ='Ratio Analysis'!I12 -> 0.1635588 | N18: ='Ratio Analysis'!J12 -> 0.15832859
I19: ROE % | L19: ='Ratio Analysis'!H13 -> 0.27805786 | M19: ='Ratio Analysis'!I13 -> 0.26471995 | N19: ='Ratio Analysis'!J13 -> 0.27490185
B20: # | C20: Table of Contents | I20: ROCE % | L20: ='Ratio Analysis'!H15 -> 0.35461515 | M20: ='Ratio Analysis'!I15 -> 0.34452036 | N20: ='Ratio Analysis'!J15 -> 0.35752474
C21: Sl.No | D21: Particulars | I21: ROIC % | L21: ='Ratio Analysis'!H16 -> 0.67898483 | M21: ='Ratio Analysis'!I16 -> 0.6964309 | N21: ='Ratio Analysis'!J16 -> 0.67620646
C22: 1 | D22: Dashboard | I22: Asset Turnover | L22: ='Ratio Analysis'!H27 -> 1.118782 | M22: ='Ratio Analysis'!I27 -> 1.0666473 | N22: ='Ratio Analysis'!J27 -> 1.1224262
C23: 2 | D23: Equity Report | I23: Debt to Equity | L23: ='Ratio Analysis'!H37 -> 0.085517084 | M23: ='Ratio Analysis'!I37 -> 0.07673462 | N23: ='Ratio Analysis'!J37 -> 0.077851049
C24: 3 | D24: Financials
C25: 4 | D25: Scenario
C26: 5 | D26: Assumptions
C27: 6 | D27: Schedule
C28: 7 | D28: DCF
C29: 8 | D29: WACC
C30: 9 | D30: Beta
C31: 10 | D31: Comps
C32: 11 | D32: Ratio Analysis
C33: 12 | D33: Analysis

Sheet Equity_report
C2: =Dashboard!C2 -> Infosys Ltd.
C3: Equity Report
C4: =Dashboard!C4 -> (In ₹ Crore, except equity share and per equity share data)
C5: (Disclaimer - The valuation analysis is conducted only for educational purposes, not as a recommendation to buy/sell stock and securities.)
B7: # | C7: Overview
C8: Infosys Ltd (Ticker: INFY) provides consulting, technology, outsourcing and next-generation digital services to enable clients to execute strategies for their digital transformation.
C9: It is the 2nd largest Information Technology company in India behind TCS. Its market cap currently is around ₹ 5,21,813 Cr. And it's share price is around ₹ 1280.00.
B12: # | C12: Investment Thesis
C13: This report presents a fundamental valuation analysis of Infosys Limited, conducted through a structured three-statement financial model and a Free Cash Flow to Firm (FCFF) framework.
C14: The objective is to determine the intrinsic value of the stock through an explicit five-year forecast period, underpinned by scenario-based assumptions.
B16: # | C16: Forecasting Methodology
C17: Revenue and expense line items are projected across three distinct scenarios — Best Case, Street Consensus, and Worst Case — to capture the range of plausible operating outcomes.
C18: A distinguishing feature of this analysis is the explicit incorporation of Artificial Intelligence (AI) adoption as a value driver within the scenario framework. AI-related expenses are modelled
C19: separately for each scenario, with each outcome reflecting a different trajectory of AI integration by the company — from conservative adoption to an accelerated AI-led operating model.
C20: Revenue forecasts and cost assumptions in each scenario are calibrated to real-world developments, including management commentary, sector tailwinds, and observable AI productivity
C21: gains within the IT services industry. All remaining line items — those not directly classified as revenue or operating expenses — are projected using standard financial modelling
C22: conventions and general assumptions.
B24: # | C24: Discount Rate
C25: The Weighted Average Cost of Capital (WACC) is computed as:
C26: WACC = Ke × [E / (E + D)] + Kd × [D / (E + D)]
C28: The cost of equity (Ke) is derived using the Capital Asset Pricing Model (CAPM): Ke = Rf + β × (Rm − Rf), where the risk-free rate (Rf) represents the prevailing 10-year Indian Government
C29: Bond yield, and the market return (Rm) is estimated as the Compounded Annual Growth Rate (CAGR) of the Nifty 50 index.
C30: Beta is estimated through a regression of Infosys stock returns against the Nifty 50, utilising historical price data spanning from December 1995 to March 2026 — the full period since the
C31: inception of the National Stock Exchange — to ensure statistical robustness. The raw beta is subsequently adjusted using the Blume adjustment formula:
C32: Adjusted Beta = (Raw Beta × w₁) + (Market Beta × w₂), where the market beta is set to 1.0.
C34: The cost of debt (Kd) is derived from the company's prevailing credit ratings: CRISIL AAA/Stable/A1+ (domestic), Moody's A3/Stable, and S&P A−. The default spread corresponding to a
C35: CRISIL AAA rating — sourced from Aswath Damodaran's ratings and default spread framework for large non-financial service firms — is applied at 40 basis points. It is noted that at the
C36: time of this valuation, Infosys carries no net financial debt; accordingly, the capital structure reflects an equity-dominant weighting. Scenario-specific WACC assumptions and a terminal
C37: growth rate ranging from 3% to 6% — consistent with long-term growth expectations for Indian IT services companies — are applied independently across each of the three scenarios.
B39: # | C39: Valuation
C40: Intrinsic value is determined by discounting projected free cash flows to the firm at the scenario-specific WACC, deriving the present value of equity, and computing the implied value per share.
C41: A Football Field analysis is subsequently employed to consolidate the valuation outputs across all scenarios and methodologies, providing a visual representation of the fair value range and
C42: contextualising the stock's current market price relative to its estimated intrinsic value.
B45: # | C45: Football Field Analysis
C46: Metrices | E46: 25th Percentile | F46: Median | G46: 75th Percentile
C47: Company Comparables:
C48: Current Share Price | E48: =Comps!E24 -> 675.25 | F48: =Comps!E22 -> 1401.9 | G48: =Comps!E23 -> 2409
C49: EV / Rev | E49: {=TRANSPOSE(Comps!K37:N37)} -> 253.0575 | F49: {=TRANSPOSE(Comps!K35:N35)} -> 701.11369 | G49: {=TRANSPOSE(Comps!K36:N36)} -> 287.94447
C50: EV / EBITDA | E50: 264.64867 | F50: 843.36799 | G50: 413.15752
C51: P / Sales | E51: 925.45347 | F51: 793.69399 | G51: 701.01715
...

Sheet Financials->

Sheet Financials
B2: =Dashboard!C2 -> Infosys Ltd.
B3: Financial statements
B4: =Dashboard!C4 -> (In ₹ Crore, except equity share and per equity share data)
B5: Actual / Forecast | F5: Actuals | J5: Forecast | O5: CAGR | Q5: Notes
B6: Date / Year | F6: 44651 | G6: =EDATE(F6,12) -> 45016 | H6: =EDATE(G6,12) -> 45382 | I6: =EDATE(H6,12) -> 45747 | J6: =EDATE(I6,12) -> 46112 | K6: =EDATE(J6,12) -> 46477 | L6: =EDATE(K6,12) -> 46843 | M6: =EDATE(L6,12) -> 47208 | N6: =EDATE(M6,12) -> 47573 | O6: 22A - 25A | P6: 25A - 30E
B8: <-Back to dashboard
B10: Templete: | C10: Standard | E10: Currency: | F10: INR | H10: Source: | I10: Company Website
B11: Period type: | C11: Annual | E11: Units: | F11: Crore | H11: Decimals: | I11: Default
A13: # | B13: Income statement | F13: 44651 | G13: =EDATE(F13,12) -> 45016 | H13: =EDATE(G13,12) -> 45382 | I13: =EDATE(H13,12) -> 45747 | J13: =EDATE(I13,12) -> 46112 | K13: =EDATE(J13,12) -> 46477 | L13: =EDATE(K13,12) -> 46843 | M13: =EDATE(L13,12) -> 47208 | N13: =EDATE(M13,12) -> 47573
B15: Revenue from operations | F15: 121641 | G15: 146767 | H15: 153670 | I15: 162990 | J15: =Scenario!J24 -> 169706.35 | K15: =Scenario!K24 -> 179444.66 | L15: =Scenario!L24 -> 190694.57 | M15: =Scenario!M24 -> 203696.63 | N15: =Scenario!N24 -> 218358.89 | O15: =_xlfn.RRI(4,F15,I15) -> 0.07589588 | P15: =_xlfn.RRI(5,J15,N15) -> 0.051706504
B16: Other income, net | F16: 2295 | G16: 2701 | H16: 4711 | I16: 3600 | J16: =Assumptions!K12 -> 3818.9935 | K16: =Assumptions!L12 -> 4038.1401 | L16: =Assumptions!M12 -> 4291.3029 | M16: =Assumptions!N12 -> 4583.8952 | N16: =Assumptions!O12 -> 4913.848 | O16: =_xlfn.RRI(4,F16,I16) -> 0.11912849 | P16: =_xlfn.RRI(5,J16,N16) -> 0.051706504
B17: Total Revenue | F17: =SUM(F15:F16) -> 123936 | G17: =SUM(G15:G16) -> 149468 | H17: =SUM(H15:H16) -> 158381 | I17: =SUM(I15:I16) -> 166590 | J17: =SUM(J15:J16) -> 173525.34 | K17: =SUM(K15:K16) -> 183482.8 | L17: =SUM(L15:L16) -> 194985.87 | M17: =SUM(M15:M16) -> 208280.52 | N17: =SUM(N15:N16) -> 223272.74 | O17: =_xlfn.RRI(4,F17,I17) -> 0.076744999 | P17: =_xlfn.RRI(5,J17,N17) -> 0.051706504
B19: Employee benefit expenses | F19: 63986 | G19: 78359 | H19: 82620 | I19: 85950 | J19: =Scenario!J52 -> 89559.9 | K19: =Scenario!K52 -> 93455.756 | L19: =Scenario!L52 -> 97661.265 | M19: =Scenario!M52 -> 102202.51 | N19: =Scenario!N52 -> 107108.23 | O19: =_xlfn.RRI(4,F19,I19) -> 0.076564934 | P19: =_xlfn.RRI(5,J19,N19) -> 0.036434478
B20: Cost of technical sub-contractors | F20: 12606 | G20: 14062 | H20: 12232 | I20: 12937 | J20: =Scenario!J90 -> 13713.22 | K20: =Scenario!K90 -> 14577.153 | L20: =Scenario!L90 -> 15539.245 | M20: =Scenario!M90 -> 16611.453 | N20: =Scenario!N90 -> 17807.477 | O20: =_xlfn.RRI(4,F20,I20) -> 0.0065006712 | P20: =_xlfn.RRI(5,J20,N20) -> 0.05364083
B21: Travel expenses | F21: 827 | G21: 1525 | H21: 1759 | I21: 1894 | J21: =Scenario!J91 -> 2045.52 | K21: =Scenario!K91 -> 2219.3892 | L21: =Scenario!L91 -> 2419.1342 | M21: =Scenario!M91 -> 2648.952 | N21: =Scenario!N91 -> 2913.8472 | O21: =_xlfn.RRI(4,F21,I21) -> 0.23017987 | P21: =_xlfn.RRI(5,J21,N21) -> 0.073328369
B22: Cost of software packages and others | F22: 6811 | G22: 10902 | H22: 13515 | I22: 15911 | J22: =Scenario!J62 -> 18774.98 | K22: =Scenario!K62 -> 22098.151 | L22: =Scenario!L62 -> 25943.23 | M22: =Scenario!M62 -> 30379.522 | N22: =Scenario!N62 -> 35483.282 | O22: =_xlfn.RRI(4,F22,I22) -> 0.23629368 | P22: =_xlfn.RRI(5,J22,N22) -> 0.13576599
B23: Communication expenses | F23: 611 | G23: 713 | H23: 677 | I23: 620 | J23: =Scenario!J92 -> 570.4 | K23: =Scenario!K92 -> 529.046 | L23: =Scenario!L92 -> 494.65801 | M23: =Scenario!M92 -> 466.21517 | N23: =Scenario!N92 -> 442.90442 | O23: =_xlfn.RRI(4,F23,I23) -> 0.0036623197 | P23: =_xlfn.RRI(5,J23,N23) -> -0.049338079
B24: Consultancy and professional charges | F24: 1885 | G24: 1684 | H24: 1726 | I24: 1655 | J24: =Scenario!J93 -> 1688.1 | K24: =Scenario!K93 -> 1728.1924 | L24: =Scenario!L93 -> 1775.7177 | M24: =Scenario!M93 -> 1831.2088 | N24: =Scenario!N93 -> 1895.3012 | O24: =_xlfn.RRI(4,F24,I24) -> -0.032008239 | P24: =_xlfn.RRI(5,J24,N24) -> 0.023424976
B25: Depreciation and amortisation expenses | F25: 3476 | G25: 4225 | H25: 4678 | I25: 4812 | J25: =Schedule!K37+Schedule!K32 -> 1553.8619 | K25: =Schedule!L37+Schedule!L32 -> 1977.8622 | L25: =Schedule!M37+Schedule!M32 -> 2339.7887 | M25: =Schedule!N37+Schedule!N32 -> 2829.4995 | N25: =Schedule!O37+Schedule!O32 -> 3356.1537 | O25: =_xlfn.RRI(4,F25,I25) -> 0.084704552 | P25: =_xlfn.RRI(5,J25,N25) -> 0.16650307
B26: Finance cost | F26: 200 | G26: 284 | H26: 470 | I26: 416 | J26: 0 | K26: 0 | L26: 0 | M26: 0 | N26: 0 | O26: =_xlfn.RRI(4,F26,I26) -> 0.20092486 | P26: =_xlfn.RRI(5,J26,N26) -> 0
B27: Other expenses | F27: 3424 | G27: 4392 | H27: 4716 | I27: 4787 | J27: =Scenario!J82 -> 5074.22 | K27: =Scenario!K82 -> 5396.433 | L27: =Scenario!L82 -> 5757.994 | M27: =Scenario!M82 -> 6163.9326 | N27: =Scenario!N82 -> 6620.0636 | O27: =_xlfn.RRI(4,F27,I27) -> 0.087382697 | P27: =_xlfn.RRI(5,J27,N27) -> 0.054626241
B28: Total Expenses | F28: =SUM(F19:F27) -> 93826 | G28: =SUM(G19:G27) -> 116146 | H28: =SUM(H19:H27) -> 122393 | I28: =SUM(I19:I27) -> 128982 | J28: =SUM(J19:J27) -> 132980.2 | K28: =SUM(K19:K27) -> 141981.98 | L28: =SUM(L19:L27) -> 151931.03 | M28: =SUM(M19:M27) -> 163133.3 | N28: =SUM(N19:N27) -> 175627.26 | O28: =_xlfn.RRI(4,F28,I28) -> 0.082808051 | P28: =_xlfn.RRI(5,J28,N28) -> 0.057209335
B30: Profit before tax | F30: =F17-F28 -> 30110 | G30: =G17-G28 -> 33322 | H30: =H17-H28 -> 35988 | I30: =I17-I28 -> 37608 | J30: =J17-J28 -> 40545.138 | K30: =K17-K28 -> 41500.818 | L30: =L17-L28 -> 43054.843 | M30: =M17-M28 -> 45147.228 | N30: =N17-N28 -> 47645.476 | O30: =_xlfn.RRI(4,F30,I30) -> 0.057164013 | P30: =_xlfn.RRI(5,J30,N30) -> 0.032800831
B32: Current tax | F32: 7811 | G32: 9287 | H32: 8390 | I32: 12130 | J32: =Assumptions!K15 -> 12163.541 | K32: =Assumptions!L15 -> 12450.245 | L32: =Assumptions!M15 -> 12916.453 | M32: =Assumptions!N15 -> 13544.169 | N32: =Assumptions!O15 -> 14293.643 | O32: =_xlfn.RRI(4,F32,I32) -> 0.11631958 | P32: =_xlfn.RRI(5,J32,N32) -> 0.032800831
B33: Deferred tax | F33: 153 | G33: -73 | H33: 1350 | I33: -1272 | J33: 0 | K33: 0 | L33: 0 | M33: 0 | N33: 0
B34: Profit for the year | F34: =F30-SUM(F32:F33) -> 22146 | G34: =G30-SUM(G32:G33) -> 24108 | H34: =H30-SUM(H32:H33) -> 26248 | I34: =I30-SUM(I32:I33) -> 26750 | J34: =J30-SUM(J32:J33) -> 28381.596 | K34: =K30-SUM(K32:K33) -> 29050.573 | L34: =L30-SUM(L32:L33) -> 30138.39 | M34: =M30-SUM(M32:M33) -> 31603.06 | N34: =N30-SUM(N32:N33) -> 33351.833 | O34: =_xlfn.RRI(4,F34,I34) -> 0.048351987 | P34: =_xlfn.RRI(5,J34,N34) -> 0.032800831
B36: Profit attributable to:
B37: Owners of the company | F37: 22110 | G37: 24095 | H37: 26233 | I37: 26713 | J37: =J34-J38 -> 28352.367 | K37: =K34-K38 -> 29020.654 | L37: =L34-L38 -> 30107.351 | M37: =M34-M38 -> 31570.513 | N37: =N34-N38 -> 33317.485
B38: Non-controlling interests | F38: 36 | G38: 13 | H38: 15 | I38: 37 | J38: =Assumptions!K18 -> 29.229252 | K38: =Assumptions!L18 -> 29.918208 | L38: =Assumptions!M18 -> 31.038514 | M38: =Assumptions!N18 -> 32.546929 | N38: =Assumptions!O18 -> 34.347932
B40: Equity per share:
B41: Basic (₹) | F41: =F37/F44 -> 52.52347 | G41: =G37/G44 -> 57.631162 | H41: =H37/H44 -> 63.386658 | I41: =I37/I44 -> 64.499045 | J41: =J37/J44 -> 68.457327 | K41: =K37/K44 -> 70.07092 | L41: =L37/L44 -> 72.69477 | M41: =M37/M44 -> 76.227601 | N41: =N37/N44 -> 80.4457 | O41: =_xlfn.RRI(4,F41,I41) -> 0.052688717 | P41: =_xlfn.RRI(5,J41,N41) -> 0.032800831
B43: Weighted average equity shares:
B44: Basic (in shares) | F44: 420.95467 | G44: 418.08979 | H44: 413.85681 | I44: 414.16117 | J44: =I44 -> 414.16117 | K44: =J44 -> 414.16117 | L44: =K44 -> 414.16117 | M44: =L44 -> 414.16117 | N44: =M44 -> 414.16117
A47: # | B47: Balance sheet | F47: 44651 | G47: =EDATE(F47,12) -> 45016 | H47: =EDATE(G47,12) -> 45382 | I47: =EDATE(H47,12) -> 45747 | J47: =EDATE(I47,12) -> 46112 | K47: =EDATE(J47,12) -> 46477 | L47: =EDATE(K47,12) -> 46843 | M47: =EDATE(L47,12) -> 47208 | N47: =EDATE(M47,12) -> 47573
B49: Non-current assets
B50: Property, plant and equipment | F50: 13075 | G50: 13346 | H50: 12370 | I50: 11778 | J50: =Schedule!K47 -> 12737.447 | K50: =Schedule!L47 -> 13376.667 | L50: =Schedule!M47 -> 14157.525 | M50: =Schedule!N47 -> 14997.931 | N50: =Schedule!O47 -> 15860.939
B51: Right of use assets | F51: 4823 | G51: 6882 | H51: 6552 | I51: 6311 | J51: =I51 -> 6311 | K51: =J51 -> 6311 | L51: =K51 -> 6311 | M51: =L51 -> 6311 | N51: =M51 -> 6311
B52: Capital work-in progress | F52: 416 | G52: 288 | H52: 293 | I52: 814 | J52: =I52-Schedule!K18 -> 238 | K52: =J52-Schedule!L18 -> 34 | L52: =K52-Schedule!M18 -> 12 | M52: =L52-Schedule!N18 -> 0 | N52: =M52-Schedule!O18 -> 0
B53: Goodwill | F53: 6195 | G53: 7248 | H53: 7303 | I53: 10106 | J53: =I53 -> 10106 | K53: =J53 -> 10106 | L53: =K53 -> 10106 | M53: =L53 -> 10106 | N53: =M53 -> 10106
B54: Other intangible assets | F54: 1707 | G54: 1749 | H54: 1397 | I54: 2766 | J54: =Schedule!K55 -> 2547.4684 | K54: =Schedule!L55 -> 2273.4898 | L54: =Schedule!M55 -> 2062.5655 | M54: =Schedule!N55 -> 1852.2544 | N54: =Schedule!O55 -> 1679.1169
...

Sheet Scenario
B2: =Dashboard!C2 -> Infosys Ltd.
B3: Scenario
B4: =Dashboard!C4 -> (In ₹ Crore, except equity share and per equity share data)
B5: Date | F5: Acutals | J5: Forecast | O5: CAGR | Q5: Notes
B6: Actual / Forecast | F6: =Financials!F6 -> 44651 | G6: =EDATE(F6,12) -> 45016 | H6: =EDATE(G6,12) -> 45382 | I6: =EDATE(H6,12) -> 45747 | J6: =EDATE(I6,12) -> 46112 | K6: =EDATE(J6,12) -> 46477 | L6: =EDATE(K6,12) -> 46843 | M6: =EDATE(L6,12) -> 47208 | N6: =EDATE(M6,12) -> 47573 | O6: 22A - 25A | P6: 26E - 30E
B8: <-Back to dashboard
A10: # | B10: Assumptions
B12: Trigger | G12: Best | H12: 1 | J12: Low AI Impact | L12: 1
G13: Street | H13: 2 | J13: Moderate AI Adoption | L13: 2
B14: Selected Scenario | E14: =VLOOKUP(Dashboard!$G$12,Scenario!$G$12:$H$14,2,1) -> 2 | G14: Worst | H14: 3 | J14: High AI Adoption | L14: 3
B15: Selected Scen. for Adoption of AI | E15: =VLOOKUP(Dashboard!$G$13,Scenario!$J$12:$L$14,3,) -> 1
A17: # | B17: Revenue Forecast | F17: 44651 | G17: =EDATE(F17,12) -> 45016 | H17: =EDATE(G17,12) -> 45382 | I17: =EDATE(H17,12) -> 45747 | J17: =EDATE(I17,12) -> 46112 | K17: =EDATE(J17,12) -> 46477 | L17: =EDATE(K17,12) -> 46843 | M17: =EDATE(L17,12) -> 47208 | N17: =EDATE(M17,12) -> 47573
B19: Revenues by geography
B20: North America | F20: 75058 | G20: 90724 | H20: 92411 | I20: 94397 | J20: =I20*(1+J28) -> 96096.146 | K20: =J20*(1+K28) -> 99939.992 | L20: =K20*(1+L28) -> 104437.29 | M20: =L20*(1+M28) -> 109659.16 | N20: =M20*(1+N28) -> 115690.41 | O20: =_xlfn.RRI(4,F20,I20) -> 0.058986201 | P20: =_xlfn.RRI(5,J20,N20) -> 0.037811019
B21: Europe | F21: 30129 | G21: 37675 | H21: 42267 | I21: 48595 | J21: =I21*(1+J32) -> 52482.6 | K21: =J21*(1+K32) -> 57206.034 | L21: =K21*(1+L32) -> 62583.401 | M21: =L21*(1+M32) -> 68716.575 | N21: =M21*(1+N32) -> 75588.232 | O21: =_xlfn.RRI(4,F21,I21) -> 0.1269424 | P21: =_xlfn.RRI(5,J21,N21) -> 0.07569158
B22: India | F22: 3585 | G22: 3861 | H22: 3881 | I22: 5014 | J22: =I22*(1+J36) -> 6518.2 | K22: =J22*(1+K36) -> 7952.204 | L22: =K22*(1+L36) -> 9542.6448 | M22: =L22*(1+M36) -> 11260.321 | N22: =M22*(1+N36) -> 12949.369 | O22: =_xlfn.RRI(4,F22,I22) -> 0.087486295 | P22: =_xlfn.RRI(5,J22,N22) -> 0.1471605
B23: Rest of the world | F23: 12869 | G23: 14507 | H23: 15111 | I23: 14984 | J23: =I23*(1+J40) -> 14609.4 | K23: =J23*(1+K40) -> 14346.431 | L23: =K23*(1+L40) -> 14131.234 | M23: =L23*(1+M40) -> 14060.578 | N23: =M23*(1+N40) -> 14130.881 | O23: =_xlfn.RRI(4,F23,I23) -> 0.038773211 | P23: =_xlfn.RRI(5,J23,N23) -> -0.0066383896
B24: Total | F24: =SUM(F20:F23) -> 121641 | G24: =SUM(G20:G23) -> 146767 | H24: =SUM(H20:H23) -> 153670 | I24: =SUM(I20:I23) -> 162990 | J24: =SUM(J20:J23) -> 169706.35 | K24: =SUM(K20:K23) -> 179444.66 | L24: =SUM(L20:L23) -> 190694.57 | M24: =SUM(M20:M23) -> 203696.63 | N24: =SUM(N20:N23) -> 218358.89 | O24: =_xlfn.RRI(4,F24,I24) -> 0.07589588 | P24: =_xlfn.RRI(5,J24,N24) -> 0.051706504
B26: Revenue Growth Anlaysis (YoY %)
B27: Revenues by geography
B28: North America | F28: 0 | G28: =G20/F20-1 -> 0.20871859 | H28: =H20/G20-1 -> 0.018594859 | I28: =I20/H20-1 -> 0.021490948 | J28: =OFFSET(J28,$E$14,0) -> 0.018 | K28: =OFFSET(K28,$E$14,0) -> 0.04 | L28: =OFFSET(L28,$E$14,0) -> 0.045 | M28: =OFFSET(M28,$E$14,0) -> 0.05 | N28: =OFFSET(N28,$E$14,0) -> 0.055 | Q28: Due to tariffs, visa and other cost barriers.
B29: Best | J29: =J30+1% -> 0.028 | K29: =K30+1% -> 0.05 | L29: =L30+1% -> 0.055 | M29: =M30+1% -> 0.06 | N29: =N30+1% -> 0.065
B30: Street | J30: 0.018 | K30: 0.04 | L30: 0.045 | M30: 0.05 | N30: 0.055
B31: Worst | J31: =J30-1% -> 0.008 | K31: =K30-1% -> 0.03 | L31: =L30-1% -> 0.035 | M31: =M30-1% -> 0.04 | N31: =N30-1% -> 0.045
B32: Europe | F32: 0 | G32: =G21/F21-1 -> 0.25045637 | H32: =H24/G24-1 -> 0.047033734 | I32: =I24/H24-1 -> 0.060649444 | J32: =OFFSET(J32,$E$14,0) -> 0.08 | K32: =OFFSET(K32,$E$14,0) -> 0.09 | L32: =OFFSET(L32,$E$14,0) -> 0.094 | M32: =OFFSET(M32,$E$14,0) -> 0.098 | N32: =OFFSET(N32,$E$14,0) -> 0.1 | Q32: Due to high/steady growth in Europe, driven by diversification (New centres, New hubs, etc.)
B33: Best | J33: =J34+1% -> 0.09 | K33: =K34+1% -> 0.1 | L33: =L34+1% -> 0.104 | M33: =M34+1% -> 0.108 | N33: =N34+1% -> 0.11
B34: Street | J34: 0.08 | K34: 0.09 | L34: 0.094 | M34: 0.098 | N34: 0.1
B35: Worst | J35: =J34-1% -> 0.07 | K35: =K34-1% -> 0.08 | L35: =L34-1% -> 0.084 | M35: =M34-1% -> 0.088 | N35: =N34-1% -> 0.09
B36: India | F36: 0 | G36: =G22/F22-1 -> 0.076987448 | H36: =H22/G22-1 -> 0.0051800052 | I36: =I22/H22-1 -> 0.29193507 | J36: =OFFSET(J36,$E$14,0) -> 0.3 | K36: =OFFSET(K36,$E$14,0) -> 0.22 | L36: =OFFSET(L36,$E$14,0) -> 0.2 | M36: =OFFSET(M36,$E$14,0) -> 0.18 | N36: =OFFSET(N36,$E$14,0) -> 0.15 | Q36: Domestic revenue contribution is expected to rise as Indian enterprises increase IT budgets, partially offsetting slower international growth.
B37: Best | J37: =J38+1% -> 0.31 | K37: =K38+1% -> 0.23 | L37: =L38+1% -> 0.21 | M37: =M38+1% -> 0.19 | N37: =N38+1% -> 0.16
B38: Street | J38: 0.3 | K38: 0.22 | L38: 0.2 | M38: 0.18 | N38: 0.15
B39: Worst | J39: =J38-1% -> 0.29 | K39: =K38-1% -> 0.21 | L39: =L38-1% -> 0.19 | M39: =M38-1% -> 0.17 | N39: =N38-1% -> 0.14
B40: Rest of the world | F40: 0 | G40: =G23/F23-1 -> 0.12728262 | H40: =H23/G23-1 -> 0.041635073 | I40: =I23/H23-1 -> -0.0084044736 | J40: =OFFSET(J40,$E$14,0) -> -0.025 | K40: =OFFSET(K40,$E$14,0) -> -0.018 | L40: =OFFSET(L40,$E$14,0) -> -0.015 | M40: =OFFSET(M40,$E$14,0) -> -0.005 | N40: =OFFSET(N40,$E$14,0) -> 0.005 | Q40: Small revenue share; growth still driven by digital demand
B41: Best | J41: =J42+1% -> -0.015 | K41: =K42+1% -> -0.008 | L41: =L42+1% -> -0.005 | M41: =M42+1% -> 0.005 | N41: =N42+1% -> 0.015
B42: Street | J42: -0.025 | K42: -0.018 | L42: -0.015 | M42: -0.005 | N42: 0.005
B43: Worst | J43: =J42-1% -> -0.035 | K43: =K42-1% -> -0.028 | L43: =L42-1% -> -0.025 | M43: =M42-1% -> -0.015 | N43: =N42-1% -> -0.005
A45: # | B45: Expenses forecast
A47: * | B47: Employee benfit expenses
B48: Salaries including bonus | F48: 61522 | G48: 75239 | H48: 79315 | I48: 82232 | J48: 0 | K48: 0 | L48: 0 | M48: 0 | N48: 0 | O48: =_xlfn.RRI(4,F48,I48) -> 0.075233042
B49: Contribution to PPF and other funds | F49: 1617 | G49: 2143 | H49: 2213 | I49: 2338 | J49: 0 | K49: 0 | L49: 0 | M49: 0 | N49: 0 | O49: =_xlfn.RRI(4,F49,I49) -> 0.096563085
...

Sheet Assumptions
B2: =Dashboard!C2 -> Infosys Ltd.
B3: Assumptions
B4: =Dashboard!C4 -> (In ₹ Crore, except equity share and per equity share data)
B5: Date | G5: Acutals | K5: Forecast | P5: CAGR | R5: Notes
B6: Actual / Forecast | G6: =Financials!F6 -> 44651 | H6: =EDATE(G6,12) -> 45016 | I6: =EDATE(H6,12) -> 45382 | J6: =EDATE(I6,12) -> 45747 | K6: =EDATE(J6,12) -> 46112 | L6: =EDATE(K6,12) -> 46477 | M6: =EDATE(L6,12) -> 46843 | N6: =EDATE(M6,12) -> 47208 | O6: =EDATE(N6,12) -> 47573 | P6: 22A - 25A | Q6: 26E - 30E
B8: <-Back to dashboard
A10: # | B10: Assumptions
B12: Other income | G12: =Financials!F16 -> 2295 | H12: =Financials!G16 -> 2701 | I12: =Financials!H16 -> 4711 | J12: =Financials!I16 -> 3600 | K12: =K13*Financials!J$15 -> 3818.9935 | L12: =L13*Financials!K$15 -> 4038.1401 | M12: =M13*Financials!L$15 -> 4291.3029 | N12: =N13*Financials!M$15 -> 4583.8952 | O12: =O13*Financials!N$15 -> 4913.848 | P12: =_xlfn.RRI(4,G12,J12) -> 0.11912849 | Q12: =_xlfn.RRI(5,K12,O12) -> 0.051706504 | R12: Other income projected as the average of other income to Revenue
B13: Other income as a % of Revenue from operations | G13: =G12/Financials!F$15 -> 0.018866994 | H13: =H12/Financials!G$15 -> 0.01840332 | I13: =I12/Financials!H$15 -> 0.030656602 | J13: =J12/Financials!I$15 -> 0.022087245 | K13: =AVERAGE(G13:J13) -> 0.02250354 | L13: =K13 -> 0.02250354 | M13: =L13 -> 0.02250354 | N13: =M13 -> 0.02250354 | O13: =N13 -> 0.02250354
B15: Current taxes | G15: =Financials!F32 -> 7811 | H15: =Financials!G32 -> 9287 | I15: =Financials!H32 -> 8390 | J15: =Financials!I32 -> 12130 | K15: =K16*Financials!J30 -> 12163.541 | L15: =L16*Financials!K30 -> 12450.245 | M15: =M16*Financials!L30 -> 12916.453 | N15: =N16*Financials!M30 -> 13544.169 | O15: =O16*Financials!N30 -> 14293.643 | P15: =_xlfn.RRI(4,G15,J15) -> 0.11631958 | Q15: =_xlfn.RRI(5,K15,O15) -> 0.032800831 | R15: Current taxes projected as average of current taxes to PBT
B16: Current taxes as a % of PBT | G16: =G15/Financials!F$30 -> 0.25941548 | H16: =H15/Financials!G$30 -> 0.27870476 | I16: =I15/Financials!H$30 -> 0.23313327 | J16: =J15/Financials!I$30 -> 0.32253776 | K16: 0.3 | L16: =K16 -> 0.3 | M16: =L16 -> 0.3 | N16: =M16 -> 0.3 | O16: =N16 -> 0.3
B18: Non-controlling interersts | G18: =Financials!F38 -> 36 | H18: =Financials!G38 -> 13 | I18: =Financials!H38 -> 15 | J18: =Financials!I38 -> 37 | K18: =K19*Financials!J34 -> 29.229252 | L18: =L19*Financials!K34 -> 29.918208 | M18: =M19*Financials!L34 -> 31.038514 | N18: =N19*Financials!M34 -> 32.546929 | O18: =O19*Financials!N34 -> 34.347932 | P18: =_xlfn.RRI(4,G18,J18) -> 0.0068732567 | Q18: =_xlfn.RRI(5,K18,O18) -> 0.032800831 | R18: NCI projected as average of NCI to PAT
B19: Non-controlling interersts as a % of Net income | G19: =G18/Financials!F$34 -> 0.0016255757 | H19: =H18/Financials!G$34 -> 0.00053924009 | I19: =I18/Financials!H$34 -> 0.00057147211 | J19: =J18/Financials!I$34 -> 0.0013831776 | K19: =AVERAGE(G19:J19) -> 0.0010298664 | L19: =K19 -> 0.0010298664 | M19: =L19 -> 0.0010298664 | N19: =M19 -> 0.0010298664 | O19: =N19 -> 0.0010298664
B21: Dividends paid | G21: 12652 | H21: 13631 | I21: 14692 | J21: 20287 | K21: =K22*Financials!J37 -> 17400.159 | L21: =L22*Financials!K37 -> 18117.996 | M21: =M22*Financials!L37 -> 19239.766 | N21: =N22*Financials!M37 -> 20800.676 | O21: =O22*Financials!N37 -> 21122.683 | P21: =_xlfn.RRI(4,G21,J21) -> 0.12529052 | Q21: =_xlfn.RRI(5,K21,O21) -> 0.039535138
B22: Dividends paid as a % of Net income | G22: =G21/Financials!F$34 -> 0.57129956 | H22: =H21/Financials!G$34 -> 0.56541397 | I22: =I21/Financials!H$34 -> 0.55973788 | J22: =J21/Financials!I$34 -> 0.75839252 | K22: =AVERAGE(G22:J22) -> 0.61371098 | L22: =AVERAGE(H22:K22) -> 0.62431384 | M22: =AVERAGE(I22:L22) -> 0.63903881 | N22: =AVERAGE(J22:M22) -> 0.65886404 | O22: =AVERAGE(K22:N22) -> 0.63398192
B24: Share buy-back | G24: 11125 | H24: 11499 | I24: 0 | J24: 0 | K24: 0 | L24: 12500 | M24: 0 | N24: 0 | O24: 10500
B25: Share buy-back as a % of Net income | G25: =IF(G24/Financials!F$34,G24/Financials!F$34,"-") -> 0.50234805 | H25: =IF(H24/Financials!G$34,H24/Financials!G$34,"-") -> 0.4769786 | I25: =IF(I24/Financials!H$34,I24/Financials!H$34,"-") -> - | J25: =IF(J24/Financials!I$34,J24/Financials!I$34,"-") -> - | K25: =IF(K24/Financials!J$34,K24/Financials!J$34,"-") -> - | L25: =IF(L24/Financials!K$34,L24/Financials!K$34,"-") -> 0.43028412 | M25: =IF(M24/Financials!L$34,M24/Financials!L$34,"-") -> - | N25: =IF(N24/Financials!M$34,N24/Financials!M$34,"-") -> - | O25: =IF(O24/Financials!M$34,O24/Financials!M$34,"-") -> 0.33224631
A28: # | B28: End

Sheet Schedule
B2: =Dashboard!C2 -> Infosys Ltd.
B3: Schedule
B4: =Dashboard!C4 -> (In ₹ Crore, except equity share and per equity share data)
B5: Date | G5: Acutals | K5: Forecast
B6: Actual / Forecast | G6: =Financials!F6 -> 44651 | H6: =EDATE(G6,12) -> 45016 | I6: =EDATE(H6,12) -> 45382 | J6: =EDATE(I6,12) -> 45747 | K6: =EDATE(J6,12) -> 46112 | L6: =EDATE(K6,12) -> 46477 | M6: =EDATE(L6,12) -> 46843 | N6: =EDATE(M6,12) -> 47208 | O6: =EDATE(N6,12) -> 47573
B8: <-Back to dashboard
A10: # | B10: Property, plant, and equipment and Intangible schedule
B12: CapEx on PPE and intangibles | I12: 2201 | J12: 2237 | K12: =K13*Financials!J15 -> 3394.1269 | L12: =L13*Financials!K15 -> 3947.7825 | M12: =M13*Financials!L15 -> 4576.6697 | N12: =N13*Financials!M15 -> 5296.1124 | O12: =O13*Financials!N15 -> 6114.049
B13: CapEx as a % of opearting revenue | I13: =I12/Financials!H$15 -> 0.0143229 | J13: =J12/Financials!I$15 -> 0.013724768 | K13: 0.02 | L13: =K13+($O$13-$K$13)/4 -> 0.022 | M13: =L13+($O$13-$K$13)/4 -> 0.024 | N13: =M13+($O$13-$K$13)/4 -> 0.026 | O13: 0.028
B15: CapEx on PPE | I15: 1761 | J15: 1843 | K15: =($J15/$J$12)*K$12 -> 2796.3236 | L15: =($J15/$J$12)*L$12 -> 3252.4646 | M15: =($J15/$J$12)*M$12 -> 3770.5866 | N15: =($J15/$J$12)*N$12 -> 4363.3148 | O15: =($J15/$J$12)*O$12 -> 5037.1892
B16: CapEx on Intangibles | I16: =I12-I15 -> 440 | J16: =J12-J15 -> 394 | K16: =($J16/$J$12)*K$12 -> 597.80331 | L16: =($J16/$J$12)*L$12 -> 695.31798 | M16: =($J16/$J$12)*M$12 -> 806.08309 | N16: =($J16/$J$12)*N$12 -> 932.79762 | O16: =($J16/$J$12)*O$12 -> 1076.8598
B18: CWIP | K18: 576 | L18: 204 | M18: 22 | N18: 12 | O18: 0
B20: Depreciation on PPE (old) | I20: 2685 | J20: 2360
B21: Average useful life (Years) | E21: 5
B23: Depreciation on PPE (new)
B24: Average useful life (Years) | E24: 12
B25: (old) | K25: =AVERAGE($I$20:$J$20)/$E$21 -> 504.5 | L25: =AVERAGE($I$20:$J$20)/$E$21 -> 504.5 | M25: =AVERAGE($I$20:$J$20)/$E$21 -> 504.5 | N25: =AVERAGE($I$20:$J$20)/$E$21 -> 504.5 | O25: =AVERAGE($I$20:$J$20)/$E$21 -> 504.5
B26: (new) | E26: 46112 | K26: =SLN($K$15,0,$E$24) -> 233.02697 | L26: =SLN($K$15,0,$E$24) -> 233.02697 | M26: =SLN($K$15,0,$E$24) -> 233.02697 | N26: =SLN($K$15,0,$E$24) -> 233.02697 | O26: =SLN($K$15,0,$E$24) -> 233.02697
B27: (new) | E27: 46477 | L27: =SLN($L$15,0,$E$24) -> 271.03871 | M27: =SLN($L$15,0,$E$24) -> 271.03871 | N27: =SLN($L$15,0,$E$24) -> 271.03871 | O27: =SLN($L$15,0,$E$24) -> 271.03871
B28: (new) | E28: 46843 | M28: =SLN($M$15,0,$E$24) -> 314.21555 | N28: =SLN($M$15,0,$E$24) -> 314.21555 | O28: =SLN($M$15,0,$E$24) -> 314.21555
B29: (new) | E29: 47208 | N29: =SLN($N$15,0,$E$24) -> 363.60956 | O29: =SLN($N$15,0,$E$24) -> 363.60956
B30: (new) | E30: 47573 | O30: =SLN($O$15,0,$E$24) -> 419.76577
B32: Total Depreciation | K32: =SUM(K25,K26:K30) -> 737.52697 | L32: =SUM(L25,L26:L30) -> 1008.5657 | M32: =SUM(M25,M26:M30) -> 1322.7812 | N32: =SUM(N25,N26:N30) -> 1686.3908 | O32: =SUM(O25,O26:O30) -> 2106.1566
B34: Disposal of PPE | G34: 1100 | H34: 2197 | I34: 1227 | J34: 1221 | K34: =K35*Financials!J15 -> 1675.3499 | L34: =L35*Financials!K15 -> 1808.6791 | M34: =M35*Financials!L15 -> 1688.9468 | N34: =N35*Financials!M15 -> 1848.5184 | O34: =O35*Financials!N15 -> 2068.0248
B35: Disposal of PPE as a % of operating revenue | G35: =G34/Financials!F$15 -> 0.0090430036 | H35: =H34/Financials!G$15 -> 0.014969305 | I35: =I34/Financials!H$15 -> 0.0079846424 | J35: =J34/Financials!I$15 -> 0.0074912571 | K35: =AVERAGE(G35:J35) -> 0.0098720521 | L35: =AVERAGE(H35:K35) -> 0.010079314 | M35: =AVERAGE(I35:L35) -> 0.0088568164 | N35: =AVERAGE(J35:M35) -> 0.00907486 | O35: =AVERAGE(K35:N35) -> 0.0094707607
B37: Amortisation on intangibles | I37: 432 | J37: 777 | K37: =K38*AVERAGE(K51,K53) -> 816.33491 | L37: =L38*AVERAGE(L51,L53) -> 969.29654 | M37: =M38*AVERAGE(M51,M53) -> 1017.0075 | N37: =N38*AVERAGE(N51,N53) -> 1143.1087 | O37: =O38*AVERAGE(O51,O53) -> 1249.9972
B38: Amortisation as a % on gross avg intangibles | I38: =I37/AVERAGE(I$51,I$53) -> 0.091787953 | J38: =J37/AVERAGE(J$51,J$53) -> 0.13239053 | K38: =AVERAGE(I38:J38) -> 0.11208924 | L38: =AVERAGE(J38:K38) -> 0.12223988 | M38: =AVERAGE(K38:L38) -> 0.11716456 | N38: =AVERAGE(L38:M38) -> 0.11970222 | O38: =AVERAGE(M38:N38) -> 0.11843339
B40: Property, plant and equipment
B41: Opening balance of gross PPE | I41: 30089 | J41: =I45 -> 30587 | K41: =J45 -> 31290 | L41: =K45 -> 32986.974 | M41: =L45 -> 34634.759 | N41: =M45 -> 36738.399 | O41: =N45 -> 39265.195
B42: Additions to PPE | K42: =K15 -> 2796.3236 | L42: =L15 -> 3252.4646 | M42: =M15 -> 3770.5866 | N42: =N15 -> 4363.3148 | O42: =O15 -> 5037.1892
B43: Transfers from CWIP | K43: =K18 -> 576 | L43: =L18 -> 204 | M43: =M18 -> 22 | N43: =N18 -> 12 | O43: =O18 -> 0
B44: Disposal of PPE | K44: =K34 -> 1675.3499 | L44: =L34 -> 1808.6791 | M44: =M34 -> 1688.9468 | N44: =N34 -> 1848.5184 | O44: =O34 -> 2068.0248
B45: Closing balance of gross PPE | I45: 30587 | J45: 31290 | K45: =K41+K42+K43-K44 -> 32986.974 | L45: =L41+L42+L43-L44 -> 34634.759 | M45: =M41+M42+M43-M44 -> 36738.399 | N45: =N41+N42+N43-N44 -> 39265.195 | O45: =O41+O42+O43-O44 -> 42234.36
B46: Accumulated depreciation | J46: -19512 | K46: =J46-K32 -> -20249.527 | L46: =K46-L32 -> -21258.093 | M46: =L46-M32 -> -22580.874 | N46: =M46-N32 -> -24267.265 | O46: =N46-O32 -> -26373.421
B47: Closing balance of Net PPE block | K47: =K45+K46 -> 12737.447 | L47: =L45+L46 -> 13376.667 | M47: =M45+M46 -> 14157.525 | N47: =N45+N46 -> 14997.931 | O47: =O45+O46 -> 15860.939
B50: Intangible assets
B51: Opening balance of gross intangible assets | I51: 4659 | J51: =I53 -> 4754 | K51: =J53 -> 6984 | L51: =K53 -> 7581.8033 | M51: =L53 -> 8277.1213 | N51: =M53 -> 9083.2044 | O51: =N53 -> 10016.002
B52: Additions to intangible assets | K52: =K16 -> 597.80331 | L52: =L16 -> 695.31798 | M52: =M16 -> 806.08309 | N52: =N16 -> 932.79762 | O52: =O16 -> 1076.8598
B53: Closing balance of gross intangible assets | I53: 4754 | J53: 6984 | K53: =K51+K52 -> 7581.8033 | L53: =L51+L52 -> 8277.1213 | M53: =M51+M52 -> 9083.2044 | N53: =N51+N52 -> 10016.002 | O53: =O51+O52 -> 11092.862
B54: Accumulated amortisation | J54: -4218 | K54: =J54-K37 -> -5034.3349 | L54: =K54-L37 -> -6003.6315 | M54: =L54-M37 -> -7020.6389 | N54: =M54-N37 -> -8163.7476 | O54: =N54-O37 -> -9413.7448
...

Sheet Valuation->
A1: \

Sheet DCF
B2: =Dashboard!C2 -> Infosys Ltd.
B3: FCFF
B4: =Dashboard!C4 -> (In ₹ Crore, except equity share and per equity share data)
B6: <-Back to dashboard
B8: Valuation as on specified date | E8: 46084
B9: Date of year ending | E9: 46387
A11: # | B11: Inputs
B13: Trigger | G13: Best | J13: Street | M13: Worst
B15: Selected Scenario: | E15: =VLOOKUP(Dashboard!$G$12,Scenario!$G$12:$H$14,2,TRUE) -> 2 | G15: WACC | H15: =K15-1% -> 0.099163543 | J15: WACC | K15: =WACC!H16 -> 0.10916354 | M15: WACC | N15: =K15+1% -> 0.11916354
B16: Selected Scen. for Adoption of AI: | E16: =VLOOKUP(Dashboard!$G$13,Scenario!$J$12:$L$14,3,) -> 1 | G16: TGR | H16: 0.05 | J16: TGR | K16: 0.04 | M16: TGR | N16: 0.03 | O16: (3%-6%) Google
B18: WACC: | E18: =CHOOSE($E$15,H15,K15,N15) -> 0.10916354
B19: TGR: | E19: =CHOOSE($E$15,H16,K16,N16) -> 0.04
A21: # | B21: Free Cash Flow to Firm | G21: =Financials!J6 -> 46112 | H21: =EDATE(G21,12) -> 46477 | I21: =EDATE(H21,12) -> 46843 | J21: =EDATE(I21,12) -> 47208 | K21: =EDATE(J21,12) -> 47573
B23: EBIT | G23: =Financials!J30 -> 40545.138 | H23: =Financials!K30 -> 41500.818 | I23: =Financials!L30 -> 43054.843 | J23: =Financials!M30 -> 45147.228 | K23: =Financials!N30 -> 47645.476
B24: Tax Rate | G24: 0.3 | H24: 0.3 | I24: 0.3 | J24: 0.3 | K24: 0.3
B25: NOPAT | G25: =G23*(1-G24) -> 28381.596 | H25: =H23*(1-H24) -> 29050.573 | I25: =I23*(1-I24) -> 30138.39 | J25: =J23*(1-J24) -> 31603.06 | K25: =K23*(1-K24) -> 33351.833
B27: Add: Deperciation & Amortisation | G27: =Financials!J106 -> 1553.8619 | H27: =Financials!K106 -> 1977.8622 | I27: =Financials!L106 -> 2339.7887 | J27: =Financials!M106 -> 2829.4995 | K27: =Financials!N106 -> 3356.1537
B28: Less: CapEx | G28: =Financials!J119+Financials!J121+Financials!J122+Financials!J123 -> -2928.9025 | H28: =Financials!K119+Financials!K121+Financials!K122+Financials!K123 -> -4513.8064 | I28: =Financials!L119+Financials!L121+Financials!L122+Financials!L123 -> -4991.7133 | J28: =Financials!M119+Financials!M121+Financials!M122+Financials!M123 -> -5823.6727 | K28: =Financials!N119+Financials!N121+Financials!N122+Financials!N123 -> -6500.2078
B29: Add/Less: Change in WC | G29: =SUM(Financials!J108:J113) -> -199.04203 | H29: =SUM(Financials!K108:K113) -> -1007.4882 | I29: =SUM(Financials!L108:L113) -> -1259.4758 | J29: =SUM(Financials!M108:M113) -> -1563.4814 | K29: =SUM(Financials!N108:N113) -> -1799.901
B30: FCF | G30: =SUM(G25:G29) -> 26807.514 | H30: =SUM(H25:H29) -> 25507.14 | I30: =SUM(I25:I29) -> 26226.99 | J30: =SUM(J25:J29) -> 27045.405 | K30: =SUM(K25:K29) -> 28407.878
B32: Dicsount Period | G32: =G33/2 -> 0.41506849 | H32: =G32+1 -> 1.4150685 | I32: =H32+1 -> 2.4150685 | J32: =I32+1 -> 3.4150685 | K32: =J32+1 -> 4.4150685
B33: Mid Year Discount | G33: =(E9-E8)/365 -> 0.83013699
B34: Terminal Value | K34: =K30*(1+tgr)/(wacc-tgr) -> 427164.26
B35: PV of FCF | G35: =G30/(1+wacc)^G32 -> 25679.129 | H35: =H30/(1+wacc)^H32 -> 22028.754 | I35: =I30/(1+wacc)^I32 -> 20421.189 | J35: =J30/(1+wacc)^J32 -> 18985.869 | K35: =(K30+K34)/(1+wacc)^K32 -> 288335.8
B36: Enterprise Value | G36: =SUM(G35:K35) -> 375450.74
B37: Add: Cash | G37: =Financials!I67+Financials!I69+Financials!I65+Financials!I56 -> 61836
B38: Less: Debt | G38: 0
B39: Equity Value | G39: =SUM(G36:G38) -> 437286.74
B40: Number of Shares | G40: =4054667899/10^7 -> 405.46679
B41: Price per Share | G41: =G39/G40 -> 1078.4773
A43: # | B43: Sensitivity Analysis
C45: Terminal Growth %
B46: WACC | C46: =G41 -> 1078.4773 | D46: 0.02 | E46: =D46+1% -> 0.03 | F46: =E46+1% -> 0.04 | G46: =F46+1% -> 0.05 | H46: =G46+1% -> 0.06
C47: =C48+1% -> 0.13 | D47: 779.94917 | E47: 821.90809 | F47: 873.19121 | G47: 937.29512 | H47: 1019.7144
C48: =C49+1% -> 0.12 | D48: 839.43515 | E48: 892.29892 | F48: 958.37862 | G48: 1043.3382 | H48: 1156.6177
C49: =C50+1% -> 0.11 | D49: 912.14655 | E49: 980.2815 | F49: 1067.8836 | G49: 1184.6863 | H49: 1348.2102
C50: =C51+1% -> 0.1 | D50: 1003.0439 | E50: 1093.3956 | F50: 1213.8647 | G50: 1382.5213 | H50: 1635.5062
C51: 0.09 | D51: 1119.9223 | E51: 1244.2077 | F51: 1418.2073 | G51: 1679.2066 | H51: 2114.2056
A53: # | B53: Street - Low AI Impact | J53: Best - Low AI Impact | R53: Worst - Low AI Impact
C55: Terminal Growth % | K55: Terminal Growth % | S55: Terminal Growth %
...

Sheet WACC
B2: =Dashboard!C2 -> Infosys Ltd.
B3: WACC
B4: =Dashboard!C4 -> (In ₹ Crore, except equity share and per equity share data)
B6: <-Back to dashboard
B8: Cost of Equity | G8: Capital Structure
B9: Risk Free Rate | D9: 0.0668 | G9: Market Cap | H9: 589562
B10: Market Returns | D10: =Beta!L21 -> 0.11561994 | G10: Debt | H10: =0 -> 0
B11: Levered beta | D11: =Beta!L18 -> 0.8677508 | G11: Total Capital | H11: =H9+H10 -> 589562
B12: Cost of equity | D12: =D9+(D10-D9)*D11 -> 0.10916354
B14: Cost of Debt | G14: Cost of Equity | H14: =D12*(H9/H11) -> 0.10916354
B15: (Using credit rating) | G15: Cost of Debt | H15: =D20*(H10/H11) -> 0
B16: Risk Free Rate | D16: 0.0668 | G16: WACC | H16: =H14+H15 -> 0.10916354
B17: Risk premium | D17: 0.004
B18: Pre-tax cost of debt | D18: =D16+D17 -> 0.0708
B19: Tax Rate | D19: 0.3
B20: Post-tax cost of debt | D20: =D18*(1-D19) -> 0.04956
B22: End
A23: #

Sheet Beta
B2: =Dashboard!C2 -> Infosys Ltd.
B3: Beta
B4: =Dashboard!C4 -> (In ₹ Crore, except equity share and per equity share data)
B6: <-Back to dashboard
B8: Infosys LTD. | F8: Nifty-50 | J8: Beta
B10: Date | C10: Price | D10: Returns | F10: Date | G10: Price | H10: Returns | J10: Calculated beta | L10: =SLOPE(D12:D374,H12:H374) -> 0.82366773 | N10: Median | P10: =MEDIAN(C11:C24) -> 1534.55
B11: 46082 | C11: 1288.9 | F11: 46082 | G11: 24865.7 | N11: 75th Percentile | P11: =PERCENTILE(C11:C24,75%) -> 1594.0125
B12: 46054 | C12: 1300.1 | D12: =C12/C11-1 -> 0.0086895803 | F12: 46054 | G12: 25178.65 | H12: =G12/G11-1 -> 0.01258561 | J12: Levered beta | L12: =L10 -> 0.82366773 | N12: 25th Percentile | P12: =PERCENTILE(C11:C24,25%) -> 1472.775
B13: 46023 | C13: 1641 | D13: =C13/C12-1 -> 0.2622106 | F13: 46023 | G13: 25320.65 | H13: =G13/G12-1 -> 0.0056396987 | J13: Raw beta weight | L13: 0.75
B14: 45992 | C14: 1615.4 | D14: =C14/C13-1 -> -0.015600244 | F14: 45992 | G14: 26129.6 | H14: =G14/G13-1 -> 0.031948232
B15: 45962 | C15: 1560.1 | D15: =C15/C14-1 -> -0.034233007 | F15: 45962 | G15: 26202.95 | H15: =G15/G14-1 -> 0.0028071612 | J15: Market beta | L15: =SLOPE(H12:H374,H12:H374) -> 1
B16: 45931 | C16: 1482.3 | D16: =C16/C15-1 -> -0.049868598 | F16: 45931 | G16: 25722.1 | H16: =G16/G15-1 -> -0.018350987 | J16: Raw beta weight | L16: 0.25
B17: 45901 | C17: 1441.8 | D17: =C17/C16-1 -> -0.027322404 | F17: 45901 | G17: 24611.1 | H17: =G17/G16-1 -> -0.04319243
B18: 45870 | C18: 1469.6 | D18: =C18/C17-1 -> 0.019281454 | F18: 45870 | G18: 24426.85 | H18: =G18/G17-1 -> -0.0074864594 | J18: Adjusted beta | L18: =(L12*L13)+(L15*L16) -> 0.8677508
B19: 45839 | C19: 1509 | D19: =C19/C18-1 -> 0.026810016 | F19: 45839 | G19: 24768.35 | H19: =G19/G18-1 -> 0.013980517
B20: 45809 | C20: 1601.8 | D20: =C20/C19-1 -> 0.061497681 | F20: 45809 | G20: 25517.05 | H20: =G20/G19-1 -> 0.030228094 | J20: Total years | L20: =YEARFRAC(F374,F11,1) -> 30.247775
B21: 45778 | C21: 1562.7 | D21: =C21/C20-1 -> -0.024410039 | F21: 45778 | G21: 24750.7 | H21: =G21/G20-1 -> -0.03003286 | J21: Market returns (%) | L21: =_xlfn.RRI(L20,G374,G11) -> 0.11561994
B22: 45748 | C22: 1500.1 | D22: =C22/C21-1 -> -0.040058872 | F22: 45748 | G22: 24334.2 | H22: =G22/G21-1 -> -0.016827807
B23: 45717 | C23: 1570.65 | D23: =C23/C22-1 -> 0.047030198 | F23: 45717 | G23: 23519.35 | H23: =G23/G22-1 -> -0.033485794
B24: 45689 | C24: 1687.7 | D24: =C24/C23-1 -> 0.074523287 | F24: 45689 | G24: 22124.7 | H24: =G24/G23-1 -> -0.059297982
B25: 45658 | C25: 1879.8 | D25: =C25/C24-1 -> 0.11382355 | F25: 45658 | G25: 23508.4 | H25: =G25/G24-1 -> 0.062540961
B26: 45627 | C26: 1880 | D26: =C26/C25-1 -> 0.0001063943 | F26: 45627 | G26: 23644.8 | H26: =G26/G25-1 -> 0.0058021813
B27: 45597 | C27: 1857.85 | D27: =C27/C26-1 -> -0.011781915 | F27: 45597 | G27: 24131.1 | H27: =G27/G26-1 -> 0.02056689
B28: 45566 | C28: 1757.25 | D28: =C28/C27-1 -> -0.054148613 | F28: 45566 | G28: 24205.35 | H28: =G28/G27-1 -> 0.0030769422
B29: 45536 | C29: 1875.6 | D29: =C29/C28-1 -> 0.067349552 | F29: 45536 | G29: 25810.85 | H29: =G29/G28-1 -> 0.066328312
B30: 45505 | C30: 1943.7 | D30: =C30/C29-1 -> 0.036308381 | F30: 45505 | G30: 25235.9 | H30: =G30/G29-1 -> -0.022275516
B31: 45474 | C31: 1868.25 | D31: =C31/C30-1 -> -0.038817719 | F31: 45474 | G31: 24951.15 | H31: =G31/G30-1 -> -0.011283529
B32: 45444 | C32: 1566.75 | D32: =C32/C31-1 -> -0.16138097 | F32: 45444 | G32: 24010.6 | H32: =G32/G31-1 -> -0.037695657
B33: 45413 | C33: 1406.9 | D33: =C33/C32-1 -> -0.10202649 | F33: 45413 | G33: 22530.7 | H33: =G33/G32-1 -> -0.061635278
... B374: 35034 | C374: 0.79 | D374: =C374/C373-1 -> 0.012820513 | F374: 35034 | G374: 908.53 | H374: =G374/G373-1 -> 0.070849343

Sheet Comps
B2: # | C2: Comparable Company Analysis of Indian IT - Software and Consulting Companies with Market Cap of above 10 Thousand Crore.
C3: (In ₹ Crore, except equity share and per equity share data)
C5: Company Name | E5: Share Price (₹) | F5: Revenue | G5: EBITDA | H5: Net Income | I5: Enterprise Value | J5: EV / Rev | K5: EV / EBITDA | L5: P / S | M5: P / E
C6: Infosys | E6: 1285 | F6: 173173 | G6: =40563+4776 -> 45339 | H6: 28003 | I6: 510024.58 | J6: =I$6/F6 -> 2.9451738 | K6: =J$6*10^5/G6 -> 6.4958949 | L6: 3.01 | M6: 18.01
C7: TCS | E7: 2409 | F7: 260802 | G7: 74775 | H7: 47963 | I7: 868076.38 | J7: =I$6/F7 -> 1.9556007 | K7: =J$6*10^5/G7 -> 3.9387145 | L7: 3.34 | M7: 17.06
C8: HCL Technologies | E8: 1401.9 | F8: 126409 | G8: 28179 | H8: 16471 | I8: 363460.66 | J8: =I$6/F8 -> 4.0347173 | K8: =J$6*10^5/G8 -> 10.451662 | L8: 3.01 | M8: 22.11
C9: Wipro | E9: 189.9 | F9: 90891.9 | G9: 21785.8 | H9: 13332 | I9: 202254.96 | J9: =I$6/F9 -> 5.6113315 | K9: =J$6*10^5/G9 -> 13.518777 | L9: 2.19 | M9: 15.02
C10: Tech Mahindra | E10: 1421.75 | F10: 55123.3 | G10: 8715.6 | H10: 4591 | I10: 136976.69 | J10: =I$6/F10 -> 9.2524319 | K10: =J$6*10^5/G10 -> 33.79198 | L10: 2.53 | M10: 28.97
C11: LTIMindtree | E11: 4288 | F11: 40787.6 | G11: 8349.3 | H11: 4724 | I11: 126533.56 | J11: =I$6/F11 -> 12.504403 | K11: =J$6*10^5/G11 -> 35.274499 | L11: 3.12 | M11: 24.59
C12: Persistent Systems | E12: 4911 | F12: 13934.63 | G12: 2777.44 | H12: 1731.62 | I12: 76671.71 | J12: =I$6/F12 -> 36.601229 | K12: =J$6*10^5/G12 -> 106.03915 | L12: 5.56 | M12: 43.11
C13: Mphasis | E13: 2131.5 | F13: 15347.02 | G13: 3155.15 | H13: 1799.45 | I13: 41036.33 | J13: =I$6/F13 -> 33.232809 | K13: =J$6*10^5/G13 -> 93.344969 | L13: 2.65 | M13: 22.24
C14: Coforge | E14: 1154.5 | F14: 15272.3 | G14: 2669.1 | H14: 1385.8 | I14: 39207.25 | J14: =I$6/F14 -> 33.395401 | K14: =J$6*10^5/G14 -> 110.34333 | L14: 2.54 | M14: 30.88
C15: Hexaware Tech. | E15: 442.5 | F15: 13430.4 | G15: 2299.7 | H15: 1368.3 | I15: 25735.6 | J15: =I$6/F15 -> 37.975383 | K15: =J$6*10^5/G15 -> 128.06774 | L15: 2.01 | M15: 18.61
C16: Tata Elxsi | E16: 4250.35 | F16: 3672.01 | G16: 986.41 | H16: 580.5 | I16: 25378.12 | J16: =I$6/F16 -> 138.8952 | K16: =J$6*10^5/G16 -> 298.57501 | L16: 7.21 | M16: 41.99
C17: KPIT Technologi. | E17: 675.25 | F17: 6272.27 | G17: 1360.64 | H17: 719.13 | I17: 18096.68 | J17: =I$6/F17 -> 81.314194 | K17: =J$6*10^5/G17 -> 216.45503 | L17: 2.95 | M17: 24.31
C18: Fractal Analyt. | E18: 841.35 | F18: 2765.4 | G18: 341.9 | H18: 220.6 | I18: 14609.46 | J18: =I$6/F18 -> 184.43067 | K18: =J$6*10^5/G18 -> 861.4138 | L18: 5.23 | M18: 69.16
C19: Zensar Tech. | E19: 542.05 | F19: 5595.9 | G19: 1107.9 | H19: 740.4 | I19: 11628.2 | J19: =I$6/F19 -> 91.142547 | K19: =J$6*10^5/G19 -> 265.8339 | L19: 2.2 | M19: 16.2
C21: Mean | E21: =AVERAGE(E7:E19) -> 1896.85 | J21: =AVERAGE(J7:J19) -> 51.565071 | K21: =AVERAGE(K7:K19) -> 167.46527 | L21: =AVERAGE(L7:L19) -> 3.4261538 | M21: =AVERAGE(M7:M19) -> 28.788462
C22: Median | E22: =MEDIAN(E7:E19) -> 1401.9 | J22: =MEDIAN(J7:J19) -> 33.395401 | K22: =MEDIAN(K7:K19) -> 106.03915 | L22: =MEDIAN(L7:L19) -> 2.95 | M22: =MEDIAN(M7:M19) -> 24.31
C23: 75th Percentile | E23: =PERCENTILE(E7:E19,75%) -> 2409 | J23: =PERCENTILE(J7:J19,75%) -> 81.314194 | K23: =PERCENTILE(K7:K19,75%) -> 216.45503 | L23: =PERCENTILE(L7:L19,75%) -> 3.34 | M23: =PERCENTILE(M7:M19,75%) -> 30.88
C24: 25th Percentile | E24: =PERCENTILE(E7:E19,25%) -> 675.25 | J24: =PERCENTILE(J7:J19,25%) -> 9.2524319 | K24: =PERCENTILE(K7:K19,25%) -> 33.79198 | L24: =PERCENTILE(L7:L19,25%) -> 2.53 | M24: =PERCENTILE(M7:M19,25%) -> 18.61
B26: # | C26: Valuation Summary
K27: Range of valuation | O27: Equity Value | S27: Equity Value
C28: Infosys Ltd. | E28: Revenue | F28: EBITDA | G28: Net Income | H28: # Share outst. | I28: Cash | J28: Debt | K28: EV / Rev | L28: EV / EBITDA | M28: P / Sales | N28: P / E | O28: EV / Rev | P28: EV / EBITDA | Q28: P / Sales | R28: P / E | S28: EV / Rev | T28: EV / EBITDA | U28: P / Sales | V28: P / E
C29: Mean | E29: =F6 -> 173173 | F29: =G6 -> 45339 | G29: =H6 -> 28003 | H29: =4054667899 -> 4054667899 | I29: 61836 | J29: 0 | K29: =J21 -> 51.565071 | L29: =K21 -> 167.46527 | M29: =L21 -> 3.4261538 | N29: =M21 -> 28.788462 | O29: =K29*E29 -> 8929678 | P29: =L29*F29 -> 7592708.1 | Q29: =M29*E29 -> 593317.34 | R29: =N29*G29 -> 806163.29 | S29: =$H29/O29 -> 454.06653 | T29: =$H29/P29 -> 534.02131 | U29: =$H29/10^1/Q29 -> 683.38942 | V29: =$H29/10^1/R29 -> 502.95864
C30: Median | E30: =E29 -> 173173 | F30: =F29 -> 45339 | G30: =G29 -> 28003 | H30: =4054667899 -> 4054667899 | I30: =I29 -> 61836 | J30: =J29 -> 0 | K30: =J22 -> 33.395401 | L30: =K22 -> 106.03915 | M30: =L22 -> 2.95 | N30: =M22 -> 24.31 | O30: =K30*E30 -> 5783181.7 | P30: =L30*F30 -> 4807709.1 | Q30: =M30*E30 -> 510860.35 | R30: =N30*G30 -> 680752.93 | S30: =$H30/O30 -> 701.11369 | T30: =$H30/P30 -> 843.36799 | U30: =$H30/10^1/Q30 -> 793.69399 | V30: =$H30/10^1/R30 -> 595.6152
C31: 75th Percentile | E31: =E30 -> 173173 | F31: =F30 -> 45339 | G31: =G30 -> 28003 | H31: =4054667899 -> 4054667899 | I31: =I30 -> 61836 | J31: =J30 -> 0 | K31: =J23 -> 81.314194 | L31: =K23 -> 216.45503 | M31: =L23 -> 3.34 | N31: =M23 -> 30.88 | O31: =K31*E31 -> 14081423 | P31: =L31*F31 -> 9813854.8 | Q31: =M31*E31 -> 578397.82 | R31: =N31*G31 -> 864732.64 | S31: =$H31/O31 -> 287.94447 | T31: =$H31/P31 -> 413.15752 | U31: =$H31/10^1/Q31 -> 701.01715 | V31: =$H31/10^1/R31 -> 468.89266
C32: 25th Percentile | E32: =E31 -> 173173 | F32: =F31 -> 45339 | G32: =G31 -> 28003 | H32: =4054667899 -> 4054667899 | I32: =I31 -> 61836 | J32: =J31 -> 0 | K32: =J24 -> 9.2524319 | L32: =K24 -> 33.79198 | M32: =L24 -> 2.53 | N32: =M24 -> 18.61 | O32: =K32*E32 -> 1602271.4 | P32: =L32*F32 -> 1532094.6 | Q32: =M32*E32 -> 438127.69 | R32: =N32*G32 -> 521135.83 | S32: =$H32/10^1/O32 -> 253.0575 | T32: =$H32/10^1/P32 -> 264.64867 | U32: =$H32/10^1/Q32 -> 925.45347 | V32: =$H32/10^1/R32 -> 778.04435
C34: Mean | K34: =S29 -> 454.06653 | L34: =T29 -> 534.02131 | M34: =U29 -> 683.38942 | N34: =V29 -> 502.95864
C35: Median | K35: =S30 -> 701.11369 | L35: =T30 -> 843.36799 | M35: =U30 -> 793.69399 | N35: =V30 -> 595.6152
C36: 75th Percentile | K36: =S31 -> 287.94447 | L36: =T31 -> 413.15752 | M36: =U31 -> 701.01715 | N36: =V31 -> 468.89266
C37: 25th Percentile | K37: =S32 -> 253.0575 | L37: =T32 -> 264.64867 | M37: =U32 -> 925.45347 | N37: =V32 -> 778.04435

Sheet Ratio Analysis
B2: =Dashboard!C2 -> Infosys Ltd.
B3: Ratio Analysis
B4: =Dashboard!C4 -> (In ₹ Crore, except equity share and per equity share data)
B6: <-Back to dashboard
A8: # | B8: Profitability Ratios | E8: 44651 | F8: =EDATE(E8,12) -> 45016 | G8: =EDATE(F8,12) -> 45382 | H8: =EDATE(G8,12) -> 45747 | I8: =EDATE(H8,12) -> 46112 | J8: =EDATE(I8,12) -> 46477 | K8: =EDATE(J8,12) -> 46843 | L8: =EDATE(K8,12) -> 47208 | M8: =EDATE(L8,12) -> 47573
B9: Gross profit margin | E9: =(Financials!F17-(Financials!F19+Financials!F20+Financials!F21+Financials!F22+Financials!F23+Financials!F24+Financials!F27))/Financials!F$17 -> 0.27260844 | F9: =(Financials!G17-(Financials!G19+Financials!G20+Financials!G21+Financials!G22+Financials!G23+Financials!G24+Financials!G27))/Financials!G$17 -> 0.25310434 | G9: =(Financials!H17-(Financials!H19+Financials!H20+Financials!H21+Financials!H22+Financials!H23+Financials!H24+Financials!H27))/Financials!H$17 -> 0.25972812 | H9: =(Financials!I17-(Financials!I19+Financials!I20+Financials!I21+Financials!I22+Financials!I23+Financials!I24+Financials!I27))/Financials!I$17 -> 0.25713428 | I9: =(Financials!J17-(Financials!J19+Financials!J20+Financials!J21+Financials!J22+Financials!J23+Financials!J24+Financials!J27))/Financials!J$17 -> 0.2426101 | J9: =(Financials!K17-(Financials!K19+Financials!K20+Financials!K21+Financials!K22+Financials!K23+Financials!K24+Financials!K27))/Financials!K$17 -> 0.23696325 | K9: =(Financials!L17-(Financials!L19+Financials!L20+Financials!L21+Financials!L22+Financials!L23+Financials!L24+Financials!L27))/Financials!L$17 -> 0.23280985 | L9: =(Financials!M17-(Financials!M19+Financials!M20+Financials!M21+Financials!M22+Financials!M23+Financials!M24+Financials!M27))/Financials!M$17 -> 0.23034668 | M9: =(Financials!N17-(Financials!N19+Financials!N20+Financials!N21+Financials!N22+Financials!N23+Financials!N24+Financials!N27))/Financials!N$17 -> 0.22842748
B10: EBITDA margin | E10: =Financials!F30/Financials!F$17 -> 0.24294797 | F10: =Financials!G30/Financials!G$17 -> 0.22293735 | G10: =Financials!H30/Financials!H$17 -> 0.22722423 | H10: =Financials!I30/Financials!I$17 -> 0.22575185 | I10: =Financials!J30/Financials!J$17 -> 0.23365543 | J10: =Financials!K30/Financials!K$17 -> 0.2261837 | K10: =Financials!L30/Financials!L$17 -> 0.22081006 | L10: =Financials!M30/Financials!M$17 -> 0.21676164 | M10: =Financials!N30/Financials!N$17 -> 0.21339585
B11: EBIT margin | E11: =(Financials!F17-(Financials!F28-Financials!F25))/Financials!F17 -> 0.27099471 | F11: =(Financials!G17-(Financials!G28-Financials!G25))/Financials!G17 -> 0.25120427 | G11: =(Financials!H17-(Financials!H28-Financials!H25))/Financials!H17 -> 0.2567606 | H11: =(Financials!I17-(Financials!I28-Financials!I25))/Financials!I17 -> 0.25463713 | I11: =(Financials!J17-(Financials!J28-Financials!J25))/Financials!J17 -> 0.2426101 | J11: =(Financials!K17-(Financials!K28-Financials!K25))/Financials!K17 -> 0.23696325 | K11: =(Financials!L17-(Financials!L28-Financials!L25))/Financials!L17 -> 0.23280985 | L11: =(Financials!M17-(Financials!M28-Financials!M25))/Financials!M17 -> 0.23034668 | M11: =(Financials!N17-(Financials!N28-Financials!N25))/Financials!N17 -> 0.22842748
B12: Net profit margin | E12: =Financials!F34/Financials!F17 -> 0.178689 | F12: =Financials!G34/Financials!G17 -> 0.16129205 | G12: =Financials!H34/Financials!H17 -> 0.16572695 | H12: =Financials!I34/Financials!I17 -> 0.16057386 | I12: =Financials!J34/Financials!J17 -> 0.1635588 | J12: =Financials!K34/Financials!K17 -> 0.15832859 | K12: =Financials!L34/Financials!L17 -> 0.15456704 | L12: =Financials!M34/Financials!M17 -> 0.15173315 | M12: =Financials!N34/Financials!N17 -> 0.1493771
B13: ROE | E13: =Financials!F34/Financials!F79 -> 0.29241048 | F13: =Financials!G34/Financials!G79 -> 0.31806847 | G13: =Financials!H34/Financials!H79 -> 0.29671833 | H13: =Financials!I34/Financials!I79 -> 0.27805786 | I13: =Financials!J34/Financials!J79 -> 0.26471995 | J13: =Financials!K34/Financials!K79 -> 0.27490185 | K13: =Financials!L34/Financials!L79 -> 0.25846385 | L13: =Financials!M34/Financials!M79 -> 0.24798237 | M13: =Financials!N34/Financials!N79 -> 0.25813263
B14: ROA | E14: =Financials!F34/Financials!F73 -> 0.18786105 | F14: =Financials!G34/Financials!G73 -> 0.19161315 | G14: =Financials!H34/Financials!H73 -> 0.1904596 | H14: =Financials!I34/Financials!I73 -> 0.17964715 | I14: =Financials!J34/Financials!J73 -> 0.17445955 | J14: =Financials!K34/Financials!K73 -> 0.17771215 | K14: =Financials!L34/Financials!L73 -> 0.17008699 | L14: =Financials!M34/Financials!M73 -> 0.16525325 | M14: =Financials!N34/Financials!N73 -> 0.16960287
B15: ROCE | E15: =Financials!F30/(Financials!F73-Financials!F95) -> 0.35725303 | F15: =Financials!G30/(Financials!G73-Financials!G95) -> 0.38464735 | G15: =Financials!H30/(Financials!H73-Financials!H95) -> 0.36344173 | H15: =Financials!I30/(Financials!I73-Financials!I95) -> 0.35461515 | I15: =Financials!J30/(Financials!J73-Financials!J95) -> 0.34452036 | J15: =Financials!K30/(Financials!K73-Financials!K95) -> 0.35752474 | K15: =Financials!L30/(Financials!L73-Financials!L95) -> 0.33866298 | L15: =Financials!M30/(Financials!M73-Financials!M95) -> 0.32668171 | M15: =Financials!N30/(Financials!N73-Financials!N95) -> 0.33963643
B16: ROIC | E16: =(Financials!F30*(1-30%))/(Schedule!G72+Financials!F50) -> 0.6661715 | F16: =(Financials!G30*(1-30%))/(Schedule!H72+Financials!G50) -> 0.66825383 | G16: =(Financials!H30*(1-30%))/(Schedule!I72+Financials!H50) -> 0.65251379 | H16: =(Financials!I30*(1-30%))/(Schedule!J72+Financials!I50) -> 0.67898483 | I16: =(Financials!J30*(1-30%))/(Schedule!K72+Financials!J50) -> 0.6964309 | J16: =(Financials!K30*(1-30%))/(Schedule!L72+Financials!K50) -> 0.67620646 | K16: =(Financials!L30*(1-30%))/(Schedule!M72+Financials!L50) -> 0.66142084 | L16: =(Financials!M30*(1-30%))/(Schedule!N72+Financials!M50) -> 0.65123342 | M16: =(Financials!N30*(1-30%))/(Schedule!O72+Financials!N50) -> 0.64400866
A18: # | B18: Liquidity Ratios | E18: 44651 | F18: =EDATE(E18,12) -> 45016 | G18: =EDATE(F18,12) -> 45382 | H18: =EDATE(G18,12) -> 45747 | I18: =EDATE(H18,12) -> 46112 | J18: =EDATE(I18,12) -> 46477 | K18: =EDATE(J18,12) -> 46843 | L18: =EDATE(K18,12) -> 47208 | M18: =EDATE(L18,12) -> 47573
B19: Current ratio | E19: =Financials!F72/Financials!F95 -> 1.9993751 | F19: =Financials!G72/Financials!G95 -> 1.8088348 | G19: =Financials!H72/Financials!H95 -> 2.3053049 | H19: =Financials!I72/Financials!I95 -> 2.266021 | I19: =Financials!J72/Financials!J95 -> 2.4708038 | J19: =Financials!K72/Financials!K95 -> 2.3472251 | K19: =Financials!L72/Financials!L95 -> 2.4769219 | L19: =Financials!M72/Financials!M95 -> 2.5810461 | M19: =Financials!N72/Financials!N95 -> 2.5057457
B20: Quick ratio | E20: =Financials!F72/Financials!F95 -> 1.9993751 | F20: =Financials!G72/Financials!G95 -> 1.8088348 | G20: =Financials!H72/Financials!H95 -> 2.3053049 | H20: =Financials!I72/Financials!I95 -> 2.266021 | I20: =Financials!J72/Financials!J95 -> 2.4708038 | J20: =Financials!K72/Financials!K95 -> 2.3472251 | K20: =Financials!L72/Financials!L95 -> 2.4769219 | L20: =Financials!M72/Financials!M95 -> 2.5810461 | M20: =Financials!N72/Financials!N95 -> 2.5057457
B21: Cash ratio | E21: =(Financials!G67+Financials!G65)/Financials!F95 -> 0.56786596 | F21: =(Financials!H67+Financials!H65)/Financials!G95 -> 0.70691063 | G21: =(Financials!I67+Financials!I65)/Financials!H95 -> 0.95213177 | H21: =(Financials!J67+Financials!J65)/Financials!I95 -> 1.1358465 | I21: =(Financials!K67+Financials!K65)/Financials!J95 -> 1.0073666 | J21: =(Financials!L67+Financials!L65)/Financials!K95 -> 1.142815 | K21: =(Financials!M67+Financials!M65)/Financials!L95 -> 1.2488149 | L21: =(Financials!N67+Financials!N65)/Financials!M95 -> 1.1637613 | M21: =(Financials!O67+Financials!O65)/Financials!N95 -> 0
B22: Operating cash flow ratio | E22: - | F22: - | G22: - | H22: - | I22: =Financials!J116/Financials!J95 -> 0.66149983 | J22: =Financials!K116/Financials!K95 -> 0.63409623 | K22: =Financials!L116/Financials!L95 -> 0.6242189 | L22: =Financials!M116/Financials!M95 -> 0.62030861 | M22: =Financials!N116/Financials!N95 -> 0.61995489
B23: Net working capital | E23: =Financials!F72-Financials!F95 -> 33582 | F23: =Financials!G72-Financials!G95 -> 31695 | G23: =Financials!H72-Financials!H95 -> 50638 | H23: =Financials!I72-Financials!I95 -> 54249 | I23: =Financials!J72-Financials!J95 -> 66182.063 | J23: =Financials!K72-Financials!K95 -> 63847.216 | K23: =Financials!L72-Financials!L95 -> 73937.89 | L23: =Financials!M72-Financials!M95 -> 83859.849 | M23: =Financials!N72-Financials!N95 -> 84868.145
B24: NWC as a % of revenue | E24: =E23/Financials!F17 -> 0.27096243 | F24: =F23/Financials!G17 -> 0.21205208 | G24: =G23/Financials!H17 -> 0.31972269 | H24: =H23/Financials!I17 -> 0.3256438 | I24: =I23/Financials!J17 -> 0.38139711 | J24: =J23/Financials!K17 -> 0.34797385 | K24: =K23/Financials!L17 -> 0.37919613 | L24: =L23/Financials!M17 -> 0.40262934 | M24: =M23/Financials!N17 -> 0.38010975
A26: # | B26: Efficiency Ratios | E26: 44651 | F26: =EDATE(E26,12) -> 45016 | G26: =EDATE(F26,12) -> 45382 | H26: =EDATE(G26,12) -> 45747 | I26: =EDATE(H26,12) -> 46112 | J26: =EDATE(I26,12) -> 46477 | K26: =EDATE(J26,12) -> 46843 | L26: =EDATE(K26,12) -> 47208 | M26: =EDATE(L26,12) -> 47573
B27: Asset turnover | E27: =Financials!F17/Financials!F73 -> 1.0513297 | F27: =Financials!G17/Financials!G73 -> 1.1879888 | G27: =Financials!H17/Financials!H73 -> 1.1492374 | H27: =Financials!I17/Financials!I73 -> 1.118782 | I27: =Financials!J17/Financials!J73 -> 1.0666473 | J27: =Financials!K17/Financials!K73 -> 1.1224262 | K27: =Financials!L17/Financials!L73 -> 1.1004092 | L27: =Financials!M17/Financials!M73 -> 1.0891045 | M27: =Financials!N17/Financials!N73 -> 1.1354008
B28: Fixed asset turnover | E28: =Financials!F17/Financials!F50 -> 9.4788528 | F28: =Financials!G17/Financials!G50 -> 11.199461 | G28: =Financials!H17/Financials!H50 -> 12.803638 | H28: =Financials!I17/Financials!I50 -> 14.144167 | I28: =Financials!J17/Financials!J50 -> 13.623244 | J28: =Financials!K17/Financials!K50 -> 13.716631 | K28: =Financials!L17/Financials!L50 -> 13.772596 | L28: =Financials!M17/Financials!M50 -> 13.887284 | M28: =Financials!N17/Financials!N50 -> 14.076893
