Workbook

Sheet IT_Comps
B2: IT - Software | Sector Comps - Relative Value Analysis
B3: (Figures in Rs. Cr., except price per share, shares outstanding, and other ratios)
B6: IT - Software Companies (Ranked in order of Market Cap in Rs. Cr)
B8: S.No. | C8: Name | D8: # Ticker | E8: CMP | F8: No. Eq. Shares Cr. | G8: Equity Value | H8: Debt | I8: Cash | J8: Enterprise Value | K8: Revenue | L8: EBITDA | M8: EBIT | N8: Net Income | O8: Book Value
B10: 1 | C10: ='Data Sheet'!B4 -> TCS | D10: TCS | E10: ='Data Sheet'!C4 -> 2488.4 | F10: ='Data Sheet'!D4 -> 361.81 | G10: =E10*F10 -> 900328 | H10: ='Data Sheet'!E4 -> 10932 | I10: ='Data Sheet'!F4 -> 15463 | J10: =G10+H10-I10 -> 895797 | K10: ='Data Sheet'!H4 -> 260802 | L10: ='Data Sheet'!I4+'Data Sheet'!J4 -> 74775 | M10: ='Data Sheet'!I4 -> 69242 | N10: ='Data Sheet'!K4 -> 47963 | O10: ='Data Sheet'!N4 -> 294.12
B11: 2 | C11: ='Data Sheet'!B5 -> Infosys | D11: INFY | E11: ='Data Sheet'!C5 -> 1284.7 | F11: ='Data Sheet'!D5 -> 405.54 | G11: =E11*F11 -> 520997.24 | H11: ='Data Sheet'!E5 -> 8796 | I11: ='Data Sheet'!F5 -> 24455 | J11: =G11+H11-I11 -> 505338.24 | K11: ='Data Sheet'!H5 -> 173173 | L11: ='Data Sheet'!I5+'Data Sheet'!J5 -> 45339 | M11: ='Data Sheet'!I5 -> 40563 | N11: ='Data Sheet'!K5 -> 28003 | O11: ='Data Sheet'!N5 -> 204.77
B12: 3 | C12: ='Data Sheet'!B6 -> HCL Technologies | D12: HCLTECH | E12: ='Data Sheet'!C6 -> 1359.45 | F12: ='Data Sheet'!D6 -> 271.37 | G12: =E12*F12 -> 368913.95 | H12: ='Data Sheet'!E6 -> 6780 | I12: ='Data Sheet'!F6 -> 21289 | J12: =G12+H12-I12 -> 354404.95 | K12: ='Data Sheet'!H6 -> 126409 | L12: ='Data Sheet'!I6+'Data Sheet'!J6 -> 28179 | M12: ='Data Sheet'!I6 -> 23876 | N12: ='Data Sheet'!K6 -> 16471 | O12: ='Data Sheet'!N6 -> 262.56
B13: 4 | C13: ='Data Sheet'!B7 -> Wipro | D13: WIPRO | E13: ='Data Sheet'!C7 -> 203.35 | F13: ='Data Sheet'!D7 -> 1048.8 | G13: =E13*F13 -> 213273.48 | H13: ='Data Sheet'!E7 -> 16163.7 | I13: ='Data Sheet'!F7 -> 12197.4 | J13: =G13+H13-I13 -> 217239.78 | K13: ='Data Sheet'!H7 -> 90891.9 | L13: ='Data Sheet'!I7+'Data Sheet'!J7 -> 21785.8 | M13: ='Data Sheet'!I7 -> 18881.9 | N13: ='Data Sheet'!K7 -> 13332 | O13: ='Data Sheet'!N7 -> 81.61
B14: 5 | C14: ='Data Sheet'!B8 -> Tech Mahindra | D14: TECHM | E14: ='Data Sheet'!C8 -> 1346.2 | F14: ='Data Sheet'!D8 -> 97.98 | G14: =E14*F14 -> 131900.68 | H14: ='Data Sheet'!E8 -> 1954.4 | I14: ='Data Sheet'!F8 -> 4542.2 | J14: =G14+H14-I14 -> 129312.88 | K14: ='Data Sheet'!H8 -> 55123.3 | L14: ='Data Sheet'!I8+'Data Sheet'!J8 -> 8715.6 | M14: ='Data Sheet'!I8 -> 6853 | N14: ='Data Sheet'!K8 -> 4591 | O14: ='Data Sheet'!N8 -> 280.73
B15: 6 | C15: ='Data Sheet'!B9 -> LTIMindtree | D15: LTM | E15: ='Data Sheet'!C9 -> 4303.6 | F15: ='Data Sheet'!D9 -> 29.65 | G15: =E15*F15 -> 127601.74 | H15: ='Data Sheet'!E9 -> 2382.6 | I15: ='Data Sheet'!F9 -> 3588.2 | J15: =G15+H15-I15 -> 126396.14 | K15: ='Data Sheet'!H9 -> 40787.6 | L15: ='Data Sheet'!I9+'Data Sheet'!J9 -> 8349.3 | M15: ='Data Sheet'!I9 -> 7308 | N15: ='Data Sheet'!K9 -> 4724 | O15: ='Data Sheet'!N9 -> 789.34
B16: 7 | C16: ='Data Sheet'!B10 -> Persistent Systems | D16: PERSISTENT | E16: ='Data Sheet'!C10 -> 4789.3 | F16: ='Data Sheet'!D10 -> 15.78 | G16: =E16*F16 -> 75575.154 | H16: ='Data Sheet'!E10 -> 403.94 | I16: ='Data Sheet'!F10 -> 1025.47 | J16: =G16+H16-I16 -> 74953.624 | K16: ='Data Sheet'!H10 -> 13934.63 | L16: ='Data Sheet'!I10+'Data Sheet'!J10 -> 2777.44 | M16: ='Data Sheet'!I10 -> 2403.93 | N16: ='Data Sheet'!K10 -> 1731.62 | O16: ='Data Sheet'!N10 -> 453.09
B17: 8 | C17: ='Data Sheet'!B11 -> Oracle Fin.Serv. | D17: OFSLL | E17: ='Data Sheet'!C11 -> 6764.5 | F17: ='Data Sheet'!D11 -> 8.7 | G17: =E17*F17 -> 58851.15 | H17: ='Data Sheet'!E11 -> 34 | I17: ='Data Sheet'!F11 -> 5951.4 | J17: =G17+H17-I17 -> 52933.75 | K17: ='Data Sheet'!H11 -> 7323.2 | L17: ='Data Sheet'!I11+'Data Sheet'!J11 -> 3467 | M17: ='Data Sheet'!I11 -> 3400.1 | N17: ='Data Sheet'!K11 -> 2441.5 | O17: ='Data Sheet'!N11 -> 846.77
B18: 9 | C18: ='Data Sheet'!B12 -> Mphasis | D18: MPHASIS | E18: ='Data Sheet'!C12 -> 2199.35 | F18: ='Data Sheet'!D12 -> 19.07 | G18: =E18*F18 -> 41941.605 | H18: ='Data Sheet'!E12 -> 1979.03 | I18: ='Data Sheet'!F12 -> 1612.58 | J18: =G18+H18-I18 -> 42308.054 | K18: ='Data Sheet'!H12 -> 15347.02 | L18: ='Data Sheet'!I12+'Data Sheet'!J12 -> 3155.15 | M18: ='Data Sheet'!I12 -> 2617.33 | N18: ='Data Sheet'!K12 -> 1799.45 | O18: ='Data Sheet'!N12 -> 504.96
B19: 10 | C19: ='Data Sheet'!B13 -> Coforge | D19: COFORGE | E19: ='Data Sheet'!C13 -> 1123.35 | F19: ='Data Sheet'!D13 -> 33.58 | G19: =E19*F19 -> 37722.093 | H19: ='Data Sheet'!E13 -> 971.5 | I19: ='Data Sheet'!F13 -> 883.2 | J19: =G19+H19-I19 -> 37810.393 | K19: ='Data Sheet'!H13 -> 15272.3 | L19: ='Data Sheet'!I13+'Data Sheet'!J13 -> 2669.1 | M19: ='Data Sheet'!I13 -> 2041.8 | N19: ='Data Sheet'!K13 -> 1385.8 | O19: ='Data Sheet'!N13 -> 205.79
B21: 1. Multiples Ratio
B23: S.No. | C23: Name | D23: EV/Revenue | E23: EV/EBITDA | F23: P/E | G23: P/BV | H23: EV/EBIT | I23: ROE % | J23: Dividend Yield % | K23: FCF Yield %
B25: 1 | C25: =C10 -> TCS | D25: =J10/K10 -> 3.4347781 | E25: =J10/L10 -> 11.9799 | F25: =E10/(N10/F10) -> 18.771303 | G25: =E10/O10 -> 8.4604923 | H25: =J10/M10 -> 12.937191 | I25: ='Data Sheet'!G28 -> 52.38 | J25: ='Data Sheet'!P4/10 -> 0.24 | K25: ='Data Sheet'!O4/J10 -> 0.050227897
B26: 2 | C26: =C11 -> Infosys | D26: =J11/K11 -> 2.9181122 | E26: =J11/L11 -> 11.145774 | F26: =E11/(N11/F11) -> 18.605051 | G26: =E11/O11 -> 6.2738682 | H26: =J11/M11 -> 12.458108 | I26: ='Data Sheet'!G29 -> 28.83 | J26: ='Data Sheet'!P5/10 -> 0.334 | K26: ='Data Sheet'!O5/J11 -> 0.066207141
B27: 3 | C27: =C12 -> HCL Technologies | D27: =J12/K12 -> 2.803637 | E27: =J12/L12 -> 12.576917 | F27: =E12/(N12/F12) -> 22.397787 | G27: =E12/O12 -> 5.1776737 | H27: =J12/M12 -> 14.843565 | I27: ='Data Sheet'!G30 -> 25 | J27: ='Data Sheet'!P6/10 -> 0.395 | K27: ='Data Sheet'!O6/J12 -> 0.059756502
B28: 4 | C28: =C13 -> Wipro | D28: =J13/K13 -> 2.3900895 | E28: =J13/L13 -> 9.9716228 | F28: =E13/(N13/F13) -> 15.997111 | G28: =E13/O13 -> 2.491729 | H28: =J13/M13 -> 11.505186 | I28: ='Data Sheet'!G31 -> 16.59 | J28: ='Data Sheet'!P7/10 -> 0.541 | K28: ='Data Sheet'!O7/J13 -> 0.072045276
B29: 5 | C29: =C14 -> Tech Mahindra | D29: =J14/K14 -> 2.3458842 | E29: =J14/L14 -> 14.836945 | F29: =E14/(N14/F14) -> 28.730271 | G29: =E14/O14 -> 4.795355 | H29: =J14/M14 -> 18.869528 | I29: ='Data Sheet'!G32 -> 14.62 | J29: ='Data Sheet'!P8/10 -> 0.337 | K29: ='Data Sheet'!O8/J14 -> 0.041007517
B30: 6 | C30: =C15 -> LTIMindtree | D30: =J15/K15 -> 3.0988864 | E30: =J15/L15 -> 15.138531 | F30: =E15/(N15/F15) -> 27.011376 | G30: =E15/O15 -> 5.4521499 | H30: =J15/M15 -> 17.295586 | I30: ='Data Sheet'!G33 -> 21.53 | J30: ='Data Sheet'!P9/10 -> 0.15 | K30: ='Data Sheet'!O9/J15 -> 0.028578404
B31: 7 | C31: =C16 -> Persistent Systems | D31: =J16/K16 -> 5.3789461 | E31: =J16/L16 -> 26.986586 | F31: =E16/(N16/F16) -> 43.644191 | G31: =E16/O16 -> 10.570306 | H31: =J16/M16 -> 31.17962 | I31: ='Data Sheet'!G34 -> 24.08 | J31: ='Data Sheet'!P10/10 -> 0.071 | K31: ='Data Sheet'!O10/J16 -> 0.012859151
B32: 8 | C32: =C17 -> Oracle Fin.Serv. | D32: =J17/K17 -> 7.2282267 | E32: =J17/L17 -> 15.267883 | F32: =E17/(N17/F17) -> 24.104505 | G32: =E17/O17 -> 7.9885919 | H32: =J17/M17 -> 15.568292 | I32: ='Data Sheet'!G35 -> 29.34 | J32: ='Data Sheet'!P11/10 -> 0.389 | K32: ='Data Sheet'!O11/J17 -> 0.040886958
B33: 9 | C33: =C18 -> Mphasis | D33: =J18/K18 -> 2.7567602 | E33: =J18/L18 -> 13.409205 | F33: =E18/(N18/F18) -> 23.308013 | G33: =E18/O18 -> 4.3554935 | H33: =J18/M18 -> 16.164585 | I33: ='Data Sheet'!G36 -> 18.22 | J33: ='Data Sheet'!P12/10 -> 0.255 | K33: ='Data Sheet'!O12/J18 -> 0.043616518
B34: 10 | C34: =C19 -> Coforge | D34: =J19/K19 -> 2.4757498 | E34: =J19/L19 -> 14.165971 | F34: =E19/(N19/F19) -> 27.220445 | G34: =E19/O19 -> 5.4587201 | H34: =J19/M19 -> 18.518167 | I34: ='Data Sheet'!G37 -> 15.98 | J34: ='Data Sheet'!P13/10 -> 0.135 | K34: ='Data Sheet'!O13/J19 -> 0.017981828
C36: Maximum | D36: =MAX(D25:D34) -> 7.2282267 | E36: =MAX(E25:E34) -> 26.986586 | F36: =MAX(F25:F34) -> 43.644191 | G36: =MAX(G25:G34) -> 10.570306 | H36: =MAX(H25:H34) -> 31.17962 | I36: =MAX(I25:I34)/100 -> 0.5238 | J36: =MAX(J25:J34) -> 0.541 | K36: =MAX(K25:K34) -> 0.072045276
C37: 75th Percentile | D37: =QUARTILE(D25:D34,3) -> 3.3508052 | E37: =QUARTILE(E25:E34,3) -> 15.063135 | F37: =QUARTILE(F25:F34,3) -> 27.168178 | G37: =QUARTILE(G25:G34,3) -> 7.559911 | H37: =QUARTILE(H25:H34,3) -> 18.212522 | I37: =QUARTILE(I25:I34,3)/100 -> 0.278725 | J37: =QUARTILE(J25:J34,3) -> 0.376 | K37: =QUARTILE(K25:K34,3) -> 0.057374351
C38: Average | D38: =AVERAGE(D25:D34) -> 3.483107 | E38: =AVERAGE(E25:E34) -> 14.547934 | F38: =AVERAGE(F25:F34) -> 24.979005 | G38: =AVERAGE(G25:G34) -> 6.102438 | H38: =AVERAGE(H25:H34) -> 16.933983 | I38: =AVERAGE(I25:I34)/100 -> 0.24657 | J38: =AVERAGE(J25:J34) -> 0.2847 | K38: =AVERAGE(K25:K34) -> 0.043316719
C39: Median | D39: =MEDIAN(D25:D34) -> 2.8608746 | E39: =MEDIAN(E25:E34) -> 13.787588 | F39: =MEDIAN(F25:F34) -> 23.706259 | G39: =MEDIAN(G25:G34) -> 5.455435 | H39: =MEDIAN(H25:H34) -> 15.866439 | I39: =MEDIAN(I25:I34)/100 -> 0.22805 | J39: =MEDIAN(J25:J34) -> 0.2945 | K39: =MEDIAN(K25:K34) -> 0.042312017
C40: 25th Percentile | D40: =QUARTILE(D25:D34,1) -> 2.5460024 | E40: =QUARTILE(E25:E34,1) -> 12.129154 | F40: =QUARTILE(F25:F34,1) -> 19.677924 | G40: =QUARTILE(G25:G34,1) -> 4.8909346 | H40: =QUARTILE(H25:H34,1) -> 13.413785 | I40: =QUARTILE(I25:I34,1)/100 -> 0.169975 | J40: =QUARTILE(J25:J34,1) -> 0.1725 | K40: =QUARTILE(K25:K34,1) -> 0.031655543
C41: Minimum | D41: =MIN(D25:D34) -> 2.3458842 | E41: =MIN(E25:E34) -> 9.9716228 | F41: =MIN(F25:F34) -> 15.997111 | G41: =MIN(G25:G34) -> 2.491729 | H41: =MIN(H25:H34) -> 11.505186 | I41: =MIN(I25:I34)/100 -> 0.1462 | J41: =MIN(J25:J34) -> 0.071 | K41: =MIN(K25:K34) -> 0.012859151
B43: 2. Quality & Momentum Signals
B45: S.No. | C45: Name | D45: Sales CAGR 3Yrs % | E45: Profit CAGR 3Yrs % | F45: Return 3Yrs% | G45: ROE 3Yr % | H45: ROCE 3Yr % | I45: Debt / Equity | J45: Int Coverage
B47: 1 | C47: =C10 -> TCS | D47: ='Data Sheet'!G16/100 -> 0.1001 | E47: ='Data Sheet'!H16/100 -> 0.0819 | F47: ='Data Sheet'!I16/100 -> -0.0896 | G47: ='Data Sheet'!J16/100 -> 0.503 | H47: ='Data Sheet'!L16/100 -> 0.6252 | I47: ='Data Sheet'!K16 -> 0.1 | J47: ='Data Sheet'!M16 -> 58.24
B48: 2 | C48: =C11 -> Infosys | D48: ='Data Sheet'!G17/100 -> 0.1025 | E48: ='Data Sheet'!H17/100 -> 0.0645 | F48: ='Data Sheet'!I17/100 -> -0.0416 | G48: ='Data Sheet'!J17/100 -> 0.3072 | H48: ='Data Sheet'!L17/100 -> 0.3932 | I48: ='Data Sheet'!K17 -> 0.11 | J48: ='Data Sheet'!M17 -> 98.22
B49: 3 | C49: =C12 -> HCL Technologies | D49: ='Data Sheet'!G18/100 -> 0.1097 | E49: ='Data Sheet'!H18/100 -> 0.0875 | F49: ='Data Sheet'!I18/100 -> 0.0684 | G49: ='Data Sheet'!J18/100 -> 0.238 | H49: ='Data Sheet'!L18/100 -> 0.2982 | I49: ='Data Sheet'!K18 -> 0.1 | J49: ='Data Sheet'!M18 -> 30.42
B50: 4 | C50: =C13 -> Wipro | D50: ='Data Sheet'!G19/100 -> 0.0395 | E50: ='Data Sheet'!H19/100 -> 0.0229 | F50: ='Data Sheet'!I19/100 -> 0.0108 | G50: ='Data Sheet'!J19/100 -> 0.1558 | H50: ='Data Sheet'!L19/100 -> 0.1803 | I50: ='Data Sheet'!K19 -> 0.19 | J50: ='Data Sheet'!M19 -> 12.89
B51: 5 | C51: =C14 -> Tech Mahindra | D51: ='Data Sheet'!G20/100 -> 0.0588 | E51: ='Data Sheet'!H20/100 -> -0.1077 | F51: ='Data Sheet'!I20/100 -> 0.0799 | G51: ='Data Sheet'!J20/100 -> 0.1363 | H51: ='Data Sheet'!L20/100 -> 0.1753 | I51: ='Data Sheet'!K20 -> 0.07 | J51: ='Data Sheet'!M20 -> 20.52
B52: 6 | C52: =C15 -> LTIMindtree | D52: ='Data Sheet'!G21/100 -> 0.1333 | E52: ='Data Sheet'!H21/100 -> 0.0521 | F52: ='Data Sheet'!I21/100 -> -0.0233 | G52: ='Data Sheet'!J21/100 -> 0.2466 | H52: ='Data Sheet'!L21/100 -> 0.3249 | I52: ='Data Sheet'!K21 -> 0.1 | J52: ='Data Sheet'!M21 -> 26.26
...

Sheet Charts
B2: IT - Software | Sector Comps - Relative Value Analysis
B3: (Figures in Rs. Cr., except price per share, shares outstanding, and other ratios)
B6: 1. Sector Summary

Sheet Data Sheet
A1: Indian IT-Software
A3: S.No. | B3: Name | C3: CMP Rs. | D3: No. Eq. Shares Cr. | E3: Debt Rs.Cr. | F3: Cash End Rs.Cr. | G3: EV Rs.Cr. | H3: Sales Rs.Cr. | I3: EBIT 12M Rs.Cr. | J3: Dep 12M Rs.Cr. | K3: NP 12M Rs.Cr. | L3: P/E | M3: OPM % | N3: B.V. Rs. | O3: Free Cash Flow Rs.Cr. | P3: Div Yld %
A4: 1 | B4: TCS | C4: 2488.4 | D4: 361.81 | E4: 10932 | F4: 15463 | G4: 896803.87 | H4: 260802 | I4: 69242 | J4: 5533 | K4: 47963 | L4: 17.6 | M4: 26.88 | N4: 294.12 | O4: 44994 | P4: 2.4
A5: 2 | B5: Infosys | C5: 1284.7 | D5: 405.54 | E5: 8796 | F5: 24455 | G5: 509877.1 | H5: 173173 | I5: 40563 | J5: 4776 | K5: 28003 | L5: 18.02 | M5: 23.67 | N5: 204.77 | O5: 33457 | P5: 3.34
A6: 3 | B6: HCL Technologies | C6: 1359.45 | D6: 271.37 | E6: 6780 | F6: 21289 | G6: 351941.21 | H6: 126409 | I6: 23876 | J6: 4303 | K6: 16471 | L6: 21.48 | M6: 20.94 | N6: 262.56 | O6: 21178 | P6: 3.95
A7: 4 | B7: Wipro | C7: 203.35 | D7: 1048.8 | E7: 16163.7 | F7: 12197.4 | G7: 216354.45 | H7: 90891.9 | I7: 18881.9 | J7: 2903.9 | K7: 13332 | L7: 16.07 | M7: 19.28 | N7: 81.61 | O7: 15651.1 | P7: 5.41
A8: 5 | B8: Tech Mahindra | C8: 1346.2 | D8: 97.98 | E8: 1954.4 | F8: 4542.2 | G8: 129565.74 | H8: 55123.3 | I8: 6853 | J8: 1862.6 | K8: 4591 | L8: 27.4 | M8: 15.07 | N8: 280.73 | O8: 5302.8 | P8: 3.37
A9: 6 | B9: LTIMindtree | C9: 4303.6 | D9: 29.65 | E9: 2382.6 | F9: 3588.2 | G9: 126996.05 | H9: 40787.6 | I9: 7308 | J9: 1041.3 | K9: 4724 | L9: 24.61 | M9: 17.6 | N9: 789.34 | O9: 3612.2 | P9: 1.5
A10: 7 | B10: Persistent Systems | C10: 4789.3 | D10: 15.78 | E10: 403.94 | F10: 1025.47 | G10: 74751.83 | H10: 13934.63 | I10: 2403.93 | J10: 373.51 | K10: 1731.62 | L10: 42.04 | M10: 18.75 | N10: 453.09 | O10: 963.84 | P10: 0.71
A11: 8 | B11: Oracle Fin.Serv. | C11: 6764.5 | D11: 8.7 | E11: 34 | F11: 5951.4 | G11: 54061.87 | H11: 7323.2 | I11: 3400.1 | J11: 66.9 | K11: 2441.5 | L11: 24.11 | M11: 43.5 | N11: 846.77 | O11: 2164.3 | P11: 3.89
A12: 9 | B12: Mphasis | C12: 2199.35 | D12: 19.07 | E12: 1979.03 | F12: 1612.58 | G12: 42297.76 | H12: 15347.02 | I12: 2617.33 | J12: 537.82 | K12: 1799.45 | L12: 22.99 | M12: 18.75 | N12: 504.96 | O12: 1845.33 | P12: 2.55
A13: 10 | B13: Coforge | C13: 1123.35 | D13: 33.58 | E13: 971.5 | F13: 883.2 | G13: 38161.22 | H13: 15272.3 | I13: 2041.8 | J13: 627.3 | K13: 1385.8 | L13: 30.02 | M13: 16.81 | N13: 205.79 | O13: 679.9 | P13: 1.35
A15: S.No. | B15: Name | C15: CMP Rs. | D15: No. Eq. Shares Cr. | E15: Sales Rs.Cr. | F15: NP 12M Rs.Cr. | G15: Sales Var 3Yrs % | H15: Profit Var 3Yrs % | I15: 3Yrs return % | J15: ROE 3Yr % | K15: Debt / Eq | L15: ROCE 3Yr % | M15: Int Coverage
A16: 1 | B16: TCS | C16: 2483.95 | D16: 361.81 | E16: 260802 | F16: 47963 | G16: 10.01 | H16: 8.19 | I16: -8.96 | J16: 50.3 | K16: 0.1 | L16: 62.52 | M16: 58.24
A17: 2 | B17: Infosys | C17: 1283.7 | D17: 405.54 | E17: 173173 | F17: 28003 | G17: 10.25 | H17: 6.45 | I17: -4.16 | J17: 30.72 | K17: 0.11 | L17: 39.32 | M17: 98.22
A18: 3 | B18: HCL Technologies | C18: 1361 | D18: 271.37 | E18: 126409 | F18: 16471 | G18: 10.97 | H18: 8.75 | I18: 6.84 | J18: 23.8 | K18: 0.1 | L18: 29.82 | M18: 30.42
A19: 4 | B19: Wipro | C19: 203.3 | D19: 1048.8 | E19: 90891.9 | F19: 13332 | G19: 3.95 | H19: 2.29 | I19: 1.08 | J19: 15.58 | K19: 0.19 | L19: 18.03 | M19: 12.89
A20: 5 | B20: Tech Mahindra | C20: 1346.9 | D20: 97.98 | E20: 55123.3 | F20: 4591 | G20: 5.88 | H20: -10.77 | I20: 7.99 | J20: 13.63 | K20: 0.07 | L20: 17.53 | M20: 20.52
A21: 6 | B21: LTIMindtree | C21: 4303.7 | D21: 29.65 | E21: 40787.6 | F21: 4724 | G21: 13.33 | H21: 5.21 | I21: -2.33 | J21: 24.66 | K21: 0.1 | L21: 32.49 | M21: 26.26
A22: 7 | B22: Persistent Systems | C22: 4774.4 | D22: 15.78 | E22: 13934.63 | F22: 1731.62 | G22: 27.87 | H22: 27 | I22: 26.68 | J22: 24.38 | K22: 0.06 | L22: 29.97 | M22: 33.18
A23: 8 | B23: Oracle Fin.Serv. | C23: 6769.95 | D23: 8.7 | E23: 7323.2 | F23: 2441.5 | G23: 9.45 | H23: 8 | I23: 28.15 | J23: 27.79 | K23: 0 | L23: 38.42 | M23: 30.91
A24: 9 | B24: Mphasis | C24: 2184.6 | D24: 19.07 | E24: 15347.02 | F24: 1799.45 | G24: 5.96 | H24: 5.66 | I24: 2.6 | J24: 19.38 | K24: 0.21 | L24: 25.19 | M24: 16.08
A25: 10 | B25: Coforge | C25: 1120 | D25: 33.58 | E25: 15272.3 | F25: 1385.8 | G25: 23.28 | H25: 6.53 | I25: 11.25 | J25: 20.87 | K25: 0.14 | L25: 26.78 | M25: 12.13
A27: S.No. | B27: Name | C27: CMP Rs. | D27: Avg EBIT 5Yrs Rs.Cr. | E27: Sales Var 5Yrs % | F27: 5Yr OPM % | G27: ROE %
A28: 1 | B28: TCS | C28: 2465.15 | D28: 57099 | E28: 10.22 | F28: 26.96 | G28: 52.38
A29: 2 | B29: Infosys | C29: 1276.35 | D29: 32849.2 | E29: 12.41 | F29: 24.82 | G29: 28.83
A30: 3 | B30: HCL Technologies | C30: 1352 | D30: 19585.6 | E30: 10.62 | F30: 23.07 | G30: 25
A31: 4 | B31: Wipro | C31: 202.1 | D31: 16106.12 | E31: 7.82 | F31: 20.23 | G31: 16.59
A32: 5 | B32: Tech Mahindra | C32: 1333.95 | D32: 5927.24 | E32: 7.52 | F32: 14.14 | G32: 14.62
A33: 6 | B33: LTIMindtree | C33: 4265 | D33: 5357.94 | E33: 28.43 | F33: 18.57 | G33: 21.53
A34: 7 | B34: Persistent Systems | C34: 4736.85 | D34: 1214.7 | E34: 27.34 | F34: 17.23 | G34: 24.08
A35: 8 | B35: Oracle Fin.Serv. | C35: 6777.15 | D35: 2796.25 | E35: 7.09 | F35: 45.66 | G35: 29.34
A36: 9 | B36: Mphasis | C36: 2184.35 | D36: 2106.16 | E36: 9.98 | F36: 18.13 | G36: 18.22
A37: 10 | B37: Coforge | C37: 1108.8 | D37: 1049.1 | E37: 23.56 | F37: 15.7 | G37: 15.98
