Workbook
Name days: Dashboard!$E$12
Name tgr: DCF!$E$15
Name tgrth1: DCF!$E$91
Name wacc: DCF!$E$14
Name wacc1: DCF!$E$90

Sheet Dashboard
C2: Lloyds Metal & Energy Ltd.
C3: Dashboard
C4: (₹ in 'Cr, except share price and shares outstanding)
B6: # | C6: Dashboard
C8: Company Name: | E8: =C2 -> Lloyds Metal & Energy Ltd.
C9: Ticker: | E9: LLOYDME
C10: Date: | E10: =TODAY() -> 46106
C11: Sector: | E11: Industrial Minerals
C12: Days: | E12: 365
C14: Scenario Selected: | E14: 1
B16: # | C16: Table of Content | H16: # | I16: Key Financial Metrices
C17: Sl No | E17: Particulars | I17: Valuation | K17: FY 25 A | L17: FY 26 E
C18: 1 | E18: Dashboard | I18: Current Price (₹) | K18: 1246 | L18: =K18 -> 1246
C19: 2 | E19: Summary | I19: Implied Price (₹) | K19: =DCF!G39 -> 922.84986 | L19: =DCF!G115 -> 1204.5544
C20: 3 | E20: Financials | I20: Premium / (Discount) | K20: =K19/K18-1 -> -0.25935003 | L20: =L19/L18-1 -> -0.033262906
C21: 4 | E21: Assuptions | I21: P/E (x) | K21: =K18/Financials!J41 -> 47.70291 | L21: =L18/Financials!K41 -> 21.920665
C22: 5 | E22: Schedule | I22: ROE % | K22: =Financials!J37/Financials!J77 -> 0.22647498 | L22: =Financials!K37/Financials!K77 -> 0.3349242
C23: 6 | E23: Company Comparables | I23: ROA % | K23: =Financials!J37/Financials!J72 -> 0.15396999 | L23: =Financials!K37/Financials!K72 -> 0.18320357
C24: 7 | E24: DCF | I24: ROCE % | K24: =Financials!J32/(Financials!J72-Financials!J96) -> 0.25964577 | L24: =Financials!K32/(Financials!K72-Financials!K96) -> 0.27443034
C25: 8 | E25: WACC | I25: EPS (₹) | K25: =Financials!J41 -> 26.12 | L25: =Financials!K41 -> 56.841342
C26: 9 | E26: Beta | I26: Annual Dividends (₹ in Cr.) | K26: =Assumptions!J81 -> 52.28 | L26: =Assumptions!K81 -> 315.63997
C27: 10 | E27: Ratio Analysis | I27: Dividend Yield % | K27: =K26/Financials!J37 -> 0.036057162 | L27: =L26/Financials!K37 -> 0.1
C28: 11 | E28: Analysis
B30: # | C30: End

Sheet Summary
C2: =Dashboard!C2 -> Lloyds Metal & Energy Ltd.
C3: Summary
C4: =Dashboard!C4 -> (₹ in 'Cr, except share price and shares outstanding)
C6: <-Back to Dashboard
B8: # | C8: Valuation
C10: Metrics | D10: DCF | E10: EV / Revenue | F10: EV / EBITDA | G10: P / Sales | H10: P / E | I10: 52 - wk range
C11: 75th Percentile | D11: =DCF!M45 -> 962.10736 | E11: =Comps!S31 -> 411.08173 | F11: =Comps!T31 -> 13.582106 | G11: =Comps!U31 -> 398.57591 | H11: =Comps!V31 -> 0.0088381485 | I11: =Comps!E40 -> 1302.2736
C12: Average | D12: =DCF!M46 -> 922.84986 | E12: =Comps!S32 -> 439.52696 | F12: =Comps!T32 -> 19.295346 | G12: =Comps!U32 -> 759.41962 | H12: =Comps!V32 -> 0.068709482 | I12: =Comps!E41 -> 1293.4
C13: Median | D13: =DCF!M47 -> 1341.0953 | E13: =Comps!S33 -> 383.2586 | F13: =Comps!T33 -> 9.3316268 | G13: =Comps!U33 -> 437.76768 | H13: =Comps!V33 -> 0.028283968 | I13: =Comps!E42 -> 1351.25
C14: 25th Percentile | D14: =DCF!M48 -> 392.24085 | E14: =Comps!S34 -> 657.6448 | F14: =Comps!T34 -> 30.366262 | G14: =Comps!U34 -> 920.74463 | H14: =Comps!V34 -> 0.065404875 | I14: =Comps!E43 -> 1226
B16: # | C16: Football Chart
C18: Metrics | D18: Min | E18: Median | F18: Max
C19: {=TRANSPOSE(D10:I10)} -> DCF | D19: {=TRANSPOSE(D14:I14)} -> 392.24085 | E19: {=TRANSPOSE(D12:I12)} -> 922.84986 | F19: {=TRANSPOSE(D11:I11)} -> 962.10736
C20: EV / Revenue | D20: 657.6448 | E20: 439.52696 | F20: 411.08173
C21: EV / EBITDA | D21: 30.366262 | E21: 19.295346 | F21: 13.582106
C22: P / Sales | D22: 920.74463 | E22: 759.41962 | F22: 398.57591
C23: P / E | D23: 0.065404875 | E23: 0.068709482 | F23: 0.0088381485
C24: 52 - wk range | D24: 1226 | E24: 1293.4 | F24: 1302.2736
B26: # | C26: End

Sheet Financials->

Sheet Financials
C2: =Dashboard!C2 -> Lloyds Metal & Energy Ltd.
C3: Financials
C4: =Dashboard!C4 -> (₹ in 'Cr, except share price and shares outstanding)
C5: Actuals / Projections | G5: Acutals | K5: Projections
C6: Date / Year | G6: 44651 | H6: =EOMONTH(G6,12) -> 45016 | I6: =EOMONTH(H6,12) -> 45382 | J6: =EOMONTH(I6,12) -> 45747 | K6: =EOMONTH(J6,12) -> 46112 | L6: =EOMONTH(K6,12) -> 46477 | M6: =EOMONTH(L6,12) -> 46843 | N6: =EOMONTH(M6,12) -> 47208 | O6: =EOMONTH(N6,12) -> 47573
C8: <-Back to Dashboard
C10: Templete: | D10: Standard | F10: Currency: | G10: INR
C11: Period type: | D11: Annual | F11: Units: | G11: Crore
C12: Source: | D12: Company Website | F12: Decimals: | G12: Default
B14: # | C14: Income Statement | G14: 44651 | H14: =EOMONTH(G14,12) -> 45016 | I14: =EOMONTH(H14,12) -> 45382 | J14: =EOMONTH(I14,12) -> 45747 | K14: =EOMONTH(J14,12) -> 46112 | L14: =EOMONTH(K14,12) -> 46477 | M14: =EOMONTH(L14,12) -> 46843 | N14: =EOMONTH(M14,12) -> 47208 | O14: =EOMONTH(N14,12) -> 47573 | Q14: Q3 2026
C16: Gross Sales From Operations | G16: 697.5 | H16: 3392.31 | I16: 6481.01 | J16: 6626.31 | K16: =Assumptions!K18 -> 14436.08 | L16: =Assumptions!L18 -> 18766.904 | M16: =Assumptions!M18 -> 23458.63 | N16: =Assumptions!N18 -> 28150.356 | O16: =Assumptions!O18 -> 33217.42 | Q16: 10827.06
C17: Gross Operating Revenues | G17: 0 | H17: 0 | I17: 43.64 | J17: 95.09 | K17: =Assumptions!K24 -> 354.52 | L17: =Assumptions!L24 -> 638.136 | M17: =Assumptions!M24 -> 1116.738 | N17: =Assumptions!N24 -> 1898.4546 | O17: =Assumptions!O24 -> 3189.4037 | Q17: 265.89
C18: Other Income | G18: 29.75 | H18: 74.46 | I18: 49.95 | J18: 51.22 | K18: =Assumptions!K30 -> 241.18667 | L18: =Assumptions!L30 -> 265.30533 | M18: =Assumptions!M30 -> 305.10113 | N18: =Assumptions!N30 -> 366.12136 | O18: =Assumptions!O30 -> 410.05592 | Q18: 180.89
C19: Total Income | G19: 727.25 | H19: 3466.77 | I19: 6574.6 | J19: 6772.62 | K19: =SUM(K16:K18) -> 15031.787 | L19: =SUM(L16:L18) -> 19670.345 | M19: =SUM(M16:M18) -> 24880.469 | N19: =SUM(N16:N18) -> 30414.932 | O19: =SUM(O16:O18) -> 36816.88 | Q19: =SUM(Q16:Q18) -> 11273.84
C21: Expenses:
C22: Cost Of Materials Consumed | G22: 373.27 | H22: 504.35 | I22: 536.62 | J22: 533.41 | K22: =Assumptions!K39 -> 1645.32 | L22: =Assumptions!L39 -> 2303.448 | M22: =Assumptions!M39 -> 3339.9996 | N22: =Assumptions!N39 -> 4943.1994 | O22: =Assumptions!O39 -> 7167.6391 | Q22: 1233.99
C23: Purchases Of Stock-In-Trade | G23: 0 | H23: 0 | I23: 370.23 | J23: 182.24 | K23: =Assumptions!K45 -> 624.34667 | L23: =Assumptions!L45 -> 780.43333 | M23: =Assumptions!M45 -> 959.933 | N23: =Assumptions!N45 -> 1161.5189 | O23: =Assumptions!O45 -> 1393.8227 | Q23: 468.26
C24: Changes In Inventories Of Finished Goods | G24: -60.4 | H24: 35.78 | I24: -14.89 | J24: 90.41 | K24: =Assumptions!K51 -> -302.57333 | L24: =Assumptions!L51 -> 121.02933 | M24: =Assumptions!M51 -> -181.544 | N24: =Assumptions!N51 -> 72.6176 | O24: =Assumptions!O51 -> -94.40288 | Q24: -226.93
C25: Employee Benefit Expenses | G25: 18.35 | H25: 54.26 | I25: 117.76 | J25: 163.27 | K25: =Assumptions!K57+Assumptions!K84 -> 1304.5814 | L25: =Assumptions!L57+Assumptions!L84 -> 1978.5541 | M25: =Assumptions!M57+Assumptions!M84 -> 2738.0796 | N25: =Assumptions!N57+Assumptions!N84 -> 3658.3231 | O25: =Assumptions!O57+Assumptions!O84 -> 4821.9499 | Q25: 843.15
C26: Finance Costs | G26: 18.14 | H26: 65.04 | I26: 5.68 | J26: 27.22 | K26: =Schedule!K63 -> 258.895 | L26: =Schedule!L63 -> 471.65881 | M26: =Schedule!M63 -> 543.96796 | N26: =Schedule!N63 -> 643.16421 | O26: =Schedule!O63 -> 746.14925 | Q26: 342.8
C27: Depreciation & Amotization Expenses | G27: 17.98 | H27: 23 | I27: 48.99 | J27: 80.8 | K27: =Schedule!K21+Schedule!K30 -> 481.01717 | L27: =Schedule!L21+Schedule!L30 -> 334.39587 | M27: =Schedule!M21+Schedule!M30 -> 380.67118 | N27: =Schedule!N21+Schedule!N30 -> 413.64307 | O27: =Schedule!O21+Schedule!O30 -> 438.12087 | Q27: 382.81
C28: Mining, Royalty And Freight Expenses | G28: 0 | H28: 0 | I28: 3239.77 | J28: 3323.96 | K28: =Assumptions!K63 -> 5380.72 | L28: =Assumptions!L63 -> 6994.936 | M28: =Assumptions!M63 -> 8813.6194 | N28: =Assumptions!N63 -> 10928.888 | O28: =Assumptions!O63 -> 13333.243 | Q28: 4035.54
C29: Other Expenses | G29: 220.74 | H29: 1987.62 | I29: 543.9 | J29: 475.2 | K29: =Assumptions!K69 -> 1523.2667 | L29: =Assumptions!L69 -> 1340.4747 | M29: =Assumptions!M69 -> 1742.6171 | N29: =Assumptions!N69 -> 2056.2881 | O29: =Assumptions!O69 -> 1439.4017 | Q29: 1142.45
C30: Total Expenses | G30: 588.08 | H30: 2670.05 | I30: 4848.06 | J30: 4876.51 | K30: =SUM(K22:K29) -> 10915.574 | L30: =SUM(L22:L29) -> 14324.93 | M30: =SUM(M22:M29) -> 18337.344 | N30: =SUM(N22:N29) -> 23877.642 | O30: =SUM(O22:O29) -> 29245.924 | Q30: =SUM(Q22:Q29) -> 8222.07
C32: Profit / (Loss) Before Execptional Items & Tax | G32: 139.17 | H32: 796.72 | I32: 1726.54 | J32: 1896.11 | K32: =K19-K30 -> 4116.2131 | L32: =L19-L30 -> 5345.4152 | M32: =M19-M30 -> 6543.1253 | N32: =N19-N30 -> 6537.2895 | O32: =O19-O30 -> 7570.9556 | Q32: =Q19-Q30 -> 3051.77
C33: Exceptional Items | G33: 51.36 | H33: 1194.4 | I33: 0 | J33: 0 | K33: =J33 -> 0 | L33: =K33 -> 0 | M33: =L33 -> 0 | N33: =M33 -> 0 | O33: =N33 -> 0 | Q33: -1.95
C34: Profit / (Loss) Before Tax | G34: 87.81 | H34: -397.68 | I34: 1726.54 | J34: 1896.11 | K34: =K32+K33 -> 4116.2131 | L34: =L32+L33 -> 5345.4152 | M34: =M32+M33 -> 6543.1253 | N34: =N32+N33 -> 6537.2895 | O34: =O32+O33 -> 7570.9556 | Q34: =SUM(Q32:Q33) -> 3049.82
C35: Current Tax | G35: 0 | H35: 0 | I35: -259.78 | J35: -456.72 | K35: =-Assumptions!K75 -> -959.81333 | L35: =-Assumptions!L75 -> -1247.7573 | M35: =-Assumptions!M75 -> -1622.0845 | N35: =-Assumptions!N75 -> -2108.7099 | O35: =-Assumptions!O75 -> -2741.3229 | Q35: -719.86
C36: Deferred Tax Income / (Expenses) | G36: 9.51 | H36: 109.14 | I36: -223.82 | J36: 10.53 | K36: 0 | L36: 0 | M36: 0 | N36: 0 | O36: 0 | Q36: -31.42
C37: Profit For The Period | G37: 97.32 | H37: -288.54 | I37: 1242.94 | J37: 1449.92 | K37: =K34+K35+K36 -> 3156.3997 | L37: =L34+L35+L36 -> 4097.6578 | M37: =M34+M35+M36 -> 4921.0408 | N37: =N34+N35+N36 -> 4428.5796 | O37: =O34+O35+O36 -> 4829.6328 | Q37: =SUM(Q34:Q36) -> 2298.54
C39: Earnings Per Share:
C40: Basic | G40: 2.85 | H40: -6.53 | I40: 24.62 | J40: 28.01 | K40: =K$37/K44 -> 60.969668 | L40: =L$37/L44 -> 79.151204 | M40: =M$37/M44 -> 95.055839 | N40: =N$37/N44 -> 85.543358 | O40: =O$37/O44 -> 93.290183
C41: Diluted | G41: 2.78 | H41: -4.74 | I41: 24.43 | J41: 26.12 | K41: =K$37/K45 -> 56.841342 | L41: =L$37/L45 -> 73.791785 | M41: =M$37/M45 -> 88.619499 | N41: =N$37/N45 -> 79.751119 | O41: =O$37/O45 -> 86.973398
C43: Shares Outstanding:
C44: Basic | G44: 34.08 | H44: 44.16 | I44: 50.49 | J44: 51.77 | K44: =J44 -> 51.77 | L44: =K44 -> 51.77 | M44: =L44 -> 51.77 | N44: =M44 -> 51.77 | O44: =N44 -> 51.77
C45: Diluted | G45: 35.56 | H45: 48.95 | I45: 50.88 | J45: 55.53 | K45: =J45 -> 55.53 | L45: =K45 -> 55.53 | M45: =L45 -> 55.53 | N45: =M45 -> 55.53 | O45: =N45 -> 55.53
B48: # | C48: Balance Sheet | G48: 44651 | H48: =EOMONTH(G48,12) -> 45016 | I48: =EOMONTH(H48,12) -> 45382 | J48: =EOMONTH(I48,12) -> 45747 | K48: =EOMONTH(J48,12) -> 46112 | L48: =EOMONTH(K48,12) -> 46477 | M48: =EOMONTH(L48,12) -> 46843 | N48: =EOMONTH(M48,12) -> 47208 | O48: =EOMONTH(N48,12) -> 47573
C50: Assets
C51: Non-Current Assets
C52: Property, Plant & Equipment | G52: 399.06 | H52: 474.6 | I52: 1156.75 | J52: 1531.51 | K52: =Schedule!K16 -> 5717.6577 | L52: =Schedule!L16 -> 6000.4735 | M52: =Schedule!M16 -> 6012.7312 | N52: =Schedule!N16 -> 5703.2095 | O52: =Schedule!O16 -> 5092.4224 | P52: x
...

Sheet Assumptions
C2: =Dashboard!C2 -> Lloyds Metal & Energy Ltd.
C3: Assumptions
C4: =Dashboard!C4 -> (₹ in 'Cr, except share price and shares outstanding)
C5: Actuals / Projections | G5: Acutals | K5: Projections
C6: Date / Year | G6: 44651 | H6: =EOMONTH(G6,12) -> 45016 | I6: =EOMONTH(H6,12) -> 45382 | J6: =EOMONTH(I6,12) -> 45747 | K6: =EOMONTH(J6,12) -> 46112 | L6: =EOMONTH(K6,12) -> 46477 | M6: =EOMONTH(L6,12) -> 46843 | N6: =EOMONTH(M6,12) -> 47208 | O6: =EOMONTH(N6,12) -> 47573
C8: <-Back to Dashboard
C10: Trigger
C12: Scenario | E12: =Dashboard!E14 -> 1
B15: # | C15: Assumptions | G15: 44651 | H15: =EOMONTH(G15,12) -> 45016 | I15: =EOMONTH(H15,12) -> 45382 | J15: =EOMONTH(I15,12) -> 45747 | K15: =EOMONTH(J15,12) -> 46112 | L15: =EOMONTH(K15,12) -> 46477 | M15: =EOMONTH(L15,12) -> 46843 | N15: =EOMONTH(M15,12) -> 47208 | O15: =EOMONTH(N15,12) -> 47573
C17: Revenue:
C18: Revenue from operations | G18: =Financials!G16 -> 697.5 | H18: =Financials!H16 -> 3392.31 | I18: =Financials!I16 -> 6481.01 | J18: =Financials!J16 -> 6626.31 | K18: =Financials!Q16*(4/3) -> 14436.08 | L18: =K18*(1+L19) -> 18766.904 | M18: =L18*(1+M19) -> 23458.63 | N18: =M18*(1+N19) -> 28150.356 | O18: =N18*(1+O19) -> 33217.42
C19: Growth % | H19: =H18/G18-1 -> 3.8635269 | I19: =I18/H18-1 -> 0.91050051 | J19: =J18/I18-1 -> 0.022419345 | K19: =K18/J18-1 -> 1.1786002 | L19: =OFFSET(L19,$E$12,0) -> 0.3 | M19: =OFFSET(M19,$E$12,0) -> 0.25 | N19: =OFFSET(N19,$E$12,0) -> 0.2 | O19: =OFFSET(O19,$E$12,0) -> 0.18
C20: 1. Base | L20: 0.3 | M20: 0.25 | N20: 0.2 | O20: 0.18
C21: 2. Conservative | L21: =L20-1% -> 0.29 | M21: =M20-1% -> 0.24 | N21: =N20-1% -> 0.19 | O21: =O20-1% -> 0.17
C22: 3. Optimistic | L22: =L20+1.5% -> 0.315 | M22: =M20+1.5% -> 0.265 | N22: =N20+1.5% -> 0.215 | O22: =O20+1.5% -> 0.195
C24: Gross Opearting Revenues | G24: =Financials!G17 -> 0 | H24: =Financials!H17 -> 0 | I24: =Financials!I17 -> 43.64 | J24: =Financials!J17 -> 95.09 | K24: =Financials!Q17*(4/3) -> 354.52 | L24: =K24*(1+L25) -> 638.136 | M24: =L24*(1+M25) -> 1116.738 | N24: =M24*(1+N25) -> 1898.4546 | O24: =N24*(1+O25) -> 3189.4037
C25: Growth % | H25: =H24/G24-1 -> #DIV/0! | I25: =I24/H24-1 -> #DIV/0! | J25: =J24/I24-1 -> 1.1789643 | K25: =K24/J24-1 -> 2.7282574 | L25: =OFFSET(L25,$E$12,0) -> 0.8 | M25: =OFFSET(M25,$E$12,0) -> 0.75 | N25: =OFFSET(N25,$E$12,0) -> 0.7 | O25: =OFFSET(O25,$E$12,0) -> 0.68
C26: 1. Base | L26: 0.8 | M26: 0.75 | N26: 0.7 | O26: 0.68
C27: 2. Conservative | L27: =L26-1% -> 0.79 | M27: =M26-1% -> 0.74 | N27: =N26-1% -> 0.69 | O27: =O26-1% -> 0.67
C28: 3. Optimistic | L28: =L26+1.5% -> 0.815 | M28: =M26+1.5% -> 0.765 | N28: =N26+1.5% -> 0.715 | O28: =O26+1.5% -> 0.695
C30: Other Income | G30: =Financials!G18 -> 29.75 | H30: =Financials!H18 -> 74.46 | I30: =Financials!I18 -> 49.95 | J30: =Financials!J18 -> 51.22 | K30: =Financials!Q18*(4/3) -> 241.18667 | L30: =K30*(1+L31) -> 265.30533 | M30: =L30*(1+M31) -> 305.10113 | N30: =M30*(1+N31) -> 366.12136 | O30: =N30*(1+O31) -> 410.05592
C31: Growth % | H31: =H30/G30-1 -> 1.5028571 | I31: =I30/H30-1 -> -0.32917002 | J31: =J30/I30-1 -> 0.025425425 | K31: =K30/J30-1 -> 3.7088377 | L31: =OFFSET(L31,$E$12,0) -> 0.1 | M31: =OFFSET(M31,$E$12,0) -> 0.15 | N31: =OFFSET(N31,$E$12,0) -> 0.2 | O31: =OFFSET(O31,$E$12,0) -> 0.12
C32: 1. Base | L32: 0.1 | M32: 0.15 | N32: 0.2 | O32: 0.12
C33: 2. Conservative | L33: =L32-1% -> 0.09 | M33: =M32-1% -> 0.14 | N33: =N32-1% -> 0.19 | O33: =O32-1% -> 0.11
C34: 3. Optimistic | L34: =L32+1.5% -> 0.115 | M34: =M32+1.5% -> 0.165 | N34: =N32+1.5% -> 0.215 | O34: =O32+1.5% -> 0.135
C36: Total Income | G36: =G18+G24+G30 -> 727.25 | H36: =H18+H24+H30 -> 3466.77 | I36: =I18+I24+I30 -> 6574.6 | J36: =J18+J24+J30 -> 6772.62 | K36: =K18+K24+K30 -> 15031.787 | L36: =L18+L24+L30 -> 19670.345 | M36: =M18+M24+M30 -> 24880.469 | N36: =N18+N24+N30 -> 30414.932 | O36: =O18+O24+O30 -> 36816.88
C38: Expenses:
C39: Cost Of Materials Consumed | G39: =Financials!G22 -> 373.27 | H39: =Financials!H22 -> 504.35 | I39: =Financials!I22 -> 536.62 | J39: =Financials!J22 -> 533.41 | K39: =Financials!Q22*(4/3) -> 1645.32 | L39: =K39*(1+L40) -> 2303.448 | M39: =L39*(1+M40) -> 3339.9996 | N39: =M39*(1+N40) -> 4943.1994 | O39: =N39*(1+O40) -> 7167.6391
C40: Growth % | H40: =H39/G39-1 -> 0.35116672 | I40: =I39/H39-1 -> 0.063983345 | J40: =J39/I39-1 -> -0.0059818866 | K40: =K39/J39-1 -> 2.0845316 | L40: =OFFSET(L40,$E$12,0) -> 0.4 | M40: =OFFSET(M40,$E$12,0) -> 0.45 | N40: =OFFSET(N40,$E$12,0) -> 0.48 | O40: =OFFSET(O40,$E$12,0) -> 0.45
C41: 1. Base | L41: 0.4 | M41: 0.45 | N41: 0.48 | O41: 0.45
C42: 2. Conservative | L42: =L41+1% -> 0.41 | M42: =M41+1% -> 0.46 | N42: =N41+1% -> 0.49 | O42: =O41+1% -> 0.46
C43: 3. Optimistic | L43: =L41-1.5% -> 0.385 | M43: =M41-1.5% -> 0.435 | N43: =N41-1.5% -> 0.465 | O43: =O41-1.5% -> 0.435
Q44: z
C45: Purchases Of Stock-In-Trade | G45: =Financials!G23 -> 0 | H45: =Financials!H23 -> 0 | I45: =Financials!I23 -> 370.23 | J45: =Financials!J23 -> 182.24 | K45: =Financials!Q23*(4/3) -> 624.34667 | L45: =K45*(1+L46) -> 780.43333 | M45: =L45*(1+M46) -> 959.933 | N45: =M45*(1+N46) -> 1161.5189 | O45: =N45*(1+O46) -> 1393.8227
C46: Growth % | H46: =H45/G45-1 -> #DIV/0! | I46: =I45/H45-1 -> #DIV/0! | J46: =J45/I45-1 -> -0.50776544 | K46: =K45/J45-1 -> 2.4259584 | L46: =OFFSET(L46,$E$12,0) -> 0.25 | M46: =OFFSET(M46,$E$12,0) -> 0.23 | N46: =OFFSET(N46,$E$12,0) -> 0.21 | O46: =OFFSET(O46,$E$12,0) -> 0.2
C47: 1. Base | L47: 0.25 | M47: 0.23 | N47: 0.21 | O47: 0.2
C48: 2. Conservative | L48: =L47+1% -> 0.26 | M48: =M47+1% -> 0.24 | N48: =N47+1% -> 0.22 | O48: =O47+1% -> 0.21
C49: 3. Optimistic | L49: =L47-1.5% -> 0.235 | M49: =M47-1.5% -> 0.215 | N49: =N47-1.5% -> 0.195 | O49: =O47-1.5% -> 0.185
C51: Changes In Inventories Of Finished Goods | G51: =Financials!G24 -> -60.4 | H51: =Financials!H24 -> 35.78 | I51: =Financials!I24 -> -14.89 | J51: =Financials!J24 -> 90.41 | K51: =Financials!Q24*(4/3) -> -302.57333 | L51: =K51*(1+L52) -> 121.02933 | M51: =L51*(1+M52) -> -181.544 | N51: =M51*(1+N52) -> 72.6176 | O51: =N51*(1+O52) -> -94.40288
C52: Growth % | H52: =H51/G51-1 -> -1.5923841 | I52: =I51/H51-1 -> -1.4161543 | J52: =J51/I51-1 -> -7.0718603 | K52: =K51/J51-1 -> -4.3466799 | L52: =OFFSET(L52,$E$12,0) -> -1.4 | M52: =OFFSET(M52,$E$12,0) -> -2.5 | N52: =OFFSET(N52,$E$12,0) -> -1.4 | O52: =OFFSET(O52,$E$12,0) -> -2.3
...

Sheet Schedule
C2: =Dashboard!C2 -> Lloyds Metal & Energy Ltd.
C3: Schedules
C4: =Dashboard!C4 -> (₹ in 'Cr, except share price and shares outstanding)
C6: <-Back to Dashboard
B8: # | C8: Property, Plant & Equipment | G8: 44651 | H8: =EOMONTH(G8,12) -> 45016 | I8: =EOMONTH(H8,12) -> 45382 | J8: =EOMONTH(I8,12) -> 45747 | K8: =EOMONTH(J8,12) -> 46112 | L8: =EOMONTH(K8,12) -> 46477 | M8: =EOMONTH(L8,12) -> 46843 | N8: =EOMONTH(M8,12) -> 47208 | O8: =EOMONTH(N8,12) -> 47573
C10: Property, Plant & Equipment
C11: Opening balance of Gross PP&E | K11: 2031.34 | L11: =K14 -> 6638.3777 | M11: =L14 -> 7216.2487 | N11: =M14 -> 7564.3927 | O11: =N14 -> 7619.8502
C12: Additons to PP&E | K12: =K18*80% -> 4810.1717 | L12: =L18*80% -> 1573.6276 | M12: =M18*80% -> 1791.3938 | N12: =N18*80% -> 1946.5556 | O12: =O18*80% -> 2061.7453
C13: Sale of PP&E | K13: =-K11*10% -> -203.134 | L13: =-L11*15% -> -995.75666 | M13: =-M11*20% -> -1443.2497 | N13: =-N11*25% -> -1891.0982 | O13: =-O11*30% -> -2285.9551
C14: Closing balance of Gross PP&E | K14: =SUM(K11:K13) -> 6638.3777 | L14: =SUM(L11:L13) -> 7216.2487 | M14: =SUM(M11:M13) -> 7564.3927 | N14: =SUM(N11:N13) -> 7619.8502 | O14: =SUM(O11:O13) -> 7395.6404
C15: Accumulated Depreciation | J15: -499.83 | K15: =J15-K21 -> -920.72003 | L15: =K15-L21 -> -1215.7752 | M15: =L15-M21 -> -1551.6615 | N15: =M15-N21 -> -1916.6407 | O15: =N15-O21 -> -2303.218
C16: Closing balance of Net PP&E | K16: =SUM(K14:K15) -> 5717.6577 | L16: =SUM(L14:L15) -> 6000.4735 | M16: =SUM(M14:M15) -> 6012.7312 | N16: =SUM(N14:N15) -> 5703.2095 | O16: =SUM(O14:O15) -> 5092.4224
C18: CapEx | G18: 56.24 | H18: 99.63 | I18: 724.01 | J18: 782.66 | K18: =K19*Financials!K19 -> 6012.7147 | L18: =L19*Financials!L19 -> 1967.0345 | M18: =M19*Financials!M19 -> 2239.2422 | N18: =N19*Financials!N19 -> 2433.1946 | O18: =O19*Financials!O19 -> 2577.1816
C19: % of Revenue | G19: =G18/Financials!G19 -> 0.077332417 | H19: =H18/Financials!H19 -> 0.028738566 | I19: =I18/Financials!I19 -> 0.11012229 | J19: =J18/Financials!J19 -> 0.11556237 | K19: 0.4 | L19: 0.1 | M19: 0.09 | N19: 0.08 | O19: 0.07
C21: Depreciation on PP&E | G21: 17.8 | H21: 21.95 | I21: 44.25 | J21: 75.48 | K21: =K22*K18 -> 420.89003 | L21: =L22*L18 -> 295.05518 | M21: =M22*M18 -> 335.88633 | N21: =N22*N18 -> 364.97918 | O21: =O22*O18 -> 386.57724
C22: % of CapEx | G22: =G21/G18 -> 0.31650071 | H22: =H21/H18 -> 0.22031517 | I22: =I21/I18 -> 0.06111794 | J22: =J21/J18 -> 0.096440344 | K22: 0.07 | L22: 0.15 | M22: 0.15 | N22: 0.15 | O22: 0.15
C24: Non-Current Assets
C25: Opening balance of Net NCA | K25: =J28 -> 570.55 | L25: =K28 -> 1712.9658 | M25: =L28 -> 2067.032 | N25: =M28 -> 2470.0956 | O25: =N28 -> 2908.0706
C26: Additions to NCA | K26: =K18*20% -> 1202.5429 | L26: =L18*20% -> 393.40691 | M26: =M18*20% -> 447.84844 | N26: =N18*20% -> 486.63891 | O26: =O18*20% -> 515.43632
C27: Depreciation on NCA | K27: =-K30 -> -60.127147 | L27: =-L30 -> -39.340691 | M27: =-M30 -> -44.784844 | N27: =-N30 -> -48.663891 | O27: =-O30 -> -51.543632
C28: Closing balance of Net NCA | G28: =Financials!G59 -> 0.87 | H28: =Financials!H59 -> 36.32 | I28: =Financials!I59 -> 307.19 | J28: =Financials!J59 -> 570.55 | K28: =K25+K26+K27 -> 1712.9658 | L28: =L25+L26+L27 -> 2067.032 | M28: =M25+M26+M27 -> 2470.0956 | N28: =N25+N26+N27 -> 2908.0706 | O28: =O25+O26+O27 -> 3371.9633
C30: Depreciation related to NCA | K30: =K31*K18 -> 60.127147 | L30: =L31*L18 -> 39.340691 | M30: =M31*M18 -> 44.784844 | N30: =N31*N18 -> 48.663891 | O30: =O31*O18 -> 51.543632
C31: % of CapEx | K31: 0.01 | L31: 0.02 | M31: 0.02 | N31: 0.02 | O31: 0.02
B34: # | C34: Working Capital Schedule | G34: 44651 | H34: =EOMONTH(G34,12) -> 45016 | I34: =EOMONTH(H34,12) -> 45382 | J34: =EOMONTH(I34,12) -> 45747 | K34: =EOMONTH(J34,12) -> 46112 | L34: =EOMONTH(K34,12) -> 46477 | M34: =EOMONTH(L34,12) -> 46843 | N34: =EOMONTH(M34,12) -> 47208 | O34: =EOMONTH(N34,12) -> 47573
C36: Inventories | G36: =Financials!G63 -> 166.84 | H36: =Financials!H63 -> 269.75 | I36: =Financials!I63 -> 231.09 | J36: =Financials!J63 -> 431.76 | K36: =K41*Financials!K19/days -> 958.28855 | L36: =L41*Financials!L19/days -> 1254.0004 | M36: =M41*Financials!M19/days -> 1586.15 | N36: =N41*Financials!N19/days -> 1938.9765 | O36: =O41*Financials!O19/days -> 2347.1058
C37: Trade Receivables | G37: =Financials!G66 -> 23.7367 | H37: =Financials!H66 -> 24.51 | I37: =Financials!I66 -> 79.91 | J37: =Financials!J66 -> 171.42 | K37: =K42*Financials!K30/days -> 383.7063 | L37: =L42*Financials!L30/days -> 503.55265 | M37: =M42*Financials!M30/days -> 644.59777 | N37: =N42*Financials!N30/days -> 839.35139 | O37: =O42*Financials!O30/days -> 1028.0582
C39: Trade Payables | G39: =Financials!G91 -> 15.18 | H39: =Financials!H91 -> 74.53 | I39: =Financials!I91 -> 395.08 | J39: =Financials!J91 -> 36.28 | K39: =K43*Financials!K30/days -> 81.209105 | L39: =L43*Financials!L30/days -> 106.57385 | M39: =M43*Financials!M30/days -> 136.4252 | N39: =N43*Financials!N30/days -> 177.64362 | O39: =O43*Financials!O30/days -> 217.58227
C41: Inventories | G41: =G36*days/Financials!G19 -> 83.735442 | H41: =H36*days/Financials!H19 -> 28.400716 | I41: =I36*days/Financials!I19 -> 12.829351 | J41: =J36*days/Financials!J19 -> 23.269045 | K41: =J41 -> 23.269045 | L41: =K41 -> 23.269045 | M41: =L41 -> 23.269045 | N41: =M41 -> 23.269045 | O41: =N41 -> 23.269045
C42: Trade Receivables | G42: =G37*days/Financials!G$30 -> 14.732512 | H42: =H37*days/Financials!H$30 -> 3.3505552 | I42: =I37*days/Financials!I$30 -> 6.0162519 | J42: =J37*days/Financials!J$30 -> 12.830549 | K42: =J42 -> 12.830549 | L42: =K42 -> 12.830549 | M42: =L42 -> 12.830549 | N42: =M42 -> 12.830549 | O42: =N42 -> 12.830549
C43: Trade Payables | G43: =G39*days/Financials!G$30 -> 9.4216773 | H43: =H39*days/Financials!H$30 -> 10.188367 | I43: =I39*days/Financials!I$30 -> 29.744723 | J43: =J39*days/Financials!J$30 -> 2.7155076 | K43: =J43 -> 2.7155076 | L43: =K43 -> 2.7155076 | M43: =L43 -> 2.7155076 | N43: =M43 -> 2.7155076 | O43: =N43 -> 2.7155076
C45: Other Current Assets | G45: =Financials!G70 -> 96.49 | H45: =Financials!H70 -> 326.14 | I45: =Financials!I70 -> 498.76 | J45: =Financials!J70 -> 1351.85 | K45: =K46*Financials!K$19 -> 1887.3188 | L45: =L46*Financials!L$19 -> 2434.6874 | M45: =M46*Financials!M$19 -> 3264.296 | N45: =N46*Financials!N$19 -> 4411.1841 | O45: =O46*Financials!O$19 -> 4837.3914
C46: % of Revenue | G46: =G45/Financials!G$19 -> 0.1326779 | H46: =H45/Financials!H$19 -> 0.094076042 | I46: =I45/Financials!I$19 -> 0.075861649 | J46: =J45/Financials!J$19 -> 0.19960517 | K46: =AVERAGE(G46:J46) -> 0.12555519 | L46: =AVERAGE(H46:K46) -> 0.12377451 | M46: =AVERAGE(I46:L46) -> 0.13119913 | N46: =AVERAGE(J46:M46) -> 0.1450335 | O46: =AVERAGE(K46:N46) -> 0.13139059
C48: Other Current Liabilities | G48: =Financials!G93 -> 14.42 | H48: =Financials!H93 -> 383.49 | I48: =Financials!I93 -> 308.39 | J48: =Financials!J93 -> 1334.43 | K48: =K49*Financials!K$19 -> 1406.9236 | L48: =L49*Financials!L$19 -> 2203.8395 | M48: =M49*Financials!M$19 -> 2796.4066 | N48: =N49*Financials!N$19 -> 3916.3935 | O48: =O49*Financials!O$19 -> 4112.3937
C49: % of Revenue | G49: =G48/Financials!G$19 -> 0.01982812 | H49: =H48/Financials!H$19 -> 0.11061882 | I49: =I48/Financials!I$19 -> 0.046906276 | J49: =J48/Financials!J$19 -> 0.19703305 | K49: =AVERAGE(G49:J49) -> 0.093596567 | L49: =AVERAGE(H49:K49) -> 0.11203868 | M49: =AVERAGE(I49:L49) -> 0.11239364 | N49: =AVERAGE(J49:M49) -> 0.12876549 | O49: =AVERAGE(K49:N49) -> 0.11169859
C51: Other Non-Current Liabilities | G51: =Financials!G84 -> 161.43 | H51: =Financials!H84 -> 0 | I51: =Financials!I84 -> 86.4 | J51: =Financials!J84 -> 75.72 | K51: =K52*Financials!K$19 -> 165.34965 | L51: =L52*Financials!L$19 -> 216.3738 | M51: =M52*Financials!M$19 -> 273.68516 | N51: =N52*Financials!N$19 -> 334.56425 | O51: =O52*Financials!O$19 -> 404.98568
C52: % of Revenue | G52: =G51/Financials!G$19 -> 0.22197319 | H52: =H51/Financials!H$19 -> 0 | I52: =I51/Financials!I$19 -> 0.013141484 | J52: =J51/Financials!J$19 -> 0.011180311 | K52: 0.011 | L52: 0.011 | M52: 0.011 | N52: 0.011 | O52: 0.011
B55: # | C55: Debt Schedule | G55: 44651 | H55: =EOMONTH(G55,12) -> 45016 | I55: =EOMONTH(H55,12) -> 45382 | J55: =EOMONTH(I55,12) -> 45747 | K55: =EOMONTH(J55,12) -> 46112 | L55: =EOMONTH(K55,12) -> 46477 | M55: =EOMONTH(L55,12) -> 46843 | N55: =EOMONTH(M55,12) -> 47208 | O55: =EOMONTH(N55,12) -> 47573
C57: Opening balance of LT borrowings | K57: =Financials!J81 -> 753.91 | L57: =K60 -> 5337.737 | M57: =L60 -> 6096.4159 | N57: =M60 -> 7252.4911 | O57: =N60 -> 8726.7438
C58: Issuance of New Debt | K58: 4810 | L58: 2360 | M58: 2985 | N58: 3650 | O58: 4420 | P58: (80% of Capex issued)
C59: Repayment of Debt | K59: =-K57*30% -> -226.173 | L59: =-L57*30% -> -1601.3211 | M59: =-M57*30% -> -1828.9248 | N59: =-N57*30% -> -2175.7473 | O59: =-O57*30% -> -2618.0231
...

Sheet Valuation->

Sheet DCF
C2: =Dashboard!C2 -> Lloyds Metal & Energy Ltd.
C3: DCF Model
C4: =Dashboard!C4 -> (₹ in 'Cr, except share price and shares outstanding)
C6: <-Back to Dashboard
B8: # | C8: Assumptions
C10: Triggers | G10: Conservative | I10: Average | K10: Base/Street | M10: Average | O10: Optimistic | Q10: Average
C12: Scenario: | E12: =Dashboard!E14 -> 1 | G12: WACC | I12: =M12+2% -> 0.21887821 | K12: WACC | M12: =WACC!J13 -> 0.19887821 | O12: WACC | Q12: =M12-2% -> 0.17887821
G13: TGR | I13: 0.02 | K13: TGR | M13: 0.03 | O13: TGR | Q13: 0.04
C14: WACC | E14: =CHOOSE(E12,M12,I12,Q12) -> 0.19887821
C15: TGR | E15: =CHOOSE(E12,M13,I13,Q13) -> 0.03
B17: # | C17: DCF | G17: 46112 | H17: =EOMONTH(G17,12) -> 46477 | I17: =EOMONTH(H17,12) -> 46843 | J17: =EOMONTH(I17,12) -> 47208 | K17: =EOMONTH(J17,12) -> 47573
C19: EBIT | G19: =Financials!K32 -> 4116.2131 | H19: =Financials!L32 -> 5345.4152 | I19: =Financials!M32 -> 6543.1253 | J19: =Financials!N32 -> 6537.2895 | K19: =Financials!O32 -> 7570.9556
C20: Tax Rate (%) | G20: 0.3 | H20: 0.3 | I20: 0.3 | J20: 0.3 | K20: 0.3
C21: NOPAT | G21: =G19*(1-G20) -> 2881.3491 | H21: =H19*(1-H20) -> 3741.7906 | I21: =I19*(1-I20) -> 4580.1877 | J21: =J19*(1-J20) -> 4576.1027 | K21: =K19*(1-K20) -> 5299.6689
C23: Add: Depreciation & Amortization | G23: =Financials!K27 -> 481.01717 | H23: =Financials!L27 -> 334.39587 | I23: =Financials!M27 -> 380.67118 | J23: =Financials!N27 -> 413.64307 | K23: =Financials!O27 -> 438.12087
C24: Add: Share-based Compensation | G24: =Assumptions!K84 -> 180.38144 | H24: =Assumptions!L84 -> 236.04414 | I24: =Assumptions!M84 -> 298.56563 | J24: =Assumptions!N84 -> 364.97918 | K24: =Assumptions!O84 -> 441.80256
C25: Less: CapEx | G25: =-Schedule!K18 -> -6012.7147 | H25: =-Schedule!L18 -> -1967.0345 | I25: =-Schedule!M18 -> -2239.2422 | J25: =-Schedule!N18 -> -2433.1946 | K25: =-Schedule!O18 -> -2577.1816
C26: Add / Less: Change in Working Capital | G26: =SUM(Financials!K111:K113) -> -693.88575 | H26: =SUM(Financials!L111:L113) -> -390.19346 | I26: =SUM(Financials!M111:M113) -> -443.34338 | J26: =SUM(Financials!N111:N113) -> -506.36168 | K26: =SUM(Financials!O111:O113) -> -556.89754
C27: FCF | G27: =SUM(G21:G26) -> -3163.8527 | H27: =SUM(H21:H26) -> 1955.0026 | I27: =SUM(I21:I26) -> 2576.8389 | J27: =SUM(J21:J26) -> 2415.1687 | K27: =SUM(K21:K26) -> 3045.5132
C29: Discount Period | G29: 1 | H29: =G29+1 -> 2 | I29: =H29+1 -> 3 | J29: =I29+1 -> 4 | K29: =J29+1 -> 5
C30: Mid Year Discount | G30: 0.5 | H30: =G30+1 -> 1.5 | I30: =H30+1 -> 2.5 | J30: =I30+1 -> 3.5 | K30: =J30+1 -> 4.5
C31: Terminal Value | K31: =K27*(1+tgr)/(wacc-tgr) -> 18574.798
C32: Discounted FCF | G32: =G27/(1+wacc)^G30 -> -2889.54 | H32: =H27/(1+wacc)^H30 -> 1489.3088 | I32: =I27/(1+wacc)^I30 -> 1637.3805 | J32: =J27/(1+wacc)^J30 -> 1280.073 | K32: =(K27+K31)/(1+wacc)^K30 -> 9558.1568
C34: Enterprise Value | G34: =SUM(G32:K32) -> 11075.379
C35: Add: Cash | G35: =Financials!J67+Financials!J68+Financials!J65+Financials!J56 -> 814.37
C36: Less: Debt | G36: =Financials!J81+Financials!J89 -> 755.75
C37: Equity Value | G37: =G34+G35-G36 -> 11133.999
C38: Number of Shares | G38: 120648
C39: Price Per Share | G39: =G37/G38*10^4 -> 922.84986
B42: # | C42: Sensitivity Analysis - Terminal Growth Rate (%) to WACC (%)
D44: Terminal Growth Rate %
C45: WACC | D45: =G39 -> 922.84986 | E45: 0.01 | F45: =E45+1% -> 0.02 | G45: =F45+1% -> 0.03 | H45: =G45+1% -> 0.04 | I45: =H45+1% -> 0.05 | K45: Mean | M45: =AVERAGE($E$56:$I$60,$E$66:$I$70,$E$76:$I$80) -> 962.10736
D46: 0.24 | E46: 622.67976 | F46: 646.17684 | G46: 671.91174 | H46: 700.22014 | I46: 731.50836 | K46: Median | M46: =MEDIAN($E$56:$I$60,$E$66:$I$70,$E$76:$I$80) -> 922.84986
D47: 0.22 | E47: 716.74008 | F47: 746.70628 | G47: 779.82682 | H47: 816.62741 | I47: 857.75749 | K47: 75th Percentile | M47: =QUARTILE(($E$56:$I$60,$E$66:$I$70,$E$76:$I$80),3) -> 1341.0953
D48: 0.19887821 | E48: 838.96141 | F48: 878.56079 | G48: 922.84986 | H48: 972.71415 | I48: 1029.2771 | K48: 25th Percentile | M48: =QUARTILE(($E$56:$I$60,$E$66:$I$70,$E$76:$I$80),1) -> 392.24085
D49: 0.18 | E49: 975.19876 | F49: 1027.1965 | G49: 1086.1273 | H49: 1153.4767 | I49: 1231.1876
D50: 0.16 | E50: 1158.555 | F50: 1230.057 | G50: 1312.5593 | H50: 1408.8119 | I50: 1522.5651
C52: Base Case
D54: Terminal Growth Rate %
C55: WACC | D55: =G49 -> 1086.1273 | E55: 0.01 | F55: =E55+1% -> 0.02 | G55: =F55+1% -> 0.03 | H55: =G55+1% -> 0.04 | I55: =H55+1% -> 0.05
...

Sheet WACC
C2: =Dashboard!C2 -> Lloyds Metal & Energy Ltd.
C3: WACC
C4: =Dashboard!C4 -> (₹ in 'Cr, except share price and shares outstanding)
C6: <-Back to Dashboard
C8: Cost of Capital | H8: Capital Structure
C9: Risk Free Rate | E9: 0.06737 | F9: Investing.com | H9: Market Cap | J9: 70112
C10: Equity Risk Premium | E10: 0.0708 | F10: Aswath Damodaran | H10: Total Debt | J10: 755.75
C11: Country Risk Premium | E11: 0.0285 | F11: Aswath Damodaran | H11: Total Capital | J11: =SUM(J9:J10) -> 70867.75
C12: Beta | E12: =Beta!L25 -> 1.4813586 | F12: Regression
C13: Cost of Equity | E13: =E9+(E10*E12)+E11 -> 0.20075019 | H13: WACC | J13: =E13*(J9/J11)+E22*(J10/J11) -> 0.19887821
C15: Cost of Debt
C16: (Using Interest Expense)
C17: Finance Cost | E17: =Financials!J26 -> 27.22
C18: Total Borrowings | E18: =Financials!J81+Financials!J89 -> 755.75
C19: Cost of Debt | E19: =E17/E18 -> 0.036017201
C21: Tax Rate (%) | E21: 0.3
C22: Cost of Debt Post Tax | E22: =E19*(1-E21) -> 0.025212041
B24: # | C24: End

Sheet Beta
C2: <-Back to Dashboard
C4: Beta
C6: LLOYDSME | G6: Nifty 500 | K6: SUMMARY OUTPUT
C8: Date | D8: Price | G8: Date | H8: Price | K8: Regression Statistics
C9: 46096 | D9: 1245.8 | G9: 46096 | H9: 21327.9 | K9: Multiple R | L9: 0.50588928
C10: 46089 | D10: 1140.8 | E10: =D9/D10-1 -> 0.092040673 | G10: 46089 | H10: 21391.2 | I10: =H9/H10-1 -> -0.0029591608 | K10: R Square | L10: 0.25592396
C11: 46082 | D11: 1184 | E11: =D10/D11-1 -> -0.036486486 | G11: 46082 | H11: 22481.3 | I11: =H10/H11-1 -> -0.048489189 | K11: Adjusted R Square | L11: 0.25045281
C12: 46075 | D12: 1233 | E12: =D11/D12-1 -> -0.03974047 | G12: 46075 | H12: 23166.85 | I12: =H11/H12-1 -> -0.029591852 | K12: Standard Error | L12: 0.04826755
C13: 46068 | D13: 1143 | E13: =D12/D13-1 -> 0.078740157 | G13: 46068 | H13: 23395 | I13: =H12/H13-1 -> -0.0097520838 | K13: Observations | L13: 138
C14: 46061 | D14: 1190.4 | E14: =D13/D14-1 -> -0.039818548 | G14: 46061 | H14: 23313.15 | I14: =H13/H14-1 -> 0.0035108941
C15: 46054 | D15: 1261.3 | E15: =D14/D15-1 -> -0.056211845 | G15: 46054 | H15: 23434 | I15: =H14/H15-1 -> -0.0051570368 | K15: ANOVA
C16: 46047 | D16: 1103.8 | E16: =D15/D16-1 -> 0.14268889 | G16: 46047 | H16: 23079.5 | I16: =H15/H16-1 -> 0.015359951 | L16: df | M16: SS | N16: MS | O16: F | P16: Significance F
C17: 46040 | D17: 1115.5 | E17: =D16/D17-1 -> -0.01048857 | G17: 46040 | H17: 22706.2 | I17: =H16/H17-1 -> 0.016440444 | K17: Regression | L17: 1 | M17: 0.10897906 | N17: 0.10897906 | O17: 46.777019 | P17: 2.4636358e-10
C18: 46033 | D18: 1229 | E18: =D17/D18-1 -> -0.092351505 | G18: 46033 | H18: 23485.3 | I18: =H17/H18-1 -> -0.033173943 | K18: Residual | L18: 136 | M18: 0.31684687 | N18: 0.0023297564
C19: 46026 | D19: 1265.2 | E19: =D18/D19-1 -> -0.028612077 | G19: 46026 | H19: 23467.35 | I19: =H18/H19-1 -> 0.0007648925 | K19: Total | L19: 137 | M19: 0.42582593
C20: 46019 | D20: 1348.8 | E20: =D19/D20-1 -> -0.06198102 | G20: 46019 | H20: 24099 | I20: =H19/H20-1 -> -0.026210631
C21: 46012 | D21: 1369.8 | E21: =D20/D21-1 -> -0.015330705 | G21: 46012 | H21: 23780.25 | I21: =H20/H21-1 -> 0.01340398 | L21: Coefficients | M21: Standard Error | N21: t Stat | O21: P-value | P21: Lower 95% | Q21: Upper 95% | R21: Lower 95.0% | S21: Upper 95.0%
C22: 46005 | D22: 1300.9 | E22: =D21/D22-1 -> 0.052963333 | G22: 46005 | H22: 23677.55 | I22: =H21/H22-1 -> 0.004337442 | K22: Intercept | L22: 0.0041052294 | M22: 0.004128244 | N22: 0.99442508 | O22: 0.32178197 | P22: -0.0040586241 | Q22: 0.012269083 | R22: -0.0040586241 | S22: 0.012269083
C23: 45998 | D23: 1288.3 | E23: =D22/D23-1 -> 0.0097803307 | G23: 45998 | H23: 23726.2 | I23: =H22/H23-1 -> -0.0020504758 | K23: X Variable 1 | L23: 1.4813586 | M23: 0.21659276 | N23: 6.8393727 | O23: 2.4636358e-10 | P23: 1.0530332 | Q23: 1.9096839 | R23: 1.0530332 | S23: 1.9096839
C24: 45991 | D24: 1220.3 | E24: =D23/D24-1 -> 0.055724002 | G24: 45991 | H24: 23835.25 | I24: =H23/H24-1 -> -0.0045751565
C25: 45984 | D25: 1220.4 | E25: =D24/D25-1 -> -8.1940347e-05 | G25: 45984 | H25: 23933.2 | I25: =H24/H25-1 -> -0.0040926412 | K25: Beta | L25: =L23 -> 1.4813586
C26: 45977 | D26: 1223 | E26: =D25/D26-1 -> -0.0021259199 | G26: 45977 | H26: 23790.25 | I26: =H25/H26-1 -> 0.0060087641
C27: 45970 | D27: 1287.3 | E27: =D26/D27-1 -> -0.049949507 | G27: 45970 | H27: 23836.35 | I27: =H26/H27-1 -> -0.0019340209 | K27: Mean | L27: =AVERAGE($D$9:$D$63) -> 1302.2736
C28: 45963 | D28: 1315.6 | E28: =D27/D28-1 -> -0.021511098 | G28: 45963 | H28: 23521.5 | I28: =H27/H28-1 -> 0.013385626 | K28: Median | L28: =MEDIAN($D$9:$D$63) -> 1293.4
C29: 45956 | D29: 1304.8 | E29: =D28/D29-1 -> 0.0082771306 | G29: 45956 | H29: 23710.4 | I29: =H28/H29-1 -> -0.0079669681 | K29: 75th Percentile | L29: =QUARTILE($D$9:$D$63,3) -> 1351.25
C30: 45949 | D30: 1336.3 | E30: =D29/D30-1 -> -0.023572551 | G30: 45949 | H30: 23686.6 | I30: =H29/H30-1 -> 0.0010047875 | K30: 25th Percentile | L30: =QUARTILE($D$9:$D$63,1) -> 1226
C31: 45942 | D31: 1323.4 | E31: =D30/D31-1 -> 0.0097476198 | G31: 45942 | H31: 23598.05 | I31: =H30/H31-1 -> 0.0037524287
C32: 45935 | D32: 1344.2 | E32: =D31/D32-1 -> -0.015473888 | G32: 45935 | H32: 23337.55 | I32: =H31/H32-1 -> 0.011162269
C33: 45928 | D33: 1312.3 | E33: =D32/D33-1 -> 0.024308466 | G33: 45928 | H33: 23027.7 | I33: =H32/H33-1 -> 0.013455534
C34: 45921 | D34: 1246 | E34: =D33/D34-1 -> 0.053210273 | G34: 45921 | H34: 22713.15 | I34: =H33/H34-1 -> 0.013848806
C35: 45914 | D35: 1328.5 | E35: =D34/D35-1 -> -0.062100113 | G35: 45914 | H35: 23486.65 | I35: =H34/H35-1 -> -0.032933603
C36: 45907 | D36: 1296.5 | E36: =D35/D36-1 -> 0.024681836 | G36: 45907 | H36: 23190.25 | I36: =H35/H36-1 -> 0.012781233
C37: 45900 | D37: 1293.4 | E37: =D36/D37-1 -> 0.0023967837 | G37: 45900 | H37: 22829.15 | I37: =H36/H37-1 -> 0.015817496
C38: 45893 | D38: 1288.8 | E38: =D37/D38-1 -> 0.0035692117 | G38: 45893 | H38: 22462.95 | I38: =H37/H38-1 -> 0.0163024
C39: 45886 | D39: 1353.7 | E39: =D38/D39-1 -> -0.047942676 | G39: 45886 | H39: 22991.3 | I39: =H38/H39-1 -> -0.022980432
C40: 45879 | D40: 1398.7 | E40: =D39/D40-1 -> -0.032172732 | G40: 45879 | H40: 22680.25 | I40: =H39/H40-1 -> 0.013714575
C41: 45872 | D41: 1400.3 | E41: =D40/D41-1 -> -0.0011426123 | G41: 45872 | H41: 22443.15 | I41: =H40/H41-1 -> 0.010564471
C42: 45865 | D42: 1445.6 | E42: =D41/D42-1 -> -0.031336469 | G42: 45865 | H42: 22673.65 | I42: =H41/H42-1 -> -0.010165986
... C147: 45130 | D147: 596.9 | E147: =D146/D147-1 -> 0.074719383 | G147: 45130 | H147: 16948.35 | I147: =H146/H147-1 -> -0.0034074113

Sheet Comps
C2: =Dashboard!C2 -> Lloyds Metal & Energy Ltd.
C3: Comparable Companies
C4: =Dashboard!C4 -> (₹ in 'Cr, except share price and shares outstanding)
C6: <-Back to Dashboard
B8: # | C8: Overview
C10: Company | E10: Revenue | F10: EBITDA | G10: EBITDA % | H10: Net Income | I10: NI % | J10: Price / Share (₹) | K10: Market Cap | L10: Enterprise Value | M10: EV / Rev | N10: EV / EBITDA | O10: P / Sales | P10: P / E
C11: Lloyds Metal & Energy | E11: 12286 | F11: =3651+405 -> 4056 | G11: =F11/$E11 -> 0.33013186 | H11: 2463 | I11: =H11/$E11 -> 0.20047208 | J11: 1246 | K11: 70112 | L11: 77299 | M11: =L11/E11 -> 6.2916328 | N11: =L11/F11 -> 19.057939 | O11: =J11/E11 -> 0.10141625 | P11: =J11/H11 -> 0.50588713
C12: NMDC | E12: 27732 | F12: =9749+466 -> 10215 | G12: =F12/$E12 -> 0.36834704 | H12: 6902 | I12: =H12/$E12 -> 0.24888216 | J12: 79.8 | K12: 70141 | L12: 63249 | M12: =L12/E12 -> 2.2807226 | N12: =L12/F12 -> 6.1917768 | O12: =J12/E12 -> 0.0028775422 | P12: =J12/H12 -> 0.011561866
C13: GMDC | E13: 2626 | F13: =846+92.6 -> 938.6 | G13: =F13/$E13 -> 0.35742574 | H13: 640 | I13: =H13/$E13 -> 0.24371668 | J13: 576 | K13: 18307 | L13: 17990 | M13: =L13/E13 -> 6.8507235 | N13: =L13/F13 -> 19.166844 | O13: =J13/E13 -> 0.21934501 | P13: =J13/H13 -> 0.9
C14: Gravita | E14: 4130 | F14: =483+35.5 -> 518.5 | G14: =F14/$E14 -> 0.12554479 | H14: 382 | I14: =H14/$E14 -> 0.092493947 | J14: 1405 | K14: 10372 | L14: 10582 | M14: =L14/E14 -> 2.5622276 | N14: =L14/F14 -> 20.408872 | O14: =J14/E14 -> 0.3401937 | P14: =J14/H14 -> 3.6780105
C15: MOIL | E15: 1489 | F15: =349+161 -> 510 | G15: =F15/$E15 -> 0.34251175 | H15: 291 | I15: =H15/$E15 -> 0.19543318 | J15: 292 | K15: 5934 | L15: 5097 | M15: =L15/E15 -> 3.4231028 | N15: =L15/F15 -> 9.9941176 | O15: =J15/E15 -> 0.19610477 | P15: =J15/H15 -> 1.0034364
C16: Ashapura Minechem Ltd | E16: 3824 | F16: =489+127 -> 616 | G16: =F16/$E16 -> 0.16108787 | H16: 381 | I16: =H16/$E16 -> 0.099633891 | J16: 503 | K16: 4804 | L16: 5710 | M16: =L16/E16 -> 1.4932008 | N16: =L16/F16 -> 9.2694805 | O16: =J16/E16 -> 0.13153766 | P16: =J16/H16 -> 1.32021
C17: Petro Carbon & Chemicals | E17: 380 | F17: =18.2+4.55 -> 22.75 | G17: =F17/$E17 -> 0.059868421 | H17: 4.15 | I17: =H17/$E17 -> 0.010921053 | J17: 246 | K17: 608 | L17: 849 | M17: =L17/E17 -> 2.2342105 | N17: =L17/F17 -> 37.318681 | O17: =J17/E17 -> 0.64736842 | P17: =J17/H17 -> 59.277108
C18: 20 Microns Ltd | E18: 920 | F18: =104+20.3 -> 124.3 | G18: =F18/$E18 -> 0.1351087 | H18: 64.8 | I18: =H18/$E18 -> 0.070434783 | J18: 151 | K18: 533 | L18: 638 | M18: =L18/E18 -> 0.69347826 | N18: =L18/F18 -> 5.1327434 | O18: =J18/E18 -> 0.16413043 | P18: =J18/H18 -> 2.3302469
C19: NILE Ltd | E19: 1001 | F19: =72.9+3.84 -> 76.74 | G19: =F19/$E19 -> 0.076663337 | H19: 51.2 | I19: =H19/$E19 -> 0.051148851 | J19: 1501 | K19: 450 | L19: 452 | M19: =L19/E19 -> 0.45154845 | N19: =L19/F19 -> 5.8900182 | O19: =J19/E19 -> 1.4995005 | P19: =J19/H19 -> 29.316406
C20: Asi Industries Ltd | E20: 149 | F20: =39.1+4.63 -> 43.73 | G20: =F20/$E20 -> 0.29348993 | H20: 26 | I20: =H20/$E20 -> 0.17449664 | J20: 24.1 | K20: 217 | L20: 225 | M20: =L20/E20 -> 1.5100671 | N20: =L20/F20 -> 5.1452092 | O20: =J20/E20 -> 0.16174497 | P20: =J20/H20 -> 0.92692308
C22: Mean | M22: =AVERAGE(M12:M20) -> 2.3888091 | N22: =AVERAGE(N12:N20) -> 13.168638 | O22: =AVERAGE(O12:O20) -> 0.37364478 | P22: =AVERAGE(P12:P20) -> 10.973767
C23: Median | M23: =MEDIAN(M12:M20) -> 2.2342105 | N23: =MEDIAN(N12:N20) -> 9.2694805 | O23: =MEDIAN(O12:O20) -> 0.19610477 | P23: =MEDIAN(P12:P20) -> 1.32021
C24: 75th Percentile | M24: =QUARTILE(M12:M20,3) -> 2.5622276 | N24: =QUARTILE(N12:N20,3) -> 19.166844 | O24: =QUARTILE(O12:O20,3) -> 0.3401937 | P24: =QUARTILE(P12:P20,3) -> 3.6780105
C25: 25th Percentile | M25: =QUARTILE(M12:M20,1) -> 1.4932008 | N25: =QUARTILE(N12:N20,1) -> 5.8900182 | O25: =QUARTILE(O12:O20,1) -> 0.16174497 | P25: =QUARTILE(P12:P20,1) -> 0.92692308
B28: # | C28: Valuation
O29: Equity Value | S29: Price Per Share
C30: Lloyds Metal & Energy Ltd. | E30: Revenue | F30: EBITDA | G30: Net Income | H30: # Shares | I30: Cash | J30: Debt | K30: EV / Revenue | L30: EV / EBITDA | M30: P / Sales | N30: P / E | O30: EV / Revenue | P30: EV / EBITDA | Q30: P / Sales | R30: P / E | S30: EV / Revenue | T30: EV / EBITDA | U30: P / Sales | V30: P / E
C31: Mean | E31: =E11 -> 12286 | F31: =F11 -> 4056 | G31: =H11 -> 2463 | H31: 120648 | I31: =Financials!L63+Financials!L64+Financials!L61+Financials!L52 -> 7254.4739 | J31: =Financials!M76+Financials!M84 -> 18297.025 | K31: =M22 -> 2.3888091 | L31: =N22 -> 13.168638 | M31: =O22 -> 0.37364478 | N31: =P22 -> 10.973767 | O31: =K31*E31 -> 29348.908 | P31: =L31*F31 -> 53411.996 | Q31: =M31*E31 -> 4590.5997 | R31: =N31*G31 -> 27028.388 | S31: =H31*10^2/O31 -> 411.08173 | T31: =I31*10^2/P31 -> 13.582106 | U31: =J31*10^2/Q31 -> 398.57591 | V31: =K31*10^2/R31 -> 0.0088381485
C32: Median | E32: =E31 -> 12286 | F32: =F31 -> 4056 | G32: =G31 -> 2463 | H32: =H31 -> 120648 | I32: =I31 -> 7254.4739 | J32: =J31 -> 18297.025 | K32: =M23 -> 2.2342105 | L32: =N23 -> 9.2694805 | M32: =O23 -> 0.19610477 | N32: =P23 -> 1.32021 | O32: =K32*E32 -> 27449.511 | P32: =L32*F32 -> 37597.013 | Q32: =M32*E32 -> 2409.3432 | R32: =N32*G32 -> 3251.6772 | S32: =H32*10^2/O32 -> 439.52696 | T32: =I32*10^2/P32 -> 19.295346 | U32: =J32*10^2/Q32 -> 759.41962 | V32: =K32*10^2/R32 -> 0.068709482
C33: 75th Percentile | E33: =E32 -> 12286 | F33: =F32 -> 4056 | G33: =G32 -> 2463 | H33: =H32 -> 120648 | I33: =I32 -> 7254.4739 | J33: =J32 -> 18297.025 | K33: =M24 -> 2.5622276 | L33: =N24 -> 19.166844 | M33: =O24 -> 0.3401937 | N33: =P24 -> 3.6780105 | O33: =K33*E33 -> 31479.528 | P33: =L33*F33 -> 77740.72 | Q33: =M33*E33 -> 4179.6199 | R33: =N33*G33 -> 9058.9398 | S33: =H33*10^2/O33 -> 383.2586 | T33: =I33*10^2/P33 -> 9.3316268 | U33: =J33*10^2/Q33 -> 437.76768 | V33: =K33*10^2/R33 -> 0.028283968
C34: 25th Percentile | E34: =E33 -> 12286 | F34: =F33 -> 4056 | G34: =G33 -> 2463 | H34: =H33 -> 120648 | I34: =I33 -> 7254.4739 | J34: =J33 -> 18297.025 | K34: =M25 -> 1.4932008 | L34: =N25 -> 5.8900182 | M34: =O25 -> 0.16174497 | N34: =P25 -> 0.92692308 | O34: =K34*E34 -> 18345.465 | P34: =L34*F34 -> 23889.914 | Q34: =M34*E34 -> 1987.1987 | R34: =N34*G34 -> 2283.0115 | S34: =H34*10^2/O34 -> 657.6448 | T34: =I34*10^2/P34 -> 30.366262 | U34: =J34*10^2/Q34 -> 920.74463 | V34: =K34*10^2/R34 -> 0.065404875
B37: # | C37: 52-Week Share Price
C39: Valuation
C40: Mean | E40: 1302.2736
C41: Median | E41: 1293.4
C42: 75th Percentile | E42: 1351.25
C43: 25th Percentile | E43: 1226
B45: # | C45: End

Sheet Ratio Analysis
C2: =Dashboard!C2 -> Lloyds Metal & Energy Ltd.
C3: Ratio Analysis
C4: =Dashboard!C4 -> (₹ in 'Cr, except share price and shares outstanding)
C6: <-Back to Dashboard
B8: 1 | C8: Profitablity Ratios | F8: 44651 | G8: =EOMONTH(F8,12) -> 45016 | H8: =EOMONTH(G8,12) -> 45382 | I8: =EOMONTH(H8,12) -> 45747 | J8: =EOMONTH(I8,12) -> 46112 | K8: =EOMONTH(J8,12) -> 46477 | L8: =EOMONTH(K8,12) -> 46843 | M8: =EOMONTH(L8,12) -> 47208 | N8: =EOMONTH(M8,12) -> 47573
C9: Gross Profit Margin | F9: =Financials!G32/Financials!G$19 -> 0.19136473 | G9: =Financials!H32/Financials!H$19 -> 0.22981623 | H9: =Financials!I32/Financials!I$19 -> 0.26260761 | I9: =Financials!J32/Financials!J$19 -> 0.27996698 | J9: =Financials!K32/Financials!K$19 -> 0.27383392 | K9: =Financials!L32/Financials!L$19 -> 0.27174994 | L9: =Financials!M32/Financials!M$19 -> 0.26298239 | M9: =Financials!N32/Financials!N$19 -> 0.21493684 | N9: =Financials!O32/Financials!O$19 -> 0.20563817
C10: EBITDA | F10: =Financials!G32+Financials!G27+Financials!G26 -> 175.29 | G10: =Financials!H32+Financials!H27+Financials!H26 -> 884.76 | H10: =Financials!I32+Financials!I27+Financials!I26 -> 1781.21 | I10: =Financials!J32+Financials!J27+Financials!J26 -> 2004.13 | J10: =Financials!K32+Financials!K27+Financials!K26 -> 4856.1252 | K10: =Financials!L32+Financials!L27+Financials!L26 -> 6151.4699 | L10: =Financials!M32+Financials!M27+Financials!M26 -> 7467.7645 | M10: =Financials!N32+Financials!N27+Financials!N26 -> 7594.0968 | N10: =Financials!O32+Financials!O27+Financials!O26 -> 8755.2257
C11: EBITDA Margin | F11: =F10/Financials!G19 -> 0.24103128 | G11: =G10/Financials!H19 -> 0.25521162 | H11: =H10/Financials!I19 -> 0.27092295 | I11: =I10/Financials!J19 -> 0.2959165 | J11: =J10/Financials!K19 -> 0.32305709 | K11: =K10/Financials!L19 -> 0.31272811 | L11: =L10/Financials!M19 -> 0.30014565 | M11: =M10/Financials!N19 -> 0.24968318 | N11: =N10/Financials!O19 -> 0.23780466
C12: EBIT Margin | F12: =(Financials!G32+Financials!G26)/Financials!G19 -> 0.21630801 | G12: =(Financials!H32+Financials!H26)/Financials!H19 -> 0.24857721 | H12: =(Financials!I32+Financials!I26)/Financials!I19 -> 0.26347154 | I12: =(Financials!J32+Financials!J26)/Financials!J19 -> 0.28398611 | J12: =(Financials!K32+Financials!K26)/Financials!K19 -> 0.29105709 | K12: =(Financials!L32+Financials!L26)/Financials!L19 -> 0.29572811 | L12: =(Financials!M32+Financials!M26)/Financials!M19 -> 0.28484565 | M12: =(Financials!N32+Financials!N26)/Financials!N19 -> 0.23608318 | N12: =(Financials!O32+Financials!O26)/Financials!O19 -> 0.22590466
C13: PBT Margin | F13: =Financials!G34/Financials!G19 -> 0.12074252 | G13: =Financials!H34/Financials!H19 -> -0.11471197 | H13: =Financials!I34/Financials!I19 -> 0.26260761 | I13: =Financials!J34/Financials!J19 -> 0.27996698 | J13: =Financials!K34/Financials!K19 -> 0.27383392 | K13: =Financials!L34/Financials!L19 -> 0.27174994 | L13: =Financials!M34/Financials!M19 -> 0.26298239 | M13: =Financials!N34/Financials!N19 -> 0.21493684 | N13: =Financials!O34/Financials!O19 -> 0.20563817
C14: Net Profit Margin | F14: =Financials!G37/Financials!G19 -> 0.13381918 | G14: =Financials!H37/Financials!H19 -> -0.083230211 | H14: =Financials!I37/Financials!I19 -> 0.18905181 | I14: =Financials!J37/Financials!J19 -> 0.21408554 | J14: =Financials!K37/Financials!K19 -> 0.20998167 | K14: =Financials!L37/Financials!L19 -> 0.20831652 | L14: =Financials!M37/Financials!M19 -> 0.1977873 | M14: =Financials!N37/Financials!N19 -> 0.14560544 | N14: =Financials!O37/Financials!O19 -> 0.13117985
C15: ROE | F15: =Financials!G37/Financials!G77 -> 0.2020848 | G15: =Financials!H37/Financials!H77 -> -0.18871775 | H15: =Financials!I37/Financials!I77 -> 0.4421905 | I15: =Financials!J37/Financials!J77 -> 0.22647498 | J15: =Financials!K37/Financials!K77 -> 0.3349242 | K15: =Financials!L37/Financials!L77 -> 0.30698303 | L15: =Financials!M37/Financials!M77 -> 0.27224682 | M15: =Financials!N37/Financials!N77 -> 0.19747206 | N15: =Financials!O37/Financials!O77 -> 0.17746325
C16: ROA | F16: =Financials!G37/Financials!G72 -> 0.11814598 | G16: =Financials!H37/Financials!H72 -> -0.14241645 | H16: =Financials!I37/Financials!I72 -> 0.31566409 | I16: =Financials!J37/Financials!J72 -> 0.15396999 | J16: =Financials!K37/Financials!K72 -> 0.18320357 | K16: =Financials!L37/Financials!L72 -> 0.17984141 | L16: =Financials!M37/Financials!M72 -> 0.16767807 | M16: =Financials!N37/Financials!N72 -> 0.12168037 | N16: =Financials!O37/Financials!O72 -> 0.11155949
C17: ROCE | F17: =Financials!G37/(Financials!G72-Financials!G96) -> 0.13794145 | G17: =Financials!H37/(Financials!H72-Financials!H96) -> -0.18571153 | H17: =Financials!I37/(Financials!I72-Financials!I96) -> 0.4211072 | I17: =Financials!J37/(Financials!J72-Financials!J96) -> 0.19854629 | J17: =Financials!K37/(Financials!K72-Financials!K96) -> 0.21043902 | K17: =Financials!L37/(Financials!L72-Financials!L96) -> 0.20765764 | L17: =Financials!M37/(Financials!M72-Financials!M96) -> 0.19167674 | M17: =Financials!N37/(Financials!N72-Financials!N96) -> 0.14032487 | N17: =Financials!O37/(Financials!O72-Financials!O96) -> 0.12636286
C18: ROIC | F18: =(Financials!G32+Financials!G35+Financials!G36)/(Financials!G72-Financials!G96) -> 0.21073916 | G18: =(Financials!H32+Financials!H35+Financials!H36)/(Financials!H72-Financials!H96) -> 0.58303405 | H18: =(Financials!I32+Financials!I35+Financials!I36)/(Financials!I72-Financials!I96) -> 0.4211072 | I18: =(Financials!J32+Financials!J35+Financials!J36)/(Financials!J72-Financials!J96) -> 0.19854629 | J18: =(Financials!K32+Financials!K35+Financials!K36)/(Financials!K72-Financials!K96) -> 0.21043902 | K18: =(Financials!L32+Financials!L35+Financials!L36)/(Financials!L72-Financials!L96) -> 0.20765764 | L18: =(Financials!M32+Financials!M35+Financials!M36)/(Financials!M72-Financials!M96) -> 0.19167674 | M18: =(Financials!N32+Financials!N35+Financials!N36)/(Financials!N72-Financials!N96) -> 0.14032487 | N18: =(Financials!O32+Financials!O35+Financials!O36)/(Financials!O72-Financials!O96) -> 0.12636286
B20: 2 | C20: Liquidity Ratios | F20: 44651 | G20: =EOMONTH(F20,12) -> 45016 | H20: =EOMONTH(G20,12) -> 45382 | I20: =EOMONTH(H20,12) -> 45747 | J20: =EOMONTH(I20,12) -> 46112 | K20: =EOMONTH(J20,12) -> 46477 | L20: =EOMONTH(K20,12) -> 46843 | M20: =EOMONTH(L20,12) -> 47208 | N20: =EOMONTH(M20,12) -> 47573
C21: Current Ratio | F21: =Financials!G71/Financials!G96 -> 2.6134566 | G21: =Financials!H71/Financials!H96 -> 2.0045731 | H21: =Financials!I71/Financials!I96 -> 1.1434976 | I21: =Financials!J71/Financials!J96 -> 1.4285126 | J21: =Financials!K71/Financials!K96 -> 2.4682215 | K21: =Financials!L71/Financials!L96 -> 3.4149411 | L21: =Financials!M71/Financials!M96 -> 4.5096375 | M21: =Financials!N71/Financials!N96 -> 4.8574604 | N21: =Financials!O71/Financials!O96 -> 6.0203254
C22: Quick Ratio | F22: =(Financials!G71-Financials!G63)/Financials!G96 -> 1.20207 | G22: =(Financials!H71-Financials!H63)/Financials!H96 -> 1.4334681 | H22: =(Financials!I71-Financials!I63)/Financials!I96 -> 0.90911212 | I22: =(Financials!J71-Financials!J63)/Financials!J96 -> 1.2242955 | J22: =(Financials!K71-Financials!K63)/Financials!K96 -> 2.0384577 | K22: =(Financials!L71-Financials!L63)/Financials!L96 -> 3.0040741 | L22: =(Financials!M71-Financials!M63)/Financials!M96 -> 4.0779735 | M22: =(Financials!N71-Financials!N63)/Financials!N96 -> 4.4564898 | N22: =(Financials!O71-Financials!O63)/Financials!O96 -> 5.5575357
C23: Cash Ratio | F23: =(Financials!G67+Financials!G68)/Financials!G96 -> 0.18500973 | G23: =(Financials!H67+Financials!H68)/Financials!H96 -> 0.56011687 | H23: =(Financials!I67+Financials!I68)/Financials!I96 -> 0.29122462 | I23: =(Financials!J67+Financials!J68)/Financials!J96 -> 0.3496656 | J23: =(Financials!K67+Financials!K68)/Financials!K96 -> 0.87381873 | K23: =(Financials!L67+Financials!L68)/Financials!L96 -> 1.934598 | L23: =(Financials!M67+Financials!M68)/Financials!M96 -> 2.9254952 | M23: =(Financials!N67+Financials!N68)/Financials!N96 -> 3.3033129 | N23: =(Financials!O67+Financials!O68)/Financials!O96 -> 4.3367605
C24: Operating Cash Flow Ratio | J24: =Financials!K117/Financials!K96 -> 1.3496539 | K24: =Financials!L117/Financials!L96 -> 1.6546516 | L24: =Financials!M117/Financials!M96 -> 1.5025635 | M24: =Financials!N117/Financials!N96 -> 1.1121398 | N24: =Financials!O117/Financials!O96 -> 1.1315897
C25: Net Working Capital | F25: =Financials!G71-Financials!G96 -> 190.7267 | G25: =Financials!H71-Financials!H96 -> 474.49 | H25: =Financials!I71-Financials!I96 -> 141.48 | I25: =Financials!J71-Financials!J96 -> 905.97 | J25: =Financials!K71-Financials!K96 -> 3273.8444 | K25: =Financials!L71-Financials!L96 -> 7370.6016 | L25: =Financials!M71-Financials!M96 -> 12896.169 | M25: =Financials!N71-Financials!N96 -> 18653.549 | N25: =Financials!O71-Financials!O96 -> 25461.313
C26: NWC as a % of Revenue | F26: =F25/Financials!G19 -> 0.26225741 | G26: =G25/Financials!H19 -> 0.13686804 | H26: =H25/Financials!I19 -> 0.02151918 | I26: =I25/Financials!J19 -> 0.1337695 | J26: =J25/Financials!K19 -> 0.21779476 | K26: =K25/Financials!L19 -> 0.37470626 | L26: =L25/Financials!M19 -> 0.518325 | M26: =M25/Financials!N19 -> 0.61330233 | N26: =N25/Financials!O19 -> 0.6915663
B28: 3 | C28: Efficiency Ratios | F28: 44651 | G28: =EOMONTH(F28,12) -> 45016 | H28: =EOMONTH(G28,12) -> 45382 | I28: =EOMONTH(H28,12) -> 45747 | J28: =EOMONTH(I28,12) -> 46112 | K28: =EOMONTH(J28,12) -> 46477 | L28: =EOMONTH(K28,12) -> 46843 | M28: =EOMONTH(L28,12) -> 47208 | N28: =EOMONTH(M28,12) -> 47573
C29: Asset Turnover | F29: =Financials!G19/Financials!G72 -> 0.88287778 | G29: =Financials!H19/Financials!H72 -> 1.7111148 | H29: =Financials!I19/Financials!I72 -> 1.6697227 | I29: =Financials!J19/Financials!J72 -> 0.71919846 | J29: =Financials!K19/Financials!K72 -> 0.87247408 | K29: =Financials!L19/Financials!L72 -> 0.86330845 | L29: =Financials!M19/Financials!M72 -> 0.84776965 | M29: =Financials!N19/Financials!N72 -> 0.83568558 | N29: =Financials!O19/Financials!O72 -> 0.85043158
C30: Fixed Asset Turnover Ratio | F30: =Financials!G19/Financials!G52 -> 1.8224077 | G30: =Financials!H19/Financials!H52 -> 7.3046144 | H30: =Financials!I19/Financials!I52 -> 5.6836827 | I30: =Financials!J19/Financials!J52 -> 4.4221846 | J30: =Financials!K19/Financials!K52 -> 2.6290113 | K30: =Financials!L19/Financials!L52 -> 3.2781322 | L30: =Financials!M19/Financials!M52 -> 4.1379646 | M30: =Financials!N19/Financials!N52 -> 5.3329502 | N30: =Financials!O19/Financials!O52 -> 7.2297379
C31: Receivables Turnover | F31: =Financials!G19/Financials!G66 -> 30.63821 | G31: =Financials!H19/Financials!H66 -> 141.44308 | H31: =Financials!I19/Financials!I66 -> 82.275059 | I31: =Financials!J19/Financials!J66 -> 39.508925 | J31: =Financials!K19/Financials!K66 -> 39.17524 | K31: =Financials!L19/Financials!L66 -> 39.063135 | L31: =Financials!M19/Financials!M66 -> 38.598441 | M31: =Financials!N19/Financials!N66 -> 36.236232 | N31: =Financials!O19/Financials!O66 -> 35.812056
C32: Inventory Turnover | F32: =Financials!G30/Financials!G63 -> 3.5248142 | G32: =Financials!H30/Financials!H63 -> 9.8982391 | H32: =Financials!I30/Financials!I63 -> 20.979099 | I32: =Financials!J30/Financials!J63 -> 11.294492 | J32: =Financials!K30/Financials!K63 -> 11.390696 | K32: =Financials!L30/Financials!L63 -> 11.423385 | L32: =Financials!M30/Financials!M63 -> 11.560914 | M32: =Financials!N30/Financials!N63 -> 12.31456 | N32: =Financials!O30/Financials!O63 -> 12.46042
C33: Payable Turnover | F33: =Financials!G30/Financials!G91 -> 38.740448 | G33: =Financials!H30/Financials!H91 -> 35.825171 | H33: =Financials!I30/Financials!I91 -> 12.271084 | I33: =Financials!J30/Financials!J91 -> 134.41318 | J33: =Financials!K30/Financials!K91 -> 134.41318 | K33: =Financials!L30/Financials!L91 -> 134.41318 | L33: =Financials!M30/Financials!M91 -> 134.41318 | M33: =Financials!N30/Financials!N91 -> 134.41318 | N33: =Financials!O30/Financials!O91 -> 134.41318
C34: DSO | F34: =Schedule!G42 -> 14.732512 | G34: =Schedule!H42 -> 3.3505552 | H34: =Schedule!I42 -> 6.0162519 | I34: =Schedule!J42 -> 12.830549 | J34: =Schedule!K42 -> 12.830549 | K34: =Schedule!L42 -> 12.830549 | L34: =Schedule!M42 -> 12.830549 | M34: =Schedule!N42 -> 12.830549 | N34: =Schedule!O42 -> 12.830549
C35: DIO | F35: =Schedule!G41 -> 83.735442 | G35: =Schedule!H41 -> 28.400716 | H35: =Schedule!I41 -> 12.829351 | I35: =Schedule!J41 -> 23.269045 | J35: =Schedule!K41 -> 23.269045 | K35: =Schedule!L41 -> 23.269045 | L35: =Schedule!M41 -> 23.269045 | M35: =Schedule!N41 -> 23.269045 | N35: =Schedule!O41 -> 23.269045
C36: DPO | F36: =Schedule!G43 -> 9.4216773 | G36: =Schedule!H43 -> 10.188367 | H36: =Schedule!I43 -> 29.744723 | I36: =Schedule!J43 -> 2.7155076 | J36: =Schedule!K43 -> 2.7155076 | K36: =Schedule!L43 -> 2.7155076 | L36: =Schedule!M43 -> 2.7155076 | M36: =Schedule!N43 -> 2.7155076 | N36: =Schedule!O43 -> 2.7155076
C37: CCC | F37: =F34+F35-F36 -> 89.046276 | G37: =G34+G35-G36 -> 21.562904 | H37: =H34+H35-H36 -> -10.89912 | I37: =I34+I35-I36 -> 33.384086 | J37: =J34+J35-J36 -> 33.384086 | K37: =K34+K35-K36 -> 33.384086 | L37: =L34+L35-L36 -> 33.384086 | M37: =M34+M35-M36 -> 33.384086 | N37: =N34+N35-N36 -> 33.384086
C38: Working Capital Turnover | F38: =Financials!G19/'Ratio Analysis'!F25 -> 3.8130477 | G38: =Financials!H19/'Ratio Analysis'!G25 -> 7.3063078 | H38: =Financials!I19/'Ratio Analysis'!H25 -> 46.470172 | I38: =Financials!J19/'Ratio Analysis'!I25 -> 7.4755455 | J38: =Financials!K19/'Ratio Analysis'!J25 -> 4.5914787 | K38: =Financials!L19/'Ratio Analysis'!K25 -> 2.6687571 | L38: =Financials!M19/'Ratio Analysis'!L25 -> 1.9292915 | M38: =Financials!N19/'Ratio Analysis'!M25 -> 1.6305172 | N38: =Financials!O19/'Ratio Analysis'!N25 -> 1.445993
B40: 4 | C40: Leverage Ratios | F40: 44651 | G40: =EOMONTH(F40,12) -> 45016 | H40: =EOMONTH(G40,12) -> 45382 | I40: =EOMONTH(H40,12) -> 45747 | J40: =EOMONTH(I40,12) -> 46112 | K40: =EOMONTH(J40,12) -> 46477 | L40: =EOMONTH(K40,12) -> 46843 | M40: =EOMONTH(L40,12) -> 47208 | N40: =EOMONTH(M40,12) -> 47573
C41: Debt to Equity | F41: =(Financials!G89+Financials!G81)/Financials!G77 -> 0.11777898 | G41: =(Financials!H89+Financials!H81)/Financials!H77 -> 0 | H41: =(Financials!I89+Financials!I81)/Financials!I77 -> 0 | I41: =(Financials!J89+Financials!J81)/Financials!J77 -> 0.11804683 | J41: =(Financials!K89+Financials!K81)/Financials!K77 -> 0.56638494 | K41: =(Financials!L89+Financials!L81)/Financials!L77 -> 0.45672341 | L41: =(Financials!M89+Financials!M81)/Financials!M77 -> 0.40122968 | M41: =(Financials!N89+Financials!N81)/Financials!N77 -> 0.38912884 | N41: =(Financials!O89+Financials!O81)/Financials!O77 -> 0.38687435
C42: Debt to Assets | F42: =(Financials!G81+Financials!G89)/Financials!G72 -> 0.06885779 | G42: =(Financials!H81+Financials!H89)/Financials!H72 -> 0 | H42: =(Financials!I81+Financials!I89)/Financials!I72 -> 0 | I42: =(Financials!J81+Financials!J89)/Financials!J72 -> 0.080254649 | J42: =(Financials!K81+Financials!K89)/Financials!K72 -> 0.30981262 | K42: =(Financials!L81+Financials!L89)/Financials!L72 -> 0.26756456 | L42: =(Financials!M81+Financials!M89)/Financials!M72 -> 0.24711921 | M42: =(Financials!N81+Financials!N89)/Financials!N72 -> 0.23977742 | N42: =(Financials!O81+Financials!O89)/Financials!O72 -> 0.24320248
