Workbook
Name UPDATE: 'Data Sheet'!$E$1

Sheet Research_Paper
D3: April 22, 2026
D5: UltraTech Cement
D7: NSE: ULTRACEMCO | BSE: 532538
D8: Sector: Construction Materials - Cement | Country: India
D11: About The Company
N12: Stock Data (As on April 22, 2026)
N13: Nifty | Q13: 24378.1
N14: CMP | Q14: 12039
N15: 52-week High/Low | Q15: ₹ 13,110/10,325
N16: Market Cap (₹ Cr.) | Q16: 359505
D17: Analyst Rating | N17: Outstanding Shares (Cr.) | Q17: 29.47
N18: Div yield (%) | Q18: 0.0064
N19: P/E Ratio | Q19: 46.3
N20: EPS (FY25 A) | Q20: =DCF!I28/Inc_Stat!O36 -> 191.47947
N21: EPS (FY26 E) | Q21: =DCF!K28/Inc_Stat!O36 -> 252.57601
D22: Key Assumptions
N23: Recommendation (As on April 22, 2026)
N24: Rating | Q24: HOLD
N25: Last Price | Q25: 12039
N26: Target Price | Q26: 13500
N27: Implied Upside | Q27: =Q26/Q25-1 -> 0.12135559
N29: Stock Performance
D32: Exhibit 1: Scale & Network [1] | I32: Figure 1: Operational Production (MMT)
D33: Particulars
D34: Installed capacity in India (MTPA) | G34: 200+ MTPA
D35: Global Capacity | G35: 205.5 MTPA
D36: Production (MMT) | G36: 34
D37: Grinding Units | G37: 35
D38: Bulk Terminals | G38: 10
D39: Channel Partner Network | G39: 145000
D40: India Market Coverage | G40: 0.8
D41: Grey Cement Market Share | G41: 0.262
D42: MTPA – Million Metric Tonnes Per Annum | I42: MMT - Million Metric Tonnes
P43: 3M | Q43: 1Y
N44: Absolute Return | P44: =AVERAGE(StockData!E4:E268) -> 0.00047400547 | Q44: =AVERAGE(StockData!F4:F268) -> 0.00015240775
N46: Shareholding Pattern (As on April 22, 2026)
N47: Promoters | Q47: 0.5933
N48: FII + DII | Q48: =13.61%+18.42% -> 0.3203
N49: Others | Q49: =0.05%+8.41%+0.17% -> 0.0863
Q50: Prepared By: Eldric Gregory Sequeira
...

Sheet Data Sheet->

Sheet Historical FS
B1: Company Name | C1: ='Data Sheet'!B1 -> ULTRATECH CEMENT LTD
B2: Ticker | C2: ULTRACEMCO | F2: PLEASE DO NOT MAKE ANY CHANGES TO THIS SHEET
B4: Figures in Cr.
B5: Number of shares | C5: ='Data Sheet'!B6 -> 29.482018
B6: Face Value | C6: ='Data Sheet'!B7 -> 10
B7: Current Price | C7: ='Data Sheet'!B8 -> 12039
B8: Market Capitalization | C8: ='Data Sheet'!B9 -> 354934.02
B10: ="Historical Financial Statement - "&C1 -> Historical Financial Statement - ULTRATECH CEMENT LTD
B11: Years | C11: ='Data Sheet'!B16 -> 42460 | D11: ='Data Sheet'!C16 -> 42825 | E11: ='Data Sheet'!D16 -> 43190 | F11: ='Data Sheet'!E16 -> 43555 | G11: ='Data Sheet'!F16 -> 43921 | H11: ='Data Sheet'!G16 -> 44286 | I11: ='Data Sheet'!H16 -> 44651 | J11: ='Data Sheet'!I16 -> 45016 | ... L11: ='Data Sheet'!K16 -> 45747 | M11: LTM
B12: Figures in Cr.
A13: # | B13: Income Statement
B14: Revenue | C14: =IFERROR('Data Sheet'!B17,0) -> 25153.24 | D14: =IFERROR('Data Sheet'!C17,0) -> 25374.94 | E14: =IFERROR('Data Sheet'!D17,0) -> 30978.62 | F14: =IFERROR('Data Sheet'!E17,0) -> 41462.26 | G14: =IFERROR('Data Sheet'!F17,0) -> 42429.89 | H14: =IFERROR('Data Sheet'!G17,0) -> 44725.8 | I14: =IFERROR('Data Sheet'!H17,0) -> 52598.83 | J14: =IFERROR('Data Sheet'!I17,0) -> 63239.98 | ... L14: =IFERROR('Data Sheet'!K17,0) -> 75955.13 | M14: =IFERROR(SUM('Data Sheet'!I42:K42),0) -> 62712.06
B15: Expenses | C15: =IFERROR(SUM('Data Sheet'!B18,'Data Sheet'!B20:B22)-1*'Data Sheet'!B19,0) -> 12397.13 | D15: =IFERROR(SUM('Data Sheet'!C18,'Data Sheet'!C20:C22)-1*'Data Sheet'!C19,0) -> 12303.62 | E15: =IFERROR(SUM('Data Sheet'!D18,'Data Sheet'!D20:D22)-1*'Data Sheet'!D19,0) -> 15744.19 | F15: =IFERROR(SUM('Data Sheet'!E18,'Data Sheet'!E20:E22)-1*'Data Sheet'!E19,0) -> 21729.72 | G15: =IFERROR(SUM('Data Sheet'!F18,'Data Sheet'!F20:F22)-1*'Data Sheet'!F19,0) -> 20600.87 | H15: =IFERROR(SUM('Data Sheet'!G18,'Data Sheet'!G20:G22)-1*'Data Sheet'!G19,0) -> 20847.7 | I15: =IFERROR(SUM('Data Sheet'!H18,'Data Sheet'!H20:H22)-1*'Data Sheet'!H19,0) -> 26536.92 | J15: =IFERROR(SUM('Data Sheet'!I18,'Data Sheet'!I20:I22)-1*'Data Sheet'!I19,0) -> 35301.93 | ... L15: =IFERROR(SUM('Data Sheet'!K18,'Data Sheet'!K20:K22)-1*'Data Sheet'!K19,0) -> 41216.74 | M15: =IFERROR(SUM('Data Sheet'!I43:K43),0) -> 51306.6
B16: Gross Profit | C16: =C14-C15 -> 12756.11 | D16: =D14-D15 -> 13071.32 | E16: =E14-E15 -> 15234.43 | F16: =F14-F15 -> 19732.54 | G16: =G14-G15 -> 21829.02 | H16: =H14-H15 -> 23878.1 | I16: =I14-I15 -> 26061.91 | J16: =J14-J15 -> 27938.05 | ... M16: =M14-M15 -> 11405.46
B17: SG&A | C17: =IFERROR(SUM('Data Sheet'!B23:B24),0) -> 7855.14 | D17: =IFERROR(SUM('Data Sheet'!C23:C24),0) -> 7858.88 | E17: =IFERROR(SUM('Data Sheet'!D23:D24),0) -> 9089.4 | F17: =IFERROR(SUM('Data Sheet'!E23:E24),0) -> 12385.6 | G17: =IFERROR(SUM('Data Sheet'!F23:F24),0) -> 12583.05 | H17: =IFERROR(SUM('Data Sheet'!G23:G24),0) -> 12310.19 | I17: =IFERROR(SUM('Data Sheet'!H23:H24),0) -> 14547.56 | J17: =IFERROR(SUM('Data Sheet'!I23:I24),0) -> 17318.2 | ... L17: =IFERROR(SUM('Data Sheet'!K23:K24),0) -> 21941.51
B18: EBITDA | C18: =C16-C17 -> 4900.97 | D18: =D16-D17 -> 5212.44 | E18: =E16-E17 -> 6145.03 | F18: =F16-F17 -> 7346.94 | G18: =G16-G17 -> 9245.97 | H18: =H16-H17 -> 11567.91 | I18: =I16-I17 -> 11514.35 | J18: =J16-J17 -> 10619.85 | ... L18: =L16-L17 -> 12796.88 | M18: =IFERROR(SUM('Data Sheet'!I50:K50),0) -> 11405.46
B19: Depreciation | C19: =IFERROR('Data Sheet'!B26,0) -> 1377.17 | D19: =IFERROR('Data Sheet'!C26,0) -> 1348.41 | E19: =IFERROR('Data Sheet'!D26,0) -> 1847.93 | F19: =IFERROR('Data Sheet'!E26,0) -> 2450.73 | G19: =IFERROR('Data Sheet'!F26,0) -> 2722.66 | H19: =IFERROR('Data Sheet'!G26,0) -> 2700.23 | I19: =IFERROR('Data Sheet'!H26,0) -> 2714.75 | J19: =IFERROR('Data Sheet'!I26,0) -> 2887.99 | ... L19: =IFERROR('Data Sheet'!K26,0) -> 4014.95 | M19: =IFERROR(SUM('Data Sheet'!I45:K45),0) -> 3436.36
B20: Interest | C20: =IFERROR('Data Sheet'!B27,0) -> 566.3 | D20: =IFERROR('Data Sheet'!C27,0) -> 640.1 | E20: =IFERROR('Data Sheet'!D27,0) -> 1237.6 | F20: =IFERROR('Data Sheet'!E27,0) -> 1777.86 | G20: =IFERROR('Data Sheet'!F27,0) -> 1991.65 | H20: =IFERROR('Data Sheet'!G27,0) -> 1485.65 | I20: =IFERROR('Data Sheet'!H27,0) -> 944.71 | J20: =IFERROR('Data Sheet'!I27,0) -> 822.72 | ... L20: =IFERROR('Data Sheet'!K27,0) -> 1650.54 | M20: =IFERROR(SUM('Data Sheet'!I46:K46),0) -> 1384.79
B21: Profit Before Tax | C21: =C18-SUM(C19:C20) -> 2957.5 | D21: =D18-SUM(D19:D20) -> 3223.93 | E21: =E18-SUM(E19:E20) -> 3059.5 | F21: =F18-SUM(F19:F20) -> 3118.35 | G21: =G18-SUM(G19:G20) -> 4531.66 | H21: =H18-SUM(H19:H20) -> 7382.03 | I21: =I18-SUM(I19:I20) -> 7854.89 | J21: =J18-SUM(J19:J20) -> 6909.14 | ... M21: =M18-SUM(M19:M20) -> 6584.31
B22: Taxes | C22: =IFERROR('Data Sheet'!B29,0) -> 941.69 | D22: =IFERROR('Data Sheet'!C29,0) -> 1158.54 | E22: =IFERROR('Data Sheet'!D29,0) -> 1077.01 | F22: =IFERROR('Data Sheet'!E29,0) -> 1068.07 | G22: =IFERROR('Data Sheet'!F29,0) -> -568.16 | H22: =IFERROR('Data Sheet'!G29,0) -> 2538.7 | I22: =IFERROR('Data Sheet'!H29,0) -> 1190.06 | J22: =IFERROR('Data Sheet'!I29,0) -> 2342.85 | ... L22: =IFERROR('Data Sheet'!K29,0) -> 1488.49 | M22: =IFERROR(SUM('Data Sheet'!I48:K48),0) -> 1758.32
B23: Effective Tax Rate | C23: =C22/C21 -> 0.31840744 | D23: =D22/D21 -> 0.35935644 | E23: =E22/E21 -> 0.35202157 | F23: =F22/F21 -> 0.34251126 | G23: =G22/G21 -> -0.12537569 | H23: =H22/H21 -> 0.34390269 | I23: =I22/I21 -> 0.15150562 | J23: =J22/J21 -> 0.3390943 | ... M23: =M22/M21 -> 0.26704696
B24: Net Profit | C24: =C21-C22 -> 2015.81 | D24: =D21-D22 -> 2065.39 | E24: =E21-E22 -> 1982.49 | F24: =F21-F22 -> 2050.28 | G24: =G21-G22 -> 5099.82 | H24: =H21-H22 -> 4843.33 | I24: =I21-I22 -> 6664.83 | J24: =J21-J22 -> 4566.29 | ... M24: =M21-M22 -> 4825.99
B26: No of Equity Shares | C26: =IFERROR('Data Sheet'!B93,0) -> 27.44 | D26: =IFERROR('Data Sheet'!C93,0) -> 27.45 | E26: =IFERROR('Data Sheet'!D93,0) -> 27.46 | F26: =IFERROR('Data Sheet'!E93,0) -> 27.46 | G26: =IFERROR('Data Sheet'!F93,0) -> 28.86 | H26: =IFERROR('Data Sheet'!G93,0) -> 28.87 | I26: =IFERROR('Data Sheet'!H93,0) -> 28.87 | J26: =IFERROR('Data Sheet'!I93,0) -> 28.87 | ... L26: =IFERROR('Data Sheet'!K93,0) -> 29.47
B28: Earnings Per Share | C28: =C24/C26 -> 73.462464 | D28: =D24/D26 -> 75.241894 | E28: =E24/E26 -> 72.195557 | F28: =F24/F26 -> 74.664239 | G28: =G24/G26 -> 176.70894 | H28: =H24/H26 -> 167.76342 | I28: =I24/I26 -> 230.8566 | J28: =J24/J26 -> 158.1673 | ... L28: =L24/L26 -> 191.47947
B29: EPS Growth % | D29: =D28/C28-1 -> 0.024222313 | E29: =E28/D28-1 -> -0.040487247 | F29: =F28/E28-1 -> 0.034194372 | G29: =G28/F28-1 -> 1.3667145 | H29: =H28/G28-1 -> -0.050622891 | I29: =I28/H28-1 -> 0.37608422 | J29: =J28/I28-1 -> -0.31486775 | K29: =K28/J28-1 -> 0.41186828 | L29: =L28/K28-1 -> -0.14254501
B31: Dividend Per Share | C31: =IFERROR('Data Sheet'!B31/'Historical FS'!C26,0) -> 9.5010933 | D31: =IFERROR('Data Sheet'!C31/'Historical FS'!D26,0) -> 10.000364 | E31: =IFERROR('Data Sheet'!D31/'Historical FS'!E26,0) -> 10.500364 | F31: =IFERROR('Data Sheet'!E31/'Historical FS'!F26,0) -> 11.501821 | G31: =IFERROR('Data Sheet'!F31/'Historical FS'!G26,0) -> 13.001386 | H31: =IFERROR('Data Sheet'!G31/'Historical FS'!H26,0) -> 36.993419 | I31: =IFERROR('Data Sheet'!H31/'Historical FS'!I26,0) -> 37.99619 | J31: =IFERROR('Data Sheet'!I31/'Historical FS'!J26,0) -> 37.998614 | ... L31: =IFERROR('Data Sheet'!K31/'Historical FS'!L26,0) -> 77.49474
B32: Dividend Payout Ratio | C32: =IFERROR(C31/C28,0) -> 0.12933263 | D32: =IFERROR(D31/D28,0) -> 0.13290952 | E32: =IFERROR(E31/E28,0) -> 0.14544336 | F32: =IFERROR(F31/F28,0) -> 0.15404725 | G32: =IFERROR(G31/G28,0) -> 0.073575146 | H32: =IFERROR(H31/H28,0) -> 0.22050944 | I32: =IFERROR(I31/I28,0) -> 0.16458784 | J32: =IFERROR(J31/J28,0) -> 0.24024317 | ... L32: =IFERROR(L31/L28,0) -> 0.40471566
B34: Retained Earnings | C34: =IFERROR(1-C32,0) -> 0.87066737 | D34: =IFERROR(1-D32,0) -> 0.86709048 | E34: =IFERROR(1-E32,0) -> 0.85455664 | F34: =IFERROR(1-F32,0) -> 0.84595275 | G34: =IFERROR(1-G32,0) -> 0.92642485 | H34: =IFERROR(1-H32,0) -> 0.77949056 | I34: =IFERROR(1-I32,0) -> 0.83541216 | J34: =IFERROR(1-J32,0) -> 0.75975683 | ... L34: =IFERROR(1-L32,0) -> 0.59528434
A36: # | B36: Balance Sheet
B37: Equity Share Capital | C37: ='Data Sheet'!B57 -> 274.43 | D37: ='Data Sheet'!C57 -> 274.51 | E37: ='Data Sheet'!D57 -> 274.61 | F37: ='Data Sheet'!E57 -> 274.64 | G37: ='Data Sheet'!F57 -> 288.63 | H37: ='Data Sheet'!G57 -> 288.65 | I37: ='Data Sheet'!H57 -> 288.67 | J37: ='Data Sheet'!I57 -> 288.69 | ... L37: ='Data Sheet'!K57 -> 294.68
B38: Reserves | C38: ='Data Sheet'!B58 -> 21671.2 | D38: ='Data Sheet'!C58 -> 24117.38 | E38: ='Data Sheet'!D58 -> 26106.55 | F38: ='Data Sheet'!E58 -> 33476.01 | G38: ='Data Sheet'!F58 -> 38755.13 | H38: ='Data Sheet'!G58 -> 43886.03 | I38: ='Data Sheet'!H58 -> 50146.6 | J38: ='Data Sheet'!I58 -> 54035.85 | ... L38: ='Data Sheet'!K58 -> 70412.09
B39: Borrowings | C39: ='Data Sheet'!B59 -> 10615.99 | D39: ='Data Sheet'!C59 -> 8474.49 | E39: ='Data Sheet'!D59 -> 19480.22 | F39: ='Data Sheet'!E59 -> 25337 | G39: ='Data Sheet'!F59 -> 23018.96 | H39: ='Data Sheet'!G59 -> 21719.39 | I39: ='Data Sheet'!H59 -> 11298.8 | J39: ='Data Sheet'!I59 -> 11057.74 | ... L39: ='Data Sheet'!K59 -> 24102.18
B40: Other Liabilities | C40: ='Data Sheet'!B60 -> 8631.49 | D40: ='Data Sheet'!C60 -> 9342.73 | E40: ='Data Sheet'!D60 -> 11279.71 | F40: ='Data Sheet'!E60 -> 17437.72 | G40: ='Data Sheet'!F60 -> 17151.09 | H40: ='Data Sheet'!G60 -> 20282.28 | I40: ='Data Sheet'!H60 -> 22077.37 | J40: ='Data Sheet'!I60 -> 25998.12 | ... L40: ='Data Sheet'!K60 -> 38823.11
B41: Total Liabilities & Equity | C41: =SUM(C37:C40) -> 41193.11 | D41: =SUM(D37:D40) -> 42209.11 | E41: =SUM(E37:E40) -> 57141.09 | F41: =SUM(F37:F40) -> 76525.37 | G41: =SUM(G37:G40) -> 79213.81 | H41: =SUM(H37:H40) -> 86176.35 | I41: =SUM(I37:I40) -> 83811.44 | J41: =SUM(J37:J40) -> 91380.4 | ... L41: =SUM(L37:L40) -> 133632.06
B43: Fixed Assets Net Block | C43: ='Data Sheet'!B62 -> 25309.42 | D43: ='Data Sheet'!C62 -> 25903.75 | E43: ='Data Sheet'!D62 -> 39715.3 | F43: ='Data Sheet'!E62 -> 56644.62 | G43: ='Data Sheet'!F62 -> 57150.96 | H43: ='Data Sheet'!G62 -> 55411.61 | I43: ='Data Sheet'!H62 -> 55487.57 | J43: ='Data Sheet'!I62 -> 59579 | ... L43: ='Data Sheet'!K62 -> 94564.22
B44: Capital Work in Progress | C44: ='Data Sheet'!B63 -> 1469.09 | D44: ='Data Sheet'!C63 -> 921.48 | E44: ='Data Sheet'!D63 -> 1511.21 | F44: ='Data Sheet'!E63 -> 1153.32 | G44: ='Data Sheet'!F63 -> 919.59 | H44: ='Data Sheet'!G63 -> 1686.68 | I44: ='Data Sheet'!H63 -> 4784.67 | J44: ='Data Sheet'!I63 -> 4040.39 | ... L44: ='Data Sheet'!K63 -> 6234.19
B45: Investments | C45: ='Data Sheet'!B64 -> 5095.18 | D45: ='Data Sheet'!C64 -> 6690.51 | E45: ='Data Sheet'!D64 -> 5446.9 | F45: ='Data Sheet'!E64 -> 2921.33 | G45: ='Data Sheet'!F64 -> 5928.69 | H45: ='Data Sheet'!G64 -> 12178.11 | I45: ='Data Sheet'!H64 -> 6335.77 | J45: ='Data Sheet'!I64 -> 7296.95 | ... L45: ='Data Sheet'!K64 -> 5156.47
B46: Other Assets | C46: ='Data Sheet'!B65-SUM('Data Sheet'!B67:B69) -> 2669.67 | D46: ='Data Sheet'!C65-SUM('Data Sheet'!C67:C69) -> 2286.86 | E46: ='Data Sheet'!D65-SUM('Data Sheet'!D67:D69) -> 4760.39 | F46: ='Data Sheet'!E65-SUM('Data Sheet'!E67:E69) -> 8180.43 | G46: ='Data Sheet'!F65-SUM('Data Sheet'!F67:F69) -> 8108.09 | H46: ='Data Sheet'!G65-SUM('Data Sheet'!G67:G69) -> 8302.7 | I46: ='Data Sheet'!H65-SUM('Data Sheet'!H67:H69) -> 8177.06 | J46: ='Data Sheet'!I65-SUM('Data Sheet'!I67:I69) -> 8835.62 | ... L46: ='Data Sheet'!K65-SUM('Data Sheet'!K67:K69) -> 10550.63
B47: Total Non Current Assets | C47: =SUM(C43:C46) -> 34543.36 | D47: =SUM(D43:D46) -> 35802.6 | E47: =SUM(E43:E46) -> 51433.8 | F47: =SUM(F43:F46) -> 68899.7 | G47: =SUM(G43:G46) -> 72107.33 | H47: =SUM(H43:H46) -> 77579.1 | I47: =SUM(I43:I46) -> 74785.07 | J47: =SUM(J43:J46) -> 79751.96 | ... L47: =SUM(L43:L46) -> 116505.51
B49: Receivables | C49: ='Data Sheet'!B67 -> 1928.21 | D49: ='Data Sheet'!C67 -> 1757.09 | E49: ='Data Sheet'!D67 -> 2220.63 | F49: ='Data Sheet'!E67 -> 2787.03 | G49: ='Data Sheet'!F67 -> 2383.22 | H49: ='Data Sheet'!G67 -> 2571.73 | I49: ='Data Sheet'!H67 -> 3071.61 | J49: ='Data Sheet'!I67 -> 3867.02 | ... L49: ='Data Sheet'!K67 -> 5890.25
...

Sheet Data Sheet
A1: COMPANY NAME | B1: ULTRATECH CEMENT LTD | E1: =IF(B2<>B3, "A NEW VERSION OF THE WORKSHEET IS AVAILABLE", "")
A2: LATEST VERSION | B2: 2.1 | E2: PLEASE DO NOT MAKE ANY CHANGES TO THIS SHEET
A3: CURRENT VERSION | B3: 2.1
A5: META
A6: Number of shares | B6: =IF(B9>0, B9/B8, 0) -> 29.482018
A7: Face Value | B7: 10
A8: Current Price | B8: 12039
A9: Market Capitalization | B9: 354934.02
A15: PROFIT & LOSS
A16: Report Date | B16: 42460 | C16: 42825 | D16: 43190 | E16: 43555 | F16: 43921 | G16: 44286 | H16: 44651 | I16: 45016 | J16: 45382 | K16: 45747
A17: Sales | B17: 25153.24 | C17: 25374.94 | D17: 30978.62 | E17: 41462.26 | F17: 42429.89 | G17: 44725.8 | H17: 52598.83 | I17: 63239.98 | J17: 70908.14 | K17: 75955.13
A18: Raw Material Cost | B18: 4436.12 | C18: 4416.9 | D18: 5399.98 | E18: 6936.74 | F18: 6875.89 | G18: 6635.66 | H18: 8348.15 | I18: 10233.17 | J18: 11986.27 | K18: 13691.46
A19: Change in Inventory | B19: 18.61 | C19: -75.69 | D19: 111.2 | E19: -46.35 | F19: 357.83 | G19: -450.15 | H19: 383.16 | I19: 518.21 | J19: 83.35 | K19: -12.27
A20: Power and Fuel | B20: 4579.25 | C20: 4271.98 | D20: 6334.07 | E20: 9436.14 | F20: 8516.87 | G20: 8331.18 | H20: 12137.26 | I20: 18491.32 | J20: 18283.32 | K20: 18419.15
A21: Other Mfr. Exp | B21: 1933.88 | C21: 1991.28 | D21: 2289.53 | E21: 3001.06 | F21: 3043.3 | G21: 3067.38 | H21: 3889.67 | I21: 4344.34 | J21: 4898.17 | K21: 5474.61
A22: Employee Cost | B22: 1466.49 | C22: 1547.77 | D22: 1831.81 | E22: 2309.43 | F22: 2522.64 | G22: 2363.33 | H22: 2545 | I22: 2751.31 | J22: 3051.99 | K22: 3619.25
A23: Selling and admin | B23: 7200.47 | C23: 7149.12 | D23: 8320.28 | E23: 11563.8 | F23: 11237.32 | G23: 11266.02 | H23: 13282.22 | I23: 15859.6 | J23: 18066.95 | K23: 19571.95
A24: Other Expenses | B24: 654.67 | C24: 709.76 | D24: 769.12 | E24: 821.8 | F24: 1345.73 | G24: 1044.17 | H24: 1265.34 | I24: 1458.6 | J24: 1726.23 | K24: 2369.56
A25: Other Income | B25: 463.81 | C25: 648.12 | D25: 241.97 | E25: 350.1 | F25: 651.06 | G25: 618.52 | H25: 669.43 | I25: 507.11 | J25: 556.96 | K25: 396.74
A26: Depreciation | B26: 1377.17 | C26: 1348.41 | D26: 1847.93 | E26: 2450.73 | F26: 2722.66 | G26: 2700.23 | H26: 2714.75 | I26: 2887.99 | J26: 3145.3 | K26: 4014.95
A27: Interest | B27: 566.3 | C27: 640.1 | D27: 1237.6 | E27: 1777.86 | F27: 1991.65 | G27: 1485.65 | H27: 944.71 | I27: 822.72 | J27: 968 | K27: 1650.54
... A31: Dividend Amount | B31: 260.71 | C31: 274.51 | D31: 288.34 | E31: 315.84 | F31: 375.22 | G31: 1068 | H31: 1096.95 | I31: 1097.02 | J31: 2020.83 | K31: 2283.77
A40: Quarters
A41: Report Date | B41: 45199 | C41: 45291 | D41: 45382 | E41: 45473 | F41: 45565 | G41: 45657 | H41: 45747 | I41: 45838 | J41: 45930 | K41: 46022
A42: Sales | B42: 16012.13 | C42: 16739.97 | D42: 20418.94 | E42: 18818.56 | F42: 16294.42 | G42: 17778.83 | H42: 23063.32 | I42: 21275.45 | J42: 19606.93 | K42: 21829.68
A43: Expenses | B43: 13461.24 | C43: 13485.4 | D43: 16305.02 | E43: 15801.46 | F43: 14268.68 | G43: 14885.35 | H43: 18455.65 | I43: 16869.42 | J43: 16518.27 | K43: 17918.91
A44: Other Income | B44: 170.62 | C44: 146.24 | D44: 72.67 | E44: 83.31 | F44: 226.22 | G44: 247.32 | H44: 92.78 | I44: 141.85 | J44: 174.14 | K44: 46.35
A45: Depreciation | B45: 797.83 | C45: 783.48 | D45: 814.92 | E45: 917.93 | F45: 979.67 | G45: 992.78 | H45: 1124.57 | I45: 1106.78 | J45: 1147.68 | K45: 1181.9
A46: Interest | B46: 233.94 | C46: 262.16 | D46: 261.15 | E46: 325.76 | F46: 392.99 | G46: 456.75 | H46: 475.04 | I46: 433.3 | J46: 459.29 | K46: 492.2
A47: Profit before tax | B47: 1689.74 | C47: 2355.17 | D47: 3110.52 | E47: 1856.72 | F47: 879.3 | G47: 1691.27 | H47: 3100.84 | I47: 3007.8 | J47: 1655.83 | K47: 2283.02
A48: Tax | B48: 409.36 | C48: 580.39 | D48: 851.94 | E48: 363.27 | F48: 171.34 | G48: 327.83 | H48: 626.05 | I48: 786.89 | J48: 417.85 | K48: 553.58
A49: Net profit | B49: 1281.45 | C49: 1776.98 | D49: 2258.12 | E49: 1494.82 | F49: 702.82 | G49: 1359.43 | H49: 2482.04 | I49: 2225.9 | J49: 1231.58 | K49: 1725.4
A50: Operating Profit | B50: 2550.89 | C50: 3254.57 | D50: 4113.92 | E50: 3017.1 | F50: 2025.74 | G50: 2893.48 | H50: 4607.67 | I50: 4406.03 | J50: 3088.66 | K50: 3910.77
A55: BALANCE SHEET
A56: Report Date | B56: 42460 | C56: 42825 | D56: 43190 | E56: 43555 | F56: 43921 | G56: 44286 | H56: 44651 | I56: 45016 | J56: 45382 | K56: 45747
A57: Equity Share Capital | B57: 274.43 | C57: 274.51 | D57: 274.61 | E57: 274.64 | F57: 288.63 | G57: 288.65 | H57: 288.67 | I57: 288.69 | J57: 288.69 | K57: 294.68
A58: Reserves | B58: 21671.2 | C58: 24117.38 | D58: 26106.55 | E58: 33476.01 | F58: 38755.13 | G58: 43886.03 | H58: 50146.6 | I58: 54035.85 | J58: 59938.79 | K58: 70412.09
A59: Borrowings | B59: 10615.99 | C59: 8474.49 | D59: 19480.22 | E59: 25337 | F59: 23018.96 | G59: 21719.39 | H59: 11298.8 | I59: 11057.74 | J59: 11402.95 | K59: 24102.18
A60: Other Liabilities | B60: 8631.49 | C60: 9342.73 | D60: 11279.71 | E60: 17437.72 | F60: 17151.09 | G60: 20282.28 | H60: 22077.37 | I60: 25998.12 | J60: 29166.68 | K60: 38823.11
A61: Total | B61: 41193.11 | C61: 42209.11 | D61: 57141.09 | E61: 76525.37 | F61: 79213.81 | G61: 86176.35 | H61: 83811.44 | I61: 91380.4 | J61: 100797.11 | K61: 133632.06
...

Sheet CF Data
C2: 42430 | D2: 42795 | E2: 43160 | F2: 43525 | G2: 43891 | H2: 44256 | I2: 44621 | J2: 44986 | K2: 45352 | L2: 45717
B3: Cash from Operating Activity - | C3: 4526 | D3: 5005 | E3: 3888 | F3: 5956 | G3: 8972 | H3: 12500 | I3: 9283 | J3: 9069 | K3: 10898 | L3: 10673
B4: Profit from operations | C4: 4948 | D4: 5220 | E4: 5986 | F4: 7362 | G4: 9348 | H4: 11465 | I4: 11311 | J4: 10530 | K4: 13029 | L4: 12645
B5: Receivables | C5: -287 | D5: 156 | E5: -454 | F5: -279 | G5: 473 | H5: -201 | I5: -495 | J5: -752 | K5: -421 | L5: -608
B6: Inventory | C6: 374 | D6: 54 | E6: -623 | F6: -15 | G6: -64 | H6: 165 | I6: -1579 | J6: -992 | K6: -1712 | L6: -317
B7: Payables | C7: 310 | D7: 482 | E7: 346 | F7: 766 | G7: 279 | H7: 2868 | I7: 2077 | J7: 1869 | K7: 1959 | L7: -476
B8: Loans Advances | C8: 0 | D8: 0 | E8: 0 | F8: 0 | G8: 0 | H8: 0 | I8: 0 | J8: 0 | K8: 0 | L8: 0
B9: Other WC items | C9: 32 | D9: -162 | E9: -525 | F9: -1167 | G9: -172 | H9: -505 | I9: -476 | J9: -461 | K9: -308 | L9: 729
B10: Working capital changes | C10: 429 | D10: 529 | E10: -1255 | F10: -696 | G10: 516 | H10: 2326 | I10: -473 | J10: -337 | K10: -481 | L10: -671
B11: Direct taxes | C11: -852 | D11: -744 | E11: -843 | F11: -710 | G11: -891 | H11: -1291 | I11: -1555 | J11: -1124 | K11: -1651 | L11: -1301
B12: Other operating items | C12: 0 | D12: 0 | E12: 0 | F12: 0 | G12: 0 | H12: 0 | I12: 0 | J12: 0 | K12: 0 | L12: 0
B13: Cash from Investing Activity - | C13: -3673 | D13: -2501 | E13: 1866 | F13: 1165 | G13: -4192 | H13: -8856 | I13: 2257 | J13: -7188 | K13: -8789 | L13: -15836
B14: Fixed assets purchased | C14: -2150 | D14: -1402 | E14: -2103 | F14: -1808 | G14: -1766 | H14: -1925 | I14: -5613 | J14: -6200 | K14: -9006 | L14: -9129
... B33: Net Cash Flow | C33: 8 | D33: -31 | E33: 18 | F33: 364 | G33: -295 | H33: -712 | I33: -958 | J33: 250 | K33: 183 | L33: -86

Sheet StockData
B2: Date | C2: UltraTech Cement | D2: Nifty 50 | J2: Price | K2: Open | L2: High | M2: Low | N2: Vol. | O2: Change % | P2: Date | Q2: Price | R2: Open | S2: High | T2: Low | U2: Vol. | V2: Change %
B3: 46134 | C3: 12193 | D3: 24378.1 | K3: 12013 | L3: 12222 | M3: 12001 | N3: 312.31K | O3: 0.0128 | P3: 46134 | R3: 24470.85 | S3: 24515.75 | T3: 24353.85 | U3: 440.52M | V3: -0.0081
B4: 46133 | C4: 12039 | D4: 24576.6 | E4: =C3/C4-1 -> 0.01279176 | F4: =D3/D4-1 -> -0.0080767885 | K4: 11800 | L4: 12065 | M4: 11800 | N4: 320.11K | O4: 0.0102 | P4: 46133 | R4: 24374.55 | S4: 24601.7 | T4: 24354.9 | U4: 425.83M | V4: 0.0087
B5: 46132 | C5: 11917 | D5: 24364.85 | E5: =C4/C5-1 -> 0.010237476 | F5: =D4/D5-1 -> 0.0086907984 | K5: 11970 | L5: 12062 | M5: 11816 | N5: 335.62K | O5: 0.0026 | P5: 46132 | R5: 24391.5 | S5: 24480.65 | T5: 24241.25 | U5: 415.94M | V5: 0.0005
B6: 46129 | C6: 11886 | D6: 24353.55 | E6: =C5/C6-1 -> 0.0026081104 | F6: =D5/D6-1 -> 0.00046399806 | K6: 11820 | L6: 11930 | M6: 11737 | N6: 165.11K | O6: 0.0051 | P6: 46129 | R6: 24165.9 | S6: 24371.9 | T6: 24096.05 | U6: 498.63M | V6: 0.0065
B7: 46128 | C7: 11826 | D7: 24196.75 | E7: =C6/C7-1 -> 0.0050735667 | F7: =D6/D7-1 -> 0.0064802091 | K7: 11840 | L7: 11859 | M7: 11710 | N7: 308.55K | O7: 0.0035 | P7: 46128 | R7: 24385.2 | S7: 24400.95 | T7: 24102.8 | U7: 508.02M | V7: -0.0014
B8: 46127 | C8: 11785 | D8: 24231.3 | E8: =C7/C8-1 -> 0.0034789987 | F8: =D7/D8-1 -> -0.0014258418 | K8: 11840 | L8: 11950 | M8: 11711 | N8: 274.81K | O8: 0.0246 | P8: 46127 | R8: 24163.8 | S8: 24280.9 | T8: 24145.8 | U8: 460.33M | V8: 0.0163
B9: 46125 | C9: 11502 | D9: 23842.65 | E9: =C8/C9-1 -> 0.024604417 | F9: =D8/D9-1 -> 0.016300621 | K9: 11366 | L9: 11522 | M9: 11282 | N9: 220.44K | O9: -0.0075 | P9: 46125 | R9: 23589.6 | S9: 23907.4 | T9: 23555.6 | U9: 488.84M | V9: -0.0086
B10: 46122 | C10: 11589 | D10: 24050.6 | E10: =C9/C10-1 -> -0.0075071188 | F10: =D9/D10-1 -> -0.0086463539 | K10: 11500 | L10: 11643 | M10: 11476 | N10: 420.34K | O10: 0.0123 | P10: 46122 | R10: 23880.55 | S10: 24074.05 | T10: 23856.35 | U10: 481.30M | V10: 0.0116
B11: 46121 | C11: 11448 | D11: 23775.1 | E11: =C10/C11-1 -> 0.012316562 | F11: =D10/D11-1 -> 0.011587754 | K11: 11425 | L11: 11562 | M11: 11390 | N11: 330.55K | O11: -0.0134 | P11: 46121 | R11: 23909.05 | S11: 23990.75 | T11: 23682.8 | U11: 466.59M | V11: -0.0093
B12: 46120 | C12: 11603 | D12: 23997.35 | E12: =C11/C12-1 -> -0.013358614 | F12: =D11/D12-1 -> -0.0092614393 | K12: 11400 | L12: 11776 | M12: 11349 | N12: 612.76K | O12: 0.061 | P12: 46120 | R12: 23855.15 | S12: 24025.15 | T12: 23828.5 | U12: 639.26M | V12: 0.0378
B13: 46119 | C13: 10936 | D13: 23123.65 | E13: =C12/C13-1 -> 0.060991222 | F13: =D12/D13-1 -> 0.037783827 | K13: 10922 | L13: 10954 | M13: 10765 | N13: 263.66K | O13: -0.0017 | P13: 46119 | R13: 22838.7 | S13: 23153.85 | T13: 22719.3 | U13: 476.98M | V13: 0.0068
B14: 46118 | C14: 10955 | D14: 22968.25 | E14: =C13/C14-1 -> -0.0017343679 | F14: =D13/D14-1 -> 0.0067658616 | K14: 10611 | L14: 10976 | M14: 10540 | N14: 374.42K | O14: 0.0315 | P14: 46118 | R14: 22780.3 | S14: 22998.35 | T14: 22542.95 | U14: 426.42M | V14: 0.0112
B15: 46114 | C15: 10620 | D15: 22713.1 | E15: =C14/C15-1 -> 0.031544256 | F15: =D14/D15-1 -> 0.011233605 | K15: 10639 | L15: 10663 | M15: 10365 | N15: 333.52K | O15: -0.0088 | P15: 46114 | R15: 22383.4 | S15: 22782.3 | T15: 22182.55 | U15: 495.12M | V15: 0.0015
... B268: 45740 | C268: 11051.2 | D268: 23658.35 | E268: =C267/C268-1 -> 0.033480527 | F268: =D267/D268-1 -> 0.00043536426 | K268: 11018.95 | L268: 11077.95 | M268: 10853.85 | N268: 294.69K | O268: 0.0068 | P268: 45740 | R268: 23515.4 | S268: 23708.75 | T268: 23433.5 | U268: 311.90M | V268: 0.0132

Sheet Historical->

Sheet Inc_Stat
D2: UltraTech Cement Ltd (NSE: ULTRACEMCO)
D3: Income Statement
D4: (Figures are in ₹ Cr, except price per share)
D6: Reported Income Statement
F7: Fiscal Year Ending March 31, | P7: ='Historical FS'!M11 -> LTM
D8: Particulars | F8: ='Historical FS'!C11 -> 42460 | G8: ='Historical FS'!D11 -> 42825 | H8: ='Historical FS'!E11 -> 43190 | I8: ='Historical FS'!F11 -> 43555 | J8: ='Historical FS'!G11 -> 43921 | K8: ='Historical FS'!H11 -> 44286 | L8: ='Historical FS'!I11 -> 44651 | M8: ='Historical FS'!J11 -> 45016 | ... O8: ='Historical FS'!L11 -> 45747 | P8: 03/31/2026
D9: Revenue | F9: ='Historical FS'!C14 -> 25153.24 | G9: ='Historical FS'!D14 -> 25374.94 | H9: ='Historical FS'!E14 -> 30978.62 | I9: ='Historical FS'!F14 -> 41462.26 | J9: ='Historical FS'!G14 -> 42429.89 | K9: ='Historical FS'!H14 -> 44725.8 | L9: ='Historical FS'!I14 -> 52598.83 | M9: ='Historical FS'!J14 -> 63239.98 | ... P9: ='Historical FS'!M14 -> 62712.06
D10: % Growth | F10: NA | G10: =G9/F9-1 -> 0.0088139739 | H10: =H9/G9-1 -> 0.2208352 | I10: =I9/H9-1 -> 0.33841533 | J10: =J9/I9-1 -> 0.023337609 | K10: =K9/J9-1 -> 0.054110675 | L10: =L9/K9-1 -> 0.17602882 | M10: =M9/L9-1 -> 0.20230773 | N10: =N9/M9-1 -> 0.12125494 | ... P10: =P9/O9-1 -> -0.17435386
D11: Cost of Goods Sold | F11: ='Historical FS'!C15 -> 12397.13 | G11: ='Historical FS'!D15 -> 12303.62 | H11: ='Historical FS'!E15 -> 15744.19 | I11: ='Historical FS'!F15 -> 21729.72 | J11: ='Historical FS'!G15 -> 20600.87 | K11: ='Historical FS'!H15 -> 20847.7 | L11: ='Historical FS'!I15 -> 26536.92 | M11: ='Historical FS'!J15 -> 35301.93 | ... P11: ='Historical FS'!M15 -> 51306.6
D12: % Margin | F12: =ABS(F11/F$9) -> 0.49286414 | G12: =ABS(G11/G$9) -> 0.48487287 | H12: =ABS(H11/H$9) -> 0.50822761 | I12: =ABS(I11/I$9) -> 0.52408431 | J12: =ABS(J11/J$9) -> 0.4855273 | K12: =ABS(K11/K$9) -> 0.46612246 | L12: =ABS(L11/L$9) -> 0.5045154 | M12: =ABS(M11/M$9) -> 0.55822171 | ... P12: =ABS(P11/P$9) -> 0.81812972
D13: Gross Margin | F13: =F9-F11 -> 12756.11 | G13: =G9-G11 -> 13071.32 | H13: =H9-H11 -> 15234.43 | I13: =I9-I11 -> 19732.54 | J13: =J9-J11 -> 21829.02 | K13: =K9-K11 -> 23878.1 | L13: =L9-L11 -> 26061.91 | M13: =M9-M11 -> 27938.05 | ... P13: =P9-P11 -> 11405.46
D14: % Margin | F14: =ABS(F13/F$9) -> 0.50713586 | G14: =ABS(G13/G$9) -> 0.51512713 | H14: =ABS(H13/H$9) -> 0.49177239 | I14: =ABS(I13/I$9) -> 0.47591569 | J14: =ABS(J13/J$9) -> 0.5144727 | K14: =ABS(K13/K$9) -> 0.53387754 | L14: =ABS(L13/L$9) -> 0.4954846 | M14: =ABS(M13/M$9) -> 0.44177829 | ... P14: =ABS(P13/P$9) -> 0.18187028
D16: Selling, General & Administration | F16: =-'Historical FS'!C17 -> -7855.14 | G16: =-'Historical FS'!D17 -> -7858.88 | H16: =-'Historical FS'!E17 -> -9089.4 | I16: =-'Historical FS'!F17 -> -12385.6 | J16: =-'Historical FS'!G17 -> -12583.05 | K16: =-'Historical FS'!H17 -> -12310.19 | L16: =-'Historical FS'!I17 -> -14547.56 | M16: =-'Historical FS'!J17 -> -17318.2 | ... P16: =-'Historical FS'!M17 -> 0
D17: % Margin | F17: =ABS(F16/F$9) -> 0.31229138 | G17: =ABS(G16/G$9) -> 0.30971029 | H17: =ABS(H16/H$9) -> 0.29340881 | I17: =ABS(I16/I$9) -> 0.29871985 | J17: =ABS(J16/J$9) -> 0.29656099 | K17: =ABS(K16/K$9) -> 0.27523689 | L17: =ABS(L16/L$9) -> 0.27657573 | M17: =ABS(M16/M$9) -> 0.27384892 | ... P17: =ABS(P16/P$9) -> 0
D18: EBITDA | F18: =F13+F16 -> 4900.97 | G18: =G13+G16 -> 5212.44 | H18: =H13+H16 -> 6145.03 | I18: =I13+I16 -> 7346.94 | J18: =J13+J16 -> 9245.97 | K18: =K13+K16 -> 11567.91 | L18: =L13+L16 -> 11514.35 | M18: =M13+M16 -> 10619.85 | ... P18: =P13+P16 -> 11405.46
D19: % Margin | F19: =ABS(F18/F$9) -> 0.19484448 | G19: =ABS(G18/G$9) -> 0.20541684 | H19: =ABS(H18/H$9) -> 0.19836358 | I19: =ABS(I18/I$9) -> 0.17719584 | J19: =ABS(J18/J$9) -> 0.21791171 | K19: =ABS(K18/K$9) -> 0.25864065 | L19: =ABS(L18/L$9) -> 0.21890886 | M19: =ABS(M18/M$9) -> 0.16792937 | ... P19: =ABS(P18/P$9) -> 0.18187028
D21: Depreciation | F21: =-'Historical FS'!C19 -> -1377.17 | G21: =-'Historical FS'!D19 -> -1348.41 | H21: =-'Historical FS'!E19 -> -1847.93 | I21: =-'Historical FS'!F19 -> -2450.73 | J21: =-'Historical FS'!G19 -> -2722.66 | K21: =-'Historical FS'!H19 -> -2700.23 | L21: =-'Historical FS'!I19 -> -2714.75 | M21: =-'Historical FS'!J19 -> -2887.99 | ... P21: =-'Historical FS'!M19 -> -3436.36
D22: % Margin | F22: =ABS(F21/F$9) -> 0.054751197 | G22: =ABS(G21/G$9) -> 0.053139436 | H22: =ABS(H21/H$9) -> 0.059651786 | I22: =ABS(I21/I$9) -> 0.059107487 | J22: =ABS(J21/J$9) -> 0.064168444 | K22: =ABS(K21/K$9) -> 0.060372984 | L22: =ABS(L21/L$9) -> 0.051612365 | M22: =ABS(M21/M$9) -> 0.045667155 | ... P22: =ABS(P21/P$9) -> 0.05479584
D23: EBIT | F23: =F18+F21 -> 3523.8 | G23: =G18+G21 -> 3864.03 | H23: =H18+H21 -> 4297.1 | I23: =I18+I21 -> 4896.21 | J23: =J18+J21 -> 6523.31 | K23: =K18+K21 -> 8867.68 | L23: =L18+L21 -> 8799.6 | M23: =M18+M21 -> 7731.86 | ... P23: =P18+P21 -> 7969.1
D24: % Margin | F24: =ABS(F23/F$9) -> 0.14009328 | G24: =ABS(G23/G$9) -> 0.1522774 | H24: =ABS(H23/H$9) -> 0.1387118 | I24: =ABS(I23/I$9) -> 0.11808835 | J24: =ABS(J23/J$9) -> 0.15374327 | K24: =ABS(K23/K$9) -> 0.19826767 | L24: =ABS(L23/L$9) -> 0.1672965 | M24: =ABS(M23/M$9) -> 0.12226221 | ... P24: =ABS(P23/P$9) -> 0.12707444
D26: Interest Expense | F26: =-'Historical FS'!C20 -> -566.3 | G26: =-'Historical FS'!D20 -> -640.1 | H26: =-'Historical FS'!E20 -> -1237.6 | I26: =-'Historical FS'!F20 -> -1777.86 | J26: =-'Historical FS'!G20 -> -1991.65 | K26: =-'Historical FS'!H20 -> -1485.65 | L26: =-'Historical FS'!I20 -> -944.71 | M26: =-'Historical FS'!J20 -> -822.72 | ... P26: =-'Historical FS'!M20 -> -1384.79
D27: % Margin | F27: =ABS(F26/F$9) -> 0.022513998 | G27: =ABS(G26/G$9) -> 0.025225675 | H27: =ABS(H26/H$9) -> 0.039950133 | I27: =ABS(I26/I$9) -> 0.042878994 | J27: =ABS(J26/J$9) -> 0.046939787 | K27: =ABS(K26/K$9) -> 0.033216846 | L27: =ABS(L26/L$9) -> 0.017960666 | M27: =ABS(M26/M$9) -> 0.013009492 | ... P27: =ABS(P26/P$9) -> 0.022081718
D28: Profit Before Taxes | F28: =F23+F26 -> 2957.5 | G28: =G23+G26 -> 3223.93 | H28: =H23+H26 -> 3059.5 | I28: =I23+I26 -> 3118.35 | J28: =J23+J26 -> 4531.66 | K28: =K23+K26 -> 7382.03 | L28: =L23+L26 -> 7854.89 | M28: =M23+M26 -> 6909.14 | ... P28: =P23+P26 -> 6584.31
D29: % Margin | F29: =ABS(F28/F$9) -> 0.11757929 | G29: =ABS(G28/G$9) -> 0.12705173 | H29: =ABS(H28/H$9) -> 0.098761662 | I29: =ABS(I28/I$9) -> 0.075209359 | J29: =ABS(J28/J$9) -> 0.10680348 | K29: =ABS(K28/K$9) -> 0.16505082 | L29: =ABS(L28/L$9) -> 0.14933583 | M29: =ABS(M28/M$9) -> 0.10925272 | ... P29: =ABS(P28/P$9) -> 0.10499272
D31: Taxes | F31: =-'Historical FS'!C22 -> -941.69 | G31: =-'Historical FS'!D22 -> -1158.54 | H31: =-'Historical FS'!E22 -> -1077.01 | I31: =-'Historical FS'!F22 -> -1068.07 | J31: =-'Historical FS'!G22 -> 568.16 | K31: =-'Historical FS'!H22 -> -2538.7 | L31: =-'Historical FS'!I22 -> -1190.06 | M31: =-'Historical FS'!J22 -> -2342.85 | ... P31: =-'Historical FS'!M22 -> -1758.32
D32: % Tax Rate | F32: =ABS(F31/F$28) -> 0.31840744 | G32: =ABS(G31/G$28) -> 0.35935644 | H32: =ABS(H31/H$28) -> 0.35202157 | I32: =ABS(I31/I$28) -> 0.34251126 | J32: =ABS(J31/J$28) -> 0.12537569 | K32: =ABS(K31/K$28) -> 0.34390269 | L32: =ABS(L31/L$28) -> 0.15150562 | M32: =ABS(M31/M$28) -> 0.3390943 | ... O32: =ABS(O31/O$28) -> 0.20872369 | P32: =ABS(P31/P$9) -> 0.028037988
D33: Net Profit | F33: =F28+F31 -> 2015.81 | G33: =G28+G31 -> 2065.39 | H33: =H28+H31 -> 1982.49 | I33: =I28+I31 -> 2050.28 | J33: =J28+J31 -> 5099.82 | K33: =K28+K31 -> 4843.33 | L33: =L28+L31 -> 6664.83 | M33: =M28+M31 -> 4566.29 | ... P33: =P28+P31 -> 4825.99
D34: % Margin | F34: =ABS(F33/F$9) -> 0.080141167 | G34: =ABS(G33/G$9) -> 0.081394872 | H34: =ABS(H33/H$9) -> 0.063995427 | I34: =ABS(I33/I$9) -> 0.049449306 | J34: =ABS(J33/J$9) -> 0.12019404 | K34: =ABS(K33/K$9) -> 0.1082894 | L34: =ABS(L33/L$9) -> 0.12671061 | M34: =ABS(M33/M$9) -> 0.072205747 | ... P34: =ABS(P33/P$9) -> 0.076954736
D36: Fully Diluted Shares | F36: ='Historical FS'!C26 -> 27.44 | G36: ='Historical FS'!D26 -> 27.45 | H36: ='Historical FS'!E26 -> 27.46 | I36: ='Historical FS'!F26 -> 27.46 | J36: ='Historical FS'!G26 -> 28.86 | K36: ='Historical FS'!H26 -> 28.87 | L36: ='Historical FS'!I26 -> 28.87 | M36: ='Historical FS'!J26 -> 28.87 | ... O36: ='Historical FS'!L26 -> 29.47 | P36: =O36 -> 29.47
D38: Earnings per Share (₹) | F38: =F33/F36 -> 73.462464 | G38: =G33/G36 -> 75.241894 | H38: =H33/H36 -> 72.195557 | I38: =I33/I36 -> 74.664239 | J38: =J33/J36 -> 176.70894 | K38: =K33/K36 -> 167.76342 | L38: =L33/L36 -> 230.8566 | M38: =M33/M36 -> 158.1673 | ... P38: =P33/P36 -> 163.75942
D39: % EPS Growth | F39: NA | G39: =G38/F38-1 -> 0.024222313 | H39: =H38/G38-1 -> -0.040487247 | I39: =I38/H38-1 -> 0.034194372 | J39: =J38/I38-1 -> 1.3667145 | K39: =K38/J38-1 -> -0.050622891 | L39: =L38/K38-1 -> 0.37608422 | M39: =M38/L38-1 -> -0.31486775 | N39: =N38/M38-1 -> 0.41186828 | ... P39: =P38/O38-1 -> -0.14476776
D41: Dividend per Share (₹) | F41: ='Data Sheet'!B31/Inc_Stat!F36 -> 9.5010933 | G41: ='Data Sheet'!C31/Inc_Stat!G36 -> 10.000364 | H41: ='Data Sheet'!D31/Inc_Stat!H36 -> 10.500364 | I41: ='Data Sheet'!E31/Inc_Stat!I36 -> 11.501821 | J41: ='Data Sheet'!F31/Inc_Stat!J36 -> 13.001386 | K41: ='Data Sheet'!G31/Inc_Stat!K36 -> 36.993419 | L41: ='Data Sheet'!H31/Inc_Stat!L36 -> 37.99619 | M41: ='Data Sheet'!I31/Inc_Stat!M36 -> 37.998614 | ... O41: ='Data Sheet'!K31/Inc_Stat!O36 -> 77.49474
D42: Dividend Payout Ratio | F42: =F41/F38 -> 0.12933263 | G42: =G41/G38 -> 0.13290952 | H42: =H41/H38 -> 0.14544336 | I42: =I41/I38 -> 0.15404725 | J42: =J41/J38 -> 0.073575146 | K42: =K41/K38 -> 0.22050944 | L42: =L41/L38 -> 0.16458784 | M42: =M41/M38 -> 0.24024317 | ... O42: =O41/O38 -> 0.40471566
D44: Retained Earnings (%) | F44: =(1-F42) -> 0.87066737 | G44: =(1-G42) -> 0.86709048 | H44: =(1-H42) -> 0.85455664 | I44: =(1-I42) -> 0.84595275 | J44: =(1-J42) -> 0.92642485 | K44: =(1-K42) -> 0.77949056 | L44: =(1-L42) -> 0.83541216 | M44: =(1-M42) -> 0.75975683 | ... O44: =(1-O42) -> 0.59528434

Sheet Bal_Sht
D2: UltraTech Cement Ltd (NSE: ULTRACEMCO)
D3: Balance Sheet
D4: (Figures are in ₹ Cr, except price per share)
D6: Reported Balance Sheet
F7: Fiscal Year Ending March 31,
D8: Particulars | F8: ='Historical FS'!C11 -> 42460 | G8: ='Historical FS'!D11 -> 42825 | H8: ='Historical FS'!E11 -> 43190 | I8: ='Historical FS'!F11 -> 43555 | J8: ='Historical FS'!G11 -> 43921 | K8: ='Historical FS'!H11 -> 44286 | L8: ='Historical FS'!I11 -> 44651 | M8: ='Historical FS'!J11 -> 45016 | ... O8: ='Historical FS'!L11 -> 45747
D9: Equity Share Capital | F9: ='Historical FS'!C37 -> 274.43 | G9: ='Historical FS'!D37 -> 274.51 | H9: ='Historical FS'!E37 -> 274.61 | I9: ='Historical FS'!F37 -> 274.64 | J9: ='Historical FS'!G37 -> 288.63 | K9: ='Historical FS'!H37 -> 288.65 | L9: ='Historical FS'!I37 -> 288.67 | M9: ='Historical FS'!J37 -> 288.69 | ... O9: ='Historical FS'!L37 -> 294.68
D10: Reserves | F10: ='Historical FS'!C38 -> 21671.2 | G10: ='Historical FS'!D38 -> 24117.38 | H10: ='Historical FS'!E38 -> 26106.55 | I10: ='Historical FS'!F38 -> 33476.01 | J10: ='Historical FS'!G38 -> 38755.13 | K10: ='Historical FS'!H38 -> 43886.03 | L10: ='Historical FS'!I38 -> 50146.6 | M10: ='Historical FS'!J38 -> 54035.85 | ... O10: ='Historical FS'!L38 -> 70412.09
D11: Borrowings | F11: ='Historical FS'!C39 -> 10615.99 | G11: ='Historical FS'!D39 -> 8474.49 | H11: ='Historical FS'!E39 -> 19480.22 | I11: ='Historical FS'!F39 -> 25337 | J11: ='Historical FS'!G39 -> 23018.96 | K11: ='Historical FS'!H39 -> 21719.39 | L11: ='Historical FS'!I39 -> 11298.8 | M11: ='Historical FS'!J39 -> 11057.74 | ... O11: ='Historical FS'!L39 -> 24102.18
D12: Other Liabilities | F12: ='Historical FS'!C40 -> 8631.49 | G12: ='Historical FS'!D40 -> 9342.73 | H12: ='Historical FS'!E40 -> 11279.71 | I12: ='Historical FS'!F40 -> 17437.72 | J12: ='Historical FS'!G40 -> 17151.09 | K12: ='Historical FS'!H40 -> 20282.28 | L12: ='Historical FS'!I40 -> 22077.37 | M12: ='Historical FS'!J40 -> 25998.12 | ... O12: ='Historical FS'!L40 -> 38823.11
D13: Total Liabilities & Equity | F13: =SUM(F9:F12) -> 41193.11 | G13: =SUM(G9:G12) -> 42209.11 | H13: =SUM(H9:H12) -> 57141.09 | I13: =SUM(I9:I12) -> 76525.37 | J13: =SUM(J9:J12) -> 79213.81 | K13: =SUM(K9:K12) -> 86176.35 | L13: =SUM(L9:L12) -> 83811.44 | M13: =SUM(M9:M12) -> 91380.4 | ... O13: =SUM(O9:O12) -> 133632.06
D15: Fixed Assets Net Block | F15: ='Historical FS'!C43 -> 25309.42 | G15: ='Historical FS'!D43 -> 25903.75 | H15: ='Historical FS'!E43 -> 39715.3 | I15: ='Historical FS'!F43 -> 56644.62 | J15: ='Historical FS'!G43 -> 57150.96 | K15: ='Historical FS'!H43 -> 55411.61 | L15: ='Historical FS'!I43 -> 55487.57 | M15: ='Historical FS'!J43 -> 59579 | ... O15: ='Historical FS'!L43 -> 94564.22
D16: Capital Work in Progress | F16: ='Historical FS'!C44 -> 1469.09 | G16: ='Historical FS'!D44 -> 921.48 | H16: ='Historical FS'!E44 -> 1511.21 | I16: ='Historical FS'!F44 -> 1153.32 | J16: ='Historical FS'!G44 -> 919.59 | K16: ='Historical FS'!H44 -> 1686.68 | L16: ='Historical FS'!I44 -> 4784.67 | M16: ='Historical FS'!J44 -> 4040.39 | ... O16: ='Historical FS'!L44 -> 6234.19
D17: Investments | F17: ='Historical FS'!C45 -> 5095.18 | G17: ='Historical FS'!D45 -> 6690.51 | H17: ='Historical FS'!E45 -> 5446.9 | I17: ='Historical FS'!F45 -> 2921.33 | J17: ='Historical FS'!G45 -> 5928.69 | K17: ='Historical FS'!H45 -> 12178.11 | L17: ='Historical FS'!I45 -> 6335.77 | M17: ='Historical FS'!J45 -> 7296.95 | ... O17: ='Historical FS'!L45 -> 5156.47
D18: Other Assets | F18: ='Historical FS'!C46 -> 2669.67 | G18: ='Historical FS'!D46 -> 2286.86 | H18: ='Historical FS'!E46 -> 4760.39 | I18: ='Historical FS'!F46 -> 8180.43 | J18: ='Historical FS'!G46 -> 8108.09 | K18: ='Historical FS'!H46 -> 8302.7 | L18: ='Historical FS'!I46 -> 8177.06 | M18: ='Historical FS'!J46 -> 8835.62 | ... O18: ='Historical FS'!L46 -> 10550.63
D19: Total Non Current Assets | F19: =SUM(F15:F18) -> 34543.36 | G19: =SUM(G15:G18) -> 35802.6 | H19: =SUM(H15:H18) -> 51433.8 | I19: =SUM(I15:I18) -> 68899.7 | J19: =SUM(J15:J18) -> 72107.33 | K19: =SUM(K15:K18) -> 77579.1 | L19: =SUM(L15:L18) -> 74785.07 | M19: =SUM(M15:M18) -> 79751.96 | ... O19: =SUM(O15:O18) -> 116505.51
D21: Receivables | F21: ='Historical FS'!C49 -> 1928.21 | G21: ='Historical FS'!D49 -> 1757.09 | H21: ='Historical FS'!E49 -> 2220.63 | I21: ='Historical FS'!F49 -> 2787.03 | J21: ='Historical FS'!G49 -> 2383.22 | K21: ='Historical FS'!H49 -> 2571.73 | L21: ='Historical FS'!I49 -> 3071.61 | M21: ='Historical FS'!J49 -> 3867.02 | ... O21: ='Historical FS'!L49 -> 5890.25
D22: Inventory | F22: ='Historical FS'!C50 -> 2454.58 | G22: ='Historical FS'!D50 -> 2400.64 | H22: ='Historical FS'!E50 -> 3267.59 | I22: ='Historical FS'!F50 -> 4098.96 | J22: ='Historical FS'!G50 -> 4183.35 | K22: ='Historical FS'!H50 -> 4017.97 | L22: ='Historical FS'!I50 -> 5595.58 | M22: ='Historical FS'!J50 -> 6611.83 | ... O22: ='Historical FS'!L50 -> 9562.98
D23: Cash & Bank | F23: ='Historical FS'!C51 -> 2266.96 | G23: ='Historical FS'!D51 -> 2248.78 | H23: ='Historical FS'!E51 -> 219.07 | I23: ='Historical FS'!F51 -> 739.68 | J23: ='Historical FS'!G51 -> 539.91 | K23: ='Historical FS'!H51 -> 2007.55 | L23: ='Historical FS'!I51 -> 359.18 | M23: ='Historical FS'!J51 -> 1149.59 | ... O23: ='Historical FS'!L51 -> 1673.32
D24: Total Current Assets | F24: =SUM(F21:F23) -> 6649.75 | G24: =SUM(G21:G23) -> 6406.51 | H24: =SUM(H21:H23) -> 5707.29 | I24: =SUM(I21:I23) -> 7625.67 | J24: =SUM(J21:J23) -> 7106.48 | K24: =SUM(K21:K23) -> 8597.25 | L24: =SUM(L21:L23) -> 9026.37 | M24: =SUM(M21:M23) -> 11628.44 | ... O24: =SUM(O21:O23) -> 17126.55
D25: Total Assets | F25: =F24+F19 -> 41193.11 | G25: =G24+G19 -> 42209.11 | H25: =H24+H19 -> 57141.09 | I25: =I24+I19 -> 76525.37 | J25: =J24+J19 -> 79213.81 | K25: =K24+K19 -> 86176.35 | L25: =L24+L19 -> 83811.44 | M25: =M24+M19 -> 91380.4 | ... O25: =O24+O19 -> 133632.06
D27: Balance Check | F27: =F13=F25 -> TRUE | G27: =G13=G25 -> TRUE | H27: =H13=H25 -> TRUE | I27: =I13=I25 -> TRUE | J27: =J13=J25 -> TRUE | K27: =K13=K25 -> TRUE | L27: =L13=L25 -> TRUE | M27: =M13=M25 -> TRUE | ... O27: =O13=O25 -> TRUE

Sheet Cash_Flow
D2: UltraTech Cement Ltd (NSE: ULTRACEMCO)
D3: Cash Flow Statement
D4: (Figures are in ₹ Cr, except price per share)
D6: Reported Cash Flow Statement
F7: Fiscal Year Ending March 31,
D8: Particulars | F8: ='Historical FS'!C11 -> 42460 | G8: ='Historical FS'!D11 -> 42825 | H8: ='Historical FS'!E11 -> 43190 | I8: ='Historical FS'!F11 -> 43555 | J8: ='Historical FS'!G11 -> 43921 | K8: ='Historical FS'!H11 -> 44286 | L8: ='Historical FS'!I11 -> 44651 | M8: ='Historical FS'!J11 -> 45016 | ... O8: ='Historical FS'!L11 -> 45747
D9: Operating Activities
D10: Profit from operations | F10: ='Historical FS'!C59 -> 4948 | G10: ='Historical FS'!D59 -> 5220 | H10: ='Historical FS'!E59 -> 5986 | I10: ='Historical FS'!F59 -> 7362 | J10: ='Historical FS'!G59 -> 9348 | K10: ='Historical FS'!H59 -> 11465 | L10: ='Historical FS'!I59 -> 11311 | M10: ='Historical FS'!J59 -> 10530 | ... O10: ='Historical FS'!L59 -> 12645
D11: Receivables | F11: ='Historical FS'!C60 -> -287 | G11: ='Historical FS'!D60 -> 156 | H11: ='Historical FS'!E60 -> -454 | I11: ='Historical FS'!F60 -> -279 | J11: ='Historical FS'!G60 -> 473 | K11: ='Historical FS'!H60 -> -201 | L11: ='Historical FS'!I60 -> -495 | M11: ='Historical FS'!J60 -> -752 | ... O11: ='Historical FS'!L60 -> -608
D12: Inventory | F12: ='Historical FS'!C61 -> 374 | G12: ='Historical FS'!D61 -> 54 | H12: ='Historical FS'!E61 -> -623 | I12: ='Historical FS'!F61 -> -15 | J12: ='Historical FS'!G61 -> -64 | K12: ='Historical FS'!H61 -> 165 | L12: ='Historical FS'!I61 -> -1579 | M12: ='Historical FS'!J61 -> -992 | ... O12: ='Historical FS'!L61 -> -317
D13: Payables | F13: ='Historical FS'!C62 -> 310 | G13: ='Historical FS'!D62 -> 482 | H13: ='Historical FS'!E62 -> 346 | I13: ='Historical FS'!F62 -> 766 | J13: ='Historical FS'!G62 -> 279 | K13: ='Historical FS'!H62 -> 2868 | L13: ='Historical FS'!I62 -> 2077 | M13: ='Historical FS'!J62 -> 1869 | ... O13: ='Historical FS'!L62 -> -476
D14: Loans Advances | F14: ='Historical FS'!C63 -> 0 | G14: ='Historical FS'!D63 -> 0 | H14: ='Historical FS'!E63 -> 0 | I14: ='Historical FS'!F63 -> 0 | J14: ='Historical FS'!G63 -> 0 | K14: ='Historical FS'!H63 -> 0 | L14: ='Historical FS'!I63 -> 0 | M14: ='Historical FS'!J63 -> 0 | ... O14: ='Historical FS'!L63 -> 0
D15: Other WC items | F15: ='Historical FS'!C64 -> 32 | G15: ='Historical FS'!D64 -> -162 | H15: ='Historical FS'!E64 -> -525 | I15: ='Historical FS'!F64 -> -1167 | J15: ='Historical FS'!G64 -> -172 | K15: ='Historical FS'!H64 -> -505 | L15: ='Historical FS'!I64 -> -476 | M15: ='Historical FS'!J64 -> -461 | ... O15: ='Historical FS'!L64 -> 729
D16: Working capital changes | F16: =SUM(F11:F15) -> 429 | G16: =SUM(G11:G15) -> 530 | H16: =SUM(H11:H15) -> -1256 | I16: =SUM(I11:I15) -> -695 | J16: =SUM(J11:J15) -> 516 | K16: =SUM(K11:K15) -> 2327 | L16: =SUM(L11:L15) -> -473 | M16: =SUM(M11:M15) -> -336 | ... O16: =SUM(O11:O15) -> -672
D17: Direct taxes | F17: ='Historical FS'!C66 -> -852 | G17: ='Historical FS'!D66 -> -744 | H17: ='Historical FS'!E66 -> -843 | I17: ='Historical FS'!F66 -> -710 | J17: ='Historical FS'!G66 -> -891 | K17: ='Historical FS'!H66 -> -1291 | L17: ='Historical FS'!I66 -> -1555 | M17: ='Historical FS'!J66 -> -1124 | ... O17: ='Historical FS'!L66 -> -1301
D18: Other operating items | F18: ='Historical FS'!C67 -> 0 | G18: ='Historical FS'!D67 -> 0 | H18: ='Historical FS'!E67 -> 0 | I18: ='Historical FS'!F67 -> 0 | J18: ='Historical FS'!G67 -> 0 | K18: ='Historical FS'!H67 -> 0 | L18: ='Historical FS'!I67 -> 0 | M18: ='Historical FS'!J67 -> 0 | ... O18: ='Historical FS'!L67 -> 0
D19: Cash Flow from Operating Activities | F19: =F10+F16+F17+F18 -> 4525 | G19: =G10+G16+G17+G18 -> 5006 | H19: =H10+H16+H17+H18 -> 3887 | I19: =I10+I16+I17+I18 -> 5957 | J19: =J10+J16+J17+J18 -> 8973 | K19: =K10+K16+K17+K18 -> 12501 | L19: =L10+L16+L17+L18 -> 9283 | M19: =M10+M16+M17+M18 -> 9070 | ... O19: =O10+O16+O17+O18 -> 10672
D21: Investing Activities
D22: Fixed assets purchased | F22: ='Historical FS'!C70 -> -2150 | G22: ='Historical FS'!D70 -> -1402 | H22: ='Historical FS'!E70 -> -2103 | I22: ='Historical FS'!F70 -> -1808 | J22: ='Historical FS'!G70 -> -1766 | K22: ='Historical FS'!H70 -> -1925 | L22: ='Historical FS'!I70 -> -5613 | M22: ='Historical FS'!J70 -> -6200 | ... O22: ='Historical FS'!L70 -> -9129
D23: Fixed assets sold | F23: ='Historical FS'!C71 -> 18 | G23: ='Historical FS'!D71 -> 35 | H23: ='Historical FS'!E71 -> 220 | I23: ='Historical FS'!F71 -> 160 | J23: ='Historical FS'!G71 -> 79 | K23: ='Historical FS'!H71 -> 86 | L23: ='Historical FS'!I71 -> 73 | M23: ='Historical FS'!J71 -> 95 | ... O23: ='Historical FS'!L71 -> 179
D24: Investments purchased | F24: ='Historical FS'!C72 -> -2698 | G24: ='Historical FS'!D72 -> -3377 | H24: ='Historical FS'!E72 -> -3960 | I24: ='Historical FS'!F72 -> -1700 | J24: ='Historical FS'!G72 -> -6086 | K24: ='Historical FS'!H72 -> -12689 | L24: ='Historical FS'!I72 -> -7795 | M24: ='Historical FS'!J72 -> -7260 | ... O24: ='Historical FS'!L72 -> -15885
D25: Investments sold | F25: ='Historical FS'!C73 -> 2948 | G25: ='Historical FS'!D73 -> 2228 | H25: ='Historical FS'!E73 -> 5588 | I25: ='Historical FS'!F73 -> 4478 | J25: ='Historical FS'!G73 -> 3443 | K25: ='Historical FS'!H73 -> 7101 | L25: ='Historical FS'!I73 -> 13965 | M25: ='Historical FS'!J73 -> 7156 | ... O25: ='Historical FS'!L73 -> 19115
D26: Interest received | F26: ='Historical FS'!C74 -> 59 | G26: ='Historical FS'!D74 -> 47 | H26: ='Historical FS'!E74 -> 67 | I26: ='Historical FS'!F74 -> 78 | J26: ='Historical FS'!G74 -> 89 | K26: ='Historical FS'!H74 -> 77 | L26: ='Historical FS'!I74 -> 174 | M26: ='Historical FS'!J74 -> 283 | ... O26: ='Historical FS'!L74 -> 342
D27: Dividends received | F27: ='Historical FS'!C75 -> 0 | G27: ='Historical FS'!D75 -> 0 | H27: ='Historical FS'!E75 -> 0 | I27: ='Historical FS'!F75 -> 22 | J27: ='Historical FS'!G75 -> 32 | K27: ='Historical FS'!H75 -> 0 | L27: ='Historical FS'!I75 -> 0 | M27: ='Historical FS'!J75 -> 0 | ... O27: ='Historical FS'!L75 -> 1
D28: Invest in subsidiaries | F28: ='Historical FS'!C76 -> -13 | G28: ='Historical FS'!D76 -> 0 | H28: ='Historical FS'!E76 -> 0 | I28: ='Historical FS'!F76 -> 0 | J28: ='Historical FS'!G76 -> 0 | K28: ='Historical FS'!H76 -> 0 | L28: ='Historical FS'!I76 -> 0 | M28: ='Historical FS'!J76 -> 0 | ... O28: ='Historical FS'!L76 -> 0
D29: Investment in group cos | F29: ='Historical FS'!C77 -> 0 | G29: ='Historical FS'!D77 -> 0 | H29: ='Historical FS'!E77 -> -1 | I29: ='Historical FS'!F77 -> -8 | J29: ='Historical FS'!G77 -> -6 | K29: ='Historical FS'!H77 -> -3 | L29: ='Historical FS'!I77 -> 0 | M29: ='Historical FS'!J77 -> 0 | ... O29: ='Historical FS'!L77 -> 0
D30: Redemp n Canc of Shares | F30: ='Historical FS'!C78 -> 0 | G30: ='Historical FS'!D78 -> 0 | H30: ='Historical FS'!E78 -> 0 | I30: ='Historical FS'!F78 -> 0 | J30: ='Historical FS'!G78 -> 0 | K30: ='Historical FS'!H78 -> 0 | L30: ='Historical FS'!I78 -> 0 | M30: ='Historical FS'!J78 -> 3 | ... O30: ='Historical FS'!L78 -> 36
D31: Acquisition of companies | F31: ='Historical FS'!C79 -> 0 | G31: ='Historical FS'!D79 -> 0 | H31: ='Historical FS'!E79 -> 0 | I31: ='Historical FS'!F79 -> 0 | J31: ='Historical FS'!G79 -> 0 | K31: ='Historical FS'!H79 -> 0 | L31: ='Historical FS'!I79 -> 0 | M31: ='Historical FS'!J79 -> -847 | ... O31: ='Historical FS'!L79 -> -10262
D32: Other investing items | F32: ='Historical FS'!C80 -> -1839 | G32: ='Historical FS'!D80 -> -32 | H32: ='Historical FS'!E80 -> 2055 | I32: ='Historical FS'!F80 -> -58 | J32: ='Historical FS'!G80 -> 22 | K32: ='Historical FS'!H80 -> -1503 | L32: ='Historical FS'!I80 -> 1518 | M32: ='Historical FS'!J80 -> -417 | ... O32: ='Historical FS'!L80 -> -232
D33: Cash Flow from Investing Activities | F33: =SUM(F22:F32) -> -3675 | G33: =SUM(G22:G32) -> -2501 | H33: =SUM(H22:H32) -> 1866 | I33: =SUM(I22:I32) -> 1164 | J33: =SUM(J22:J32) -> -4193 | K33: =SUM(K22:K32) -> -8856 | L33: =SUM(L22:L32) -> 2322 | M33: =SUM(M22:M32) -> -7187 | ... O33: =SUM(O22:O32) -> -15835
D35: Financing Activities
D36: Proceeds from shares | F36: ='Historical FS'!C83 -> 3 | G36: ='Historical FS'!D83 -> 7 | H36: ='Historical FS'!E83 -> 16 | I36: ='Historical FS'!F83 -> 5 | J36: ='Historical FS'!G83 -> 3 | K36: ='Historical FS'!H83 -> 14 | L36: ='Historical FS'!I83 -> 13 | M36: ='Historical FS'!J83 -> 13 | ... O36: ='Historical FS'!L83 -> 33
D37: Proceeds from borrowings | F37: ='Historical FS'!C84 -> 2821 | G37: ='Historical FS'!D84 -> 3656 | H37: ='Historical FS'!E84 -> 15775 | I37: ='Historical FS'!F84 -> 9772 | J37: ='Historical FS'!G84 -> 1510 | K37: ='Historical FS'!H84 -> 4103 | L37: ='Historical FS'!I84 -> 175 | M37: ='Historical FS'!J84 -> 1032 | ... O37: ='Historical FS'!L84 -> 9410
D38: Repayment of borrowings | F38: ='Historical FS'!C85 -> -2775 | G38: ='Historical FS'!D85 -> -5272 | H38: ='Historical FS'!E85 -> -19982 | I38: ='Historical FS'!F85 -> -14420 | J38: ='Historical FS'!G85 -> -4154 | K38: ='Historical FS'!H85 -> -6499 | L38: ='Historical FS'!I85 -> -10346 | M38: ='Historical FS'!J85 -> -579 | ... O38: ='Historical FS'!L85 -> -550
D39: Interest paid fin | F39: ='Historical FS'!C86 -> -596 | G39: ='Historical FS'!D86 -> -614 | H39: ='Historical FS'!E86 -> -1210 | I39: ='Historical FS'!F86 -> -1685 | J39: ='Historical FS'!G86 -> -1950 | K39: ='Historical FS'!H86 -> -1481 | L39: ='Historical FS'!I86 -> -1026 | M39: ='Historical FS'!J86 -> -765 | ... O39: ='Historical FS'!L86 -> -1540
D40: Dividends paid | F40: ='Historical FS'!C87 -> -297 | G40: ='Historical FS'!D87 -> -312 | H40: ='Historical FS'!E87 -> -334 | I40: ='Historical FS'!F87 -> -346 | J40: ='Historical FS'!G87 -> -380 | K40: ='Historical FS'!H87 -> -375 | L40: ='Historical FS'!I87 -> -1065 | M40: ='Historical FS'!J87 -> -1091 | ... O40: ='Historical FS'!L87 -> -2012
D41: Financial liabilities | F41: ='Historical FS'!C88 -> 0 | G41: ='Historical FS'!D88 -> 0 | H41: ='Historical FS'!E88 -> 0 | I41: ='Historical FS'!F88 -> 0 | J41: ='Historical FS'!G88 -> -101 | K41: ='Historical FS'!H88 -> -118 | L41: ='Historical FS'!I88 -> -157 | M41: ='Historical FS'!J88 -> -126 | ... O41: ='Historical FS'!L88 -> -165
D42: Other financing items | F42: ='Historical FS'!C89 -> 1 | G42: ='Historical FS'!D89 -> 0 | H42: ='Historical FS'!E89 -> 0 | I42: ='Historical FS'!F89 -> -83 | J42: ='Historical FS'!G89 -> -4 | K42: ='Historical FS'!H89 -> 0 | L42: ='Historical FS'!I89 -> -91 | M42: ='Historical FS'!J89 -> -115 | ... O42: ='Historical FS'!L89 -> -100
D43: Cash Flow from Financing Activities | F43: =SUM(F36:F42) -> -843 | G43: =SUM(G36:G42) -> -2535 | H43: =SUM(H36:H42) -> -5735 | I43: =SUM(I36:I42) -> -6757 | J43: =SUM(J36:J42) -> -5076 | K43: =SUM(K36:K42) -> -4356 | L43: =SUM(L36:L42) -> -12497 | M43: =SUM(M36:M42) -> -1631 | ... O43: =SUM(O36:O42) -> 5076
D45: Net Cash Flow | F45: =F19+F33+F43 -> 7 | G45: =G19+G33+G43 -> -30 | H45: =H19+H33+H43 -> 18 | I45: =I19+I33+I43 -> 364 | J45: =J19+J33+J43 -> -296 | K45: =K19+K33+K43 -> -711 | L45: =L19+L33+L43 -> -892 | M45: =M19+M33+M43 -> 252 | ... O45: =O19+O33+O43 -> -87

Sheet Com_Size
D2: UltraTech Cement Ltd (NSE: ULTRACEMCO)
D3: Common Size Statement
D4: (Figures are in ₹ Cr, except price per share)
D6: Common Size Income Statement
F7: Fiscal Year Ending March 31,
D8: Particulars | F8: ='Historical FS'!C11 -> 42460 | G8: ='Historical FS'!D11 -> 42825 | H8: ='Historical FS'!E11 -> 43190 | I8: ='Historical FS'!F11 -> 43555 | J8: ='Historical FS'!G11 -> 43921 | K8: ='Historical FS'!H11 -> 44286 | L8: ='Historical FS'!I11 -> 44651 | M8: ='Historical FS'!J11 -> 45016 | ... O8: ='Historical FS'!L11 -> 45747
D9: Revenue | F9: ='Data Sheet'!B17/'Data Sheet'!B$17 -> 1 | G9: ='Data Sheet'!C17/'Data Sheet'!C$17 -> 1 | H9: ='Data Sheet'!D17/'Data Sheet'!D$17 -> 1 | I9: ='Data Sheet'!E17/'Data Sheet'!E$17 -> 1 | J9: ='Data Sheet'!F17/'Data Sheet'!F$17 -> 1 | K9: ='Data Sheet'!G17/'Data Sheet'!G$17 -> 1 | L9: ='Data Sheet'!H17/'Data Sheet'!H$17 -> 1 | M9: ='Data Sheet'!I17/'Data Sheet'!I$17 -> 1 | ... O9: ='Data Sheet'!K17/'Data Sheet'!K$17 -> 1
D10: ='Data Sheet'!A18 -> Raw Material Cost | F10: ='Data Sheet'!B18/'Data Sheet'!B$17 -> 0.17636376 | G10: ='Data Sheet'!C18/'Data Sheet'!C$17 -> 0.17406544 | H10: ='Data Sheet'!D18/'Data Sheet'!D$17 -> 0.17431312 | I10: ='Data Sheet'!E18/'Data Sheet'!E$17 -> 0.16730251 | J10: ='Data Sheet'!F18/'Data Sheet'!F$17 -> 0.16205298 | K10: ='Data Sheet'!G18/'Data Sheet'!G$17 -> 0.14836314 | L10: ='Data Sheet'!H18/'Data Sheet'!H$17 -> 0.15871361 | M10: ='Data Sheet'!I18/'Data Sheet'!I$17 -> 0.16181488 | ... O10: ='Data Sheet'!K18/'Data Sheet'!K$17 -> 0.18025721
D11: ='Data Sheet'!A19 -> Change in Inventory | F11: ='Data Sheet'!B19/'Data Sheet'!B$17 -> 0.00073986492 | G11: ='Data Sheet'!C19/'Data Sheet'!C$17 -> -0.0029828642 | H11: ='Data Sheet'!D19/'Data Sheet'!D$17 -> 0.0035895724 | I11: ='Data Sheet'!E19/'Data Sheet'!E$17 -> -0.0011178841 | J11: ='Data Sheet'!F19/'Data Sheet'!F$17 -> 0.0084334416 | K11: ='Data Sheet'!G19/'Data Sheet'!G$17 -> -0.010064661 | L11: ='Data Sheet'!H19/'Data Sheet'!H$17 -> 0.0072845727 | M11: ='Data Sheet'!I19/'Data Sheet'!I$17 -> 0.0081943416 | ... O11: ='Data Sheet'!K19/'Data Sheet'!K$17 -> -0.00016154274
D12: ='Data Sheet'!A20 -> Power and Fuel | F12: ='Data Sheet'!B20/'Data Sheet'!B$17 -> 0.18205408 | G12: ='Data Sheet'!C20/'Data Sheet'!C$17 -> 0.16835429 | H12: ='Data Sheet'!D20/'Data Sheet'!D$17 -> 0.20446585 | I12: ='Data Sheet'!E20/'Data Sheet'!E$17 -> 0.22758383 | J12: ='Data Sheet'!F20/'Data Sheet'!F$17 -> 0.20072807 | K12: ='Data Sheet'!G20/'Data Sheet'!G$17 -> 0.18627235 | L12: ='Data Sheet'!H20/'Data Sheet'!H$17 -> 0.23075152 | M12: ='Data Sheet'!I20/'Data Sheet'!I$17 -> 0.29239921 | ... O12: ='Data Sheet'!K20/'Data Sheet'!K$17 -> 0.24250041
D13: ='Data Sheet'!A21 -> Other Mfr. Exp | F13: ='Data Sheet'!B21/'Data Sheet'!B$17 -> 0.076883932 | G13: ='Data Sheet'!C21/'Data Sheet'!C$17 -> 0.078474274 | H13: ='Data Sheet'!D21/'Data Sheet'!D$17 -> 0.073906778 | I13: ='Data Sheet'!E21/'Data Sheet'!E$17 -> 0.072380521 | J13: ='Data Sheet'!F21/'Data Sheet'!F$17 -> 0.07172538 | K13: ='Data Sheet'!G21/'Data Sheet'!G$17 -> 0.068581892 | L13: ='Data Sheet'!H21/'Data Sheet'!H$17 -> 0.073949744 | M13: ='Data Sheet'!I21/'Data Sheet'!I$17 -> 0.0686961 | ... O13: ='Data Sheet'!K21/'Data Sheet'!K$17 -> 0.072076896
D14: ='Data Sheet'!A22 -> Employee Cost | F14: ='Data Sheet'!B22/'Data Sheet'!B$17 -> 0.058302231 | G14: ='Data Sheet'!C22/'Data Sheet'!C$17 -> 0.060996006 | H14: ='Data Sheet'!D22/'Data Sheet'!D$17 -> 0.059131427 | I14: ='Data Sheet'!E22/'Data Sheet'!E$17 -> 0.055699569 | J14: ='Data Sheet'!F22/'Data Sheet'!F$17 -> 0.059454314 | K14: ='Data Sheet'!G22/'Data Sheet'!G$17 -> 0.052840419 | L14: ='Data Sheet'!H22/'Data Sheet'!H$17 -> 0.048385107 | M14: ='Data Sheet'!I22/'Data Sheet'!I$17 -> 0.043505864 | ... O14: ='Data Sheet'!K22/'Data Sheet'!K$17 -> 0.047649843
D15: ='Data Sheet'!A23 -> Selling and admin | F15: ='Data Sheet'!B23/'Data Sheet'!B$17 -> 0.28626412 | G15: ='Data Sheet'!C23/'Data Sheet'!C$17 -> 0.28173939 | H15: ='Data Sheet'!D23/'Data Sheet'!D$17 -> 0.26858136 | I15: ='Data Sheet'!E23/'Data Sheet'!E$17 -> 0.27889941 | J15: ='Data Sheet'!F23/'Data Sheet'!F$17 -> 0.26484443 | K15: ='Data Sheet'!G23/'Data Sheet'!G$17 -> 0.25189085 | L15: ='Data Sheet'!H23/'Data Sheet'!H$17 -> 0.25251931 | M15: ='Data Sheet'!I23/'Data Sheet'!I$17 -> 0.25078439 | ... O15: ='Data Sheet'!K23/'Data Sheet'!K$17 -> 0.25767779
D16: ='Data Sheet'!A24 -> Other Expenses | F16: ='Data Sheet'!B24/'Data Sheet'!B$17 -> 0.026027263 | G16: ='Data Sheet'!C24/'Data Sheet'!C$17 -> 0.027970904 | H16: ='Data Sheet'!D24/'Data Sheet'!D$17 -> 0.024827446 | I16: ='Data Sheet'!E24/'Data Sheet'!E$17 -> 0.019820434 | J16: ='Data Sheet'!F24/'Data Sheet'!F$17 -> 0.031716556 | K16: ='Data Sheet'!G24/'Data Sheet'!G$17 -> 0.023346033 | L16: ='Data Sheet'!H24/'Data Sheet'!H$17 -> 0.024056429 | M16: ='Data Sheet'!I24/'Data Sheet'!I$17 -> 0.023064523 | ... O16: ='Data Sheet'!K24/'Data Sheet'!K$17 -> 0.03119684
D17: ='Data Sheet'!A25 -> Other Income | F17: ='Data Sheet'!B25/'Data Sheet'!B$17 -> 0.018439374 | G17: ='Data Sheet'!C25/'Data Sheet'!C$17 -> 0.025541735 | H17: ='Data Sheet'!D25/'Data Sheet'!D$17 -> 0.0078108709 | I17: ='Data Sheet'!E25/'Data Sheet'!E$17 -> 0.0084438234 | J17: ='Data Sheet'!F25/'Data Sheet'!F$17 -> 0.015344372 | K17: ='Data Sheet'!G25/'Data Sheet'!G$17 -> 0.013829155 | L17: ='Data Sheet'!H25/'Data Sheet'!H$17 -> 0.012727089 | M17: ='Data Sheet'!I25/'Data Sheet'!I$17 -> 0.0080188197 | ... O17: ='Data Sheet'!K25/'Data Sheet'!K$17 -> 0.005223347
D18: ='Data Sheet'!A26 -> Depreciation | F18: ='Data Sheet'!B26/'Data Sheet'!B$17 -> 0.054751197 | G18: ='Data Sheet'!C26/'Data Sheet'!C$17 -> 0.053139436 | H18: ='Data Sheet'!D26/'Data Sheet'!D$17 -> 0.059651786 | I18: ='Data Sheet'!E26/'Data Sheet'!E$17 -> 0.059107487 | J18: ='Data Sheet'!F26/'Data Sheet'!F$17 -> 0.064168444 | K18: ='Data Sheet'!G26/'Data Sheet'!G$17 -> 0.060372984 | L18: ='Data Sheet'!H26/'Data Sheet'!H$17 -> 0.051612365 | M18: ='Data Sheet'!I26/'Data Sheet'!I$17 -> 0.045667155 | ... O18: ='Data Sheet'!K26/'Data Sheet'!K$17 -> 0.052859497
D19: ='Data Sheet'!A27 -> Interest | F19: ='Data Sheet'!B27/'Data Sheet'!B$17 -> 0.022513998 | G19: ='Data Sheet'!C27/'Data Sheet'!C$17 -> 0.025225675 | H19: ='Data Sheet'!D27/'Data Sheet'!D$17 -> 0.039950133 | I19: ='Data Sheet'!E27/'Data Sheet'!E$17 -> 0.042878994 | J19: ='Data Sheet'!F27/'Data Sheet'!F$17 -> 0.046939787 | K19: ='Data Sheet'!G27/'Data Sheet'!G$17 -> 0.033216846 | L19: ='Data Sheet'!H27/'Data Sheet'!H$17 -> 0.017960666 | M19: ='Data Sheet'!I27/'Data Sheet'!I$17 -> 0.013009492 | ... O19: ='Data Sheet'!K27/'Data Sheet'!K$17 -> 0.021730461
D20: ='Data Sheet'!A28 -> Profit before tax | F20: ='Data Sheet'!B28/'Data Sheet'!B$17 -> 0.13601866 | G20: ='Data Sheet'!C28/'Data Sheet'!C$17 -> 0.15259346 | H20: ='Data Sheet'!D28/'Data Sheet'!D$17 -> 0.10657253 | I20: ='Data Sheet'!E28/'Data Sheet'!E$17 -> 0.083653182 | J20: ='Data Sheet'!F28/'Data Sheet'!F$17 -> 0.12214785 | K20: ='Data Sheet'!G28/'Data Sheet'!G$17 -> 0.17887998 | L20: ='Data Sheet'!H28/'Data Sheet'!H$17 -> 0.16206292 | M20: ='Data Sheet'!I28/'Data Sheet'!I$17 -> 0.11727154 | ... O20: ='Data Sheet'!K28/'Data Sheet'!K$17 -> 0.099112858
D21: ='Data Sheet'!A29 -> Tax | F21: ='Data Sheet'!B29/'Data Sheet'!B$17 -> 0.037438119 | G21: ='Data Sheet'!C29/'Data Sheet'!C$17 -> 0.045656857 | H21: ='Data Sheet'!D29/'Data Sheet'!D$17 -> 0.034766236 | I21: ='Data Sheet'!E29/'Data Sheet'!E$17 -> 0.025760053 | J21: ='Data Sheet'!F29/'Data Sheet'!F$17 -> -0.01339056 | K21: ='Data Sheet'!G29/'Data Sheet'!G$17 -> 0.056761422 | L21: ='Data Sheet'!H29/'Data Sheet'!H$17 -> 0.022625218 | M21: ='Data Sheet'!I29/'Data Sheet'!I$17 -> 0.037046976 | ... O21: ='Data Sheet'!K29/'Data Sheet'!K$17 -> 0.019596965
