Workbook
Name scenario: DCF!$E$17
Name tgr: DCF!$E$22
Name wacc: DCF!$E$21

Sheet Summary
B2: Walmart Inc.
B3: Summary
B4: ($ in 'Billions, except per share data and number of employees in '000)
A6: * | B6: Valuation
B8: Metrics | C8: DCF | D8: EV / Revenue | E8: EV / EBITDA | F8: P / Sales | G8: P / E | H8: 52 - wk range
B9: 75th Percentile | C9: =DCF!L191 -> 72.034035 | D9: =Comps!R30 -> 12.517437 | E9: =Comps!S30 -> 9.6120511 | F9: =Comps!T30 -> 40.537366 | G9: =Comps!U30 -> 35.648384 | H9: =Comps!D39 -> 113.56
B10: Average | C10: =DCF!L192 -> 59.842471 | D10: =Comps!R31 -> 10.633325 | E10: =Comps!S31 -> 8.1557751 | F10: =Comps!T31 -> 55.137229 | G10: =Comps!U31 -> 53.334523 | H10: =Comps!D40 -> 104.44327
B11: Median | C11: =DCF!L193 -> 53.335455 | D11: =Comps!R32 -> 6.0804137 | E11: =Comps!S32 -> 6.752042 | F11: =Comps!T32 -> 14.978242 | G11: =Comps!U32 -> 16.334053 | H11: =Comps!D41 -> 101.84
B12: 25th Percentile | C12: =DCF!L194 -> 35.884431 | D12: =Comps!R33 -> 5.6471299 | E12: =Comps!S33 -> 5.8434136 | F12: =Comps!T33 -> 6.8224205 | G12: =Comps!U33 -> 10.021673 | H12: =Comps!D42 -> 96.775
A15: * | B15: Football Chart
B17: Method | C17: Min | D17: Median | E17: Max
B18: DCF | C18: {=TRANSPOSE(C12:H12)} -> 35.884431 | D18: {=TRANSPOSE(C11:H11)} -> 53.335455 | E18: {=TRANSPOSE(C9:H9)} -> 72.034035
B19: EV / Revenue | C19: 5.6471299 | D19: 6.0804137 | E19: 12.517437
B20: EV / EBITDA | C20: 5.8434136 | D20: 6.752042 | E20: 9.6120511
B21: P / Sales | C21: 6.8224205 | D21: 14.978242 | E21: 40.537366
B22: P / E | C22: 10.021673 | D22: 16.334053 | E22: 35.648384
B23: 52 - wk range | C23: 96.775 | D23: 101.84 | E23: 113.56
A25: * | B25: End

Sheet Comps
B2: Walmart Inc.
B3: Companies Comparable
B4: ($ in 'Billions, except per share data and number of employees in '000)
A6: * | B6: Overview
B8: Name | D8: Employees | E8: Revenue | F8: EBITDA | G8: EBITDA % | H8: Net Income | I8: NI % | J8: Price / Share ($) | K8: Market Cap | L8: EV | M8: EV / Revenue | N8: EV / EBITDA | O8: P / Sales | P8: P / E
B9: Walmart | D9: 2100 | E9: 713.16 | F9: 44.03 | G9: =F9/E9 -> 0.061739301 | H9: 21.89 | I9: =H9/E9 -> 0.030694374 | J9: 119.02 | K9: 949.57 | L9: 1010
B10: Costco Wholesale Corp | D10: 341 | E10: 286.27 | F10: 13.46 | G10: =F10/E10 -> 0.047018549 | H10: 8.55 | I10: =H10/E10 -> 0.029866909 | J10: 972.33 | K10: 448.48 | L10: 439.4 | M10: =L10/E10 -> 1.5349146 | N10: =L10/F10 -> 32.644874 | O10: =J10/E10 -> 3.3965487 | P10: =J10/H10 -> 113.72281
B11: Target Corp | D11: 440 | E11: 104.78 | F11: 8.07 | G11: =F11/E11 -> 0.077018515 | H11: 3.7 | I11: =H11/E11 -> 0.035312082 | J11: 113.26 | K11: 47.76 | L11: 63.98 | M11: =L11/E11 -> 0.61061271 | N11: =L11/F11 -> 7.9281289 | O11: =J11/E11 -> 1.0809315 | P11: =J11/H11 -> 30.610811
B12: CVS Health Corp | D12: 300 | E12: 399.83 | F12: 14.63 | G12: =F12/E12 -> 0.036590551 | H12: 1.77 | I12: =H12/E12 -> 0.0044268814 | J12: 71.5 | K12: 100.87 | L12: 171.39 | M12: =L12/E12 -> 0.42865718 | N12: =L12/F12 -> 11.714969 | O12: =J12/E12 -> 0.178826 | P12: =J12/H12 -> 40.39548
B13: Loblaw Companies Limited | D13: 220 | E13: 63.9 | F13: 5.63 | G13: =F13/E13 -> 0.088106416 | H13: 2.53 | I13: =H13/E13 -> 0.039593114 | J13: 44.02 | K13: 45.56 | L13: 56.55 | M13: =L13/E13 -> 0.88497653 | N13: =L13/F13 -> 10.044405 | O13: =J13/E13 -> 0.68888889 | P13: =J13/H13 -> 17.399209
B14: Kroger Co. | D14: 409 | E14: 147.64 | F14: 7.96 | G14: =F14/E14 -> 0.053914928 | H14: 1.02 | I14: =H14/E14 -> 0.0069086968 | J14: 73.2 | K14: 39.77 | L14: 59.91 | M14: =L14/E14 -> 0.40578434 | N14: =L14/F14 -> 7.5263819 | O14: =J14/E14 -> 0.4958006 | P14: =J14/H14 -> 71.764706
B15: Tesco Plc | D15: 341 | E15: 71.18 | F15: 4.26 | G15: =F15/E15 -> 0.059848272 | H15: 1.53 | I15: =H15/E15 -> 0.021494802 | J15: 625.47 | K15: 29.8 | L15: 40.2 | M15: =L15/E15 -> 0.56476538 | N15: =L15/F15 -> 9.4366197 | O15: =J15/E15 -> 8.7871593 | P15: =J15/H15 -> 408.80392
B16: Us Foods Holding Corp | D16: 30 | E16: 39.42 | F16: 1.71 | G16: =F16/E16 -> 0.043378995 | H16: 0.676 | I16: =H16/E16 -> 0.017148656 | J16: 89.4 | K16: 16.61 | L16: 21.67 | M16: =L16/E16 -> 0.54972095 | N16: =L16/F16 -> 12.672515 | O16: =J16/E16 -> 2.2678843 | P16: =J16/H16 -> 132.24852
B17: Sysco Corporation | D17: 75 | E17: 82.65 | F17: 4.52 | G17: =F17/E17 -> 0.054688445 | H17: 1.8 | I17: =H17/E17 -> 0.021778584 | J17: 81.33 | K17: 35.29 | L17: 49.03 | M17: =L17/E17 -> 0.59322444 | N17: =L17/F17 -> 10.847345 | O17: =J17/E17 -> 0.98402904 | P17: =J17/H17 -> 45.183333
B18: O`Reilly Automotive, Inc. | D18: 95 | E18: 17.78 | F18: 3.97 | G18: =F18/E18 -> 0.22328459 | H18: 2.54 | I18: =H18/E18 -> 0.14285714 | J18: 87.3 | K18: 65.37 | L18: 72.35 | M18: =L18/E18 -> 4.0691789 | N18: =L18/F18 -> 18.224181 | O18: =J18/E18 -> 4.9100112 | P18: =J18/H18 -> 34.370079
B19: Casey`s General Stores, Inc. | D19: 23.4 | E19: 16.98 | F19: 1.39 | G19: =F19/E19 -> 0.081861013 | H19: 0.65 | I19: =H19/E19 -> 0.03828033 | J19: 659.63 | K19: 22.48 | L19: 24.91 | M19: =L19/E19 -> 1.46702 | N19: =L19/F19 -> 17.920863 | O19: =J19/E19 -> 38.847468 | P19: =J19/H19 -> 1014.8154
B21: 75th Percentile | M21: =QUARTILE(M10:M19,3) -> 1.3215091 | N21: =QUARTILE(N10:N19,3) -> 16.608776 | O21: =QUARTILE(O10:O19,3) -> 4.5316456 | P21: =QUARTILE(P10:P19,3) -> 127.61709
B22: Average | M22: =AVERAGE(M10:M19) -> 1.1108855 | N22: =AVERAGE(N10:N19) -> 13.896028 | O22: =AVERAGE(O10:O19) -> 6.1637547 | P22: =AVERAGE(P10:P19) -> 190.93143
B23: Median | M23: =MEDIAN(M10:M19) -> 0.60191858 | N23: =MEDIAN(N10:N19) -> 11.281157 | O23: =MEDIAN(O10:O19) -> 1.6744079 | P23: =MEDIAN(P10:P19) -> 58.47402
B24: 25th Percentile | M24: =QUARTILE(M10:M19,1) -> 0.55348206 | N24: =QUARTILE(N10:N19,1) -> 9.588566 | O24: =QUARTILE(O10:O19,1) -> 0.76267393 | P24: =QUARTILE(P10:P19,1) -> 35.876429
A27: * | B27: Valuation
N28: Equity Value | R28: Price Per Share
B29: Walmart Inc. | D29: Revenue | E29: EBITDA | F29: Net Income | G29: # Shares | H29: Cash | I29: Debt | J29: EV / Revenue | K29: EV / EBITDA | L29: P / Sales | M29: P / E | N29: EV / Revenue | O29: EV / EBITDA | P29: P / Sales | Q29: P / E | R29: EV / Revenue | S29: EV / EBITDA | T29: P / Sales | U29: P / E
B30: 75th Percentile | D30: 713.163 | E30: 42.798 | F30: 22.27 | G30: 7972.4025 | H30: 10.727 | I30: 44.762 | J30: =M21 -> 1.3215091 | K30: =N21 -> 16.608776 | L30: =O21 -> 4.5316456 | M30: =P21 -> 127.61709 | N30: =J30*D30+H30+I30 -> 997.94043 | O30: =K30*E30+H30+I30 -> 766.3114 | P30: =L30*D30 -> 3231.802 | Q30: =M30*F30 -> 2842.0326 | R30: =N30*100/$G30 -> 12.517437 | S30: =O30*100/$G30 -> 9.6120511 | T30: =P30*100/$G30 -> 40.537366 | U30: =Q30*100/$G30 -> 35.648384
B31: Average | D31: 713.163 | E31: 42.798 | F31: 22.27 | G31: 7972.4025 | H31: 10.727 | I31: 44.762 | J31: =M22 -> 1.1108855 | K31: =N22 -> 13.896028 | L31: =O22 -> 6.1637547 | M31: =P22 -> 190.93143 | N31: =J31*D31+H31+I31 -> 847.73144 | O31: =K31*E31+H31+I31 -> 650.21122 | P31: =L31*D31 -> 4395.7618 | Q31: =M31*F31 -> 4252.0428 | R31: =N31*100/$G31 -> 10.633325 | S31: =O31*100/$G31 -> 8.1557751 | T31: =P31*100/$G31 -> 55.137229 | U31: =Q31*100/$G31 -> 53.334523
B32: Median | D32: 713.163 | E32: 42.798 | F32: 22.27 | G32: 7972.4025 | H32: 10.727 | I32: 44.762 | J32: =M23 -> 0.60191858 | K32: =N23 -> 11.281157 | L32: =O23 -> 1.6744079 | M32: =P23 -> 58.47402 | N32: =J32*D32+H32+I32 -> 484.75506 | O32: =K32*E32+H32+I32 -> 538.29997 | P32: =L32*D32 -> 1194.1258 | Q32: =M32*F32 -> 1302.2164 | R32: =N32*100/$G32 -> 6.0804137 | S32: =O32*100/$G32 -> 6.752042 | T32: =P32*100/$G32 -> 14.978242 | U32: =Q32*100/$G32 -> 16.334053
B33: 25th Percentile | D33: 713.163 | E33: 42.798 | F33: 22.27 | G33: 7972.4025 | H33: 10.727 | I33: 44.762 | J33: =M24 -> 0.55348206 | K33: =N24 -> 9.588566 | L33: =O24 -> 0.76267393 | M33: =P24 -> 35.876429 | N33: =J33*D33+H33+I33 -> 450.21193 | O33: =K33*E33+H33+I33 -> 465.86045 | P33: =L33*D33 -> 543.91083 | Q33: =M33*F33 -> 798.96808 | R33: =N33*100/$G33 -> 5.6471299 | S33: =O33*100/$G33 -> 5.8434136 | T33: =P33*100/$G33 -> 6.8224205 | U33: =Q33*100/$G33 -> 10.021673
A36: * | B36: 52 Week Share Price
B38: Valuation
B39: 75th Percentile | D39: =QUARTILE(Input!S4:S58,3) -> 113.56
B40: Average | D40: =AVERAGE(Input!S4:S58) -> 104.44327
B41: Median | D41: =MEDIAN(Input!S4:S58) -> 101.84
B42: 25th Percentile | D42: =QUARTILE(Input!S4:S58,1) -> 96.775
A44: * | B44: End

Sheet DCF
B2: Walmart Inc.
B3: DCF Model
B4: ($ in 'Millions, except per share data)
A6: * | B6: Overview
B8: Company Name: | E8: Walmart Inc. | G8: Implied Share Price: | J8: =O185 -> 39.729146
B9: Ticker: | E9: WMT US | G9: % Delta vs Current: | J9: =J8/E11-1 -> -0.66614163
B10: Date: | E10: =TODAY() -> 46106
B11: Price Per Share: | E11: 119
A13: * | B13: Assumptions (31/12 CYE)
B15: Triggers | G15: Conservative | H15: Year | I15: Average | K15: Base/Street | L15: Year | M15: Average | O15: Optimistic | P15: Year | Q15: Average
B17: Scenario: | E17: 1 | G17: Revenue | H17: 27'-31' | I17: -0.00014529609 | K17: Revenue | L17: 27'-31' | M17: 0.045044039 | O17: Revenue | P17: 27'-31' | Q17: 0.059521416
G18: Cost of Sales | H18: 27'-31' | I18: 0.063106601 | K18: Cost of Sales | L18: 27'-31' | M18: 0.048084527 | O18: Cost of Sales | P18: 27'-31' | Q18: 0.037067888
G19: OSG&A | H19: 27'-31' | I19: 0.0088729277 | K19: OSG&A | L19: 27'-31' | M19: 0.032653214 | O19: OSG&A | P19: 27'-31' | Q19: 0.042192472
B21: WACC | E21: =CHOOSE(scenario,M21,I21,Q21) -> 0.075210832 | G21: WACC | I21: 0.082 | K21: WACC | M21: =WACC!L11 -> 0.075210832 | O21: WACC | Q21: 0.068
B22: TGR | E22: =CHOOSE(scenario,M22,I22,Q22) -> 0.02 | G22: TGR | I22: 0.015 | K22: TGR | M22: =WACC!L12 -> 0.02 | O22: TGR | Q22: 0.025
A24: * | B24: Income Statement (31/12 CYE)
J25: Historicals | O25: Projections
B26: $ 'Millions | J26: 44592 | K26: =EOMONTH(J26,12) -> 44957 | L26: =EOMONTH(K26,12) -> 45322 | M26: =EOMONTH(L26,12) -> 45688 | N26: =EOMONTH(M26,12) -> 46053 | O26: =EOMONTH(N26,12) -> 46418 | P26: =EOMONTH(O26,12) -> 46783 | Q26: =EOMONTH(P26,12) -> 47149 | R26: =EOMONTH(Q26,12) -> 47514 | S26: =EOMONTH(R26,12) -> 47879
B28: Walmart U.S. Segment
B29: Sales | J29: =Input!H38 -> 393247 | K29: =Input!I38 -> 420553 | L29: =Input!J38 -> 441817 | M29: =Input!K38 -> 462415 | N29: =Input!L38 -> 482975 | O29: =N29*(1+O30) -> 504708.87 | P29: =O29*(1+P30) -> 525906.65 | Q29: =P29*(1+Q30) -> 548520.63 | R29: =Q29*(1+R30) -> 571009.98 | S29: =R29*(1+S30) -> 595563.41
B30: % Growth | K30: =K29/J29-1 -> 0.069437275 | L30: =L29/K29-1 -> 0.050561998 | M30: =M29/L29-1 -> 0.046621112 | N30: =N29/M29-1 -> 0.044462225 | O30: =OFFSET(O30,scenario,0) -> 0.045 | P30: =OFFSET(P30,scenario,0) -> 0.042 | Q30: =OFFSET(Q30,scenario,0) -> 0.043 | R30: =OFFSET(R30,scenario,0) -> 0.041 | S30: =OFFSET(S30,scenario,0) -> 0.043
B31: 1. Base | O31: 0.045 | P31: 0.042 | Q31: 0.043 | R31: 0.041 | S31: 0.043
B32: 2. Conservative | O32: =O31-1% -> 0.035 | P32: =P31-1% -> 0.032 | Q32: =Q31-1% -> 0.033 | R32: =R31-1% -> 0.031 | S32: =S31-1% -> 0.033
B33: 3. Optimistic | O33: =O31+1% -> 0.055 | P33: =P31+1% -> 0.052 | Q33: =Q31+1% -> 0.053 | R33: =R31+1% -> 0.051 | S33: =S31+1% -> 0.053
B34: Membership | J34: =Input!H39 -> 1924.398 | K34: =Input!I39 -> 2084.7645 | L34: =Input!J39 -> 1985 | M34: =Input!K39 -> 2594 | N34: =Input!L39 -> 2624 | O34: =N34*(1+O35) -> 2676.48 | P34: =O34*(1+P35) -> 2727.3331 | Q34: =P34*(1+Q35) -> 2787.3344 | R34: =Q34*(1+R35) -> 2854.2305 | S34: =R34*(1+S35) -> 2928.4405
B35: % Growth | K35: =K34/J34-1 -> 0.083333333 | L35: =L34/K34-1 -> -0.047854069 | M35: =M34/L34-1 -> 0.30680101 | N35: =N34/M34-1 -> 0.01156515 | O35: =OFFSET(O35,scenario,0) -> 0.02 | P35: =OFFSET(P35,scenario,0) -> 0.019 | Q35: =OFFSET(Q35,scenario,0) -> 0.022 | R35: =OFFSET(R35,scenario,0) -> 0.024 | S35: =OFFSET(S35,scenario,0) -> 0.026
B36: 1. Base | O36: 0.02 | P36: 0.019 | Q36: 0.022 | R36: 0.024 | S36: 0.026
B37: 2. Conservative | O37: =O36-1% -> 0.01 | P37: =P36-1% -> 0.009 | Q37: =Q36-1% -> 0.012 | R37: =R36-1% -> 0.014 | S37: =S36-1% -> 0.016
B38: 3. Optimistic | O38: =O36+1% -> 0.03 | P38: =P36+1% -> 0.029 | Q38: =Q36+1% -> 0.032 | R38: =R36+1% -> 0.034 | S38: =S36+1% -> 0.036
B39: Total Revenue | J39: =Input!H40 -> 395171.4 | K39: =Input!I40 -> 422637.76 | L39: =Input!J40 -> 443802 | M39: =Input!K40 -> 465009 | N39: =Input!L40 -> 485599 | O39: =O29+O34 -> 507385.35 | P39: =P29+P34 -> 528633.98 | Q39: =Q29+Q34 -> 551307.97 | R39: =R29+R34 -> 573864.21 | S39: =S29+S34 -> 598491.85
B41: Cost of Sales | J41: =Input!H42 -> 281957.5 | K41: =Input!I42 -> 304777.66 | L41: =Input!J42 -> 323563 | M41: =Input!K42 -> 336451 | N41: =Input!L42 -> 350360 | O41: =N41*(1+O42) -> 365425.48 | P41: =O41*(1+P42) -> 380407.92 | Q41: =P41*(1+Q42) -> 396385.06 | R41: =Q41*(1+R42) -> 413826 | S41: =R41*(1+S42) -> 431620.52
B42: % Growth | K42: =K41/J41-1 -> 0.080934732 | L42: =L41/K41-1 -> 0.061636227 | M42: =M41/L41-1 -> 0.039831501 | N42: =N41/M41-1 -> 0.041340344 | O42: =OFFSET(O42,scenario,0) -> 0.043 | P42: =OFFSET(P42,scenario,0) -> 0.041 | Q42: =OFFSET(Q42,scenario,0) -> 0.042 | R42: =OFFSET(R42,scenario,0) -> 0.044 | S42: =OFFSET(S42,scenario,0) -> 0.043
B43: 1. Base | O43: 0.043 | P43: 0.041 | Q43: 0.042 | R43: 0.044 | S43: 0.043
B44: 2. Conservative | O44: =O43-1% -> 0.033 | P44: =P43-1% -> 0.031 | Q44: =Q43-1% -> 0.032 | R44: =R43-1% -> 0.034 | S44: =S43-1% -> 0.033
B45: 3. Optimistic | O45: =O43+1% -> 0.053 | P45: =P43+1% -> 0.051 | Q45: =Q43+1% -> 0.052 | R45: =R43+1% -> 0.054 | S45: =S43+1% -> 0.053
B46: Operating, selling, general and administrative expenses | J46: =Input!H43 -> 88005.534 | K46: =Input!I43 -> 94973.548 | L46: =Input!J43 -> 98085 | M46: =Input!K43 -> 104676 | N46: =Input!L43 -> 110081 | O46: =N46*(1+O47) -> 112282.62 | P46: =O46*(1+P47) -> 114303.71 | Q46: =P46*(1+Q47) -> 116132.57 | R46: =Q46*(1+R47) -> 117758.42 | S46: =R46*(1+S47) -> 119171.52
B47: % Growth | K47: =K46/J46-1 -> 0.079176994 | L47: =L46/K46-1 -> 0.03276125 | M47: =M46/L46-1 -> 0.067196819 | N47: =N46/M46-1 -> 0.051635523 | O47: =OFFSET(O47,scenario,0) -> 0.02 | P47: =OFFSET(P47,scenario,0) -> 0.018 | Q47: =OFFSET(Q47,scenario,0) -> 0.016 | R47: =OFFSET(R47,scenario,0) -> 0.014 | S47: =OFFSET(S47,scenario,0) -> 0.012
B48: 1. Base | O48: 0.02 | P48: 0.018 | Q48: 0.016 | R48: 0.014 | S48: 0.012
B49: 2. Conservative | O49: =O48-1% -> 0.01 | P49: =P48-1% -> 0.008 | Q49: =Q48-1% -> 0.006 | R49: =R48-1% -> 0.004 | S49: =S48-1% -> 0.002
B50: 3. Optimistic | O50: =O48+1% -> 0.03 | P50: =P48+1% -> 0.028 | Q50: =Q48+1% -> 0.026 | R50: =R48+1% -> 0.024 | S50: =S48+1% -> 0.022
...

Sheet WACC
A3: * | B3: Weighted Average Cost of Capital
B5: Cost of Equity | I5: Capital Structure
I6: Market Cap | L6: 949566
B7: Risk Free Rate | E7: 0.04392 | F7: US 10-Year Treasury Yield | I7: Total Debt | L7: 44762
B8: Equity Risk Premium | E8: 0.0446 | F8: Aswath Damodharan | I8: Total | L8: =SUM(L6:L7) -> 994328
B9: Country Risk Premium | E9: 0.0023 | F9: Aswath Damodharan
B10: Beta | E10: =Input!AB22 -> 0.6905058 | F10: Regression
B11: Cost of Equity | E11: =E7+(E8*E10)+E9 -> 0.077016559 | I11: WACC | L11: =(E25*(L7/L8))+(E11*(L6/L8)) -> 0.075210832
I12: Terminal Growth Rate | L12: 0.02 | M12: (1%-3%) Google
B14: Cost of Debt
B15: Using YTM Approach
B17: CMP | E17: 111.431 | F17: Investing.com
B18: Face Value | E18: 100
B19: Maturity Year | E19: 50510
B20: Total Years | E20: =YEARFRAC(TODAY(),E19,1) -> 12.05813
B21: Coupon Rate | E21: 0.062 | F21: Investing.com
B22: YTM | E22: =RATE(E20,(E18*E21),-E17,E18) -> 0.049206348
B24: Tax Rate | E24: 0.25
B25: Post Tax Cost of Debt | E25: =E22*(1-E24) -> 0.036904761
A27: * | B27: End

Sheet Data->

Sheet Input
B2: Income Statement
B3: (Amounts in millions, except per share data) | H3: 2022 | I3: 2023 | J3: 2024 | K3: 2025 | L3: 2026 | R3: Date | S3: Price | V3: Date | W3: Price | AA3: SUMMARY OUTPUT
B4: Revenues: | R4: 46096 | S4: 119.02 | V4: 46096 | W4: 21616.7
B5: Net sales | H5: 567762 | I5: 605881 | J5: 642637 | K5: 674538 | L5: 706413 | R5: 46089 | S5: 126.52 | T5: =S4/S5-1 -> -0.059279165 | V5: 46089 | W5: 22050.9 | X5: =W4/W5-1 -> -0.019690806 | AA5: Regression Statistics
B6: Membership and other income | H6: 4992 | I6: 5408 | J6: 5488 | K6: 6447 | L6: 6750 | R6: 46082 | S6: 123.8 | T6: =S5/S6-1 -> 0.021970921 | V6: 46082 | W6: 22518.1 | X6: =W5/W6-1 -> -0.020747754 | AA6: Multiple R | AB6: 0.45516506
B7: Total revenues | H7: 572754 | I7: 611289 | J7: 648125 | K7: 680985 | L7: 713163 | R7: 46075 | S7: 127.95 | T7: =S6/S7-1 -> -0.032434545 | V7: 46075 | W7: 23494.4 | X7: =W6/W7-1 -> -0.041554583 | AA7: R Square | AB7: 0.20717523
B8: Costs and expenses: | R8: 46068 | S8: 122.99 | T8: =S7/S8-1 -> 0.040328482 | V8: 46068 | W8: 23452.6 | X8: =W7/W8-1 -> 0.0017823184 | AA8: Adjusted R Square | AB8: 0.20422793
B9: Cost of sales | H9: 429000 | I9: 463721 | J9: 490142 | K9: 511753 | L9: 535395 | R9: 46061 | S9: 133.89 | T9: =S8/S9-1 -> -0.081410113 | V9: 46061 | W9: 23326.1 | X9: =W8/W9-1 -> 0.0054231097 | AA9: Standard Error | AB9: 0.02743684
B10: Operating, selling, general and administrative expenses | H10: 117812 | I10: 127140 | J10: 130971 | K10: 139884 | L10: 147943 | R10: 46054 | S10: 131.18 | T10: =S9/S10-1 -> 0.020658637 | V10: 46054 | W10: 23252.8 | X10: =W9/W10-1 -> 0.0031523085 | AA10: Observations | AB10: 271
B11: Operating income | H11: 25942 | I11: 20428 | J11: 27012 | K11: 29348 | L11: 29825 | R11: 46047 | S11: 119.14 | T11: =S10/S11-1 -> 0.10105758 | V11: 46047 | W11: 22719.3 | X11: =W10/W11-1 -> 0.023482238
B12: Interest: | R12: 46040 | S12: 117.73 | T12: =S11/S12-1 -> 0.011976557 | V12: 46040 | W12: 22757.2 | X12: =W11/W12-1 -> -0.001665407 | AA12: ANOVA
B13: Debt | H13: 1674 | I13: 1787 | J13: 2259 | K13: 2249 | L13: 2318 | R13: 46033 | S13: 119.7 | T13: =S12/S13-1 -> -0.016457811 | V13: 46033 | W13: 22807.1 | X13: =W12/W13-1 -> -0.0021879152 | AB13: df | AC13: SS | AD13: MS | AE13: F | AF13: Significance F
B14: Finance lease | H14: 320 | I14: 341 | J14: 424 | K14: 479 | L14: 481 | R14: 46026 | S14: 114.53 | T14: =S13/S14-1 -> 0.045141011 | V14: 46026 | W14: 22591.7 | X14: =W13/W14-1 -> 0.0095344751 | AA14: Regression | AB14: 1 | AC14: 0.05291528 | AD14: 0.05291528 | AE14: 70.293133 | AF14: 2.8966402e-15
B15: Interest income | H15: -158 | I15: -254 | J15: -546 | K15: -483 | L15: -368 | R15: 46019 | S15: 112.76 | T15: =S14/S15-1 -> 0.015697056 | V15: 46019 | W15: 22233.8 | X15: =W14/W15-1 -> 0.016097113 | AA15: Residual | AB15: 269 | AC15: 0.20249788 | AD15: 0.00075278021
B16: Interest, net | H16: 1836 | I16: 1874 | J16: 2137 | K16: 2245 | L16: 2431 | R16: 46012 | S16: 111.74 | T16: =S15/S16-1 -> 0.0091283336 | V16: 46012 | W16: 22246.6 | X16: =W15/W16-1 -> -0.00057536882 | AA16: Total | AB16: 270 | AC16: 0.25541316
B17: Loss on extinguishment of debt | H17: 2410 | I17: — | J17: — | K17: — | L17: — | R17: 46005 | S17: 114.36 | T17: =S16/S17-1 -> -0.022910108 | V17: 46005 | W17: 21923.9 | X17: =W16/W17-1 -> 0.014719097
B18: Other (gains) and losses | H18: 3000 | I18: 1538 | J18: 3027 | K18: 794 | L18: -2075 | R18: 45998 | S18: 116.7 | T18: =S17/S18-1 -> -0.020051414 | V18: 45998 | W18: 22004.3 | X18: =W17/W18-1 -> -0.0036538313 | AB18: Coefficients | AC18: Standard Error | AD18: t Stat | AE18: P-value | AF18: Lower 95% | AG18: Upper 95% | AH18: Lower 95.0% | AI18: Upper 95.0%
B19: Income before income taxes | H19: 18696 | I19: 17016 | J19: 21848 | K19: 26309 | L19: 29469 | R19: 45991 | S19: 115.11 | T19: =S18/S19-1 -> 0.013812875 | V19: 45991 | W19: 21810.1 | X19: =W18/W19-1 -> 0.0089041316 | AA19: Intercept | AB19: 0.0026901003 | AC19: 0.0016716337 | AD19: 1.6092643 | AE19: 0.10873147 | AF19: -0.00060104879 | AG19: 0.0059812495 | AH19: -0.00060104879 | AI19: 0.0059812495
B20: Provision for income taxes | H20: 4756 | I20: 5724 | J20: 5578 | K20: 6152 | L20: 7199 | R20: 45984 | S20: 110.51 | T20: =S19/S20-1 -> 0.041625192 | V20: 45984 | W20: 21824.7 | X20: =W19/W20-1 -> -0.00066896681 | AA20: X Variable 1 | AB20: 0.6905058 | AC20: 0.082358965 | AD20: 8.3841 | AE20: 2.8966402e-15 | AF20: 0.52835566 | AG20: 0.85265594 | AH20: 0.52835566 | AI20: 0.85265594
B21: Consolidated net income | H21: 13940 | I21: 11292 | J21: 16270 | K21: 20157 | L21: 22270 | R21: 45977 | S21: 105.32 | T21: =S20/S21-1 -> 0.04927839 | V21: 45977 | W21: 21177 | X21: =W20/W21-1 -> 0.030585069
B22: Consolidated net income attributable to noncontrolling interest | H22: -267 | I22: 388 | J22: -759 | K22: -721 | L22: -377 | R22: 45970 | S22: 102.48 | T22: =S21/S22-1 -> 0.027712724 | V22: 45970 | W22: 21470.3 | X22: =W21/W22-1 -> -0.013660731 | AA22: Beta | AB22: 0.6905058
B23: Consolidated net income attributable to Walmart | H23: 13673 | I23: 11680 | J23: 15511 | K23: 19436 | L23: 21893 | R23: 45963 | S23: 102.59 | T23: =S22/S23-1 -> -0.0010722293 | V23: 45963 | W23: 21408.6 | X23: =W22/W23-1 -> 0.0028820194
R24: 45956 | S24: 101.18 | T24: =S23/S24-1 -> 0.01393556 | V24: 45956 | W24: 21459.6 | X24: =W23/W24-1 -> -0.0023765587
B25: Net income per common share: | R25: 45949 | S25: 106.17 | T25: =S24/S25-1 -> -0.047000094 | V25: 45949 | W25: 21698.1 | X25: =W24/W25-1 -> -0.010991746
B26: Basic net income per common share attributable to Walmart | H26: 4.9 | I26: 4.29 | J26: 1.92 | K26: 2.42 | L26: 2.74 | R26: 45942 | S26: 107.73 | T26: =S25/S26-1 -> -0.014480646 | V26: 45942 | W26: 21411.4 | X26: =W25/W26-1 -> 0.013390063
B27: Diluted net income per common share attributable to Walmart | H27: 4.87 | I27: 4.27 | J27: 1.91 | K27: 2.41 | L27: 2.73 | R27: 45935 | S27: 101.84 | T27: =S26/S27-1 -> 0.057835821 | V27: 45935 | W27: 21096.9 | X27: =W26/W27-1 -> 0.014907403
R28: 45928 | S28: 102.07 | T28: =S27/S28-1 -> -0.0022533555 | V28: 45928 | W28: 21725.4 | X28: =W27/W28-1 -> -0.028929272
B29: Weighted-average common shares outstanding: | R29: 45921 | S29: 103.16 | T29: =S28/S29-1 -> -0.010566111 | V29: 45921 | W29: 21477.5 | X29: =W28/W29-1 -> 0.011542312
B30: Basic | H30: 2792 | I30: 2724 | J30: 8077 | K30: 8041 | L30: 7983 | R30: 45914 | S30: 102.33 | T30: =S29/S30-1 -> 0.0081110134 | V30: 45914 | W30: 21494 | X30: =W29/W30-1 -> -0.00076765609
B31: Diluted | H31: 2805 | I31: 2734 | J31: 8108 | K31: 8081 | L31: 8022 | R31: 45907 | S31: 103.49 | T31: =S30/S31-1 -> -0.011208812 | V31: 45907 | W31: 21374.3 | X31: =W30/W31-1 -> 0.0056001834
R32: 45900 | S32: 100.51 | T32: =S31/S32-1 -> 0.029648791 | V32: 45900 | W32: 21136 | X32: =W31/W32-1 -> 0.011274603
B33: Dividends declared per common share | H33: 2.2 | I33: 2.24 | J33: 0.76 | K33: 0.83 | L33: 0.94 | R33: 45893 | S33: 96.98 | T33: =S32/S33-1 -> 0.036399258 | V33: 45893 | W33: 21151.5 | X33: =W32/W33-1 -> -0.00073280855
R34: 45886 | S34: 96.83 | T34: =S33/S34-1 -> 0.0015491067 | V34: 45886 | W34: 21150.1 | X34: =W33/W34-1 -> 6.619354e-05
B35: Revenue Break Down | H35: 2022 | I35: 2023 | J35: 2024 | K35: 2025 | L35: 2026 | R35: 45879 | S35: 100 | T35: =S34/S35-1 -> -0.0317 | V35: 45879 | W35: 20802.7 | X35: =W34/W35-1 -> 0.016699755
R36: 45872 | S36: 103.73 | T36: =S35/S36-1 -> -0.035958739 | V36: 45872 | W36: 20524.2 | X36: =W35/W36-1 -> 0.013569347
B37: Walmart U.S. Segment | R37: 45865 | S37: 98.49 | T37: =S36/S37-1 -> 0.053203371 | V37: 45865 | W37: 20267.7 | X37: =W36/W37-1 -> 0.012655605
B38: Sales | H38: 393247 | I38: 420553 | J38: 441817 | K38: 462415 | L38: 482975 | R38: 45858 | S38: 97.47 | T38: =S37/S38-1 -> 0.010464758 | V38: 45858 | W38: 20950.4 | X38: =W37/W38-1 -> -0.03258649
B39: Membership | H39: 1924.398 | I39: 2084.7645 | J39: 1985 | K39: 2594 | L39: 2624 | N39: Membership | P39: =AVERAGE(J39:L39)/AVERAGE(J$71:L$71) -> 0.38549639 | R39: 45851 | S39: 95.05 | T39: =S38/S39-1 -> 0.025460284 | V39: 45851 | W39: 20541.6 | X39: =W38/W39-1 -> 0.019901079
B40: Total Revenue | H40: 395171.4 | I40: 422637.76 | J40: 443802 | K40: 465009 | L40: 485599 | R40: 45844 | S40: 94.4 | T40: =S39/S40-1 -> 0.0068855932 | V40: 45844 | W40: 20547.7 | X40: =W39/W40-1 -> -0.00029687021
R41: 45837 | S41: 98.36 | T41: =S40/S41-1 -> -0.040260268 | V41: 45837 | W41: 20725.8 | X41: =W40/W41-1 -> -0.0085931544
...
